Workbook

Sheet Intro
E2: Reference Model
E4: Bharti Airtel
E5: Prepared By: Amod Pawar
D6: Year | E6: 2017
E13: http://proschoolonline.com
E14: Email ID : mumbai@proschoolonline.com
E16: Mumbai
E18: IMS Proschool Pvt Ltd,
E19: Maharashtra High School Complex,
E20: Principal N.M Kale Marg, Off Gokhale Rd,
E21: Dadar (W), Mumbai 400028
E22: Tel. No. : 022-65285393/94
E23: +91 9372895050

Sheet IS
F1: 37346 | G1: =EOMONTH(F1,12) | H1: =EOMONTH(G1,12) | I1: =EOMONTH(H1,12) | J1: =EOMONTH(I1,12) | K1: =EOMONTH(J1,12) | L1: =EOMONTH(K1,12) | M1: =EOMONTH(L1,12) | N1: =EOMONTH(M1,12) | ... Z1: =EOMONTH(Y1,12)
F2: Rs/Millions | G2: Rs/Millions | H2: Rs/Millions | I2: Rs/Millions | J2: Rs/Millions | K2: Rs/Millions | L2: Rs/Millions | M2: Rs/Millions | N2: Rs/Millions | O2: Rs/Millions | P2: Rs/Millions | Q2: Rs/Millions | R2: Rs/Millions | S2: Rs/Millions | T2: Rs/Millions | U2: Rs/Millions | V2: Rs/Millions | W2: Rs/Millions | X2: Rs/Millions | Y2: Rs/Millions | Z2: Rs/Millions
A3: Income
B4: Revenue from Operations | F4: 14664 | G4: 29876 | H4: 49308 | I4: 80077 | J4: 115393 | K4: 183492 | L4: 268728 | M4: 372328 | N4: 418472 | O4: 595383 | P4: 714508 | Q4: 769045 | R4: 857461 | S4: 920394 | T4: 965321 | U4: 954683 | V4: ='REVENUE METRIX'!U17 | W4: ='REVENUE METRIX'!V17 | X4: ='REVENUE METRIX'!W17 | Y4: ='REVENUE METRIX'!X17 | Z4: ='REVENUE METRIX'!Y17
B5: Other Income | F5: 377 | G5: 678 | H5: 1062 | I5: 1481 | J5: 1862 | K5: 710 | L5: 1394 | M5: 1192 | N5: 697 | O5: 635 | P5: 550 | Q5: 425 | R5: 1174 | S5: 957 | T5: 871 | U5: 1206 | V5: ='COST METRIX'!U5 | W5: ='COST METRIX'!V5 | X5: ='COST METRIX'!W5 | Y5: ='COST METRIX'!X5 | Z5: ='COST METRIX'!Y5
F6: =F4+F5 | G6: =G4+G5 | H6: =H4+H5 | I6: =I4+I5 | J6: =J4+J5 | K6: =K4+K5 | L6: =L4+L5 | M6: =M4+M5 | ... Z6: =Z4+Z5
A7: Expenses
B8: Network operating expenses | F8: 1344 | G8: 3101 | H8: 4347 | I8: 7103 | J8: 12126 | K8: 20342 | L8: 32430 | M8: 62328 | N8: 89316 | O8: 127163 | P8: 157598 | Q8: 173333 | R8: 197202 | S8: 203372 | T8: 201567 | U8: 209154 | V8: ='COST METRIX'!U7 | W8: ='COST METRIX'!V7 | X8: ='COST METRIX'!W7 | Y8: ='COST METRIX'!X7 | Z8: ='COST METRIX'!Y7
B9: Access charges | F9: 2781 | G9: 6385 | H9: 11437 | I9: 16893 | J9: 21795 | K9: 31378 | L9: 41111 | M9: 52909 | N9: 44806 | O9: 74718 | P9: 97361 | Q9: 113227 | R9: 111923 | S9: 112759 | T9: 109423 | U9: 102786 | V9: ='COST METRIX'!U8 | W9: ='COST METRIX'!V8 | X9: ='COST METRIX'!W8 | Y9: ='COST METRIX'!X8 | Z9: ='COST METRIX'!Y8
B10: License fee / spectrum charges (revenue share) | F10: 2008 | G10: 3393 | H10: 5561 | I10: 7789 | J10: 11137 | K10: 16953 | L10: 26900 | M10: 38270 | N10: 40875 | O10: 52600 | P10: 61099 | Q10: 66486 | R10: 75971 | S10: 87391 | T10: 94928 | U10: 92760 | V10: ='COST METRIX'!U9 | W10: ='COST METRIX'!V9 | X10: ='COST METRIX'!W9 | Y10: ='COST METRIX'!X9 | Z10: ='COST METRIX'!Y9
B11: Employee benefit cost | F11: 1273 | G11: 2754 | H11: 3721 | I11: 5194 | J11: 8005 | K11: 12012 | L11: 14392 | M11: 17023 | N11: 19028 | O11: 32784 | P11: 35159 | Q11: 38823 | R11: 46228 | S11: 47123 | T11: 49108 | U11: 43032 | V11: ='COST METRIX'!U10 | W11: ='COST METRIX'!V10 | X11: ='COST METRIX'!W10 | Y11: ='COST METRIX'!X10 | Z11: ='COST METRIX'!Y10
B12: sales and marketing expenses | F12: 1943 | G12: 3171 | H12: 3873 | I12: 6588 | J12: 8336 | K12: 11387 | L12: 19350 | M12: 24611 | N12: 56814 | O12: 107743 | P12: 126310 | Q12: 144632 | R12: 147979 | S12: 155533 | T12: 82410 | U12: 71400 | V12: ='COST METRIX'!U11 | W12: ='COST METRIX'!V11 | X12: ='COST METRIX'!W11 | Y12: ='COST METRIX'!X11 | Z12: ='COST METRIX'!Y11
B13: Total Opex | F13: =SUM(F8:F12) | G13: =SUM(G8:G12) | H13: =SUM(H8:H12) | I13: =SUM(I8:I12) | J13: =SUM(J8:J12) | K13: =SUM(K8:K12) | L13: =SUM(L8:L12) | M13: =SUM(M8:M12) | ... Z13: =SUM(Z8:Z12)
B15: Gross Profit | F15: =F6-F13 | G15: =G6-G13 | H15: =H6-H13 | I15: =I6-I13 | J15: =J6-J13 | K15: =K6-K13 | L15: =L6-L13 | M15: =M6-M13 | ... Z15: =Z6-Z13
B17: Other expenses | F17: 1896 | G17: 4129 | H17: 4376 | I17: 7332 | J17: 13606 | K17: 17723 | L17: 21922 | M17: 25521 | P17: 408 | Q17: 390 | R17: 902 | S17: 1290 | T17: 88043 | U17: 82253 | V17: ='COST METRIX'!U14 | W17: ='COST METRIX'!V14 | X17: ='COST METRIX'!W14 | Y17: ='COST METRIX'!X14 | Z17: ='COST METRIX'!Y14
B19: EBITDA | F19: =F15-F17 | G19: =G15-G17 | H19: =H15-H17 | I19: =I15-I17 | J19: =J15-J17 | K19: =K15-K17 | L19: =L15-L17 | M19: =M15-M17 | ... Z19: =Z15-Z17
B21: Depreciation and amortisation | F21: 3692 | G21: 6575 | H21: 8794 | I21: 11882 | J21: 16420 | K21: 26191 | L21: 38102 | M21: 49639 | N21: 62832 | O21: 102066 | P21: 133681 | Q21: 148148 | R21: 156496 | S21: 155311 | T21: 174498 | U21: 197730 | V21: =Schedule!U14 | W21: =Schedule!V14 | X21: =Schedule!W14 | Y21: =Schedule!X14 | Z21: =Schedule!Y14
B22: EBIT | F22: =F19-F21 | G22: =G19-G21 | H22: =H19-H21 | I22: =I19-I21 | J22: =J19-J21 | K22: =K19-K21 | L22: =L19-L21 | M22: =M19-M21 | ... Z22: =Z19-Z21
B24: Finance costs | F24: 1087 | G24: 2730 | H24: 2693 | I24: 2440 | J24: 2244 | K24: 2488 | L24: 5279 | M24: 18613 | N24: 17559 | O24: 25349 | P24: 40828 | Q24: 45187 | R24: 58788 | S24: 73252 | T24: 85461 | U24: 95466 | V24: ='Debt Schedule'!T24 | W24: ='Debt Schedule'!U24 | X24: ='Debt Schedule'!V24 | Y24: ='Debt Schedule'!W24 | Z24: ='Debt Schedule'!X24
B25: Finance income | K25: -1119 | L25: -2796 | M25: -1524 | N25: -17381 | O25: -3536 | P25: -2643 | Q25: -5103 | R25: -10408 | S25: -24788 | T25: -16326 | U25: -18492 | V25: ='COST METRIX'!U17 | W25: ='COST METRIX'!V17 | X25: ='COST METRIX'!W17 | Y25: ='COST METRIX'!X17 | Z25: ='COST METRIX'!Y17
B26: EBT | F26: =F22-SUM(F24:F25) | G26: =G22-SUM(G24:G25) | H26: =H22-SUM(H24:H25) | I26: =I22-SUM(I24:I25) | J26: =J22-SUM(J24:J25) | K26: =K22-SUM(K24:K25) | L26: =L22-SUM(L24:L25) | M26: =M22-SUM(M24:M25) | ... Z26: =Z22-SUM(Z24:Z25)
B28: Non-operating expenses(net) | F28: 972 | G28: 371 | H28: 41 | I28: 506 | J28: 132 | K28: 63 | L28: 317 | M28: 220 | N28: 181 | O28: 292 | R28: 660 | S28: 1669 | T28: 1024 | U28: 1319 | V28: ='COST METRIX'!U18 | W28: ='COST METRIX'!V18 | X28: ='COST METRIX'!W18 | Y28: ='COST METRIX'!X18 | Z28: ='COST METRIX'!Y18
B29: Exceptional Items (note 7) | G29: -293 | R29: -538 | S29: 8532 | T29: -21741 | U29: 11697
B30: PBT | F30: =F26-SUM(F28:F29) | G30: =G26-SUM(G28:G29) | H30: =H26-SUM(H28:H29) | I30: =I26-SUM(I28:I29) | J30: =J26-SUM(J28:J29) | K30: =K26-SUM(K28:K29) | L30: =L26-SUM(L28:L29) | M30: =M26-SUM(M28:M29) | ... Z30: =Z26-SUM(Z28:Z29)
A32: Tax expenses (Note 7)
B33: Current tax | F33: 84 | G33: 2 | H33: 1057 | I33: 131 | J33: 1971 | K33: 5609 | L33: 9756 | M33: 10808 | N33: 22319 | O33: 23961 | P33: 26776 | Q33: 27927 | R33: 41270 | S33: 57877 | T33: 44690 | U33: 21240 | V33: =V30*'COST METRIX'!U40 | W33: =W30*'COST METRIX'!V40 | X33: =X30*'COST METRIX'!W40 | Y33: =Y30*'COST METRIX'!X40 | Z33: =Z30*'COST METRIX'!Y40
B34: Deferred tax | F34: -321 | H34: -1379 | I34: 3464 | J34: 937 | K34: 72 | L34: -1595 | M34: -5340 | N34: -8866 | O34: -6171 | P34: -4174 | Q34: -2743 | R34: 7179 | S34: -3830 | T34: 14843 | U34: 13579
B35: PAT | F35: =F30-SUM(F33:F34) | G35: =G30-SUM(G33:G34) | H35: =H30-SUM(H33:H34) | I35: =I30-SUM(I33:I34) | J35: =J30-SUM(J33:J34) | K35: =K30-SUM(K33:K34) | L35: =L30-SUM(L33:L34) | M35: =M30-SUM(M33:M34) | ... Z35: =Z30-SUM(Z33:Z34)
B37: Less: Minority Interest | F37: 86 | G37: 286 | H37: 12 | I37: 121 | J37: 267 | K37: 482 | L37: 1000 | M37: 1852 | N37: 1870 | O37: -1475 | P37: -13 | Q37: -88 | R37: 2467 | S37: 1248 | T37: 8163 | U37: 4416 | V37: ='COST METRIX'!U20 | W37: ='COST METRIX'!V20 | X37: ='COST METRIX'!W20 | Y37: ='COST METRIX'!X20 | Z37: ='COST METRIX'!Y20
B38: Add: Associate profit/loss | N38: 48 | O38: 57 | P38: 74 | Q38: -3506 | R38: -5211 | S38: -7223 | T38: -10666 | U38: -10449 | V38: =U38 | W38: =V38 | X38: =W38 | Y38: =X38 | Z38: =Y38
B39: Net Income | F39: =F35-SUM(F37:F38) | G39: =G35-SUM(G37:G38) | H39: =H35-SUM(H37:H38) | I39: =I35-SUM(I37:I38) | J39: =J35-SUM(J37:J38) | K39: =K35-SUM(K37:K38) | L39: =L35-SUM(L37:L38) | M39: =M35-SUM(M37:M38) | ... Z39: =Z35-SUM(Z37:Z38)
B41: Weighted average shares outstanding for basic EPS | F41: 1706 | G41: 1853 | H41: 1853 | I41: 1856 | J41: 1882 | K41: 1895 | L41: 1897 | M41: 3796 | N41: 3796 | O41: 3795 | P41: 3795 | Q41: 3794 | R41: 3952 | S41: 3996 | T41: 3996 | U41: 3996 | V41: 3996 | W41: 3996 | X41: 3996 | Y41: 3996 | Z41: 3996
B42: Weighted average shares outstanding for diluted EPS | F42: 1706 | G42: 1853 | H42: 1853 | I42: 1893 | J42: 1897 | K42: 1897 | L42: 1899 | M42: 3797 | N42: 3797 | O42: 3795 | P42: 3796 | Q42: 3796 | R42: 3955 | S42: 3998 | T42: 3996 | U42: 3997 | V42: 3997 | W42: 3997 | X42: 3997 | Y42: 3997 | Z42: 3997
A45: Other comprehensive income
B46: Items to be reclassfied subsequently to profit or loss
B47: Net (losses) / gains due to foreign currency translation differences | N47: -1028 | O47: 12681 | P47: -20410 | Q47: -25669 | R47: 15716 | S47: -69186 | T47: -4920 | U47: -41423
B48: Net gains / (losses) on net investments hedge | S48: 32925 | T48: -7108 | U48: -10330
B49: Net gains on cash flow hedge | S49: -5350 | T49: -724 | U49: 857
B50: Net gain / ( losses) on fair value through OCI investments | T50: 9 | U50: 107
B51: Income tax (Charge) / credit | R51: -150 | T51: 503 | U51: -16
...

Sheet BS
I1: 37346 | J1: 37711 | K1: 38077 | L1: 38442 | M1: 38807 | N1: 39172 | O1: 39538 | P1: 39903 | Q1: 40268 | R1: 40633 | S1: 40999 | T1: 41364 | U1: 41729 | V1: 42094 | W1: 42460 | X1: 42825 | Y1: 43190 | Z1: 43555 | AA1: 43921 | AB1: 44286 | AC1: 44651
I2: Rs/Millions | J2: Rs/Millions | K2: Rs/Millions | L2: Rs/Millions | M2: Rs/Millions | N2: Rs/Millions | O2: Rs/Millions | P2: Rs/Millions | Q2: Rs/Millions | R2: Rs/Millions | S2: Rs/Millions | T2: Rs/Millions | U2: Rs/Millions | V2: Rs/Millions | W2: Rs/Millions | X2: Rs/Millions | Y2: Rs/Millions | Z2: Rs/Millions | AA2: Rs/Millions | AB2: Rs/Millions | AC2: Rs/Millions
A3: Assets
B4: Non-current assets
C5: Property,plant and equipment | I5: =35739-I7 | J5: =52675-J7 | K5: 86077 | L5: =103825-L7-L8 | M5: =138186-M7-M8 | N5: =205044-N7-N8 | O5: =325494-O7-O8 | P5: =439486-P7-P8 | Q5: 482629 | R5: 651426 | S5: 674932 | T5: 638277 | U5: 596429 | V5: 579157 | W5: 610508 | X5: 620088 | Y5: =Schedule!U6 | Z5: =Schedule!V6 | AA5: =Schedule!W6 | AB5: =Schedule!X6 | AC5: =Schedule!Y6
C6: Capital work-in-progress | I6: 13799 | J6: 5306 | K6: 4531 | L6: 10167 | M6: 24365 | N6: 24709 | O6: 35700 | P6: 41436 | V6: 48702 | W6: 47304 | X6: 23942 | Y6: =Schedule!U8 | Z6: =Schedule!V8 | AA6: =Schedule!W8 | AB6: =Schedule!X8 | AC6: =Schedule!Y8
C7: Goodwill | I7: 4755 | J7: 8025 | L7: 2927 | M7: 2685 | N7: 2417 | O7: 7277 | P7: 35789 | Q7: 42240 | R7: 388050 | S7: 407560 | T7: 413598 | U7: 469136 | V7: 414823 | W7: 428381 | X7: 338082 | Y7: =Schedule!U9 | Z7: =Schedule!V9 | AA7: =Schedule!W9 | AB7: =Schedule!X9 | AC7: =Schedule!Y9
C8: Other intangible assets | I8: 0 | J8: 0 | L8: =32+1833+15941 | M8: =12+1955+14736 | N8: =5026+13527 | O8: =6432+12688 | P8: =49798-P7 | Q8: =59890-Q7 | R8: =637317-R7 | S8: =660889-S7 | T8: =648386-T7 | U8: 340580 | V8: =922283-V7-V9-V6 | W8: 684039 | X8: 824181 | Y8: =Schedule!U10 | Z8: =Schedule!V10 | AA8: =Schedule!W10 | AB8: =Schedule!X10 | AC8: =Schedule!Y10
C9: Intangible assets under development | V9: 118487 | W9: 9716 | X9: 84443 | Y9: =Schedule!U11 | Z9: =Schedule!V11 | AA9: =Schedule!W11 | AB9: =Schedule!X11 | AC9: =Schedule!Y11
C10: investment injoint ventures and associates | Q10: 57 | S10: 223 | T10: 11552 | U10: 56702 | V10: 46257 | W10: 60990 | X10: 82277 | Y10: =X10 | Z10: =Y10 | AA10: =Z10 | AB10: =AA10 | AC10: =AB10
C11: Financial Assets
D12: Investment | I12: 5083 | J12: 3551 | K12: 3346 | L12: 4781 | M12: 2480 | N12: 1471 | O12: 48097 | P12: 23490 | S12: 0 | T12: 0 | U12: 36341 | V12: 31260 | W12: 28622 | X12: 44187 | Y12: =X12 | Z12: =Y12 | AA12: =Z12 | AB12: =AA12 | AC12: =AB12
D13: Derivative instruments | Q13: 3337 | R13: 1998 | S13: 2756 | T13: 3566 | U13: 2761 | V13: 7303 | W13: 13999 | X13: 4732 | Y13: =X13 | Z13: =Y13 | AA13: =Z13 | AB13: =AA13 | AC13: =AB13
D14: Security Deposits | V14: 9529 | W14: 10441 | X14: 9630 | Y14: =X14 | Z14: =Y14 | AA14: =Z14 | AB14: =AA14 | AC14: =AB14
D15: Others | Q15: 7368 | R15: 7930 | S15: 16887 | V15: =16018-V14 | W15: 17502 | X15: 16653 | Y15: =X15 | Z15: =Y15 | AA15: =Z15 | AB15: =AA15 | AC15: =AB15
C16: Deferred tax assets (net) | I16: 1059 | J16: 1059 | K16: 2438 | L16: 0 | P16: 293 | Q16: 12489 | R16: 45061 | S16: 51277 | T16: 58491 | U16: 62627 | V16: 59502 | W16: 46738 | X16: 26262 | Y16: =X16 | Z16: =Y16-($Y$16-AC16)/5 | AA16: =Z16-($Y$16-AD16)/5 | AB16: =AA16-($Y$16-AE16)/5 | AC16: 10000
C17: Other non-current assets | Q17: 7485 | R17: 9255 | S17: 15568 | T17: 35075 | U17: 43339 | V17: 28383 | W17: 70440 | X17: 49875 | Y17: =X17 | Z17: =Y17 | AA17: =Z17 | AB17: =AA17 | AC17: =AB17
I18: =SUM(I5:I17) | J18: =SUM(J5:J17) | K18: =SUM(K5:K17) | L18: =SUM(L5:L17) | M18: =SUM(M5:M17) | N18: =SUM(N5:N17) | O18: =SUM(O5:O17) | P18: =SUM(P5:P17) | ... AC18: =SUM(AC5:AC17)
B19: Current Assets
C20: inventories | I20: 87 | J20: 209 | K20: 317 | L20: 545 | M20: 381 | N20: 912 | O20: 1142 | P20: 962 | Q20: 484 | R20: 2139 | S20: 1308 | T20: 1109 | U20: 1422 | V20: 1339 | W20: 1692 | X20: 488 | Y20: =X20 | Z20: =Y20 | AA20: =Z20 | AB20: =AA20 | AC20: =AB20
C21: Financial Assets
D22: Investment | Q22: 52264 | R22: 6224 | S22: 18132 | T22: 65546 | U22: 62265 | V22: 92840 | W22: 16159 | X22: 16923 | Y22: =X22 | Z22: =Y22 | AA22: =Z22 | AB22: =AA22 | AC22: =AB22
D23: Derivative instruments | Q23: 144 | R23: 2682 | S23: 2137 | T23: 1097 | U23: 819 | V23: 1207 | W23: 4765 | X23: 2060 | Y23: =X23 | Z23: =Y23 | AA23: =Z23 | AB23: =AA23 | AC23: =AB23
D24: Trade receivables | I24: 1168 | J24: 3698 | K24: 5310 | L24: 7415 | M24: 11140 | N24: 18712 | O24: 28399 | P24: 28998 | Q24: 35711 | R24: 54929 | S24: 63735 | T24: 67824 | U24: 62441 | V24: 67252 | W24: 55039 | X24: 49838 | Y24: =(Y77*IS!V4*2/365)-BS!X24 | Z24: =(Z77*IS!W4*2/365)-BS!Y24 | AA24: =(AA77*IS!X4*2/365)-BS!Z24 | AB24: =(AB77*IS!Y4*2/365)-BS!AA24 | AC24: =(AC77*IS!Z4*2/365)-BS!AB24
D25: Cash and cash equivalents | I25: =967-I26 | J25: =888-J26 | K25: =1354-K26 | L25: =4098-L26 | M25: =3511-M26 | N25: =8521-N26 | O25: =7034-O26 | P25: 27660 | Q25: =25323-Q26 | R25: 8839 | S25: =20300-S26 | T25: 14285 | U25: 44505 | V25: =11719-V26 | W25: 37087 | X25: 12817 | Y25: =CF!R63 | Z25: =CF!S63 | AA25: =CF!T63 | AB25: =CF!U63 | AC25: =CF!V63
D26: Bank deposits | I26: 419 | J26: 177 | K26: 54 | L26: 2031 | M26: 1355 | N26: 5836 | O26: 4562 | P26: 0 | Q26: 15381 | R26: 736 | S26: 8719 | T26: 1793 | U26: 5303 | V26: 8823 | W26: 13900 | X26: 3360 | Y26: 13360 | Z26: =Y26 | AA26: =Z26 | AB26: =AA26 | AC26: =AB26
D27: Others | P27: 1553 | Q27: 98 | R27: 744 | S27: 802 | T27: 4299 | U27: 8127 | V27: 10075 | W27: 32511 | X27: 52105 | Y27: =X27 | Z27: =Y27 | AA27: =Z27 | AB27: =AA27 | AC27: =AB27
C28: Current tax assets | P28: 0 | Q28: 2826 | R28: 5280 | S28: 9049 | T28: 10093 | U28: 9319 | V28: 5750 | W28: 11570 | X28: 21454 | Y28: =X28 | Z28: =Y28 | AA28: =Z28 | AB28: =AA28 | AC28: =AB28
C29: Other current assets | I29: =243+16289+7017+334 | J29: =189+16829+7220 | K29: =7984+6+75 | L29: =10820+583 | M29: =15089+79 | N29: =17257+27 | O29: =28491+2 | P29: 60535 | Q29: 20835 | R29: 30504 | S29: 32621 | T29: 30860 | U29: 29656 | V29: 31828 | W29: 48827 | X29: 44105 | Y29: =X29 | Z29: =Y29 | AA29: =Z29 | AB29: =AA29 | AC29: =AB29
C30: Assets-held-for-sale | S30: 0 | U30: 0 | V30: 45645 | W30: 7002
I31: =SUM(I20:I30) | J31: =SUM(J20:J30) | K31: =SUM(K20:K30) | L31: =SUM(L20:L30) | M31: =SUM(M20:M30) | N31: =SUM(N20:N30) | O31: =SUM(O20:O30) | P31: =SUM(P20:P30) | ... AC31: =SUM(AC20:AC30)
A33: Total Assets | I33: =I18+I31 | J33: =J18+J31 | K33: =K18+K31 | L33: =L18+L31 | M33: =M18+M31 | N33: =N18+N31 | O33: =O18+O31 | P33: =P18+P31 | ... AC33: =AC18+AC31
A35: Equities and liabilities
B36: Equity
C37: Share Capital | I37: 18534 | J37: 18534 | K37: 18534 | L37: 18561 | M37: 18939 | N37: 18959 | O37: 18979 | P37: 18982 | Q37: 18988 | R37: 18988 | S37: 18988 | T37: 18988 | U37: 19987 | V37: 19987 | W37: 19987 | X37: 19987 | Y37: 19987 | Z37: 19987 | AA37: 19987 | AB37: 19987 | AC37: 19987
C38: Other Equity | I38: =29706-3567 | J38: =29728-11700 | K38: =30613-6748 | L38: =34639-7854 | M38: 54685 | N38: 95924 | O38: 198264 | P38: 272297 | Q38: 402952 | R38: 468680 | S38: 487125 | T38: 484229 | U38: =U39-U37 | V38: 599577 | W38: 647706 | X38: 654576 | Y38: =X38+IS!V35-Schedule!U22 | Z38: =Y38+IS!W35-Schedule!V22 | AA38: =Z38+IS!X35-Schedule!W22 | AB38: =AA38+IS!Y35-Schedule!X22 | AC38: =AB38+IS!Z35-Schedule!Y22
B39: Equity attributable to equity holders of the parent | I39: =SUM(I37:I38) | J39: =SUM(J37:J38) | K39: =SUM(K37:K38) | L39: =SUM(L37:L38) | M39: =SUM(M37:M38) | N39: =SUM(N37:N38) | O39: =SUM(O37:O38) | P39: =SUM(P37:P38) | ... T39: =SUM(T37:T38) | U39: 597560 | V39: =SUM(V37:V38) | W39: =SUM(W37:W38) | X39: =SUM(X37:X38) | Y39: =SUM(Y37:Y38) | Z39: =SUM(Z37:Z38) | AA39: =SUM(AA37:AA38) | AB39: =SUM(AB37:AB38) | AC39: =SUM(AC37:AC38)
C40: Non controlling Interest | I40: 1240 | J40: 921 | K40: 104 | L40: 925 | M40: 1091 | N40: 1948 | O40: 10142 | P40: 12297 | Q40: 25285 | R40: 28563 | S40: 27695 | T40: 40886 | U40: 42102 | V40: 48525 | W40: 54981 | X40: 68750 | Y40: =X40 | Z40: =Y40 | AA40: =Z40 | AB40: =AA40 | AC40: =AB40
I41: =I39+I40 | J41: =J39+J40 | K41: =K39+K40 | L41: =L39+L40 | M41: =M39+M40 | N41: =N39+N40 | O41: =O39+O40 | P41: =P39+P40 | ... AC41: =AC39+AC40
B42: Non current liabilities
...

Sheet CF
A1: Partlculars | B1: March 31,2002 | C1: March 31,2003 | D1: March 31,2004 | E1: March 31,2005 | F1: March 31,2006 | G1: March 31,2007 | H1: March 31,2008 | I1: March 31,2009 | J1: March 31,2010 | K1: March 31,2011 | L1: March 31,2012 | M1: March 31,2013 | N1: March 31,2014 | O1: March 31,2015 | P1: March 31,2016 | Q1: March 31,2017 | R1: March 31,2018 | S1: March 31,2019 | T1: March 31,2020 | U1: March 31,2021 | V1: March 31,2022
B2: Rs/Millions | C2: Rs/Millions | D2: Rs/Millions | E2: Rs/Millions | F2: Rs/Millions | G2: Rs/Millions | H2: Rs/Millions | I2: Rs/Millions | J2: Rs/Millions | K2: Rs/Millions | L2: Rs/Millions | M2: Rs/Millions | N2: Rs/Millions | O2: Rs/Millions | P2: Rs/Millions | Q2: Rs/Millions | R2: Rs/Millions | S2: Rs/Millions | T2: Rs/Millions | U2: Rs/Millions | V2: Rs/Millions
A3: Cash flows from operating activities
A4: Profit before tax | B4: =IS!F30 | C4: =IS!G30 | D4: =IS!H30 | E4: =IS!I30 | F4: =IS!J30 | G4: =IS!K30 | H4: =IS!L30 | I4: =IS!M30 | ... V4: =IS!Z30
A5: Adjustments for:
A6: Depreciation and amortisation | B6: =IS!F21-B11 | C6: =IS!G21-C11 | D6: =IS!H21-D11 | E6: =IS!I21-E11 | F6: =IS!J21-F11 | G6: =IS!K21-G11 | H6: =IS!L21-H11 | I6: =IS!M21-I11 | ... Q6: =IS!U21-Q11 | R6: =Schedule!U14 | S6: =Schedule!V14 | T6: =Schedule!W14 | U6: =Schedule!X14 | V6: =Schedule!Y14
A7: Finance costs | B7: =IS!F24 | C7: =IS!G24 | D7: =IS!H24 | E7: =IS!I24 | F7: =IS!J24 | G7: =IS!K24 | H7: =IS!L24 | I7: =IS!M24 | ... V7: =IS!Z24
A8: Finance Income | B8: =IS!F25 | C8: =IS!G25 | D8: =IS!H25 | E8: =IS!I25 | F8: =IS!J25 | G8: =IS!K25 | H8: =IS!L25 | I8: =IS!M25 | ... V8: =IS!Z25
A9: Share of results of joint ventures and associates
A10: Exceptional items | M10: - | N10: -2481 | O10: 1941 | P10: -31321 | Q10: -276
A11: Employee share-based payment expense | B11: 96 | C11: 115 | D11: 71 | E11: 47 | F11: 127 | G11: 227 | H11: 337 | I11: 895 | J11: 1494 | K11: 1561 | L11: 783 | M11: 403 | N11: 8 | O11: -4 | P11: 248 | Q11: 338
A12: Other non-cash items | B12: 1221 | C12: 1307 | D12: 910 | E12: 1654 | F12: 4748 | G12: 4778 | H12: 4474 | I12: 4695 | J12: 1923 | K12: 2041 | L12: 2317 | M12: 739 | N12: -781 | O12: -49 | P12: 105 | Q12: 603
A13: Operating cash flow before changes In working capital | B13: =B4+SUM(B6:B12) | C13: =C4+SUM(C6:C12) | D13: =D4+SUM(D6:D12) | E13: =E4+SUM(E6:E12) | F13: =F4+SUM(F6:F12) | G13: =G4+SUM(G6:G12) | H13: =H4+SUM(H6:H12) | I13: =I4+SUM(I6:I12) | ... V13: =V4+SUM(V6:V12)
A14: Changes In working capital
A15: Trade receivables | B15: =-1261-4255 | C15: =-4073-1050 | D15: =-2594-831 | E15: =-3250-2920 | F15: =-5748-5885 | G15: =-5509-8760 | H15: -23204 | I15: -29634 | J15: 11666 | K15: -9207 | L15: -14094 | M15: -3823 | N15: 2072 | O15: -11144 | P15: 12656 | Q15: 13001 | R15: =BS!X24-BS!Y24 | S15: =BS!Y24-BS!Z24 | T15: =BS!Z24-BS!AA24 | U15: =BS!AA24-BS!AB24 | V15: =BS!AB24-BS!AC24
A16: Trade payables | B16: 5346 | C16: 1459 | D16: 5395 | E16: =11077 | F16: 16312 | G16: 25178 | H16: 37868 | I16: 22594 | J16: 648 | K16: 16987 | L16: 23961 | M16: 24055 | N16: 16818 | O16: -2 | P16: -3504 | Q16: 9633 | R16: =BS!Y57-BS!X57 | S16: =BS!Z57-BS!Y57 | T16: =BS!AA57-BS!Z57 | U16: =BS!AB57-BS!AA57 | V16: =BS!AC57-BS!AB57
A17: Inventories | B17: -52 | C17: -122 | D17: -108 | E17: -203 | F17: 76 | G17: 523 | H17: -273 | I17: -340 | J17: 479 | K17: -211 | L17: 1475 | M17: 268 | N17: -147 | O17: 14203 | P17: -872 | Q17: 948
A18: Provisions | J18: 680 | K18: -160 | L18: 397 | M18: 1093 | N18: 2511 | O18: 1144 | P18: -277 | Q18: -26
A19: Other financial and non financial liabilities | B19: 230 | C19: 577 | J19: 4816 | K19: 4282 | L19: 9505 | M19: 2294 | N19: 10506 | O19: -99 | P19: 9939 | Q19: 3558
A20: Other financial and non financial assets | B20: -1751 | J20: -6062 | K20: -2114 | L20: -6194 | M20: -4253 | N20: -14227 | O20: -5741 | P20: -21897 | Q20: -54543
A21: Net cash generated from operations before tax and dividend | B21: =SUM(B13:B20) | C21: =SUM(C13:C20) | D21: =SUM(D13:D20) | E21: =SUM(E13:E20) | F21: =SUM(F13:F20) | G21: =SUM(G13:G20) | H21: =SUM(H13:H20) | I21: =SUM(I13:I20) | ... O21: =SUM(O13:O20) | P21: 326259 | Q21: =SUM(Q13:Q20) | R21: =SUM(R13:R20) | S21: =SUM(S13:S20) | T21: =SUM(T13:T20) | U21: =SUM(U13:U20) | V21: =SUM(V13:V20)
A22: Dividend received | J22: 0 | K22: 0 | L22: 0 | M22: 4050 | N22: 2200 | O22: 16407 | P22: 0 | Q22: 9510
A23: Income tax paid | B23: -141 | C23: 29 | D23: -948 | E23: -1413 | F23: -2307 | G23: -4845 | H23: -9321 | I23: -12838 | J23: -21961 | K23: -24388 | L23: -29453 | M23: -31294 | N23: -35039 | O23: -46111 | P23: -46836 | Q23: -31587 | R23: =-IS!V33 | S23: =-IS!W33 | T23: =-IS!X33 | U23: =-IS!Y33 | V23: =-IS!Z33
A24: Net cash generated from operating activities (a) | B24: =SUM(B21:B23) | C24: =SUM(C21:C23) | D24: =SUM(D21:D23) | E24: =SUM(E21:E23) | F24: =SUM(F21:F23) | G24: =SUM(G21:G23) | H24: =SUM(H21:H23) | I24: =SUM(I21:I23) | ... V24: =SUM(V21:V23)
A26: Cash flows from Investing activities
A27: Purchase of property, plant and equipment | B27: -8508 | C27: -29054 | D27: -24493 | E27: -27734 | F27: -55343 | G27: -86169 | H27: -136375 | I27: -168590 | J27: -127989 | K27: -109952 | L27: -144436 | M27: -125722 | N27: -114159 | O27: -146411 | P27: -193313 | Q27: -223030 | R27: =-Schedule!U18 | S27: =-Schedule!V18 | T27: =-Schedule!W18 | U27: =-Schedule!X18 | V27: =-Schedule!Y18
A28: Proceeds from sale of property. plant and equipment | B28: 46 | C28: 185 | D28: 188 | E28: 518 | F28: 119 | G28: 1134 | H28: 1607 | I28: 1869 | J28: 6202 | K28: 783 | L28: 1074 | M28: 1403 | N28: 4360 | O28: 2595 | P28: 3798 | Q28: 4462
A29: Purchase of intangible assets | B29: -10407 | D29: -633 | E29: -50 | J29: -2527 | K29: -167925 | L29: -6921 | M29: -5744 | N29: -64860 | O29: -65970 | P29: -81452 | Q29: -165477
A30: Net movement In current investments | B30: -9307 | C30: 8736 | I30: =300-14915 | J30: -13198 | K30: 46590 | L30: -10823 | M30: -47389 | N30: -21998 | O30: -13821 | P30: 63771 | Q30: 5785
A31: Purchase of non-current Investments | B31: -53527 | C31: -22124 | D31: -35679 | E31: -105435 | F31: -69827 | G31: -99247 | H31: -221274 | I31: -393572 | M31: 0 | N31: -8842 | O31: -3078 | P31: -3218 | Q31: -89073
A32: Sale of non-current investments | B32: 53904 | C32: 23908 | D32: 36069 | E32: 104445 | F32: 71943 | G32: 100590 | H32: 175342 | I32: 420787 | N32: - | O32: 5618 | P32: 7642 | Q32: 82557
A33: Investment in subsidiaries,net of cash acquired | B33: =40-14039 | D33: -1354 | E33: =465-753 | F33: =43-122 | G33: =-1044 | H33: 109 | I33: -643 | J33: -1 | K33: -373991 | L33: -24985 | M33: 102 | N33: -6044 | O33: -358 | P33: -135 | Q33: -283
A34: Sale of subsidiaries | H34: 0 | I34: 1186 | L34: 2543 | M34: -385 | N34: -8009 | O34: 1021 | P34: 0 | Q34: 59604
A35: Sale of tower assets | P35: 56821 | Q35: 7120
A36: Investment in associate | H36: -4386 | I36: -181 | J36: -90 | L36: -285 | M36: -9281 | N36: -2 | O36: -10 | P36: 0 | Q36: -250
A37: Proceeds from sale of interest in associate/joint venture | N37: 0 | O37: 87 | P37: 55 | Q37: 447
A38: Loan to joint venture/associate | L38: -172 | M38: -130 | N38: -30179 | O38: -154 | P38: -19 | Q38: 0
A39: Loan repayment received from joint venture/associate | L39: 210 | O39: -9173 | P39: 14 | Q39: 0
A40: Dividend received | M40: 113 | N40: 898 | O40: 480 | P40: 118 | Q40: 279
A41: Interest received | B41: 504 | C41: 16 | D41: 27 | E41: 66 | F41: 202 | G41: 268 | H41: 259 | I41: 1363 | J41: 2038 | K41: 565 | L41: 401 | M41: 1878 | N41: 1688 | O41: 1307 | P41: 3661 | Q41: 2305
...

Sheet Debt Schedule
D1: 37346 | E1: =EOMONTH(D1,12) | F1: =EOMONTH(E1,12) | G1: =EOMONTH(F1,12) | H1: =EOMONTH(G1,12) | I1: =EOMONTH(H1,12) | J1: =EOMONTH(I1,12) | K1: =EOMONTH(J1,12) | L1: =EOMONTH(K1,12) | ... X1: =EOMONTH(W1,12)
D2: Rs/Millions | E2: Rs/Millions | F2: Rs/Millions | G2: Rs/Millions | H2: Rs/Millions | I2: Rs/Millions | J2: Rs/Millions | K2: Rs/Millions | L2: Rs/Millions | M2: Rs/Millions | N2: Rs/Millions | O2: Rs/Millions | P2: Rs/Millions | Q2: Rs/Millions | R2: Rs/Millions | S2: Rs/Millions | T2: Rs/Millions | U2: Rs/Millions | V2: Rs/Millions | W2: Rs/Millions | X2: Rs/Millions
A4: Cash BOP | D4: =CF!B62 | E4: =CF!C62 | F4: =CF!D62 | G4: =CF!E62 | H4: =CF!F62 | I4: =CF!G62 | J4: =CF!H62 | K4: =CF!I62 | ... X4: =CF!V62
A5: Cash Flow Before Financing (CFO+CFI WITHOUT INV) | D5: =SUM(CF!B24,CF!B27:B29,CF!B32:B41) | E5: =SUM(CF!C24,CF!C27:C29,CF!C32:C41) | F5: =SUM(CF!D24,CF!D27:D29,CF!D32:D41) | G5: =SUM(CF!E24,CF!E27:E29,CF!E32:E41) | H5: =SUM(CF!F24,CF!F27:F29,CF!F32:F41) | I5: =SUM(CF!G24,CF!G27:G29,CF!G32:G41) | J5: =SUM(CF!H24,CF!H27:H29,CF!H32:H41) | K5: =SUM(CF!I24,CF!I27:I29,CF!I32:I41) | ... X5: =SUM(CF!V24,CF!V27:V29,CF!V32:V41)
A6: Cash For other financing items | D6: =SUM(CF!B46,CF!B50:B58) | E6: =SUM(CF!C46,CF!C50:C58) | F6: =SUM(CF!D46,CF!D50:D58) | G6: =SUM(CF!E46,CF!E50:E58) | H6: =SUM(CF!F46,CF!F50:F58) | I6: =SUM(CF!G46,CF!G50:G58) | J6: =SUM(CF!H46,CF!H50:H58) | K6: =SUM(CF!I46,CF!I50:I58) | ... X6: =SUM(CF!V46,CF!V50:V58)
A7: Minimum Cash | C7: 1000 | D7: =-C7 | E7: =D7 | F7: =E7 | G7: =F7 | H7: =G7 | I7: =H7 | J7: =I7 | K7: =J7 | L7: =K7 | ... X7: =W7
A8: Cash Available for debt repayment | D8: =SUM(D4:D7) | E8: =SUM(E4:E7) | F8: =SUM(F4:F7) | G8: =SUM(G4:G7) | H8: =SUM(H4:H7) | I8: =SUM(I4:I7) | J8: =SUM(J4:J7) | K8: =SUM(K4:K7) | ... X8: =SUM(X4:X7)
A11: Repayment of Debt | D11: =CF!B48 | E11: =-CF!C48 | F11: =-CF!D48 | G11: =-CF!E48 | H11: =-CF!F48 | I11: =-CF!G48 | J11: =-CF!H48 | K11: =-CF!I48 | L11: =-CF!J48 | ... S11: =-CF!Q48 | T11: 212031 | U11: 175984 | V11: 187710 | W11: 189236 | X11: 237954
A13: New Borrowings | T13: =T11-T8 | U13: =U11-U8 | V13: 0 | W13: =W11-W8 | X13: 0
A16: BS as Debt
A17: Secured Debt | D17: 14839 | E17: =E20 | F17: 40049 | G17: =G20 | H17: =H20 | I17: 2453 | J17: 583 | K17: 14287 | L17: 49584 | M17: 112355 | N17: 109959 | O17: 86351 | P17: 106552 | Q17: =68962 | R17: =26299 | S17: =11375 | T17: =S17 | U17: =T17 | V17: =U17 | W17: =V17 | X17: =W17
A18: Unsecured Debt | D18: =D20-D17 | E18: 0 | F18: =F20-F17 | G18: 0 | H18: 0 | I18: =I20-I17 | J18: =J20-J17 | K18: =K20-K17 | L18: =L20-L17 | M18: =M20-M17 | N18: =N20-N17 | O18: =O20-O17 | P18: =P20-P17 | ... X18: =X20-X17
A20: Total Debt | D20: =BS!I44 | E20: =BS!J44 | F20: =BS!K44 | G20: =BS!L44 | H20: =BS!M44 | I20: =BS!N44 | J20: =BS!O44 | K20: =BS!P44 | ... S20: =BS!X44 | T20: =S20-T11+T13 | U20: =T20-U11+U13 | V20: =U20-V11+V13 | W20: =V20-W11+W13 | X20: =W20-X11+X13
A24: Interest and Finance Charges | T24: =S20*T25 | U24: =T20*U25 | V24: =U20*V25 | W24: =V20*W25 | X24: =W20*X25
A25: 10 % Interest Rate | T25: 0.1 | U25: =T25 | V25: =U25 | W25: =V25 | X25: =W25

Sheet Segment Revenue
H1: 37346 | I1: 37711 | J1: 38077 | K1: 38442 | L1: 38807 | M1: 39172 | N1: 39538 | O1: 39903 | P1: 40268 | Q1: 40633 | R1: 40999 | S1: 41364 | T1: 41729 | U1: 42094 | V1: 42460 | W1: 42825
H2: Rs/Millions | I2: Rs/Millions | J2: Rs/Millions | K2: Rs/Millions | L2: Rs/Millions | M2: Rs/Millions | N2: Rs/Millions | O2: Rs/Millions | P2: Rs/Millions | Q2: Rs/Millions | R2: Rs/Millions | S2: Rs/Millions | T2: Rs/Millions | U2: Rs/Millions | V2: Rs/Millions | W2: Rs/Millions
A3: 1. Segment Revenue
B4: Mobile Services India | H4: =12475+328 | I4: =20855+7349 | J4: =32870+12182 | K4: =55436+18737 | L4: 83095 | M4: 141189 | N4: 218697 | O4: 304188 | P4: 331275 | Q4: 363400 | R4: 403091 | S4: 430705 | T4: 466835 | U4: 519636 | V4: 560638 | W4: 565511
B5: Mobile Services Africa | Q5: 130834 | R5: 198265 | S5: 240439 | T5: 272488 | U5: 269070 | V5: 251333 | W5: 219568
B6: Mobile Services South Asia | S6: 12330 | T6: 17403 | U6: 15759 | V6: 16454 | W6: 11743
B7: Airtel Business | J7: 2625 | K7: 5406 | L7: =24673+6933 | M7: =34950+9304 | N7: =43798+13885 | O7: 83417 | P7: 44798 | Q7: 41463 | R7: 44541 | S7: 53203 | T7: 63361 | U7: 67130 | V7: 96993 | W7: 109429
B8: Tower Infrastructure Services | N8: 6023 | O8: 50912 | P8: 70852 | Q8: 85555 | R8: 95109 | S8: 49865 | T8: 51087 | U8: 54282 | V8: 55588 | W8: 60829
B9: Homes Services | H9: =1630+745 | I9: =3591+1262 | J9: 7766 | K9: 11311 | L9: 15075 | M9: 22491 | N9: 28615 | O9: 33427 | P9: 34154 | Q9: 36324 | R9: 37271 | S9: 35896 | T9: 39352 | U9: 44325 | V9: 25066 | W9: 27518
B10: Digital TV Services | Q10: 7760 | R10: 12960 | S10: 16295 | T10: 20771 | U10: 24759 | V10: 29178 | W10: 34306
B11: Others | H11: 32 | I11: 189 | J11: 303 | K11: 379 | L11: -1 | M11: 854 | N11: 2537 | O11: 4000 | P11: 5825 | Q11: 2741 | R11: 3117 | S11: 3359 | T11: 3197 | U11: 2914 | V11: 3446 | W11: 3736
B12: Unallocated | S12: 0 | T12: 0 | U12: 0 | V12: 0 | W12: 0
B13: Total | H13: =SUM(H4:H12) | I13: =SUM(I4:I12) | J13: =SUM(J4:J12) | K13: =SUM(K4:K12) | L13: =SUM(L4:L12) | M13: =SUM(M4:M12) | N13: =SUM(N4:N12) | O13: =SUM(O4:O12) | ... W13: =SUM(W4:W12)
B14: Less: Inter-segment revenue | H14: 169 | I14: 2692 | J14: 5376 | K14: 9711 | L14: 12520 | M14: 23468 | N14: 40637 | O14: 100900 | P14: 68432 | Q14: 72694 | R14: 79846 | S14: 73047 | T14: 77033 | U14: 77481 | V14: 73375 | W14: 77957
A15: Net sales / Income from operations | H15: =H13-H14 | I15: =I13-I14 | J15: =J13-J14 | K15: =K13-K14 | L15: =L13-L14 | M15: =M13-M14 | N15: =N13-N14 | O15: =O13-O14 | ... W15: =W13-W14
A17: 2. Segment Results
A18: Profit before net finance costs,
A19: non-operating (income ) / expense - (net) exceptional Items & tax
B20: Mobile Services India | H20: =486-101 | I20: =1315+1188 | J20: =5156+2726 | K20: =10384+4716 | L20: 16853 | M20: 34908 | N20: 59270 | O20: 68746 | P20: 94403 | Q20: 85551 | R20: 82221 | S20: 66552 | T20: 91216 | U20: 124703 | V20: 128324 | W20: 105494
B21: Mobile Services Africa | Q21: 2381 | R21: 14147 | S21: 15569 | T21: 16983 | U21: 11727 | V21: 4909 | W21: 10189
B22: Mobile Services South Asia | S22: -5117 | T22: -4271 | U22: -6138 | V22: -6394 | W22: -4660
B23: Airtel Business | J23: 1086 | K23: 2284 | L23: =7794+1761 | M23: =11636+3293 | N23: =11285+5247 | O23: 31637 | P23: 9336 | Q23: 5546 | R23: 2629 | S23: 3110 | T23: 8078 | U23: 7713 | V23: 18853 | W23: 22737
B24: Tower Infrastructure Services | N24: 1243 | O24: 3204 | P24: 7362 | Q24: 11688 | R24: 14641 | S24: 10894 | T24: 16185 | U24: 21731 | V24: 25506 | W24: 29195
B25: Homes Services | H25: =-1328-416 | I25: =-733+49 | J25: -59 | K25: 1441 | L25: 606 | M25: 1698 | N25: 6109 | O25: 8187 | P25: 7589 | Q25: 8334 | R25: 7172 | S25: 6999 | T25: 5541 | U25: 8689 | V25: 5682 | W25: 6868
B26: Digital TV Services | Q26: -5181 | R26: -7198 | S26: -8105 | T26: -4821 | U26: -1581 | V26: 1843 | W26: 3577
B27: Others | H27: -445 | I27: -851 | J27: -690 | K27: -545 | L27: -1316 | M27: -2107 | N27: -4193 | O27: -6860 | P27: -13193 | Q27: 47 | R27: -416 | S27: 83 | T27: 62 | U27: 16 | V27: -560 | W27: -2496
B28: Unallocated | Q28: -9714 | R28: -9792 | S28: -2027 | T28: -2213 | U28: -1064 | V28: -1544 | W28: -1418
B29: Total | H29: =SUM(H20:H28) | I29: =SUM(I20:I28) | J29: =SUM(J20:J28) | K29: =SUM(K20:K28) | L29: =SUM(L20:L28) | M29: =SUM(M20:M28) | N29: =SUM(N20:N28) | O29: =SUM(O20:O28) | ... W29: =SUM(W20:W28)
B30: Less:
B31: (i) Inter - Segment aliminations | H31: 151 | K31: 10 | M31: 156 | N31: 567 | O31: 392 | P31: 180 | R31: -38 | S31: 21 | T31: 275 | U31: 1 | V31: -262 | W31: 2263
B32: (ii) Net finance costs | I32: 2730 | J32: 2692 | K32: 2439 | L32: 2244 | M32: 2488 | N32: 5279 | O32: 18612 | P32: =17559+48 | Q32: 25349 | R32: 40828 | S32: 45187 | T32: 55513 | U32: 73252 | V32: 69135 | W32: 76974
B33: (iii) Non - operating (income) / expense (net) | P33: -17381 | Q33: =57-3536 | R33: =74-2643 | S33: =-5103 | T33: =-7133 | U33: -23119 | V33: 1024 | W33: 1319
B34: (iv) Exceptional items | T34: -538 | U34: 8532 | V34: -21741 | W34: 11697
A35: Profit before tax | H35: =H29-SUM(H31:H34) | I35: =I29-SUM(I31:I34) | J35: =J29-SUM(J31:J34) | K35: =K29-SUM(K31:K34) | L35: =L29-SUM(L31:L34) | M35: =M29-SUM(M31:M34) | N35: =N29-SUM(N31:N34) | O35: =O29-SUM(O31:O34) | ... W35: =W29-SUM(W31:W34)
A37: 3. Segment Assets
B38: Mobile Services India | H38: =48153+9657 | I38: =53591+14328 | J38: =64292+18269 | K38: =90135+33484 | L38: 128790 | M38: 201022 | N38: 264508 | O38: 377048 | P38: 601721 | Q38: 594629 | R38: 678106 | S38: 769097 | T38: 933083 | U38: 1251137 | V38: 1489054 | W38: 1642949
B39: Mobile Services Africa | Q39: 584051 | R39: 679350 | S39: 687652 | T39: 788468 | U39: 680586 | V39: 710446 | W39: 556281
B40: Mobile Services South Asia | S40: 39218 | T40: 51537 | U40: 47416 | V40: 47038 | W40: 29048
B41: Airtel Business | J41: 2789 | K41: 5405 | L41: =44944+11882 | M41: =67534+22039 | N41: =103503+21254 | O41: 172389 | P41: 82566 | Q41: 100630 | R41: 102660 | S41: 111307 | T41: 130199 | U41: 169346 | V41: 229437 | W41: 331833
B42: Tower Infrastructure Services | N42: 235086 | O42: 220068 | P42: 210913 | Q42: 203105 | R42: 206446 | S42: 194969 | T42: 211850 | U42: 207433 | V42: 209382 | W42: 210023
...

Sheet REVENUE METRIX
E1: 37346 | F1: =EOMONTH(E1,12) | G1: =EOMONTH(F1,12) | H1: =EOMONTH(G1,12) | I1: =EOMONTH(H1,12) | J1: =EOMONTH(I1,12) | K1: =EOMONTH(J1,12) | L1: =EOMONTH(K1,12) | M1: =EOMONTH(L1,12) | ... Y1: =EOMONTH(X1,12)
E2: Rs/Millions | F2: Rs/Millions | G2: Rs/Millions | H2: Rs/Millions | I2: Rs/Millions | J2: Rs/Millions | K2: Rs/Millions | L2: Rs/Millions | M2: Rs/Millions | N2: Rs/Millions | O2: Rs/Millions | P2: Rs/Millions | Q2: Rs/Millions | R2: Rs/Millions | S2: Rs/Millions | T2: Rs/Millions | U2: Rs/Millions | V2: Rs/Millions | W2: Rs/Millions | X2: Rs/Millions | Y2: Rs/Millions
A5: Segment Wise:
A6: Mobile Services India | E6: ='Segment Revenue'!H4 | F6: ='Segment Revenue'!I4 | G6: ='Segment Revenue'!J4 | H6: ='Segment Revenue'!K4 | I6: ='Segment Revenue'!L4 | J6: ='Segment Revenue'!M4 | K6: ='Segment Revenue'!N4 | L6: ='Segment Revenue'!O4 | ... T6: ='Segment Revenue'!W4 | U6: =T6*(1+U19) | V6: =U6*(1+V19) | W6: =V6*(1+W19) | X6: =W6*(1+X19) | Y6: =X6*(1+Y19)
A7: Mobile Services Africa | E7: ='Segment Revenue'!H5 | F7: ='Segment Revenue'!I5 | G7: ='Segment Revenue'!J5 | H7: ='Segment Revenue'!K5 | I7: ='Segment Revenue'!L5 | J7: ='Segment Revenue'!M5 | K7: ='Segment Revenue'!N5 | L7: ='Segment Revenue'!O5 | ... T7: ='Segment Revenue'!W5 | U7: =T7*(1+U20) | V7: =U7*(1+V20) | W7: =V7*(1+W20) | X7: =W7*(1+X20) | Y7: =X7*(1+Y20)
A8: Mobile Services South Asia | E8: ='Segment Revenue'!H6 | F8: ='Segment Revenue'!I6 | G8: ='Segment Revenue'!J6 | H8: ='Segment Revenue'!K6 | I8: ='Segment Revenue'!L6 | J8: ='Segment Revenue'!M6 | K8: ='Segment Revenue'!N6 | L8: ='Segment Revenue'!O6 | ... T8: ='Segment Revenue'!W6 | U8: =T8*(1+U21) | V8: =U8*(1+V21) | W8: =V8*(1+W21) | X8: =W8*(1+X21) | Y8: =X8*(1+Y21)
A9: Airtel Business | E9: ='Segment Revenue'!H7 | F9: ='Segment Revenue'!I7 | G9: ='Segment Revenue'!J7 | H9: ='Segment Revenue'!K7 | I9: ='Segment Revenue'!L7 | J9: ='Segment Revenue'!M7 | K9: ='Segment Revenue'!N7 | L9: ='Segment Revenue'!O7 | ... T9: ='Segment Revenue'!W7 | U9: =T9*(1+U22) | V9: =U9*(1+V22) | W9: =V9*(1+W22) | X9: =W9*(1+X22) | Y9: =X9*(1+Y22)
A10: Tower Infrastructure Services | E10: ='Segment Revenue'!H8 | F10: ='Segment Revenue'!I8 | G10: ='Segment Revenue'!J8 | H10: ='Segment Revenue'!K8 | I10: ='Segment Revenue'!L8 | J10: ='Segment Revenue'!M8 | K10: ='Segment Revenue'!N8 | L10: ='Segment Revenue'!O8 | ... T10: ='Segment Revenue'!W8 | U10: =T10*(1+U23) | V10: =U10*(1+V23) | W10: =V10*(1+W23) | X10: =W10*(1+X23) | Y10: =X10*(1+Y23)
A11: Homes Services | E11: ='Segment Revenue'!H9 | F11: ='Segment Revenue'!I9 | G11: ='Segment Revenue'!J9 | H11: ='Segment Revenue'!K9 | I11: ='Segment Revenue'!L9 | J11: ='Segment Revenue'!M9 | K11: ='Segment Revenue'!N9 | L11: ='Segment Revenue'!O9 | ... T11: ='Segment Revenue'!W9 | U11: =T11*(1+U24) | V11: =U11*(1+V24) | W11: =V11*(1+W24) | X11: =W11*(1+X24) | Y11: =X11*(1+Y24)
A12: Digital TV Services | E12: ='Segment Revenue'!H10 | F12: ='Segment Revenue'!I10 | G12: ='Segment Revenue'!J10 | H12: ='Segment Revenue'!K10 | I12: ='Segment Revenue'!L10 | J12: ='Segment Revenue'!M10 | K12: ='Segment Revenue'!N10 | L12: ='Segment Revenue'!O10 | ... T12: ='Segment Revenue'!W10 | U12: =T12*(1+U25) | V12: =U12*(1+V25) | W12: =V12*(1+W25) | X12: =W12*(1+X25) | Y12: =X12*(1+Y25)
A13: Others | E13: ='Segment Revenue'!H11 | F13: ='Segment Revenue'!I11 | G13: ='Segment Revenue'!J11 | H13: ='Segment Revenue'!K11 | I13: ='Segment Revenue'!L11 | J13: ='Segment Revenue'!M11 | K13: ='Segment Revenue'!N11 | L13: ='Segment Revenue'!O11 | ... T13: ='Segment Revenue'!W11 | U13: =T13*(1+U26) | V13: =U13*(1+V26) | W13: =V13*(1+W26) | X13: =W13*(1+X26) | Y13: =X13*(1+Y26)
A14: Unallocated | E14: ='Segment Revenue'!H12 | F14: ='Segment Revenue'!I12 | G14: ='Segment Revenue'!J12 | H14: ='Segment Revenue'!K12 | I14: ='Segment Revenue'!L12 | J14: ='Segment Revenue'!M12 | K14: ='Segment Revenue'!N12 | L14: ='Segment Revenue'!O12 | ... T14: ='Segment Revenue'!W12 | U14: =T14*(1+U27) | V14: =U14*(1+V27) | W14: =V14*(1+W27) | X14: =W14*(1+X27) | Y14: =X14*(1+Y27)
E15: =SUM(E6:E14) | F15: =SUM(F6:F14) | G15: =SUM(G6:G14) | H15: =SUM(H6:H14) | I15: =SUM(I6:I14) | J15: =SUM(J6:J14) | K15: =SUM(K6:K14) | L15: =SUM(L6:L14) | ... Y15: =SUM(Y6:Y14)
A16: Less: Inter-segment revenue | E16: ='Segment Revenue'!H14 | F16: ='Segment Revenue'!I14 | G16: ='Segment Revenue'!J14 | H16: ='Segment Revenue'!K14 | I16: ='Segment Revenue'!L14 | J16: ='Segment Revenue'!M14 | K16: ='Segment Revenue'!N14 | L16: ='Segment Revenue'!O14 | ... T16: ='Segment Revenue'!W14 | U16: =T16*(1+U29) | V16: =U16*(1+V29) | W16: =V16*(1+W29) | X16: =W16*(1+X29) | Y16: =X16*(1+Y29)
A17: Total Revenue | E17: =E15-E16 | F17: =F15-F16 | G17: =G15-G16 | H17: =H15-H16 | I17: =I15-I16 | J17: =J15-J16 | K17: =K15-K16 | L17: =L15-L16 | ... Y17: =Y15-Y16
A19: Mobile Services India | T19: =T6/S6-1 | U19: 0.005 | V19: 0.005 | W19: 0.015 | X19: 0.02 | Y19: 0.025
A20: Mobile Services Africa | T20: =T7/S7-1 | U20: -0.06 | V20: 0 | W20: 0.05 | X20: =W20 | Y20: =X20
A21: Mobile Services South Asia | T21: =T8/S8-1 | U21: 0.02 | V21: -0.07 | W21: 0.06 | X21: 0.01 | Y21: 0.08
A22: Airtel Business | T22: =(T9/M9)^(1/7)-1 | U22: =T22 | V22: =U22-($U$22-$Y$22)/4 | W22: =V22-($U$22-$Y$22)/4 | X22: =W22-($U$22-$Y$22)/4 | Y22: 0.1
A23: Tower Infrastructure Services | T23: =T10/S10-1 | U23: 0.1 | V23: =U23 | W23: =V23 | X23: =W23 | Y23: =X23
A24: Homes Services | T24: =T11/S11-1 | U24: 0.08 | V24: =U24 | W24: =V24 | X24: =W24 | Y24: 0.1
A25: Digital TV Services | T25: =T12/S12-1 | U25: =T25 | V25: 0.17 | W25: 0.16 | X25: 0.15 | Y25: 0.14
A26: Others | T26: =(T13/E13)^(1/16)-1 | U26: 0.2 | V26: =U26-($U$26-$Y$26)/4 | W26: =V26-($U$26-$Y$26)/4 | X26: =W26-($U$26-$Y$26)/4 | Y26: 0.15
A27: Unallocated
T28: 0 | U28: =T28 | V28: =U28 | W28: =V28 | X28: =W28 | Y28: =X28
A29: Less: Inter-segment revenue | T29: =(T16/M16)^(1/7)-1 | U29: =T29 | V29: =U29 | W29: =V29 | X29: =W29 | Y29: =X29
A30: YoY Growth | F30: =F17/E17-1 | G30: =G17/F17-1 | H30: =H17/G17-1 | I30: =I17/H17-1 | J30: =J17/I17-1 | K30: =K17/J17-1 | L30: =L17/K17-1 | M30: =M17/L17-1 | ... Y30: =Y17/X17-1

Sheet COST METRIX
E1: 37346 | F1: =EOMONTH(E1,12) | G1: =EOMONTH(F1,12) | H1: =EOMONTH(G1,12) | I1: =EOMONTH(H1,12) | J1: =EOMONTH(I1,12) | K1: =EOMONTH(J1,12) | L1: =EOMONTH(K1,12) | M1: =EOMONTH(L1,12) | ... Y1: =EOMONTH(X1,12)
E2: Rs/Millions | F2: Rs/Millions | G2: Rs/Millions | H2: Rs/Millions | I2: Rs/Millions | J2: Rs/Millions | K2: Rs/Millions | L2: Rs/Millions | M2: Rs/Millions | N2: Rs/Millions | O2: Rs/Millions | P2: Rs/Millions | Q2: Rs/Millions | R2: Rs/Millions | S2: Rs/Millions | T2: Rs/Millions | U2: Rs/Millions | V2: Rs/Millions | W2: Rs/Millions | X2: Rs/Millions | Y2: Rs/Millions
A3: Revenue from Operations | E3: =IS!F4 | F3: =IS!G4 | G3: =IS!H4 | H3: =IS!I4 | I3: =IS!J4 | J3: =IS!K4 | K3: =IS!L4 | L3: =IS!M4 | ... Y3: =IS!Z4
B5: Other Income | E5: =IS!F5 | F5: =IS!G5 | G5: =IS!H5 | H5: =IS!I5 | I5: =IS!J5 | J5: =IS!K5 | K5: =IS!L5 | L5: =IS!M5 | ... T5: =IS!U5 | U5: =AVERAGE(T5,V5) | V5: 1000 | W5: =V5+($Y$5-$V$5)/3 | X5: =W5+($Y$5-$V$5)/3 | Y5: 1500
B7: Network operating expenses | E7: =IS!F8 | F7: =IS!G8 | G7: =IS!H8 | H7: =IS!I8 | I7: =IS!J8 | J7: =IS!K8 | K7: =IS!L8 | L7: =IS!M8 | ... T7: =IS!U8 | U7: =U$3*U25 | V7: =V$3*V25 | W7: =W$3*W25 | X7: =X$3*X25 | Y7: =Y$3*Y25
B8: Access charges | E8: =IS!F9 | F8: =IS!G9 | G8: =IS!H9 | H8: =IS!I9 | I8: =IS!J9 | J8: =IS!K9 | K8: =IS!L9 | L8: =IS!M9 | ... T8: =IS!U9 | U8: =U$3*U26 | V8: =V$3*V26 | W8: =W$3*W26 | X8: =X$3*X26 | Y8: =Y$3*Y26
B9: License fee / spectrum charges (revenue share) | E9: =IS!F10 | F9: =IS!G10 | G9: =IS!H10 | H9: =IS!I10 | I9: =IS!J10 | J9: =IS!K10 | K9: =IS!L10 | L9: =IS!M10 | ... T9: =IS!U10 | U9: =U$3*U27 | V9: =V$3*V27 | W9: =W$3*W27 | X9: =X$3*X27 | Y9: =Y$3*Y27
B10: Employee benefit cost | E10: =IS!F11 | F10: =IS!G11 | G10: =IS!H11 | H10: =IS!I11 | I10: =IS!J11 | J10: =IS!K11 | K10: =IS!L11 | L10: =IS!M11 | ... T10: =IS!U11 | U10: =U$3*U28 | V10: =V$3*V28 | W10: =W$3*W28 | X10: =X$3*X28 | Y10: =Y$3*Y28
B11: sales and marketing expenses | E11: =IS!F12 | F11: =IS!G12 | G11: =IS!H12 | H11: =IS!I12 | I11: =IS!J12 | J11: =IS!K12 | K11: =IS!L12 | L11: =IS!M12 | ... T11: =IS!U12 | U11: =U$3*U29 | V11: =V$3*V29 | W11: =W$3*W29 | X11: =X$3*X29 | Y11: =Y$3*Y29
B12: Total Opex | E12: =SUM(E7:E11) | F12: =SUM(F7:F11) | G12: =SUM(G7:G11) | H12: =SUM(H7:H11) | I12: =SUM(I7:I11) | J12: =SUM(J7:J11) | K12: =SUM(K7:K11) | L12: =SUM(L7:L11) | ... T12: =SUM(T7:T11) | U12: =U$3*U30 | V12: =V$3*V30 | W12: =W$3*W30 | X12: =X$3*X30 | Y12: =Y$3*Y30
B14: Other expenses | E14: =IS!F17 | F14: =IS!G17 | G14: =IS!H17 | H14: =IS!I17 | I14: =IS!J17 | J14: =IS!K17 | K14: =IS!L17 | L14: =IS!M17 | ... T14: =IS!U17 | U14: =U32*U3 | V14: =V32*V3 | W14: =W32*W3 | X14: =X32*X3 | Y14: =Y32*Y3
B15: Depreciation and amortisation | E15: =IS!F21 | F15: =IS!G21 | G15: =IS!H21 | H15: =IS!I21 | I15: =IS!J21 | J15: =IS!K21 | K15: =IS!L21 | L15: =IS!M21 | ... Y15: =IS!Z21
B16: Finance costs | E16: =IS!F24 | F16: =IS!G24 | G16: =IS!H24 | H16: =IS!I24 | I16: =IS!J24 | J16: =IS!K24 | K16: =IS!L24 | L16: =IS!M24 | ... Y16: =IS!Z24
B17: Finance income | E17: =IS!F25 | F17: =IS!G25 | G17: =IS!H25 | H17: =IS!I25 | I17: =IS!J25 | J17: =IS!K25 | K17: =IS!L25 | L17: =IS!M25 | ... T17: =IS!U25 | U17: =U35*U$3 | V17: =V35*V$3 | W17: =W35*W$3 | X17: =X35*X$3 | Y17: =Y35*Y$3
B18: Non-operating expenses(net) | E18: =IS!F28 | F18: =IS!G28 | G18: =IS!H28 | H18: =IS!I28 | I18: =IS!J28 | J18: =IS!K28 | K18: =IS!L28 | L18: =IS!M28 | ... T18: =IS!U28 | U18: =U36*U$3 | V18: =V36*V$3 | W18: =W36*W$3 | X18: =X36*X$3 | Y18: =Y36*Y$3
B19: Current tax | E19: =IS!F33 | F19: =IS!G33 | G19: =IS!H33 | H19: =IS!I33 | I19: =IS!J33 | J19: =IS!K33 | K19: =IS!L33 | L19: =IS!M33 | ... Y19: =IS!Z33
B20: Less: Minority Interest | E20: =IS!F37 | F20: =IS!G37 | G20: =IS!H37 | H20: =IS!I37 | I20: =IS!J37 | J20: =IS!K37 | K20: =IS!L37 | L20: =IS!M37 | ... T20: =IS!U37 | U20: =U3*U38 | V20: =V3*V38 | W20: =W3*W38 | X20: =X3*X38 | Y20: =Y3*Y38
A22: Common Size Analysis
B23: Other Income | E23: =E5/E3 | F23: =F5/F3 | G23: =G5/G3 | H23: =H5/H3 | I23: =I5/I3 | J23: =J5/J3 | K23: =K5/K3 | L23: =L5/L3 | ... T23: =T5/T3
B25: Network operating expenses | E25: =E7/E$3 | F25: =F7/F$3 | G25: =G7/G$3 | H25: =H7/H$3 | I25: =I7/I$3 | J25: =J7/J$3 | K25: =K7/K$3 | L25: =L7/L$3 | ... T25: =T7/T$3 | U25: 0.22 | V25: 0.22 | W25: 0.22 | X25: 0.23 | Y25: 0.23
B26: Access charges | E26: =E8/E$3 | F26: =F8/F$3 | G26: =G8/G$3 | H26: =H8/H$3 | I26: =I8/I$3 | J26: =J8/J$3 | K26: =K8/K$3 | L26: =L8/L$3 | ... T26: =T8/T$3 | U26: 0.1 | V26: 0.11 | W26: 0.12 | X26: 0.11 | Y26: 0.11
B27: License fee / spectrum charges (revenue share) | E27: =E9/E$3 | F27: =F9/F$3 | G27: =G9/G$3 | H27: =H9/H$3 | I27: =I9/I$3 | J27: =J9/J$3 | K27: =K9/K$3 | L27: =L9/L$3 | ... T27: =T9/T$3 | U27: =T27-($T$27-$Y$27)/5 | V27: =U27-($T$27-$Y$27)/5 | W27: =V27-($T$27-$Y$27)/5 | X27: =W27-($T$27-$Y$27)/5 | Y27: 0.085
B28: Employee benefit cost | E28: =E10/E$3 | F28: =F10/F$3 | G28: =G10/G$3 | H28: =H10/H$3 | I28: =I10/I$3 | J28: =J10/J$3 | K28: =K10/K$3 | L28: =L10/L$3 | ... T28: =T10/T$3 | U28: =T28-($T$28-$Y$28)/5 | V28: =U28-($T$28-$Y$28)/5 | W28: =V28-($T$28-$Y$28)/5 | X28: =W28-($T$28-$Y$28)/5 | Y28: 0.04
B29: sales and marketing expenses | E29: =E11/E$3 | F29: =F11/F$3 | G29: =G11/G$3 | H29: =H11/H$3 | I29: =I11/I$3 | J29: =J11/J$3 | K29: =K11/K$3 | L29: =L11/L$3 | ... T29: =T11/T$3 | U29: 0.11 | V29: 0.105 | W29: 0.1 | X29: 0.09 | Y29: 0.08
B30: Total Opex | E30: =SUM(E25:E29) | F30: =SUM(F25:F29) | G30: =SUM(G25:G29) | H30: =SUM(H25:H29) | I30: =SUM(I25:I29) | J30: =SUM(J25:J29) | K30: =SUM(K25:K29) | L30: =SUM(L25:L29) | ... Y30: =SUM(Y25:Y29)
B32: Other expenses | E32: =E14/E$3 | F32: =F14/F$3 | G32: =G14/G$3 | H32: =H14/H$3 | I32: =I14/I$3 | J32: =J14/J$3 | K32: =K14/K$3 | L32: =L14/L$3 | ... T32: =T14/T$3 | U32: =T32-0.5% | V32: =U32-0.5% | W32: =V32-0.5% | X32: =W32-0.5% | Y32: =X32-0.5%
B33: Depreciation and amortisation | E33: =E15/E$3 | F33: =F15/F$3 | G33: =G15/G$3 | H33: =H15/H$3 | I33: =I15/I$3 | J33: =J15/J$3 | K33: =K15/K$3 | L33: =L15/L$3 | ... T33: =T15/T$3 | U33: =U15/U3 | V33: =V15/V3 | W33: =W15/W3 | X33: =X15/X3 | Y33: =Y15/Y3
B34: Finance costs | E34: =E16/E$3 | F34: =F16/F$3 | G34: =G16/G$3 | H34: =H16/H$3 | I34: =I16/I$3 | J34: =J16/J$3 | K34: =K16/K$3 | L34: =L16/L$3 | ... T34: =T16/T$3 | U34: =U16/U3 | V34: =V16/V3 | W34: =W16/W3 | X34: =X16/X3 | Y34: =Y16/Y3
B35: Finance income | E35: =E17/E$3 | F35: =F17/F$3 | G35: =G17/G$3 | H35: =H17/H$3 | I35: =I17/I$3 | J35: =J17/J$3 | K35: =K17/K$3 | L35: =L17/L$3 | ... T35: =T17/T$3 | U35: =T35 | V35: =U35 | W35: =V35 | X35: =W35 | Y35: =X35
B36: Non-operating expenses(net) | E36: =E18/E$3 | F36: =F18/F$3 | G36: =G18/G$3 | H36: =H18/H$3 | I36: =I18/I$3 | J36: =J18/J$3 | K36: =K18/K$3 | L36: =L18/L$3 | ... T36: =T18/T$3 | U36: =T36 | V36: =U36 | W36: =V36 | X36: =W36 | Y36: =X36
B37: Current tax | E37: =E19/E$3 | F37: =F19/F$3 | G37: =G19/G$3 | H37: =H19/H$3 | I37: =I19/I$3 | J37: =J19/J$3 | K37: =K19/K$3 | L37: =L19/L$3 | ... T37: =T19/T$3
B38: Less: Minority Interest | E38: =E20/E$3 | F38: =F20/F$3 | G38: =G20/G$3 | H38: =H20/H$3 | I38: =I20/I$3 | J38: =J20/J$3 | K38: =K20/K$3 | L38: =L20/L$3 | ... T38: =T20/T$3 | U38: =T38+($Y$38-$T$38)/5 | V38: =U38+($Y$38-$T$38)/5 | W38: =V38+($Y$38-$T$38)/5 | X38: =W38+($Y$38-$T$38)/5 | Y38: 0.007
B40: Effective Tax Rate % | E40: =IS!F33/IS!F30 | F40: =IS!G33/IS!G30 | G40: =IS!H33/IS!H30 | H40: =IS!I33/IS!I30 | I40: =IS!J33/IS!J30 | J40: =IS!K33/IS!K30 | K40: =IS!L33/IS!L30 | L40: =IS!M33/IS!M30 | ... T40: =IS!U33/IS!U30 | U40: 0.35 | V40: =U40 | W40: =V40 | X40: =W40 | Y40: =X40

Sheet Schedule
E1: 37346 | F1: 37711 | G1: 38077 | H1: 38442 | I1: 38807 | J1: 39172 | K1: 39538 | L1: 39903 | M1: 40268 | N1: 40633 | O1: 40999 | P1: 41364 | Q1: 41729 | R1: 42094 | S1: 42460 | T1: 42825 | U1: 43190 | V1: 43555 | W1: 43921 | X1: 44286 | Y1: 44651
E2: Rs/Millions | F2: Rs/Millions | G2: Rs/Millions | H2: Rs/Millions | I2: Rs/Millions | J2: Rs/Millions | K2: Rs/Millions | L2: Rs/Millions | M2: Rs/Millions | N2: Rs/Millions | O2: Rs/Millions | P2: Rs/Millions | Q2: Rs/Millions | R2: Rs/Millions | S2: Rs/Millions | T2: Rs/Millions | U2: Rs/Millions | V2: Rs/Millions | W2: Rs/Millions | X2: Rs/Millions | Y2: Rs/Millions
A4: Property,plant and equipment(Gross) | E4: =44093-E9 | F4: =66463-F9 | G4: 112192 | H4: =140627-H9-H10 | I4: =190488-I9-I10 | J4: =281199-J9-J10 | K4: =423224-K9-K10 | L4: =586616-L9-L10 | M4: 678122 | N4: 931873 | O4: 1053012 | P4: 1112602 | Q4: 1175977 | R4: 1189140 | S4: 1356266 | T4: 1392547 | U4: =T4+U18 | V4: =U4+V18 | W4: =V4+W18 | X4: =W4+X18 | Y4: =X4+Y18
A5: Accumulated Depreciation | E5: 8354 | F5: 13788 | G5: 26115 | H5: 36802 | I5: 52302 | J5: 76155 | K5: 97730 | L5: 147130 | M5: 195493 | N5: 280447 | O5: 378080 | P5: 474325 | Q5: 579548 | R5: 609983 | S5: 745758 | T5: 772459 | U5: =T5+T14 | V5: =U5+U14 | W5: =V5+V14 | X5: =W5+W14 | Y5: =X5+X14
A6: Net Block | E6: =E4-E5 | F6: =F4-F5 | G6: =G4-G5 | H6: =H4-H5 | I6: =I4-I5 | J6: =J4-J5 | K6: =K4-K5 | L6: =L4-L5 | ... Y6: =Y4-Y5
A8: Capital work-in-progress | E8: =BS!I6 | F8: =BS!J6 | G8: =BS!K6 | H8: =BS!L6 | I8: =BS!M6 | J8: =BS!N6 | K8: =BS!O6 | L8: =BS!P6 | ... T8: =BS!X6 | U8: =T8 | V8: =U8 | W8: =V8 | X8: =W8 | Y8: =X8
A9: Goodwill | E9: =BS!I7 | F9: =BS!J7 | G9: =BS!K7 | H9: =BS!L7 | I9: =BS!M7 | J9: =BS!N7 | K9: =BS!O7 | L9: =BS!P7 | ... T9: =BS!X7 | U9: =T9 | V9: =U9 | W9: =V9 | X9: =W9 | Y9: =X9
A10: Other intangible assets | E10: =BS!I8 | F10: =BS!J8 | G10: =BS!K8 | H10: =BS!L8 | I10: =BS!M8 | J10: =BS!N8 | K10: =BS!O8 | L10: =BS!P8 | ... T10: =BS!X8 | U10: =T10 | V10: =U10 | W10: =V10 | X10: =W10 | Y10: =X10
A11: Intangible assets under development | E11: =BS!I9 | F11: =BS!J9 | G11: =BS!K9 | H11: =BS!L9 | I11: =BS!M9 | J11: =BS!N9 | K11: =BS!O9 | L11: =BS!P9 | ... T11: =BS!X9 | U11: =T11 | V11: =U11 | W11: =V11 | X11: =W11 | Y11: =X11
A12: Total Net Block | E12: =SUM(E6:E11) | F12: =SUM(F5:F11) | G12: =SUM(G5:G11) | H12: =SUM(H5:H11) | I12: =SUM(I5:I11) | J12: =SUM(J5:J11) | K12: =SUM(K5:K11) | L12: =SUM(L5:L11) | M12: =SUM(M5:M11) | ... Y12: =SUM(Y5:Y11)
A14: Depreciation | E14: =IS!F21 | F14: =IS!G21 | G14: =IS!H21 | H14: =IS!I21 | I14: =IS!J21 | J14: =IS!K21 | K14: =IS!L21 | L14: =IS!M21 | ... T14: =IS!U21 | U14: =U16*U12 | V14: =V16*V12 | W14: =W16*W12 | X14: =X16*X12 | Y14: =Y16*Y12
A16: % to total | E16: =E14/E12 | F16: =F14/AVERAGE(F12,E12) | G16: =G14/AVERAGE(G12,F12) | H16: =H14/AVERAGE(H12,G12) | I16: =I14/AVERAGE(I12,H12) | J16: =J14/AVERAGE(J12,I12) | K16: =K14/AVERAGE(K12,J12) | L16: =L14/AVERAGE(L12,K12) | M16: =M14/AVERAGE(M12,L12) | ... T16: =T14/AVERAGE(T12,S12) | U16: =T16+($Y$16-$T$16)/5 | V16: =U16+($Y$16-$T$16)/5 | W16: =V16+($Y$16-$T$16)/5 | X16: =W16+($Y$16-$T$16)/5 | Y16: 0.065
A18: Capex | E18: =-CF!B27 | F18: =-CF!C27 | G18: =-CF!D27 | H18: =-CF!E27 | I18: =-CF!F27 | J18: =-CF!G27 | K18: =-CF!H27 | L18: =-CF!I27 | ... T18: =-CF!Q27 | U18: =U19*IS!V4 | V18: =V19*IS!W4 | W18: =W19*IS!X4 | X18: =X19*IS!Y4 | Y18: =Y19*IS!Z4
A19: % Revenue | E19: =E18/IS!F4 | F19: =F18/IS!G4 | G19: =G18/IS!H4 | H19: =H18/IS!I4 | I19: =I18/IS!J4 | J19: =J18/IS!K4 | K19: =K18/IS!L4 | L19: =L18/IS!M4 | ... T19: =T18/IS!U4 | U19: 0.31 | V19: 0.2 | W19: 0.17 | X19: 0.16 | Y19: 0.15
A22: Dividends Paid including dividend tax | E22: =-CF!B55 | F22: =-CF!C55 | G22: =-CF!D55 | H22: =-CF!E55 | I22: =-CF!F55 | J22: =-CF!G55 | K22: =-CF!H55 | L22: =-CF!I55 | ... T22: =-CF!Q55 | U22: =T22 | V22: =U22 | W22: =V22 | X22: =W22 | Y22: =X22
A23: Dividend without DDT | E23: =E22/(1+15%) | F23: =F22/(1+15%) | G23: =G22/(1+15%) | H23: =H22/(1+15%) | I23: =I22/(1+15%) | J23: =J22/(1+15%) | K23: =K22/(1+15%) | L23: =L22/(1+15%) | ... T23: =T22/(1+15%) | U23: =U24*IS!V41 | V23: =V24*IS!W41 | W23: =W24*IS!X41 | X23: =X24*IS!Y41 | Y23: =Y24*IS!Z41
A24: Dividends Declared (DPS) | E24: =E23/IS!F41 | F24: =F23/IS!G41 | G24: =G23/IS!H41 | H24: =H23/IS!I41 | I24: =I23/IS!J41 | J24: =J23/IS!K41 | K24: =K23/IS!L41 | L24: =L23/IS!M41 | ... T24: =T23/IS!U41 | U24: =T24 | V24: =U24 | W24: =V24 | X24: =W24 | Y24: =X24

Sheet DCF - Valuation
A1: KPIT Cummins Infosystems Ltd.
A2: DCF - Valuation
A3: (All Data in Million INR,except per share price data)
A4: (Red=Assumption,Blue=Actual,Black=Calculation)
A6: Growth Assumptions | E6: Enterprise Value (EV) | K6: Debt Equity Weightage
A7: Long term World GDP growth rate | B7: 0.06 | K7: E/(D+E) | M7: =H10/(H10+H13)
E8: Current Market Price | H8: 498 | K8: D/(D+E) | M8: =1-M7
E9: Diluted Shares | H9: =IS!U42 | I9: mn
A10: CAPM Assumptions | E10: Market Capitalisation | H10: =H8*H9 | K10: Interest Rate (%) | M10: 0.1
A11: Ke | B11: =(B14*B13)+B12 | E11: Debt | H11: =BS!X80 | K11: Tax Rate (@) | M11: 0.35
A12: RFR | B12: 0.06 | E12: Less: Cash & Cash Equivalents | H12: =BS!X25+BS!X26
A13: Beta | B13: 0.87 | E13: Net Debt | H13: =H11-H12 | K13: WACC Calculation
A14: Rp | B14: 0.07 | E14: Current Enterprise Value (EV) | H14: =H10-H13 | K14: WACC | M14: =(M8*(1-M11)*M10)+M7*B11
A16: Calculation of Free Cash Flow
C17: Explicit Forecast Period | I17: Terminal Year
C18: 2017-A | D18: 2018-E | E18: 2019-E | F18: 2020-E | G18: 2021-E | H18: =LEFT(G18,4)+1&"-E" | I18: =LEFT(H18,4)+1&"-E"
A20: Revenues | C20: =IS!U4 | D20: =IS!V4 | E20: =IS!W4 | F20: =IS!X4 | G20: =IS!Y4 | H20: =IS!Z4 | I20: =H20*(1+I38)
A21: EBIT | C21: =IS!U22 | D21: =IS!V22 | E21: =IS!W22 | F21: =IS!X22 | G21: =IS!Y22 | H21: =IS!Z22 | I21: =I20*I42
A22: Tax Rate | C22: ='COST METRIX'!T40 | D22: ='COST METRIX'!U40 | E22: ='COST METRIX'!V40 | F22: ='COST METRIX'!W40 | G22: ='COST METRIX'!X40 | H22: ='COST METRIX'!Y40 | I22: =H22
A23: Net Operating Profit After Tax (NOPAT) | C23: =C21*(1-C22) | D23: =D21*(1-D22) | E23: =E21*(1-E22) | F23: =F21*(1-F22) | G23: =G21*(1-G22) | H23: =H21*(1-H22) | I23: =I21*(1-I22)
A24: Depreciation & Amortisation | C24: =IS!U21 | D24: =IS!V21 | E24: =IS!W21 | F24: =IS!X21 | G24: =IS!Y21 | H24: =IS!Z21 | I24: =I20*I43
A25: Working Capital Change | C25: =CF!Q15+CF!Q16 | D25: =CF!R15+CF!R16 | E25: =CF!S15+CF!S16 | F25: =CF!T15+CF!T16 | G25: =CF!U15+CF!U16 | H25: =CF!V15+CF!V16 | I25: =H25
A26: Operating Cash Flow | C26: =SUM(C23:C25) | D26: =SUM(D23:D25) | E26: =SUM(E23:E25) | F26: =SUM(F23:F25) | G26: =SUM(G23:G25) | H26: =SUM(H23:H25) | I26: =SUM(I23:I25)
A27: Capex | C27: =CF!Q27 | D27: =CF!R27 | E27: =CF!S27 | F27: =CF!T27 | G27: =CF!U27 | H27: =CF!V27 | I27: =I20*I44
A28: FCFF | C28: =C26+C27 | D28: =D26+D27 | E28: =E26+E27 | F28: =F26+F27 | G28: =G26+G27 | H28: =H26+H27 | I28: =I26+I27
A30: Diluted Shares
C31: =C18 | D31: =D18 | E31: =E18 | F31: =F18 | G31: =G18 | H31: =H18
A32: Projection Year | D32: 1 | E32: =D32+1 | F32: =E32+1 | G32: =F32+1 | H32: =G32+1
A33: Discount Factor | D33: =1/(1+$M$14)^D32 | E33: =1/(1+$M$14)^E32 | F33: =1/(1+$M$14)^F32 | G33: =1/(1+$M$14)^G32 | H33: =1/(1+$M$14)^H32
A34: Present Value of FCFF
C36: =C31 | D36: =D31 | E36: =E31 | F36: =F31 | G36: =G31 | H36: =H31
A37: Y/Y Growth Analysis
A38: Revenues | C38: =IS!U4/IS!T4-1 | D38: =D20/C20-1 | E38: =E20/D20-1 | F38: =F20/E20-1 | G38: =G20/F20-1 | H38: =H20/G20-1 | I38: 0.06
A40: Margin Analysis (As % of Revenues)
A42: EBIT Margin | C42: =C21/C20 | D42: =D21/D20 | E42: =E21/E20 | F42: =F21/F20 | G42: =G21/G20 | H42: =H21/H20 | I42: 0.14
A43: Depreciation & Amortisation | C43: =C24/C20 | D43: =D24/D20 | E43: =E24/E20 | F43: =F24/F20 | G43: =G24/G20 | H43: =H24/H20 | I43: 0.2
A44: Capex | C44: =C27/C20 | D44: =D27/D20 | E44: =E27/E20 | F44: =F27/F20 | G44: =G27/G20 | H44: =H27/H20 | I44: -0.16
A47: Terminal Value | E47: Calculated Equity Value | J47: Intrinsic Value
A48: Sum of PV of FCFF for explicit forecast period | C48: =NPV(M14,D28:H28) | E48: Enterprise Value | H48: =C48+C52 | J48: Equity Value | M48: =H52
A49: WACC | C49: =M14 | E49: - Debt | H49: =H11 | J49: Diluted Shares | M49: =IS!U42
...

Sheet Relative Valuation
A1: Relative Valuation
A3: Company | B3: CMP | C3: NOS. | D3: M Cap | E3: Debt | F3: Cash | G3: EV | I3: Sales (Rs. mn) | K3: EBITDA(Rs.)
I4: FY18E | J4: FY19E | K4: FY18E | L4: FY19E
A5: Bharti Airtel | B5: 498 | C5: =IS!Z41 | D5: =B5*C5 | E5: ='DCF - Valuation'!H11 | F5: ='DCF - Valuation'!H12 | G5: ='DCF - Valuation'!H14 | I5: =IS!V4 | J5: =IS!W4 | K5: =IS!V19 | L5: =IS!W19
A6: Idea Cellular+Vodafone | B6: 102.8 | C6: 7867.6 | D6: =B6*C6 | E6: 1030620 | F6: 312.7 | G6: =D6+E6-F6 | I6: 647137 | J6: 679324 | K6: 128435 | L6: 144792
A7: Tata Comm | B7: 651.85 | C7: 285 | D7: =B7*C7 | E7: 7372 | F7: 1017.9 | G7: =D7+E7-F7 | I7: 172282 | J7: 184462 | K7: 23396 | L7: 29308
A8: Reliance Comm | B8: 31.2 | C8: 2489 | D8: =B8*C8 | E8: 265570 | F8: 6430 | G8: =D8+E8-F8 | I8: 236690 | J8: 240120 | K8: 75740 | L8: 76210
A9: Bharti Infratel | B9: 346 | C9: 1866 | D9: =B9*C9 | E9: 2785 | F9: 1121 | G9: =D9+E9-F9 | I9: 157311 | J9: 168562 | K9: 74413 | L9: 82535
A12: Company | B12: EV/Revenue | D12: P/S | F12: EV/EBITDA
B13: FY18E | C13: FY19E | D13: FY18E | E13: FY19E | F13: FY18E | G13: FY19E
A14: Idea Cellular+Vodafone | B14: =$G6/I6 | C14: =$G6/J6 | D14: =$D6/I6 | E14: =$D6/J6 | F14: =$G6/K6 | G14: =$G6/L6
A15: Tata Comm | B15: =$G7/I7 | C15: =$G7/J7 | D15: =$D7/I7 | E15: =$D7/J7 | F15: =$G7/K7 | G15: =$G7/L7
A16: Reliance Comm | B16: =$G8/I8 | C16: =$G8/J8 | D16: =$D8/I8 | E16: =$D8/J8 | F16: =$G8/K8 | G16: =$G8/L8
A17: Bharti Infratel | B17: =$G9/I9 | C17: =$G9/J9 | D17: =$D9/I9 | E17: =$D9/J9 | F17: 10.1 | G17: 9.3
A19: Muiltiple | B19: =QUARTILE(B14:B17,3) | C19: =QUARTILE(C14:C17,3) | D19: =QUARTILE(D14:D17,3) | E19: =QUARTILE(E14:E17,3) | F19: =QUARTILE(F14:F17,3) | G19: =QUARTILE(G14:G17,3)
A22: Valuation of Bharti Airtel based on EV/Revenue
C23: Multiple | D23: EV | E23: Debt | F23: Cash | G23: Equity Value | H23: Price
A24: FY18E | B24: EV/Revenue | C24: =B19 | D24: =C24*I5 | E24: ='Debt Schedule'!T20 | F24: =$F$5 | G24: =D24-E24+F24 | H24: =G24/$C$5
A25: FY19E | B25: EV/Revenue | C25: =C19 | D25: =C25*J5 | E25: ='Debt Schedule'!U20 | F25: =$F$5 | G25: =D25-E25+F25 | H25: =G25/$C$5
A27: Valuation of Bharti Airtel based on P/S
C28: Multiple | D28: Price
A29: FY18E | B29: P/S | C29: =D19 | D29: =C29*I5/$C$5
A30: FY19E | B30: P/S | C30: =E19 | D30: =C30*J5/C5
A32: Valuation of Bharti Airtel based on EV/EBITDA
C33: Multiple | D33: EV | E33: Debt | F33: Cash | G33: Equity Value | H33: Price
A34: FY18E | B34: EV/EBITDA | C34: =F19 | D34: =C34*K5 | E34: =E24 | F34: =$F$5 | G34: =D34-E34+F34 | H34: =G34/$C$5
A35: FY19E | B35: EV/EBITDA | C35: =G19 | D35: =C35*L5 | E35: =E25 | F35: =$F$5 | G35: =D35-E35+F35 | H35: =G35/$C$5
A38: Sales Price - Valuation | B38: Min | C38: Max | D38: Diff
A39: DCF | B39: =MIN('DCF - Valuation'!E64:I69) | C39: =MAX('DCF - Valuation'!E64:I69) | D39: =C39-B39
A40: EV/Revenue | B40: =MIN(H24:H25) | C40: =MAX(H24:H25) | D40: =C40-B40
A41: P/S | B41: =MIN(D29:D30) | C41: =MAX(D29:D30) | D41: =C41-B41
A42: EV/EBITDA | B42: =MIN(H34:H35) | C42: =MAX(H34:H35) | D42: =C42-B42
