Workbook

Sheet Cover
E3: Reference Model
E5: GAIL India Limited
E6: Prepared By: Disha Vyas, Distance learning, Mumbai
E15: http://proschoolonline.com
E16: Email ID : mumbai@proschoolonline.com
E18: Mumbai
E20: IMS Proschool Pvt Ltd,
E21: Maharashtra High School Complex,
E22: Principal N.M Kale Marg, Off Gokhale Rd,
E23: Dadar (W), Mumbai 400028
E24: Tel. No. : 022-65285393/94
E25: +91 9372895050

Sheet Directions
A1: Directions
A3: GAIL has successfully evolved into a major integrated gas company with presence across the natural gas value chain and with global footprints. A financial model of such a company is in great demand in the investment market. This gave us the opportunity to guide our student to come out with a financial model on the company. These exercises help the student at IMS Proschool to hone their financial modeling skills. This model is being developed by a financial modeling student at IMS Proschool. This is provided as reference model and is for information purpose only. Keeping in view the objective of the reference model, the formulas and linkages of the model are kept intact. IMS Proschool provides certificate programs in Financial Modeling. The program grooms the candidates for entry level jobs in the finance sector which require financial analysis and modeling skills. The program aims to impart the necessary skills required to perform the role of a Financial Research Analyst. The program equips students with the practical skill sets required to perform financial analysis, modeling and valuation through Excel. For more details, please contact the address furnished below. You can also email us at the below mentioned email-id.
I20: IMS Proschool Pvt Ltd,
I21: Maharashtra High School Complex,
I22: Principal N.M Kale Marg, Off Gokhale Rd,
I23: Dadar (W), Mumbai 400028
I24: Tel. No. : 022-65285393/94
I25: +91 9372895050
I26: Email ID : mumbai@proschoolonline.com

Sheet COMPANY OVERVIEW
A1: GAIL (INDIA) LTD.
A2: Company Overview
A3: (Figures in Rs. Millions.)
A5: Company Information | F5: Company Description
A6: Industry | B6: Natural Gas Industry | F6: GAIL (India) Limited, is India's flagship Natural Gas company, integrating all aspects of the Natural Gas value chain (including Exploration & Production, Processing, Transmission, Distribution and Marketing) and its related services. In a rapidly changing scenario, we are spearheading the move to a new era of clean fuel industrialisation, creating a quadrilateral of green energy corridors that connect major consumption centres in India with major gas fields, LNG terminals and other cross border gas sourcing points. GAIL is also expanding its business to become a player in the International Market.
A7: Sector | B7: Natural Gas Sector
A8: Country | B8: INDIA
A9: Current Market Price | B9: RS.420.65
A10: Ticker | B10: NSE
A11: Market Capitalization ($MM) | B11: 5335861
A12: Relative Index (S&P 500) | B12: (S&P 500)
A13: Year end | B13: 40268 | F13: Products
A14: Reporting currency | B14: INDIAN (Rs.) | F14: Natural Gas value chain and beyond including Exploration, Production, Transmission, Marketing, Extraction, Processing, Distribution, utilisation including Petrochemicals and Power and Natural Gas related infrastructure, products and services.
A17: Per Share Data & Key Ratios
A18: (in Rs.crores)
A19: RATIOS | B19: 31MAR '06 | C19: 31MAR '07 | D19: 31MAR '08 | E19: 31MAR '09 | F19: 31MAR '10 | G19: 31MAR '11 | H19: 31MAR '12 | I19: 31MAR '13 | J19: 31MAR '14
B20: 2005-06A | C20: 2006-07A | D20: 2007-08 A | E20: 2008-09 A | F20: 2009-2010E | G20: 2010-11E | H20: 2011-12E | I20: 2012-13E | J20: 2013-14E
A21: EPS BASIC | C21: ='INCOME STATEMENT'!H49 | D21: ='INCOME STATEMENT'!O49 | E21: ='INCOME STATEMENT'!V49 | F21: ='INCOME STATEMENT'!AC49 | G21: ='INCOME STATEMENT'!AD49 | H21: ='INCOME STATEMENT'!AE49 | I21: ='INCOME STATEMENT'!AF49 | J21: ='INCOME STATEMENT'!AG49
A22: EBITDA/sales (%) | C22: ='INCOME STATEMENT'!H21/'INCOME STATEMENT'!H6 | D22: ='INCOME STATEMENT'!O21/'INCOME STATEMENT'!O6 | E22: ='INCOME STATEMENT'!V21/'INCOME STATEMENT'!V6 | F22: ='INCOME STATEMENT'!AC21/'INCOME STATEMENT'!AC6 | G22: ='INCOME STATEMENT'!AD21/'INCOME STATEMENT'!AD6 | H22: ='INCOME STATEMENT'!AE21/'INCOME STATEMENT'!AE6 | I22: ='INCOME STATEMENT'!AF21/'INCOME STATEMENT'!AF6 | J22: ='INCOME STATEMENT'!AG21/'INCOME STATEMENT'!AG6
A23: Net income/sales (%) | C23: ='INCOME STATEMENT'!O41/'INCOME STATEMENT'!O6 | D23: ='INCOME STATEMENT'!V41/'INCOME STATEMENT'!V6 | E23: ='INCOME STATEMENT'!V41/'INCOME STATEMENT'!V6 | F23: ='INCOME STATEMENT'!AC41/'INCOME STATEMENT'!AC6 | G23: ='INCOME STATEMENT'!AD41/'INCOME STATEMENT'!AD6 | H23: ='INCOME STATEMENT'!AE41/'INCOME STATEMENT'!AE6 | I23: ='INCOME STATEMENT'!AF41/'INCOME STATEMENT'!AF6 | J23: ='INCOME STATEMENT'!AG41/'INCOME STATEMENT'!AG6
A24: Interest Cover | C24: ='Ratio Analysis'!C19 | D24: ='Ratio Analysis'!D19 | E24: ='Ratio Analysis'!E19 | F24: ='Ratio Analysis'!F19 | G24: ='Ratio Analysis'!G19 | H24: ='Ratio Analysis'!H19 | I24: ='Ratio Analysis'!I19 | J24: ='Ratio Analysis'!J19
A25: EV/Sales | E25: =Valuation!G13/'INCOME STATEMENT'!V6 | F25: =Valuation!G13/'INCOME STATEMENT'!AC6 | G25: =Valuation!G13/'INCOME STATEMENT'!AD6 | H25: =Valuation!G13/'INCOME STATEMENT'!AE6 | I25: =Valuation!G13/'INCOME STATEMENT'!AF6 | J25: =Valuation!G13/'INCOME STATEMENT'!AG6
A26: EV/EBITDA | E26: =Valuation!G13/'INCOME STATEMENT'!V21 | F26: =Valuation!G13/'INCOME STATEMENT'!AC21 | G26: =Valuation!G13/'INCOME STATEMENT'!AD21 | H26: =Valuation!G13/'INCOME STATEMENT'!AE21 | I26: =Valuation!G13/'INCOME STATEMENT'!AF21 | J26: =Valuation!G13/'INCOME STATEMENT'!AG21
A27: P/E | E27: =Valuation!G7/'INCOME STATEMENT'!V49 | F27: =Valuation!G7/'INCOME STATEMENT'!AC49 | G27: =Valuation!G7/'INCOME STATEMENT'!AD49 | H27: =Valuation!G7/'INCOME STATEMENT'!AE49 | I27: =Valuation!G7/'INCOME STATEMENT'!AF49 | J27: =Valuation!G7/'INCOME STATEMENT'!AG49
A28: P/Sales | E28: =Valuation!G7/'INCOME STATEMENT'!V6 | F28: =Valuation!G7/'INCOME STATEMENT'!AC6 | G28: =Valuation!G7/'INCOME STATEMENT'!AD6 | H28: =Valuation!G7/'INCOME STATEMENT'!AE6 | I28: =Valuation!G7/'INCOME STATEMENT'!AF6 | J28: =Valuation!G7/'INCOME STATEMENT'!AG6
A30: Segment revenue breakup for 2009
A32: Natural Gas Trading | B32: 183084
A33: Transmission Services - Natural Gas | B33: 25081
A34: Petrochemicals | B34: 27335
A35: LPG & Liquid Hydrocarbons | B35: 29900
A36: Transmission Services - LPG | B36: 3819
A37: Gailtel | B37: 243
A38: Others | B38: 5749
A39: Total | B39: =SUM(B32:B38)
A48: Revenue Forecast
B49: 2006-07 | C49: 2007-08 | D49: 2008-09 | E49: 2009-10 | F49: 2010-11 | G49: 2011-12
A50: Natural Gas Trading | B50: 121198 | C50: 127476 | D50: 183084 | E50: 205054 | F50: 246064 | G50: 295277
A51: Transmission Services - Natural Gas | B51: 21155 | C51: 21966 | D51: 25081 | E51: 34862 | F51: 45321 | G51: 61183
A52: Petrochemicals | B52: 25702 | C52: 27031 | D52: 27335 | E52: 29574 | F52: 32531 | G52: 36110
A53: LPG & Liquid Hydrocarbons | B53: 21219 | C53: 26961 | D53: 29900 | E53: 29996 | F53: 35995 | G53: 41395
...

Sheet PRESENTATION
A1: GAIL (INDIA) LTD.
A2: Segment Revenue Model | S2: BSE Q RES
A3: (Figures in Rs. Millions.) | B3: 2006-07 | G3: 2007-08 | L3: 2008-09 | Q3: 2009-10
B4: APR - JUN | C4: JUL - SEPT | D4: OCT - DEC | E4: JAN - MAR | F4: 31st MAR '07 | G4: APR - JUN | H4: JUL - SEPT | I4: OCT - DEC | J4: JAN - MAR | K4: 31st MAR '07 | L4: APR - JUN | M4: JUL - SEPT | N4: OCT - DEC | O4: JAN - MAR | P4: 31st MAR '07 | Q4: APR - JUN | R4: JUL - SEPT | S4: OCT - DEC | T4: JAN - MAR | U4: 31st MAR '10 | V4: 31st MAR '11 | W4: 31st MAR '12 | X4: 31st MAR '13 | Y4: 31st MAR '14
B5: Q1 2006 | C5: Q2 2006 | D5: Q3 2006 | E5: Q4 2007 | F5: 2006-07A | G5: Q1 2007 | H5: Q2 2007 | I5: Q3 2007 | J5: Q4 2008 | K5: 2007-08A | L5: Q1 2008 | M5: Q2 2008 | N5: Q3 2008 | O5: Q4 2009 | P5: 2008-09A | Q5: Q1 2009 | R5: Q2 2009 | S5: Q3 2009 | T5: Q4 2010 | U5: 2009-10E | V5: 2010-11E | W5: 2011-12E | X5: 2012-13E | Y5: 2013-14E
A7: Segment Revenues
A8: Natural Gas Trading | B8: 30766.59 | C8: 29236.8 | D8: 31494.1 | E8: 29700.8 | F8: =SUM(B8:E8) | G8: 30067.23 | H8: 32486.93 | I8: 31120.1 | J8: 33801.6 | K8: =SUM(G8:J8) | L8: 41192.8 | M8: 44953.8 | N8: 49507.4 | O8: 47429.6 | P8: =SUM(L8:O8) | Q8: 46417.1 | R8: 49691.3 | S8: 45274.4 | T8: =U8-(Q8+R8+S8) | U8: 205053.63 | V8: 246064 | W8: 295277 | X8: 369097 | Y8: 479825
A9: Transmission Services - Natural Gas | B9: 5008.51 | C9: 4971.7 | D9: 6412.5 | E9: 4761.8 | F9: =SUM(B9:E9) | G9: 4894.67 | H9: 5288.57 | I9: 6021.6 | J9: 5761.5 | K9: =SUM(G9:J9) | L9: 6213.8 | M9: 6215 | N9: 6140.9 | O9: 6511 | P9: =SUM(L9:O9) | Q9: 7331.5 | R9: 8429.5 | S9: 8527.8 | T9: =U9-(Q9+R9+S9) | U9: 34862 | V9: 45321 | W9: 61183 | X9: 82597 | Y9: 113984
A10: Petrochemicals | B10: 5502.8 | C10: 5455.6 | D10: 7306 | E10: 7437.2 | F10: =SUM(B10:E10) | G10: 7783.9 | H10: 6402.2 | I10: 5378.1 | J10: 7467 | K10: =SUM(G10:J10) | L10: 8007.9 | M10: 6287.3 | N10: 6226.8 | O10: 6813.3 | P10: =SUM(L10:O10) | Q10: 6225.7 | R10: 6156.6 | S10: 7927.1 | T10: =U10-(Q10+R10+S10) | U10: 29574 | V10: 32531 | W10: 36110 | X10: 40443 | Y10: 46105
A11: LPG & Liquid Hydrocarbons | B11: 6406.2 | C11: 4219.1 | D11: 6261.1 | E11: 4332.1 | F11: =SUM(B11:E11) | G11: 6751.5 | H11: 7033.3 | I11: 5278.3 | J11: 7897.8 | K11: =SUM(G11:J11) | L11: 7997 | M11: 10902.1 | N11: 3329.9 | O11: 7671.4 | P11: =SUM(L11:O11) | Q11: 6839 | R11: 5150.9 | S11: 7102.6 | T11: =U11-(Q11+R11+S11) | U11: 29996 | V11: 35995 | W11: 41395 | X11: 49674 | Y11: 60602
A12: Transmission Services - LPG | B12: 714.9 | C12: 816 | D12: 993.7 | E12: 915 | F12: =SUM(B12:E12) | G12: 922.5 | H12: 896 | I12: 995.5 | J12: 1079.1 | K12: =SUM(G12:J12) | L12: 855.4 | M12: 905.9 | N12: 1064.9 | O12: 992.4 | P12: =SUM(L12:O12) | Q12: 1057.3 | R12: 1029.3 | S12: 1160.6 | T12: =U12-(Q12+R12+S12) | U12: 4358 | V12: 5012 | W12: 5814 | X12: 6860 | Y12: 8232
A13: Gailtel | B13: 50.8 | C13: 62.7 | D13: 70.7 | E13: 69.4 | F13: =SUM(B13:E13) | G13: 67.1 | H13: 76.4 | I13: 70.3 | J13: 71.7 | K13: =SUM(G13:J13) | L13: 65.3 | M13: 65.4 | N13: 63.5 | O13: 49.1 | P13: =SUM(L13:O13) | Q13: 37.8 | R13: 34.2 | S13: 28.5 | T13: =U13-(Q13+R13+S13) | U13: 193 | V13: 222 | W13: 244 | X13: 273 | Y13: 309
A14: Others | B14: 742.1 | C14: 1607 | D14: 1764.2 | E14: 983.8 | F14: =SUM(B14:E14) | G14: 806 | H14: 1636.1 | I14: 1571.4 | J14: 1054.6 | K14: =SUM(G14:J14) | L14: 1231.1 | M14: 1929.3 | N14: 2526.2 | O14: 62.8 | P14: =SUM(L14:O14) | Q14: 100.4 | R14: 142.1 | S14: 136.8 | T14: =U14-(Q14+R14+S14) | U14: 402 | V14: 443 | W14: 496 | X14: 555 | Y14: 633
A15: Total | B15: =SUM(B8:B14) | C15: =SUM(C8:C14) | D15: =SUM(D8:D14) | E15: =SUM(E8:E14) | F15: =F8+F9+F10+F11+F12+F13+F14 | G15: =SUM(G8:G14) | H15: =SUM(H8:H14) | I15: =SUM(I8:I14) | J15: =SUM(J8:J14) | K15: =K8+K9+K10+K11+K12+K13+K14 | L15: =SUM(L8:L14) | M15: =SUM(M8:M14) | N15: =SUM(N8:N14) | O15: =SUM(O8:O14) | P15: =P8+P9+P10+P11+P12+P13+P14 | Q15: =SUM(Q8:Q14) | R15: =SUM(R8:R14) | S15: =SUM(S8:S14) | T15: =SUM(T8:T14) | U15: =Q15+R15+S15+T15 | V15: =SUM(V8:V14) | W15: =SUM(W8:W14) | X15: =SUM(X8:X14) | Y15: =SUM(Y8:Y14)
A16: Less: Inter Segment Revenue | B16: 6519.3 | C16: 6513.1 | D16: 7278.5 | E16: 6844.3 | F16: =SUM(B16:E16) | G16: 6452.1 | H16: 6724.5 | I16: 5603.8 | J16: 6783.8 | K16: 8245 | L16: 7108.5 | M16: 7676.8 | N16: 8391.5 | O16: 8486.5 | P16: =SUM(L16:O16) | Q16: -7794.6 | R16: -8612.1 | S16: -8279.4 | T16: 35175.2 | U16: =SUM(Q16:T16) | V16: 26223 | W16: 62935 | X16: 151043 | Y16: 370055
A17: Net sales/income from Operations | B17: =B15-B16 | C17: =C15-C16 | D17: =D15-D16 | E17: =E15-E16 | F17: =SUM(B17:E17) | G17: =G15-G16 | H17: =H15-H16 | I17: =I15-I16 | J17: =J15-J16 | K17: =K15-K16 | L17: =L15-L16 | M17: =M15-M16 | N17: =N15-N16 | ... P17: =P15-P16 | Q17: =SUM(Q15:Q16) | R17: =SUM(R15:R16) | S17: =SUM(S15:S16) | T17: =T15-T16 | U17: =U15-U16 | V17: =V15-V16 | W17: =W15-W16 | X17: =X15-X16 | Y17: =Y15-Y16
A22: INCOME STATEMENT MODEL | B22: FY 2006-07 | H22: A | I22: FY 2007-08 | O22: A | P22: FY 2008-09 | V22: A | W22: FY 2009-10 | AC22: E | AD22: FY 2010-11 E | AE22: FY 2011-12 E | AF22: FY 2012-13 E | AG22: FY 2013-14 E
A23: (Figures in Rs. Crores.) | B23: Q1 | C23: Q2 | D23: 6M | E23: Q3 | F23: 9M | G23: Q4 | H23: FY 2007 | I23: Q1 | J23: Q2 | K23: 6M | L23: Q3 | M23: 9M | N23: Q4 | O23: FY 2008 | P23: Q1 | Q23: Q2 | R23: 6M | S23: Q3 | T23: 9M | U23: Q4 | V23: FY 2009 | W23: Q1 | X23: Q2 | Y23: 6M | Z23: Q3 | AA23: 9M | AB23: Q4 | AC23: FY 2010
B24: APR-JUN | C24: JUL-SEPT | E24: OCT-DEC | G24: JAN-MAR | I24: APR-JUN | J24: JUL-SEPT | L24: OCT-DEC | N24: JAN-MAR | P24: APR-JUN | Q24: JUL-SEPT | S24: OCT-DEC | U24: JAN-MAR | W24: APR-JUN | X24: JUL-SEPT | Z24: OCT-DEC | AB24: JAN-MAR | AD24: APR 1,2010-MAR 31,2011 | AE24: APR 1,2011-MAR 31,2012 | AF24: APR 1,2012-MAR 31,2013 | AG24: APR 1,2013-MAR 31,2014
A25: Net Sales/ Income from Operations | B25: 473034 | C25: 435830 | D25: =B25+C25 | E25: 510622 | F25: =D25+E25 | G25: 388340 | H25: 1604718 | I25: 424568 | J25: 452890 | K25: =I25+J25 | L25: 429833 | M25: =K25+L25 | N25: 493529 | O25: =M25+N25 | P25: 573071 | Q25: 617261 | R25: =P25+Q25 | S25: 581602 | T25: =R25+S25 | U25: 623395 | V25: 2377595 | W25: 604133 | X25: 622434 | Y25: =W25+X25 | Z25: 620571 | AA25: =Y25+Z25 | AB25: 625000 | AC25: =AA25+AB25 | AD25: 3263222.2 | AE25: 4405350 | AF25: 6167490 | AG25: 8942860
A26: Total Expenditure | B26: =B27+B28+B29+B30+B31 | C26: =C27+C28+C29+C30+C31 | D26: =D27+D28+D29+D30+D31 | E26: =E27+E28+E29+E30+E31 | F26: =F27+F28+F29+F30+F31 | G26: =G27+G28+G29+G30+G31 | H26: =H27+H28+H30+H29 | I26: =I27+I28+I30+I29+I61 | J26: =J27+J28+J30+J29+J31 | K26: 39178 | L26: =L27+L28+L30+L29+L31 | M26: =M27+M28+M30+M29+M31 | N26: =N27+N28+N30+N29+N31 | O26: =O27+O28+O30+O29+O31 | P26: =P27+P28+P30+P29+P31 | Q26: =Q27+Q28+U30+Q29+Q31 | R26: =R27+R28+R30+R29+R31 | S26: =S27+S28+S29+S30+S31 | T26: =T27+T28+T30+T29+T31 | U26: =U27+U28+U30+U29+U31 | V26: =V27+V28+V30+V29+V31 | W26: =W27+W28+W30+W29+W31 | X26: =X27+X28+X30+X29+X31 | Y26: =Y27+Y28+Y30+Y29+Y31 | Z26: =Z27+Z28+Z30+Z29+Z31 | AA26: =AA27+AA28+AA30+AA29+AA31 | ... AC26: =AC27+AC28+AC30+AC29+AC31 | AD26: =AD27+AD28+AD29+AD30+AD31 | AE26: =AE27+AE28+AE29+AE30+AE31 | AF26: =AF27+AF28+AF29+AF30+AF31 | AG26: =AG27+AG28+AG29+AG30+AG31
A27: (Increase) / Decrease In Stock In Trade & WIP | B27: 13288 | C27: -27170 | D27: =B27+C27 | E27: -5883 | F27: =D27+E27 | G27: 28380 | H27: -7526 | I27: 322 | J27: -563 | K27: =I27+J27 | L27: 5466 | M27: =K27+L27 | N27: -8213 | O27: =M27+N27 | P27: 2858 | Q27: -7349 | R27: =P27+Q27 | S27: 6256 | T27: =R27+S27 | U27: 2265 | V27: 500 | W27: 3839 | X27: 1354 | Y27: =W27+X27 | Z27: 849 | AA27: =Y27+Z27 | AB27: 1000 | AC27: =AA27+AB27 | AD27: 48948 | AE27: 74891 | AF27: 104847 | AG27: 169914
A28: Consumption of Raw Materials | B28: 356206 | C28: 329333 | D28: =B28+C28 | E28: 361270 | F28: =E28+D28 | G28: 278947 | H28: 1121412 | I28: 129390 | J28: 45029 | K28: =I28+J28 | L28: 47246 | M28: =L28+K28 | N28: 36070 | O28: 1191550 | P28: 49620 | Q28: 55114 | R28: =P28+Q28 | S28: 52395 | T28: =S28+R28 | U28: 55702 | V28: 212831 | W28: 51644 | X28: 58766 | Y28: =W28+X28 | Z28: 55557 | AA28: =Z28+Y28 | AB28: 56280 | AC28: =AA28+AB28 | AD28: 293690 | AE28: 396481 | AF28: 555074 | AG28: 804857
A29: Employees Cost | B29: 5513 | C29: 9047 | D29: =B29+C29 | E29: 6509 | F29: =E29+D29 | G29: 8163 | H29: =F29+G29 | I29: 6876 | J29: 8239 | K29: =I29+J29 | L29: 9854 | M29: =L29+K29 | N29: 22032 | O29: =M29+N29 | P29: 8663 | Q29: 11802 | R29: =P29+Q29 | S29: 32256 | T29: =S29+R29 | U29: 4946 | V29: =T29+U29 | W29: 13201 | X29: 12685 | Y29: =W29+X29 | Z29: 25387 | AA29: =Z29+Y29 | AB29: 40150 | AC29: =AA29+AB29 | AD29: 195793 | AE29: 308374 | AF29: 431724 | AG29: 626000
A30: Other Expenditure | B30: 30440 | C30: 35822 | D30: =B30+C30 | E30: 50547 | F30: =E30+D30 | G30: 43827 | H30: 161871 | I30: 35075 | J30: 58378 | K30: =I30+J30 | L30: 38138 | M30: =L30+K30 | N30: 38742 | O30: =M30+N30 | P30: 39182 | Q30: 47979 | R30: =P30+U30 | S30: 46490 | T30: =S30+R30 | U30: 60476 | V30: 194127 | W30: 48476 | X30: 44481 | Y30: =W30+X30 | Z30: 40451 | AA30: =Z30+Y30 | AB30: 50000 | AC30: =AA30+AB30 | AD30: 261058 | AE30: 396481 | AF30: 555074 | AG30: 804857
A31: Consumption of Materials/Purchase | B31: 0 | C31: 0 | D31: =B31+C31 | E31: 0 | F31: =E31+D31 | H31: =F31+G31 | I31: 235285 | J31: 253976 | K31: =I61+J31 | L31: 241903 | M31: =L31+K31 | N31: 288902 | O31: 0 | P31: 332805 | Q31: 362240 | R31: =P31+Q31 | S31: 417171 | T31: =S31+R31 | U31: 395823 | V31: =T31+U31 | W31: 378432 | X31: 401202 | Y31: =W31+X31 | Z31: 371276 | AA31: =Z31+Y31 | AB31: 375000 | AC31: =AA31+AB31 | AD31: 2023198 | AE31: 2643210 | AF31: 3823844 | AG31: 5365716
A32: OPBDIT | B32: =B25-B26 | C32: =C25-C26 | D32: =D25-D26 | E32: =E25-E26 | F32: =F25-F26 | G32: =G25-G26 | H32: =H25-H26 | I32: =I25-I26 | J32: =J25-J26 | K32: =L25-K26 | L32: =L25-L26 | M32: =M25-M26 | N32: =N25-N26 | O32: =O25-O26 | P32: =P25-P26 | Q32: =Q25-Q26 | R32: =R25-R26 | S32: =S25-S26 | ... AG32: =AG25-AG26
A33: OP Margin | B33: =(B32/B25)*100 | C33: =(C32/C25)*100 | D33: =(D32/D25)*100 | E33: =(E32/E25)*100 | F33: =(F32/F25)*100 | G33: =(G32/G25)*100 | H33: =H32/H25*100 | I33: =(I32/I25)*100 | J33: =(J32/J25)*100 | K33: =(K32/L25)*100 | L33: =(L32/L25)*100 | M33: =(M32/M25)*100 | N33: =(N32/N25)*100 | O33: =O32/O25*100 | P33: =(P32/P25)*100 | Q33: =(Q32/Q25)*100 | R33: =(R32/R25)*100 | S33: =(S32/S25)*100 | T33: =(T32/T25)*100 | U33: =(U32/U25)*100 | V33: =V32/V25*100 | W33: =(W32/W25)*100 | X33: =(X32/X25)*100 | Y33: =(Y32/Y25)*100 | Z33: =(Z32/Z25)*100 | AA33: =(AA32/AA25)*100 | AB33: =(AB32/AB25)*100 | AC33: =(AC32/AC25)*100 | AD33: =(AD32/AD25)*100 | ... AG33: =(AG32/AG25)*100
A34: Interest | B34: 2880 | C34: 2912 | D34: =B34+C34 | E34: 2705 | F34: =D34+E34 | G34: 2211 | H34: =F34+G34 | I34: 2040 | J34: 2009 | K34: =I34+J34 | L34: 1955 | M34: =K34+L34 | N34: 1953 | O34: =M34+N34 | P34: 1902 | Q34: 1890 | R34: =P34+Q34 | S34: 1851 | T34: =R34+S34 | U34: 3057 | V34: =T34+U34 | W34: 1792 | X34: 1785 | Y34: =W34+X34 | Z34: 1422 | AA34: =Y34+Z34 | AB34: 1790 | AC34: =AA34+AB34 | AD34: 7765 | AE34: 6594 | AF34: 5423 | AG34: 5889
A35: Depreciation | B35: 14081 | C35: 14357 | D35: =B35+C35 | E35: 14387 | F35: =D35+E35 | G35: 14713 | H35: =F35+G35 | I35: 14070 | J35: 14916 | K35: =I35+J35 | L35: 13869 | M35: =K35+L35 | N35: 14247 | O35: =M35+N35 | P35: 14296 | Q35: 13858 | R35: =P35+Q35 | S35: 13739 | T35: =R35+S35 | U35: 14098 | V35: =T35+U35 | W35: 14041 | X35: 14162 | Y35: =W35+X35 | Z35: 14091 | AA35: =Y35+Z35 | AB35: 14397 | AC35: 56691 | AD35: 57516 | AE35: 58466 | AF35: 59266 | AG35: 60050
A36: PBT From Operations | B36: =B32-(B34+B35) | C36: =C32-(C34+C35) | D36: =D32-(D34+D35) | E36: =E32-(E34+E35) | F36: =F32-(F34+F35) | G36: =G32-(G34+G35) | H36: =H32-(H34+H35) | I36: =I32-(I34+I35) | ... AG36: =AG32-(AG34+AG35)
A37: Other Income | B37: 8006 | C37: 16737 | D37: =B37+C37 | E37: 18463 | F37: =D37+E37 | G37: 11289 | H37: =F37+G37 | I37: 9127 | J37: 18060 | K37: =I37+J37 | L37: 18482 | M37: =K37+L37 | N37: 9966 | O37: =M37+N37 | P37: 11477 | Q37: 4333 | R37: =P37+Q37 | S37: 437 | T37: =R37+S37 | U37: 12964 | V37: =61177+18485 | W37: 1991 | X37: 2216 | Y37: =W37+X37 | Z37: 1787 | AA37: =Y37+Z37 | AB37: 2000 | AC37: =AA37+AB37 | AD37: 25000 | AE37: 30000 | AF37: 37000 | AG37: 43000
A38: PBT & Exceptional Item | B38: =B36+B37 | C38: =C36+C37 | D38: =D36+D37 | E38: =E36+E37 | F38: =F36+F37 | G38: =G36+G37 | H38: =H36+H37 | I38: =I36+I37 | ... AG38: =AG36+AG37
A39: Exceptional Item | B39: 0 | C39: 0 | D39: 0 | E39: 0 | F39: 0 | G39: 5540 | H39: 0 | I39: 0 | J39: 0 | K39: 0 | L39: 0 | M39: =K39+L39 | N39: 0 | O39: 0 | R39: =P39+Q39 | T39: =R39+S39 | V39: 0 | W39: 0 | X39: 0 | Y39: =W39+X39 | AA39: =Y39+Z39 | AD39: 0 | AE39: 0 | AF39: 0 | AG39: 0
A40: Profit Before Tax | B40: =B38+B39 | C40: =C38+C39 | D40: =D38+D39 | E40: =E38+E39 | F40: =F38+F39 | G40: =G38+G39 | H40: =H38+H39 | I40: =I38+I39 | ... O40: =O38+O39 | P40: =P38-P39 | Q40: =Q38-Q39 | R40: =R38-R39 | S40: =S38-S39 | T40: =T38-T39 | U40: =U38-U39 | V40: =V38-V39 | W40: =W38-W39 | ... AG40: =AG38-AG39
A41: Current Tax | B41: -26000 | C41: 13539 | D41: =B41+C41 | E41: -21238 | F41: =D41+E41 | G41: 13466 | H41: 47311 | I41: 27547 | J41: 29708 | K41: =I41+J41 | L41: 24150 | M41: =K41+L41 | N41: 43093 | O41: 125354 | P41: 44394 | Q41: 48928 | R41: =P41+Q41 | S41: 7561 | T41: =R41+S41 | U41: 37752 | V41: 140032 | W41: 33982 | X41: 30940 | Y41: =W41+X41 | Z41: 37111 | AA41: =Y41+Z41 | AB41: 46236.3 | AC41: =AA41+AB41 | AD41: =AD40*33% | AE41: =AE40*33% | AF41: =AF40*33% | AG41: =AG40*33%
A42: Deferred Tax | B42: 0 | C42: 0 | D42: =B42+C42 | E42: 0 | F42: =D42+E42 | G42: 0 | H42: =F42+G42 | I42: 514 | J42: 1684 | K42: =I42+J42 | L42: 3463 | M42: =K42+L42 | N42: -5760 | O42: 0 | P42: 999 | Q42: -1156 | R42: =P42+Q42 | S42: 1372 | T42: =R42+S42 | U42: 591 | V42: 0 | W42: -865 | X42: 412 | Y42: =W42+X42 | Z42: 2720 | AA42: =Y42+Z42 | AB42: 2720 | AC42: =AA42+AB42 | AD42: 0 | AE42: 0 | AF42: 0 | AG42: 0
A43: Fringe Benefit Tax | B43: 0 | C43: 0 | D43: =B43+C43 | E43: 0 | F43: =D43+E43 | G43: 0 | H43: =F43+G43 | I43: -1404 | J43: 320 | K43: =I43+J43 | L43: 139 | M43: =K43+L43 | N43: 191 | O43: 0 | P43: 142 | Q43: 169 | R43: =P43+Q43 | S43: 254 | T43: =R43+S43 | U43: 208 | V43: 0 | W43: 0 | Y43: =W43+X43 | AA43: =Y43+Z43 | AB43: 0 | AD43: 0 | AE43: 0 | AF43: 0 | AG43: 0
A44: Profit After Tax | B44: =B40-B41-B42-B43 | C44: =C40-C41-C42-C43 | D44: =D40-D41-D42-D43 | E44: =E40-E41-E42-E43 | F44: =F40-F41-F42-F43 | G44: =G40-G41-G42-G43 | H44: =H40-H41-H42-H43 | I44: =I40-I41-I42-I43 | ... AG44: =AG40-AG41-AG42-AG43
A45: NET PROFIT | B45: =B44 | C45: =C44 | D45: =D44 | E45: =E44 | F45: =F44 | G45: =G44 | H45: =H44 | I45: =I44 | ... AG45: =AG44
...

Sheet Segment Revenue Model
A1: GAIL (INDIA) LTD.
A2: Segment Revenue Model | I2: BSE | L2: BSE | M2: BSE | N2: BSE | O2: BSE | S2: BSE Q RES
A3: ( Figures in Rs. Millions.) | B3: 2006-07 | G3: 2007-08 | L3: 2008-09 | Q3: 2009-10
B4: APR - JUN | C4: JUL - SEPT | D4: OCT - DEC | E4: JAN - MAR | F4: 31st MAR '07 | G4: APR - JUN | H4: JUL - SEPT | I4: OCT - DEC | J4: JAN - MAR | K4: 31st MAR '07 | L4: APR - JUN | M4: JUL - SEPT | N4: OCT - DEC | O4: JAN - MAR | P4: 31st MAR '07 | Q4: APR - JUN | R4: JUL - SEPT | S4: OCT - DEC | T4: JAN - MAR | U4: 31st MAR '10 | V4: 31st MAR '11 | W4: 31st MAR '11 | X4: 31st MAR '11 | Y4: 31st MAR '11
B5: Q1 2006 | C5: Q2 2006 | D5: Q3 2006 | E5: Q4 2007 | F5: 2006-07A | G5: Q1 2007 | H5: Q2 2007 | I5: Q3 2007 | J5: Q4 2008 | K5: 2007-08A | L5: Q1 2008 | M5: Q2 2008 | N5: Q3 2008 | O5: Q4 2009 | P5: 2008-09A | Q5: Q1 2009 | R5: Q2 2009 | S5: Q3 2009 | T5: Q4 2010 | U5: 2009-10E | V5: 2010-11E | W5: 2011-12E | X5: 2012-13E | Y5: 2013-14E
A7: Segment Revenues
A8: Natural Gas Trading | B8: 30766.59 | C8: 29236.8 | D8: 31494.1 | E8: 29700.8 | F8: =SUM(B8:E8) | G8: 30067.23 | H8: 32486.93 | I8: 31120.1 | J8: 33801.6 | K8: =SUM(G8:J8) | L8: 41192.8 | M8: 44953.8 | N8: 49507.4 | O8: 47429.6 | P8: =SUM(L8:O8) | Q8: 46417.1 | R8: 49691.3 | S8: 45274.4 | T8: =U8-(Q8+R8+S8) | U8: =(U24+1)*P8 | V8: =(V24+1)*U8 | W8: =(W24+1)*V8 | X8: =(X24+1)*W8 | Y8: =(Y24+1)*X8
A9: Transmission Services - Natural Gas | B9: 5008.51 | C9: 4971.7 | D9: 6412.5 | E9: 4761.8 | F9: =SUM(B9:E9) | G9: 4894.67 | H9: 5288.57 | I9: 6021.6 | J9: 5761.5 | K9: =SUM(G9:J9) | L9: 6213.8 | M9: 6215 | N9: 6140.9 | O9: 6511 | P9: =SUM(L9:O9) | Q9: 7331.5 | R9: 8429.5 | S9: 8527.8 | T9: =U9-(Q9+R9+S9) | U9: =(U25+1)*P9 | V9: =(V25+1)*U9 | W9: =(W25+1)*V9 | X9: =(X25+1)*W9 | Y9: =(Y25+1)*X9
A10: Petrochemicals | B10: 5502.8 | C10: 5455.6 | D10: 7306 | E10: 7437.2 | F10: =SUM(B10:E10) | G10: 7783.9 | H10: 6402.2 | I10: 5378.1 | J10: 7467 | K10: =SUM(G10:J10) | L10: 8007.9 | M10: 6287.3 | N10: 6226.8 | O10: 6813.3 | P10: =SUM(L10:O10) | Q10: 6225.7 | R10: 6156.6 | S10: 7927.1 | T10: =U10-(Q10+R10+S10) | U10: =(U26+1)*P10 | V10: =(V26+1)*U10 | W10: =(W26+1)*V10 | X10: =(X26+1)*W10 | Y10: =(Y26+1)*X10
A11: LPG & Liquid Hydrocarbons | B11: 6406.2 | C11: 4219.1 | D11: 6261.1 | E11: 4332.1 | F11: =SUM(B11:E11) | G11: 6751.5 | H11: 7033.3 | I11: 5278.3 | J11: 7897.8 | K11: =SUM(G11:J11) | L11: 7997 | M11: 10902.1 | N11: 3329.9 | O11: 7671.4 | P11: =SUM(L11:O11) | Q11: 6839 | R11: 5150.9 | S11: 7102.6 | T11: =U11-(Q11+R11+S11) | U11: =(U27+1)*P11 | V11: =(V27+1)*U11 | W11: =(W27+1)*V11 | X11: =(X27+1)*W11 | Y11: =(Y27+1)*X11
A12: Transmission Services - LPG | B12: 714.9 | C12: 816 | D12: 993.7 | E12: 915 | F12: =SUM(B12:E12) | G12: 922.5 | H12: 896 | I12: 995.5 | J12: 1079.1 | K12: =SUM(G12:J12) | L12: 855.4 | M12: 905.9 | N12: 1064.9 | O12: 992.4 | P12: =SUM(L12:O12) | Q12: 1057.3 | R12: 1029.3 | S12: 1160.6 | T12: =U12-(Q12+R12+S12) | U12: =(U28+1)*3819 | V12: =(V28+1)*U12 | W12: =(W28+1)*V12 | X12: =(X28+1)*W12 | Y12: =(Y28+1)*X12
A13: Gailtel | B13: 50.8 | C13: 62.7 | D13: 70.7 | E13: 69.4 | F13: =SUM(B13:E13) | G13: 67.1 | H13: 76.4 | I13: 70.3 | J13: 71.7 | K13: =SUM(G13:J13) | L13: 65.3 | M13: 65.4 | N13: 63.5 | O13: 49.1 | P13: =SUM(L13:O13) | Q13: 37.8 | R13: 34.2 | S13: 28.5 | T13: =U13-(Q13+R13+S13) | U13: =(U29+1)*P13 | V13: =(V29+1)*U13 | W13: =(W29+1)*V13 | X13: =(X29+1)*W13 | Y13: =(Y29+1)*X13
A14: Others | B14: 742.1 | C14: 1607 | D14: 1764.2 | E14: 983.8 | F14: =SUM(B14:E14) | G14: 806 | H14: 1636.1 | I14: 1571.4 | J14: 1054.6 | K14: =SUM(G14:J14) | L14: 1231.1 | M14: 1929.3 | N14: 2526.2 | O14: 62.8 | P14: =SUM(L14:O14) | Q14: 100.4 | R14: 142.1 | S14: 136.8 | T14: =U14-(Q14+R14+S14) | U14: =(U30+1)*P14 | V14: =(V30+1)*U14 | W14: =(W30+1)*V14 | X14: =(X30+1)*W14 | Y14: =(Y30+1)*X14
A15: Total | B15: =SUM(B8:B14) | C15: =SUM(C8:C14) | D15: =SUM(D8:D14) | E15: =SUM(E8:E14) | F15: =F8+F9+F10+F11+F12+F13+F14 | G15: =SUM(G8:G14) | H15: =SUM(H8:H14) | I15: =SUM(I8:I14) | J15: =SUM(J8:J14) | K15: =K8+K9+K10+K11+K12+K13+K14 | L15: =SUM(L8:L14) | M15: =SUM(M8:M14) | N15: =SUM(N8:N14) | O15: =SUM(O8:O14) | P15: =P8+P9+P10+P11+P12+P13+P14 | Q15: =SUM(Q8:Q14) | R15: =SUM(R8:R14) | S15: =SUM(S8:S14) | T15: =SUM(T8:T14) | U15: =Q15+R15+S15+T15 | V15: =SUM(V8:V14) | W15: =(W31+1)*V15 | X15: =(X31+1)*W15 | Y15: =(Y31+1)*X15
A16: Less: Inter Segment Revenue | B16: 6519.3 | C16: 6513.1 | D16: 7278.5 | E16: 6844.3 | F16: =SUM(B16:E16) | G16: 6452.1 | H16: 6724.5 | I16: 5603.8 | J16: 6783.8 | K16: 8245 | L16: 7108.5 | M16: 7676.8 | N16: 8391.5 | O16: 8486.5 | P16: =SUM(L16:O16) | Q16: -7794.6 | R16: -8612.1 | S16: -8279.4 | T16: 35175.2 | U16: =SUM(Q16:T16) | V16: =(V32+1)*U16 | W16: =(W32+1)*V16 | X16: =(X32+1)*W16 | Y16: =(Y32+1)*X16
A17: Net sales/income from Operations | B17: =B15-B16 | C17: =C15-C16 | D17: =D15-D16 | E17: =E15-E16 | F17: =SUM(B17:E17) | G17: =G15-G16 | H17: =H15-H16 | I17: =I15-I16 | J17: =J15-J16 | K17: =K15-K16 | L17: =L15-L16 | M17: =M15-M16 | N17: =N15-N16 | ... P17: =P15-P16 | Q17: =SUM(Q15:Q16) | R17: =SUM(R15:R16) | S17: =SUM(S15:S16) | T17: =T15-T16 | U17: =U15-U16 | V17: =V15-V16 | W17: =W15-W16 | X17: =X15-X16 | Y17: =Y15-Y16
A22: Y/Y (%) Growth
A24: Natural Gas Trading | G24: =G8/B8-1 | H24: =H8/C8-1 | I24: =I8/D8-1 | J24: =J8/E8-1 | K24: =K8/F8-1 | L24: =L8/G8-1 | M24: =M8/H8-1 | N24: =N8/I8-1 | ... T24: =T8/O8-1 | U24: 0.12 | V24: 0.2 | W24: 0.2 | X24: 0.25 | Y24: 0.3
A25: Transmission Services - Natural Gas | G25: =G9/B9-1 | H25: =H9/C9-1 | I25: =I9/D9-1 | J25: =J9/E9-1 | K25: =K9/F9-1 | L25: =L9/G9-1 | M25: =M9/H9-1 | N25: =N9/I9-1 | ... T25: =T9/O9-1 | U25: 0.39 | V25: 0.3 | W25: 0.35 | X25: 0.35 | Y25: 0.38
A26: Petrochemicals | G26: =G10/B10-1 | H26: =H10/C10-1 | I26: =I10/D10-1 | J26: =J10/E10-1 | K26: =K10/F10-1 | L26: =L10/G10-1 | M26: =M10/H10-1 | N26: =N10/I10-1 | ... T26: =T10/O10-1 | U26: 0.0819 | V26: 0.1 | W26: 0.11 | X26: 0.12 | Y26: 0.14
A27: LPG & Liquid Hydrocarbons | G27: =G11/B11-1 | H27: =H11/C11-1 | I27: =I11/D11-1 | J27: =J11/E11-1 | K27: =K11/F11-1 | L27: =L11/G11-1 | M27: =M11/H11-1 | N27: =N11/I11-1 | ... T27: =T11/O11-1 | U27: 0.0032 | V27: 0.2 | W27: 0.15 | X27: 0.2 | Y27: 0.22
A28: Transmission Services - LPG | G28: =G12/B12-1 | H28: =H12/C12-1 | I28: =I12/D12-1 | J28: =J12/E12-1 | K28: =K12/F12-1 | L28: =L12/G12-1 | M28: =M12/H12-1 | N28: =N12/I12-1 | ... T28: =T12/O12-1 | U28: 0.1412 | V28: 0.15 | W28: 0.16 | X28: 0.18 | Y28: 0.2
A29: Gailtel | G29: =G13/B13-1 | H29: =H13/C13-1 | I29: =I13/D13-1 | J29: =J13/E13-1 | K29: =K13/F13-1 | L29: =L13/G13-1 | M29: =M13/H13-1 | N29: =N13/I13-1 | ... T29: =T13/O13-1 | U29: -0.207 | V29: 0.15 | W29: 0.1 | X29: 0.12 | Y29: 0.13
A30: Others | G30: =G14/B14-1 | H30: =H14/C14-1 | I30: =I14/D14-1 | J30: =J14/E14-1 | K30: =K14/F14-1 | L30: =L14/G14-1 | M30: =M14/H14-1 | N30: =N14/I14-1 | ... T30: =T14/O14-1 | U30: -0.93 | V30: 0.1 | W30: 0.12 | X30: 0.12 | Y30: 0.14
A31: Total | G31: =G15/B15-1 | H31: =H15/C15-1 | I31: =I15/D15-1 | J31: =J15/E15-1 | K31: =K15/F15-1 | L31: =L15/G15-1 | M31: =M15/H15-1 | N31: =N15/I15-1 | ... T31: =T15/O15-1 | U31: 0.0245 | V31: 0.11 | W31: 0.205 | X31: 0.24735 | Y31: 0.29152
A32: Less: Inter Segment Revenue | G32: =G16/B16-1 | H32: =H16/C16-1 | I32: =I16/D16-1 | J32: =J16/E16-1 | K32: =K16/F16-1 | L32: =L16/G16-1 | M32: =M16/H16-1 | N32: =N16/I16-1 | ... T32: =T16/O16-1 | U32: 0.9 | V32: 1.5 | W32: 1.4 | X32: 1.4 | Y32: 1.45
A33: Net sales/income from Operations | G33: =G17/B17-1 | H33: =H17/C17-1 | I33: =I17/D17-1 | J33: =J17/E17-1 | K33: =K17/F17-1 | L33: =L17/G17-1 | M33: =M17/H17-1 | N33: =N17/I17-1 | ... U33: =U17/P17-1 | V33: =V17/U17-1 | W33: =W17/V17-1 | X33: =X17/W17-1 | Y33: =Y17/X17-1
A35: Segment Revenue As % of Total Revenues
A37: Natural Gas Trading | G37: =G8/G17 | H37: =H8/H17 | I37: =I8/I17 | J37: =J8/J17 | K37: =K8/K17 | L37: =L8/L17 | M37: =M8/M17 | N37: =N8/N17 | ... Y37: =Y8/Y17
A38: Transmission Services - Natural Gas | G38: =G9/G17 | H38: =H9/H17 | I38: =I9/I17 | J38: =J9/J17 | K38: =K9/K17 | L38: =L9/L17 | M38: =M9/M17 | N38: =N9/N17 | ... Y38: =Y9/Y17
A39: Petrochemicals | G39: =G10/G17 | H39: =H10/H17 | I39: =I10/I17 | J39: =J10/J17 | K39: =K10/K17 | L39: =L10/L17 | M39: =M10/M17 | N39: =N10/N17 | ... Y39: =Y10/Y17
A40: LPG & Liquid Hydrocarbons | G40: =G11/G17 | H40: =H11/H17 | I40: =I11/I17 | J40: =J11/J17 | K40: =K11/K17 | L40: =L11/L17 | M40: =M11/M17 | N40: =N11/N17 | ... Y40: =Y11/Y17
A41: Transmission Services - LPG | G41: =G12/G17 | H41: =H12/H17 | I41: =I12/I17 | J41: =J12/J17 | K41: =K12/K17 | L41: =L12/L17 | M41: =M12/M17 | N41: =N12/N17 | ... T41: =T12/T17 | V41: =V12/V17 | W41: =W12/W17 | X41: =X12/X17 | Y41: =Y12/Y17
A42: Gailtel | G42: =G13/G17 | H42: =H13/H17 | I42: =I13/I17 | J42: =J13/J17 | K42: =K13/K17 | L42: =L13/L17 | M42: =M13/M17 | N42: =N13/N17 | ... Y42: =Y13/Y17
A43: Others | G43: =G14/G17 | H43: =H14/H17 | I43: =I14/I17 | J43: =J14/J17 | K43: =K14/K17 | L43: =L14/L17 | M43: =M14/M17 | N43: =N14/N17 | ... Y43: =Y14/Y17
A44: Total | G44: =G15/G17 | H44: =H15/H17 | I44: =I15/I17 | J44: =J15/J17 | K44: =K15/K17 | L44: =L15/L17 | M44: =M15/M17 | N44: =N15/N17 | ... Y44: =Y15/Y17
A45: Less: Inter Segment Revenue | G45: =G16/G17 | H45: =H16/H17 | I45: =I16/I17 | J45: =J16/J17 | K45: =K16/K17 | L45: =L16/L17 | M45: =M16/M17 | N45: =N16/N17 | ... Y45: =Y16/Y17
A46: Net sales/income from Operations | G46: =G17/G17 | H46: =H17/H17 | I46: =I17/I17 | J46: =J17/J17 | K46: =K17/K17 | L46: =L17/L17 | M46: =M17/M17 | N46: =N17/N17 | ... Y46: =Y17/Y17
A50: Segment Results
A51: Natural Gas Trading | B51: 48171 | C51: 6135 | D51: 5634 | E51: 4924 | F51: =SUM(C51:E51) | G51: 39304 | H51: 46584 | I51: 402.3 | J51: 6915 | K51: =G51+H51+I51+I52+J52+J51 | L51: 947.5 | M51: 1113.4 | N51: 823.1 | O51: 592 | P51: =SUM(L51:O51) | Q51: 1062.6 | R51: 1104.7 | S51: 1179.2 | T51: 1286.7 | U51: =SUM(Q51:T51) | V51: 5104 | W51: 5673 | X51: 6123 | Y51: 6700
...

Sheet INCOME STATEMENT
A1: GAIL (INDIA) LTD.
A3: INCOME STATEMENT | B3: FY 2006-07 | H3: A | I3: FY 2007-08 | O3: A | P3: FY 2008-09 | V3: A | W3: FY 2009-10 | AC3: E | AD3: FY 2010-11 E | AE3: FY 2011-12 E | AF3: FY 2012-13 E | AG3: FY 2013-14 E
A4: (Figures in Rs. Crores.) | B4: Q1 | C4: Q2 | D4: 6M | E4: Q3 | F4: 9M | G4: Q4 | H4: FY 2007 | I4: Q1 | J4: Q2 | K4: 6M | L4: Q3 | M4: 9M | N4: Q4 | O4: FY 2008 | P4: Q1 | Q4: Q2 | R4: 6M | S4: Q3 | T4: 9M | U4: Q4 | V4: FY 2009 | W4: Q1 | X4: Q2 | Y4: 6M | Z4: Q3 | AA4: 9M | AB4: Q4 | AC4: FY 2010
B5: APR-JUN | C5: JUL-SEP | E5: OCT-DEC | G5: JAN-MAR | I5: APR-JUN | J5: JUL-SEPT | L5: OCT-DEC | N5: JAN-MAR | P5: APR-JUN | Q5: JUL-SEPT | S5: OCT-DEC | U5: JAN-MAR | W5: APR-JUN | X5: JUL-SEPT | Z5: OCT-DEC | AB5: JAN-MAR | AD5: APR-MAR | AE5: APR-MAR | AF5: APR-MAR | AG5: APR-MAR
A6: Net Sales/ Income from Operations | B6: 473034 | C6: 435830 | D6: =B6+C6 | E6: 510622 | F6: =D6+E6 | G6: 388340 | H6: 1604718 | I6: 424568 | J6: 452890 | K6: =I6+J6 | L6: 429833 | M6: =K6+L6 | N6: 493529 | O6: =M6+N6 | P6: 573071 | Q6: 617261 | R6: =P6+Q6 | S6: 581602 | T6: =R6+S6 | U6: 623395 | V6: 2377595 | W6: 604133 | X6: 622434 | Y6: =W6+X6 | Z6: 620571 | AA6: =Y6+Z6 | AB6: 625000 | AC6: =AA6+AB6 | AD6: 3263222.2 | AE6: 4405350 | AF6: 6167490 | AG6: 8942860
A7: % full year | B7: =B6/$H6*100 | C7: =C6/$H6*100 | D7: =D6/$H6*100 | E7: =E6/$H6*100 | F7: =F6/$H6*100 | G7: =G6/$H6*100 | H7: =F7+G7 | I7: =I6/O6*100 | J7: =J6/$O6*100 | K7: =K6/$O6*100 | L7: =L6/$O6*100 | M7: =M6/$O6*100 | N7: =N6/$O6*100 | O7: =M7+N7 | P7: =P6/$V6*100 | Q7: =Q6/$V6*100 | R7: =R6/$V6*100 | S7: =S6/$V6*100 | T7: =T6/$V6*100 | U7: =U6/$V6*100 | V7: =T7+U7 | W7: =W6/$AC6*100 | X7: =X6/$AC6*100 | Y7: =Y6/$AC6*100 | Z7: =Z6/$AC6*100 | AA7: =AA6/$AC6*100 | AB7: =AB6/$AC6*100 | AC7: =AA7+AB7
A8: % growth y-o-y | H8: =(H6/#REF!-1)*100 | I8: =(I6/B6-1)*100 | J8: =(J6/C6-1)*100 | K8: =(L6/D6-1)*100 | L8: =L6/E6-1*100 | M8: =(M6/F6-1)*100 | N8: =(N6/G6-1)*100 | O8: =(O6/H6-1)*100 | P8: =(P6/I6-1)*100 | Q8: =(Q6/J6-1)*100 | R8: =(R6/L6-1)*100 | S8: =(S6/L6-1)*100 | T8: =(T6/M6-1)*100 | U8: =(U6/N6-1)*100 | V8: =(V6/O6-1)*100 | W8: =(W6/P6-1)*100 | X8: =(X6/Q6-1)*100 | Y8: =(Y6/R6-1)*100 | Z8: =(Z6/S6-1)*100 | ... AC8: =(AC6/V6-1)*100 | AD8: =(AD6/AC6-1)*100 | AE8: =(AE6/AD6-1)*100 | AF8: =(AF6/AE6-1)*100 | AG8: =(AG6/AF6-1)*100
A9: % growth q-o-q | C9: =(C6/B6-1)*100 | E9: =(E6/C6-1)*100 | G9: =(G6/E6-1)*100 | I9: =(I6/G6-1)*100 | J9: =(J6/I6-1)*100 | L9: =(L6/J6-1)*100 | N9: =(N6/L6-1)*100 | P9: =(P6/N6-1)*100 | Q9: =(Q6/P6-1)*100 | S9: =(S6/Q6-1)*100 | U9: =(U6/S6-1)*100 | W9: =(W6/U6-1)*100 | X9: =(X6/W6-1)*100 | Z9: =(Z6/X6-1)*100 | AB9: =(AB6/Z6-1)*100
A10: Total Expenditure | B10: =B11+B13+B15+B17+B19 | C10: =C11+C13+C15+C17+C19 | D10: =D11+D13+D15+D17+D19 | E10: =E11+E13+E15+E17+E19 | F10: =F11+F13+F15+F17+F19 | G10: =G11+G13+G15+G17+G19 | H10: =H11+H13+H17+H15 | I10: =I11+I13+I17+I15+I51 | J10: =J11+J13+J17+J15+J19 | K10: 39178 | L10: =L11+L13+L17+L15+L19 | M10: =M11+M13+M17+M15+M19 | N10: =N11+N13+N17+N15+N19 | O10: =O11+O13+O17+O15+O19 | P10: =P11+P13+P17+P15+P19 | Q10: =Q11+Q13+U17+Q15+Q19 | R10: =R11+R13+R17+R15+R19 | S10: =S11+S13+S15+S17+S19 | T10: =T11+T13+T17+T15+T19 | U10: =U11+U13+U17+U15+U19 | V10: =V11+V13+V17+V15+V19 | W10: =W11+W13+W17+W15+W19 | X10: =X11+X13+X17+X15+X19 | Y10: =Y11+Y13+Y17+Y15+Y19 | Z10: =Z11+Z13+Z17+Z15+Z19 | AA10: =AA11+AA13+AA17+AA15+AA19 | ... AC10: =AC11+AC13+AC17+AC15+AC19 | AD10: =AD11+AD13+AD15+AD17+AD19 | AE10: =AE11+AE13+AE15+AE17+AE19 | AF10: =AF11+AF13+AF15+AF17+AF19 | AG10: =AG11+AG13+AG15+AG17+AG19
A11: (Increase) / Decrease In Stock In Trade & WIP | B11: 13288 | C11: -27170 | D11: =B11+C11 | E11: -5883 | F11: =D11+E11 | G11: 28380 | H11: -7526 | I11: 322 | J11: -563 | K11: =I11+J11 | L11: 5466 | M11: =K11+L11 | N11: -8213 | O11: =M11+N11 | P11: 2858 | Q11: -7349 | R11: =P11+Q11 | S11: 6256 | T11: =R11+S11 | U11: 2265 | V11: 500 | W11: 3839 | X11: 1354 | Y11: =W11+X11 | Z11: 849 | AA11: =Y11+Z11 | AB11: 1000 | AC11: =AA11+AB11 | AD11: =AD6*AD12% | AE11: =AE6*AE12% | AF11: =AF6*AF12% | AG11: =AG6*AG12%
A12: % of Revenue | B12: =B11/B$6% | C12: =C11/C$6% | D12: =D11/D$6% | E12: =E11/E$6% | F12: =F11/F$6% | G12: =G11/G$6% | H12: =H11/H$6% | I12: =I11/I$6% | J12: =J11/J$6% | K12: =K11/L$6% | L12: =L11/L6% | M12: =M11/M$6% | N12: =N11/N$6% | O12: =O11/O$6% | P12: =P11/P$6% | Q12: =Q11/Q$6% | R12: =R11/R$6% | S12: =S11/S$6% | T12: =T11/T$6% | ... V12: =V11/V$6% | W12: =(W11/W6)*100 | X12: =X11/X$6% | Y12: =Y11/Y$6% | Z12: =Z11/Z$6% | AA12: =AA11/AA$6% | AB12: =AB11/AB$6% | AC12: =AC11/AC$6% | AD12: 1.5 | AE12: 1.7 | AF12: 1.7 | AG12: 1.9
A13: Consumption of Raw Materials | B13: 356206 | C13: 329333 | D13: =B13+C13 | E13: 361270 | F13: =E13+D13 | G13: 278947 | H13: 1121412 | I13: 129390 | J13: 45029 | K13: =I13+J13 | L13: 47246 | M13: =L13+K13 | N13: 36070 | O13: 1191550 | P13: 49620 | Q13: 55114 | R13: =P13+Q13 | S13: 52395 | T13: =S13+R13 | U13: 55702 | V13: 212831 | W13: 51644 | X13: 58766 | Y13: =W13+X13 | Z13: 55557 | AA13: =Z13+Y13 | AB13: 56280 | AC13: =AA13+AB13 | AD13: =AD6*AD14% | AE13: =AE6*AE14% | AF13: =AF6*AF14% | AG13: =AG6*AG14%
A14: % of Revenue | B14: =B13/B$6% | C14: =C13/C$6% | D14: =D13/D$6% | E14: =E13/E$6% | F14: =F13/F$6% | G14: =G13/G$6% | H14: =H13/H$6% | I14: =I13/I$6% | J14: =J13/J$6% | K14: =K13/L$6% | L14: =L13/L6% | M14: =M13/M$6% | N14: =N13/N$6% | O14: =O13/O$6% | P14: =P13/P$6% | Q14: =Q13/Q$6% | R14: =R13/R$6% | S14: =S13/S$6% | T14: =T13/T$6% | ... AC14: =AC13/AC$6% | AD14: 9 | AE14: 9 | AF14: 9 | AG14: 9
A15: Employees Cost | B15: 5513 | C15: 9047 | D15: =B15+C15 | E15: 6509 | F15: =E15+D15 | G15: 8163 | H15: =F15+G15 | I15: 6876 | J15: 8239 | K15: =I15+J15 | L15: 9854 | M15: =L15+K15 | N15: 22032 | O15: =M15+N15 | P15: 8663 | Q15: 11802 | R15: =P15+Q15 | S15: 32256 | T15: =S15+R15 | U15: 4946 | V15: =T15+U15 | W15: 13201 | X15: 12685 | Y15: =W15+X15 | Z15: 25387 | AA15: =Z15+Y15 | AB15: 40150 | AC15: =AA15+AB15 | AD15: =AD6*AD16% | AE15: =AE6*AE16% | AF15: =AF6*AF16% | AG15: =AG6*AG16%
A16: % of Revenue | B16: =B15/B$6% | C16: =C15/C$6% | D16: =D15/D$6% | E16: =E15/E$6% | F16: =F15/F$6% | G16: =G15/G$6% | H16: =H15/H$6% | I16: =I15/I$6% | J16: =J15/J$6% | K16: =K15/L$6% | L16: =L15/L6% | M16: =M15/M$6% | N16: =N15/N$6% | O16: =O15/O$6% | P16: =P15/P$6% | Q16: =Q15/Q$6% | R16: =R15/R$6% | S16: =S15/S$6% | T16: =T15/T$6% | ... AC16: =AC15/AC$6% | AD16: 6 | AE16: 7 | AF16: 7 | AG16: 7
A17: Other Expenditure | B17: 30440 | C17: 35822 | D17: =B17+C17 | E17: 50547 | F17: =E17+D17 | G17: 43827 | H17: 161871 | I17: 35075 | J17: 58378 | K17: =I17+J17 | L17: 38138 | M17: =L17+K17 | N17: 38742 | O17: =M17+N17 | P17: 39182 | Q17: 47979 | R17: =P17+U17 | S17: 46490 | T17: =S17+R17 | U17: 60476 | V17: 194127 | W17: 48476 | X17: 44481 | Y17: =W17+X17 | Z17: 40451 | AA17: =Z17+Y17 | AB17: 50000 | AC17: =AA17+AB17 | AD17: =AD6*AD18% | AE17: =AE6*AE18% | AF17: =AF6*AF18% | AG17: =AG6*AG18%
A18: % of Revenue | B18: =B17/B$6% | C18: =C17/C$6% | D18: =D17/D$6% | E18: =E17/E$6% | F18: =F17/F$6% | G18: =G17/G$6% | H18: =H17/H$6% | I18: =I17/I$6% | J18: =J17/J$6% | K18: =K17/L$6% | L18: =L17/L6% | M18: =M17/M$6% | N18: =N17/N$6% | O18: =O17/O$6% | P18: =P17/P$6% | Q18: =U17/Q$6% | R18: =R17/R$6% | S18: =S17/S$6% | T18: =T17/T$6% | U18: =U17/U6% | V18: =V17/V$6% | W18: =W17/W$6% | X18: =X17/X$6% | Y18: =Y17/Y$6% | Z18: =Z17/Z$6% | AA18: =AA17/AA$6% | AB18: =AB17/AB$6% | AC18: =AC17/AC$6% | AD18: 8 | AE18: 9 | AF18: 9 | AG18: 9
A19: Consumption of Materials/Purchase | B19: 0 | C19: 0 | D19: =B19+C19 | E19: 0 | F19: =E19+D19 | H19: =F19+G19 | I19: 235285 | J19: 253976 | K19: =I51+J19 | L19: 241903 | M19: =L19+K19 | N19: 288902 | O19: 0 | P19: 332805 | Q19: 362240 | R19: =P19+Q19 | S19: 417171 | T19: =S19+R19 | U19: 395823 | V19: =T19+U19 | W19: 378432 | X19: 401202 | Y19: =W19+X19 | Z19: 371276 | AA19: =Z19+Y19 | AB19: 375000 | AC19: =AA19+AB19 | AD19: =AD6*AD20% | AE19: =AE6*AE20% | AF19: =AF6*AF20% | AG19: =AG6*AG20%
A20: % of Revenue | B20: =B51/B$6% | C20: =C51/C$6% | D20: =D19/D$6% | E20: =E51/E$6% | F20: =F19/F$6% | G20: =G19/G$6% | H20: =H19/H$6% | I20: =I51/I$6% | J20: =J19/J$6% | K20: =K19/L$6% | L20: =L19/L6% | M20: =M19/M$6% | N20: =N19/N$6% | O20: =O19/O$6% | P20: =P19/P$6% | Q20: =Q19/Q$6% | R20: =R19/R$6% | S20: =S19/S$6% | T20: =T19/T$6% | ... AC20: =AC19/AC$6% | AD20: 62 | AE20: 60 | AF20: 62 | AG20: 60
A21: OPBDIT | B21: =B6-B10 | C21: =C6-C10 | D21: =D6-D10 | E21: =E6-E10 | F21: =F6-F10 | G21: =G6-G10 | H21: =H6-H10 | I21: =I6-I10 | J21: =J6-J10 | K21: =L6-K10 | L21: =L6-L10 | M21: =M6-M10 | N21: =N6-N10 | O21: =O6-O10 | P21: =P6-P10 | Q21: =Q6-Q10 | R21: =R6-R10 | S21: =S6-S10 | ... AG21: =AG6-AG10
A22: % full year (OR) %Y-o-Y | B22: =B21/$H21*100 | C22: =C21/$H21*100 | D22: =D21/$H21*100 | E22: =E21/$H21*100 | F22: =F21/$H21*100 | G22: =G21/$H21*100 | H22: =F22+G22 | I22: =I21/$O21*100 | J22: =J21/$O21*100 | K22: =K21/$O21*100 | L22: =L21/$O21*100 | M22: =M21/$O21*100 | N22: =N21/$O21*100 | O22: =M22+N22 | P22: =P21/$V21*100 | Q22: =Q21/$V21*100 | R22: =R21/$V21*100 | S22: =S21/$V21*100 | T22: =T21/$V21*100 | U22: =U21/$V21*100 | V22: =T22+U22 | W22: =W21/$AC21*100 | X22: =X21/$AC21*100 | Y22: =Y21/$AC21*100 | Z22: =Z21/$AC21*100 | AA22: =AA21/$AC21*100 | AB22: =AB21/$AC21*100 | AC22: =AA22+AB22
A23: % growth y-o-y | I23: =(I21/B21-1)*100 | J23: =(J21/C21-1)*100 | K23: =(K21/D21-1)*100 | L23: =(L21/E21-1)*100 | M23: =(M21/F21-1)*100 | N23: =(N21/G21-1)*100 | O23: =(O21/H21-1)*100 | P23: =(P21/I21-1)*100 | ... AC23: =(AC21/V21-1)*100 | AD23: =((AD21/AC21)-1)*100 | AE23: =((AE21/AD21)-1)*100 | AF23: =((AF21/AE21)-1)*100 | AG23: =((AG21/AF21)-1)*100
A24: % growth q-o-q | C24: =(C21/B21-1)*100 | E24: =(E21/C21-1)*100 | G24: =(G21/E21-1)*100 | I24: =(I21/G21-1)*100 | J24: =(J21/I21-1)*100 | L24: =(L21/J21-1)*100 | N24: =(N21/L21-1)*100 | P24: =(P21/N21-1)*100 | Q24: =(Q21/P21-1)*100 | S24: =(S21/Q21-1)*100 | U24: =(U21/S21-1)*100 | W24: =(W21/U21-1)*100 | X24: =(X21/W21-1)*100 | Z24: =(Z21/X21-1)*100 | AB24: =(AB21/Z21-1)*100
A25: OP Margin | B25: =(B21/B6)*100 | C25: =(C21/C6)*100 | D25: =(D21/D6)*100 | E25: =(E21/E6)*100 | F25: =(F21/F6)*100 | G25: =(G21/G6)*100 | H25: =H21/H6*100 | I25: =(I21/I6)*100 | J25: =(J21/J6)*100 | K25: =(K21/L6)*100 | L25: =(L21/L6)*100 | M25: =(M21/M6)*100 | N25: =(N21/N6)*100 | O25: =O21/O6*100 | P25: =(P21/P6)*100 | Q25: =(Q21/Q6)*100 | R25: =(R21/R6)*100 | S25: =(S21/S6)*100 | T25: =(T21/T6)*100 | U25: =(U21/U6)*100 | V25: =V21/V6*100 | W25: =(W21/W6)*100 | X25: =(X21/X6)*100 | Y25: =(Y21/Y6)*100 | Z25: =(Z21/Z6)*100 | AA25: =(AA21/AA6)*100 | AB25: =(AB21/AB6)*100 | AC25: =(AC21/AC6)*100 | AD25: =(AD21/AD6)*100 | ... AG25: =(AG21/AG6)*100
A26: Interest | B26: 2880 | C26: 2912 | D26: =B26+C26 | E26: 2705 | F26: =D26+E26 | G26: 2211 | H26: =F26+G26 | I26: 2040 | J26: 2009 | K26: =I26+J26 | L26: 1955 | M26: =K26+L26 | N26: 1953 | O26: =M26+N26 | P26: 1902 | Q26: 1890 | R26: =P26+Q26 | S26: 1851 | T26: =R26+S26 | U26: 3057 | V26: =T26+U26 | W26: 1792 | X26: 1785 | Y26: =W26+X26 | Z26: 1422 | AA26: =Y26+Z26 | AB26: 1790 | AC26: =AA26+AB26 | AD26: 7765 | AE26: 6594 | AF26: 5423 | AG26: 5889
A27: Depreciation | B27: 14081 | C27: 14357 | D27: =B27+C27 | E27: 14387 | F27: =D27+E27 | G27: 14713 | H27: =F27+G27 | I27: 14070 | J27: 14916 | K27: =I27+J27 | L27: 13869 | M27: =K27+L27 | N27: 14247 | O27: =M27+N27 | P27: 14296 | Q27: 13858 | R27: =P27+Q27 | S27: 13739 | T27: =R27+S27 | U27: 14098 | V27: =T27+U27 | W27: 14041 | X27: 14162 | Y27: =W27+X27 | Z27: 14091 | AA27: =Y27+Z27 | AB27: 14397 | AC27: 56691 | AD27: 57516 | AE27: 58466 | AF27: 59266 | AG27: 60050
A28: PBT From Operations | B28: =B21-(B26+B27) | C28: =C21-(C26+C27) | D28: =D21-(D26+D27) | E28: =E21-(E26+E27) | F28: =F21-(F26+F27) | G28: =G21-(G26+G27) | H28: =H21-(H26+H27) | I28: =I21-(I26+I27) | ... AG28: =AG21-(AG26+AG27)
A29: Other Income | B29: 8006 | C29: 16737 | D29: =B29+C29 | E29: 18463 | F29: =D29+E29 | G29: 11289 | H29: =F29+G29 | I29: 9127 | J29: 18060 | K29: =I29+J29 | L29: 18482 | M29: =K29+L29 | N29: 9966 | O29: =M29+N29 | P29: 11477 | Q29: 4333 | R29: =P29+Q29 | S29: 437 | T29: =R29+S29 | U29: 12964 | V29: =61177+18485 | W29: 1991 | X29: 2216 | Y29: =W29+X29 | Z29: 1787 | AA29: =Y29+Z29 | AB29: 2000 | AC29: =AA29+AB29 | AD29: 25000 | AE29: 30000 | AF29: 37000 | AG29: 43000
A30: PBT & Exceptional Item | B30: =B28+B29 | C30: =C28+C29 | D30: =D28+D29 | E30: =E28+E29 | F30: =F28+F29 | G30: =G28+G29 | H30: =H28+H29 | I30: =I28+I29 | ... AG30: =AG28+AG29
A31: Exceptional Item | B31: 0 | C31: 0 | D31: 0 | E31: 0 | F31: 0 | H31: 0 | I31: 0 | J31: 0 | K31: 0 | L31: 0 | M31: =K31+L31 | N31: 0 | O31: 0 | R31: =P31+Q31 | T31: =R31+S31 | V31: 0 | W31: 0 | X31: 0 | Y31: =W31+X31 | AA31: =Y31+Z31 | AD31: 0 | AE31: 0 | AF31: 0 | AG31: 0
A32: Profit Before Tax | B32: =B30+B31 | C32: =C30+C31 | D32: =D30+D31 | E32: =E30+E31 | F32: =F30+F31 | G32: =G30+G51 | H32: =H30+H31 | I32: =I30+I31 | J32: =J30+J31 | K32: =K30+K31 | L32: =L30+L31 | M32: =M30+M31 | N32: =N30+N31 | O32: =O30+O31 | P32: =P30-P31 | Q32: =Q30-Q31 | R32: =R30-R31 | S32: =S30-S31 | T32: =T30-T31 | U32: =U30-U31 | V32: =V30-V31 | W32: =W30-W31 | ... AG32: =AG30-AG31
A33: Current Tax | B33: -26000 | C33: 13539 | D33: =B33+C33 | E33: -21238 | F33: =D33+E33 | G33: 13466 | H33: 47311 | I33: 27547 | J33: 29708 | K33: =I33+J33 | L33: 24150 | M33: =K33+L33 | N33: 43093 | O33: 125354 | P33: 44394 | Q33: 48928 | R33: =P33+Q33 | S33: 7561 | T33: =R33+S33 | U33: 37752 | V33: 140032 | W33: 33982 | X33: 30940 | Y33: =W33+X33 | Z33: 37111 | AA33: =Y33+Z33 | AB33: 46236.3 | AC33: =AA33+AB33 | AD33: =AD32*33% | AE33: =AE32*33% | AF33: =AF32*33% | AG33: =AG32*33%
A34: Deferred Tax | B34: 0 | C34: 0 | D34: =B34+C34 | E34: 0 | F34: =D34+E34 | G34: 0 | H34: =F34+G34 | I34: 514 | J34: 1684 | K34: =I34+J34 | L34: 3463 | M34: =K34+L34 | N34: -5760 | O34: 0 | P34: 999 | Q34: -1156 | R34: =P34+Q34 | S34: 1372 | T34: =R34+S34 | U34: 591 | V34: 0 | W34: -865 | X34: 412 | Y34: =W34+X34 | Z34: 2720 | AA34: =Y34+Z34 | AB34: 2720 | AC34: =AA34+AB34 | AD34: 0 | AE34: 0 | AF34: 0 | AG34: 0
A35: Fringe Benefit Tax | B35: 0 | C35: 0 | D35: =B35+C35 | E35: 0 | F35: =D35+E35 | G35: 0 | H35: =F35+G35 | I35: -1404 | J35: 320 | K35: =I35+J35 | L35: 139 | M35: =K35+L35 | N35: 191 | O35: 0 | P35: 142 | Q35: 169 | R35: =P35+Q35 | S35: 254 | T35: =R35+S35 | U35: 208 | V35: 0 | W35: 0 | Y35: =W35+X35 | AA35: =Y35+Z35 | AB35: 0 | AD35: 0 | AE35: 0 | AF35: 0 | AG35: 0
A36: Eff tax rate - non deferred | B36: =B33/B32% | C36: =C33/C32% | D36: =D33/D32% | E36: =E33/E32% | F36: =F33/F32% | G36: =G33/G32% | H36: =H33/H32% | I36: =I33/I32% | ... AG36: =AG33/AG32%
A37: Eff tax rate (%) | B37: =((B33+B34+B35)/B32)*100 | C37: =((C33+C34+C35)/C32)*100 | D37: =((D33+D34+D35)/D32)*100 | E37: =((E33+E34+E35)/E32)*100 | F37: =((F33+F34+F35)/F32)*100 | G37: =((G33+G34+G35)/G32)*100 | H37: =((H33+H34+H35)/H32)*100 | I37: =((I33+I34+I35)/I32)*100 | ... AG37: =((AG33+AG34+AG35)/AG32)*100
A38: Profit After Tax | B38: =B32-B33-B34-B35 | C38: =C32-C33-C34-C35 | D38: =D32-D33-D34-D35 | E38: =E32-E33-E34-E35 | F38: =F32-F33-F34-F35 | G38: =G32-G33-G34-G35 | H38: =H32-H33-H34-H35 | I38: =I32-I33-I34-I35 | ... AG38: =AG32-AG33-AG34-AG35
A39: Prior Period Items | B39: 0 | C39: 0 | D39: =B39+C39 | E39: 0 | F39: 0 | G39: 0 | H39: =F39+G39 | I39: 0 | J39: 0 | K39: 0 | L39: 0 | M39: 0 | N39: 0 | O39: 0 | P39: 0 | Q39: -2672.5 | R39: 0 | S39: 0 | T39: 0 | U39: 0 | V39: 0 | W39: 0 | X39: 0 | Y39: 0 | Z39: 0 | AA39: 0 | AC39: 0 | AD39: 0 | AE39: 0 | AF39: 0 | AG39: 0
A40: Extraordinary Items | B40: 0 | C40: 0 | D40: =B40+C40 | E40: 0 | F40: 0 | G40: 0 | H40: 0 | I40: 0 | J40: 0 | K40: 0 | L40: 0 | M40: 0 | N40: 0 | O40: 0 | P40: 0 | Q40: 0 | R40: 0 | S40: 0 | T40: 0 | U40: 0 | V40: 0 | W40: 0 | X40: 0 | Y40: 0 | Z40: 0 | AA40: 0 | AC40: 0 | AD40: 0 | AE40: 0 | AF40: 0 | AG40: 0
A41: Net Profit | B41: =B38-B39-B40 | C41: =C38-C39-C40 | D41: =D38-D39-D40 | E41: =E38-E39-E40 | F41: =F38-F39-F40 | G41: =G38-G39-G40 | H41: =H38-H39-H40 | I41: =I38-I39-I40 | ... AB41: =AB38-AB39-AB40 | AC41: =AA41+AB41 | AD41: 268170 | AE41: 369071 | AF41: 448389 | AG41: 769546
...

Sheet CASH FOW STATEMENT
A1: GAIL INDIA LTD.
A2: CASH FLOW STATEMENT
A3: (in Rs.crores)
A4: CASH FLOW STATEMENT | B4: 31st MAR '07 | C4: 31st MAR '08 | D4: 31st MAR '09 | E4: 31st MAR '10 | F4: 31st MAR '11 | G4: 31st MAR '12 | H4: 31st MAR '13 | I4: 31st MAR '14
B5: 2006-07A | C5: 2007-08 A | D5: 2008-09 A | E5: 2009-2010E | F5: 2010-11E | G5: 2011-12E | H5: 2012-13E | I5: 2013-14E
A7: Particulars
A8: PBT | B8: ='INCOME STATEMENT'!H32 | C8: ='INCOME STATEMENT'!O32 | D8: ='INCOME STATEMENT'!V32 | E8: ='INCOME STATEMENT'!AC32 | F8: ='INCOME STATEMENT'!AE32 | G8: ='INCOME STATEMENT'!AF32 | H8: ='INCOME STATEMENT'!AG32 | I8: ='INCOME STATEMENT'!AH32
A9: Tax - non deferred | B9: ='INCOME STATEMENT'!H33-'INCOME STATEMENT'!H34 | C9: ='INCOME STATEMENT'!O33-'INCOME STATEMENT'!O34 | D9: ='INCOME STATEMENT'!V33-'INCOME STATEMENT'!V34 | E9: ='INCOME STATEMENT'!AC33-'INCOME STATEMENT'!AC34 | F9: ='INCOME STATEMENT'!AE33-'INCOME STATEMENT'!AE34 | G9: ='INCOME STATEMENT'!AF33-'INCOME STATEMENT'!AF34 | H9: ='INCOME STATEMENT'!AG33-'INCOME STATEMENT'!AG34 | I9: ='INCOME STATEMENT'!AH33-'INCOME STATEMENT'!AH34
A10: PAT | B10: =B8-B9 | C10: =C8-C9 | D10: =D8-D9 | E10: =E8-E9 | F10: =F8-F9 | G10: =G8-G9 | H10: =H8-H9 | I10: =I8-I9
A11: Depreciation | B11: ='INCOME STATEMENT'!H27 | C11: ='INCOME STATEMENT'!O27 | D11: ='INCOME STATEMENT'!V27 | E11: ='INCOME STATEMENT'!AC27 | F11: ='INCOME STATEMENT'!AD27 | G11: ='INCOME STATEMENT'!AE27 | H11: ='INCOME STATEMENT'!AF27 | I11: ='INCOME STATEMENT'!AG27
A12: Operating Cash Flow | B12: =B10+B11 | C12: =C10+C11 | D12: =D10+D11 | E12: =E10+E11 | F12: =F10+F11 | G12: =G10+G11 | H12: =H10+H11 | I12: =I10+I11
A13: Capex | B13: =(BALANCESHEET!C28-BALANCESHEET!B28)+(BALANCESHEET!C31-BALANCESHEET!B31) | C13: =(BALANCESHEET!D28-BALANCESHEET!C28)+(BALANCESHEET!D31-BALANCESHEET!C31) | D13: =(BALANCESHEET!E28-BALANCESHEET!D28)+(BALANCESHEET!E31-BALANCESHEET!D31) | E13: =(BALANCESHEET!F28-BALANCESHEET!E28)+(BALANCESHEET!F31-BALANCESHEET!E31) | F13: =(BALANCESHEET!G28-BALANCESHEET!F28)+(BALANCESHEET!G31-BALANCESHEET!F31) | G13: =(BALANCESHEET!H28-BALANCESHEET!G28)+(BALANCESHEET!H31-BALANCESHEET!G31) | H13: =(BALANCESHEET!I28-BALANCESHEET!H28)+(BALANCESHEET!I31-BALANCESHEET!H31) | I13: =(BALANCESHEET!J28-BALANCESHEET!I28)+(BALANCESHEET!J31-BALANCESHEET!I31)
A14: Net cash Flow | B14: =B12-B13 | C14: =C12-C13 | D14: =D12-D13 | E14: =E12-E13 | F14: =F12-F13 | G14: =G12-G13 | H14: =H12-H13 | I14: =I12-I13
A15: Cash Flow / Share | B15: 5170.9431 | C15: 3703.9793 | D15: 3918.8848 | E15: 3499.5571
A16: Dividend/dividend tax | B16: 0 | C16: 0 | D16: 0 | E16: 0
A17: Increase in equity capital | B17: =BALANCESHEET!C9-BALANCESHEET!B9 | C17: =BALANCESHEET!D9-BALANCESHEET!C9 | D17: =BALANCESHEET!E9-BALANCESHEET!D9 | E17: =BALANCESHEET!F9-BALANCESHEET!E9 | F17: =BALANCESHEET!G9-BALANCESHEET!F9 | G17: =BALANCESHEET!H9-BALANCESHEET!G9 | H17: =BALANCESHEET!I9-BALANCESHEET!H9 | I17: =BALANCESHEET!J9-BALANCESHEET!I9
A19: Inc/(Dec) in Investments | B19: =BALANCESHEET!C33-BALANCESHEET!B33 | C19: =BALANCESHEET!D33-BALANCESHEET!C33 | D19: =BALANCESHEET!E33-BALANCESHEET!D33 | E19: =BALANCESHEET!F33-BALANCESHEET!E33 | F19: =BALANCESHEET!G33-BALANCESHEET!F33 | G19: =BALANCESHEET!H33-BALANCESHEET!G33 | H19: =BALANCESHEET!I33-BALANCESHEET!H33 | I19: =BALANCESHEET!J33-BALANCESHEET!I33
A20: Inc/Dec in Net Working Capital | B20: =(BALANCESHEET!C37+BALANCESHEET!C38+BALANCESHEET!C40+BALANCESHEET!C41-BALANCESHEET!C43)-(BALANCESHEET!B37+BALANCESHEET!B38+BALANCESHEET!B40+BALANCESHEET!B41-BALANCESHEET!B43) | C20: =(BALANCESHEET!D37+BALANCESHEET!D38+BALANCESHEET!D40+BALANCESHEET!D41-BALANCESHEET!D43)-(BALANCESHEET!C37+BALANCESHEET!C38+BALANCESHEET!C40+BALANCESHEET!C41-BALANCESHEET!C43) | D20: =(BALANCESHEET!E37+BALANCESHEET!E38+BALANCESHEET!E40+BALANCESHEET!E41-BALANCESHEET!E43)-(BALANCESHEET!D37+BALANCESHEET!D38+BALANCESHEET!D40+BALANCESHEET!D41-BALANCESHEET!D43) | E20: =(BALANCESHEET!F37+BALANCESHEET!F38+BALANCESHEET!F40+BALANCESHEET!F41-BALANCESHEET!F43)-(BALANCESHEET!E37+BALANCESHEET!E38+BALANCESHEET!E40+BALANCESHEET!E41-BALANCESHEET!E43) | F20: =(BALANCESHEET!G37+BALANCESHEET!G38+BALANCESHEET!G40+BALANCESHEET!G41-BALANCESHEET!G43)-(BALANCESHEET!F37+BALANCESHEET!F38+BALANCESHEET!F40+BALANCESHEET!F41-BALANCESHEET!F43) | G20: =(BALANCESHEET!H37+BALANCESHEET!H38+BALANCESHEET!H40+BALANCESHEET!H41-BALANCESHEET!H43)-(BALANCESHEET!G37+BALANCESHEET!G38+BALANCESHEET!G40+BALANCESHEET!G41-BALANCESHEET!G43) | H20: =(BALANCESHEET!I37+BALANCESHEET!I38+BALANCESHEET!I40+BALANCESHEET!I41-BALANCESHEET!I43)-(BALANCESHEET!H37+BALANCESHEET!H38+BALANCESHEET!H40+BALANCESHEET!H41-BALANCESHEET!H43) | I20: =(BALANCESHEET!J37+BALANCESHEET!J38+BALANCESHEET!J40+BALANCESHEET!J41-BALANCESHEET!J43)-(BALANCESHEET!I37+BALANCESHEET!I38+BALANCESHEET!I40+BALANCESHEET!I41-BALANCESHEET!I43)
A21: Inc/Dec in loan funds | B21: =BALANCESHEET!C19-BALANCESHEET!B19 | C21: =BALANCESHEET!D19-BALANCESHEET!C19 | D21: =BALANCESHEET!E19-BALANCESHEET!D19 | E21: =BALANCESHEET!F19-BALANCESHEET!E19 | F21: =BALANCESHEET!G19-BALANCESHEET!F19 | G21: =BALANCESHEET!H19-BALANCESHEET!G19 | H21: =BALANCESHEET!I19-BALANCESHEET!H19 | I21: =BALANCESHEET!J19-BALANCESHEET!I19
A22: Opening cash balance | B22: 4495.94 | C22: 2260.41 | D22: 4472.99 | E22: =D24 | F22: 3500.76 | G22: 3657.75 | H22: 3699 | I22: 3734
A23: Total cash flow | B23: =B14-B16+B17-B19-B20+B18+B21 | C23: =(C14-C16)+(C17-C19)-(B20+C18+C21) | D23: =(D14-D16)+(D17-D19)-(C20+D18+D21) | E23: =E14-E16+E17-E19-D20+E18+E21 | F23: =F14-F16+F17-F19-E20+F18+F21 | G23: =G14-G16+G17-G19-F20+G18+G21 | H23: =H14-H16+H17-H19-G20+H18+H21 | I23: =I14-I16+I17-I19-H20+I18+I21
A24: Closing cash balance | B24: 2660.39 | C24: 4472.99 | D24: 3456.15 | E24: =E22+E23 | F24: =F22+F23 | G24: =G22+G23 | H24: =H22+H23 | I24: =I22+I23

Sheet BALANCESHEET
A1: GAIL INDIA LTD.
A2: BALANCESHEET
A3: (in Rs.crores)
A4: BALANCESHEET | B4: 31st MAR '06 | C4: 31st MAR '07 | D4: 31st MAR '08 | E4: 31st MAR '09 | F4: 31st MAR '10 | G4: 31st MAR '11 | H4: 31st MAR '12 | I4: 31st MAR '13 | J4: 31st MAR '14
B5: 2005-06A | C5: 2006-07A | D5: 2007-08 A | E5: 2008-09 A | F5: 2009-2010E | G5: 2010-11E | H5: 2011-12E | I5: 2012-13E | J5: 2013-14E
A7: SOURCES OF FUNDS
A8: Shareholder's funds | B8: =SUM(B9:B10) | C8: =SUM(C9:C10) | D8: =SUM(D9:D10) | E8: =SUM(E9:E10) | F8: =SUM(F9:F10) | G8: =SUM(G9:G10) | H8: =SUM(H9:H10) | I8: =SUM(I9:I10) | J8: =SUM(J9:J10)
A9: Capital:Issued, Subscribed & Paid-up. | B9: 845.65 | C9: 845.65 | D9: 845.65 | E9: 1268.48 | F9: 1268.48 | G9: 1268.48 | H9: 1268.48 | I9: 1268.48 | J9: 1268.48
A10: Reserves and Surplus: | B10: =SUM(B11:B17) | C10: =SUM(C11:C17) | D10: =SUM(D11:D17) | E10: =SUM(E11:E17) | F10: =SUM(F11:F17) | G10: =SUM(G11:G17) | H10: =SUM(H11:H17) | I10: =SUM(I11:I17) | J10: =SUM(J11:J17)
A11: Capital Reserve | B11: 2.1 | C11: 1.98 | D11: 1.86 | E11: 1.74 | F11: 1.7 | G11: 1.65 | H11: 1.65 | I11: 1.63 | J11: 1.6
A12: Share Premium Account | B12: 0.27 | C12: 0.27 | D12: 0.27 | E12: 0.27 | F12: 0.27 | G12: 0.27 | H12: 0.27 | I12: 0.27 | J12: 0.27
A13: Investment Allowance Reserve | B13: 251.31 | C13: 215.1 | D13: 146.48 | E13: 19.11 | F13: 19.11 | G13: 19.11 | H13: 19.11 | I13: 19.11 | J13: 19.11
A14: Bonds Redemption Reserve | B14: 96.38 | C14: 128.51 | D14: 160.64 | E14: 192.77 | F14: 192.77 | G14: 192.77 | H14: 192.77 | I14: 192.77 | J14: 192.77
A15: Foreign Currency Translation Reserve | B15: -2.33 | C15: 0 | D15: 0 | E15: 0 | F15: 0 | G15: 0 | H15: 0 | I15: 0 | J15: 0
A16: General Reserve | B16: 1409.49 | C16: 1684.37 | D16: 2013.14 | E16: 1997.68 | F16: 2347.68 | G16: 2747.68 | H16: 3172.68 | I16: 3622.68 | J16: 4122.68
A17: Profit and Loss A ccount | B17: 7370.43 | C17: 8517.03 | D17: 9836.84 | E17: 11289.58 | F17: 12741.74 | G17: 14193.9 | H17: 15646.06 | I17: 17098.22 | J17: 18550.38
A19: Loan Funds | B19: =SUM(B20:B21) | C19: =SUM(C20:C21) | D19: =SUM(D20:D21) | E19: =SUM(E20:E21) | F19: =SUM(F20:F21) | G19: =SUM(G20:G21) | H19: =SUM(H20:H21) | I19: =SUM(I20:I21) | J19: =SUM(J20:J21)
A20: Secured Loans | B20: 1600 | C20: 1100 | D20: 1100 | E20: 1100 | F20: 1100 | G20: 1100 | H20: 1100 | I20: 1100 | J20: 1100
A21: Unsecured Loans | B21: 316.56 | C21: 237.85 | D21: 165.87 | E21: 100.13 | F21: 86.33 | G21: 72.34 | H21: 54.36 | I21: 41.82 | J21: 36.24
A23: Deferred Tax Liability (Net) | B23: 1299.7 | C23: 1318.67 | D23: 1319.69 | E23: 1325.93 | F23: 1327.87 | G23: 1333.54 | H23: 1341.86 | I23: 1351.67 | J23: 1363.51
A24: TOTAL | B24: =B9+B10+B19+B23 | C24: =C9+C10+C19+C23 | D24: =D9+D10+D19+D23 | E24: =E9+E10+E19+E23 | F24: =F9+F10+F19+F23 | G24: =G9+G10+G19+G23 | H24: =H9+H10+H19+H23 | I24: =I9+I10+I19+I23 | J24: =J9+J10+J19+J23
A26: APPLICATION OF FUNDS
A27: Fixed Assets | B27: =SUM(B30:B31) | C27: =SUM(C30:C31) | D27: =SUM(D30:D31) | E27: =SUM(E30:E31) | F27: =SUM(F30:F31) | G27: =SUM(G30:G31) | H27: =SUM(H30:H31) | I27: =SUM(I30:I31) | J27: =SUM(J30:J31)
A28: Gross Block | B28: 14469.48 | C28: 14932.56 | D28: 16957.86 | E28: 17603.98 | F28: 18850.98 | G28: 19850.77 | H28: 20977.16 | I28: 21301.43 | J28: 22623.13
A29: Less: Depreciation | B29: 6913.52 | C29: 7478.19 | D29: 8024.57 | E29: 8553.66 | F29: 9062.89 | G29: 9555.53 | H29: 10041.85 | I29: 10507.54 | J29: 10955.43
A30: NET BLOCK | B30: =B28-B29 | C30: =C28-C29 | D30: =D28-D29 | E30: =E28-E29 | F30: =F28-F29 | G30: =G28-G29 | H30: =H28-H29 | I30: =I28-I29 | J30: =J28-J29
A31: Capital Work -in- Progress | B31: 615.59 | C31: 1936.94 | D31: 816.66 | E31: 2426.33 | F31: 3747.68 | G31: 2862.68 | H31: 5137.77 | I31: 6059.77 | J31: 7314.77
A33: Investments | B33: 927.57 | C33: 1441.05 | D33: 1441.09 | E33: 1437.52 | F33: 1540.88 | G33: 1623.35 | H33: 1688.45 | I33: 1744.54 | J33: 1828.77
A34: Advances For Investment (Pending Allotment) | B34: 515.79 | C34: 22.79 | D34: 49.79 | E34: 299.75 | F34: 50.8 | G34: 235.98 | H34: 435 | I34: 33.45 | J34: 480
A36: Current Assets, Loans and Advances | B36: =SUM(B37:B41) | C36: =SUM(C37:C41) | D36: =SUM(D37:D41) | E36: =SUM(E37:E41) | F36: =SUM(F37:F41) | G36: =SUM(G37:G41) | H36: =SUM(H37:H41) | I36: =SUM(I37:I41) | J36: =SUM(J37:J41)
A37: Inventories | B37: 483.19 | C37: 552.36 | D37: 569.81 | E37: 601.41 | F37: 632.45 | G37: 656.67 | H37: 685.55 | I37: 715.65 | J37: 740.99
A38: Sundry Debtors | B38: 753.47 | C38: 790.71 | D38: 1073.54 | E38: 1503.34 | F38: 1828.76 | G38: 2135.56 | H38: 2465 | I38: 2667.78 | J38: 2989.97
A39: Cash and Bank balances | B39: 4495.94 | C39: 2660.41 | D39: 4472.99 | E39: 3456.15 | F39: 3500.76 | G39: 3657.75 | H39: 3699 | I39: 3734 | J39: 3800
A40: Other Current Assets | B40: 39.65 | C40: 31.67 | D40: 56.82 | E40: 54.63 | F40: 58.87 | G40: 61.98 | H40: 64.65 | I40: 66.67 | J40: 68.88
A41: Loans and Advances | B41: 6516.39 | C41: 3710.36 | D41: 4236.86 | E41: 6621.01 | F41: 6435.82 | G41: 5623.36 | H41: 4521.67 | I41: 5161.24 | J41: 5075.73
A43: Less: Current Liabilities and Provisions | B43: =B44+B52 | C43: =C44+C52 | D43: =D44+D52 | E43: =E44+E52 | F43: 6629.29 | G43: 5432.23 | H43: 7456.68 | I43: 7878.78 | J43: 9235.53
A44: Current Liabilities: | B44: =SUM(B45:B50) | C44: =SUM(C45:C50) | D44: =SUM(D45:D50) | E44: =SUM(E45:E50) | F44: =SUM(F45:F50) | G44: =SUM(G45:G50) | H44: =SUM(H45:H50) | I44: =SUM(I45:I50) | J44: =SUM(J45:J50)
A45: Sundry Creditors | B45: 1520.24 | C45: 1448.36 | D45: 1797.75 | E45: 1972.49
A46: Deposits/Retention Money from Contractors and Others | B46: 123.91 | C46: 308.14 | D46: 185.38 | E46: 212.28
A47: Other Liabilities | B47: 762.93 | C47: 726.25 | D47: 637.5 | E47: 452.93
...

Sheet Debt Schedule
A1: GAIL (INDIA) LTD.
A2: DEBT SCHEDULE | B2: FY 2006-07 A | C2: FY 2008 A | D2: FY 2009 A | E2: FY 2010 E | F2: FY 2011 E | G2: FY 2012 E | H2: FY 2013 E | I2: FY 2014 E
A3: (Figures in Rs. Millions.)
A5: SECURED LOANS
A6: BOND SERIES-I
A7: 6.10% Non-Convertible Redeemable Bonds | B7: 5000 | C7: 5000 | D7: 5000 | E7: 5000 | F7: 5000 | G7: 5000 | H7: 5000 | I7: 5000
A8: BOND SERIES-II
