Workbook

Sheet Table of Contents
A1: ='DETAIL.XLS'!$A$1
A2: Financial Model: Table of Contents
B4: 1) | C4: PRELIMINARY STATEMENTS
C5: - | D5: Instructions | I5: 1
C6: - | D6: Assumptions | I6: =I5+1
B8: 2) | C8: SUMMARY STATEMENTS
C9: - | D9: Income Statement | I9: =I6+2
C10: - | D10: Balance Sheet | I10: =I9+1
C11: - | D11: Statement of Sources & Uses | I11: =I10+1
C12: - | D12: Revenue, Gross Margin, & Profit Graph | I12: =I11+1
C13: - | D13: Breakeven Chart | I13: =I12+1
B15: 3) | C15: DETAILED FINANCIAL STATEMENTS
C16: - | D16: Receipts & Disbursements | I16: =I13+1
C17: - | D17: Statement of Sources & Uses | I17: =I16+3
C18: - | D18: Income Statement | I18: =I17+3
C19: - | D19: Balance Sheet | I19: =I18+6
B21: 4) | C21: SALES PROJECTIONS AND MARGIN ANALYSES
C22: - | D22: =Assumptions!I10 | I22: =I19+3
C23: - | D23: =Assumptions!I11 | I23: =I22+3
C24: - | D24: =Assumptions!I12 | I24: =I23+3
C25: - | D25: =Assumptions!I13 | I25: =I24+3
B27: 5) | C27: STAFFING PLAN | I27: =I25+3
B29: 6) | C29: EQUIPMENT PURCHASES | I29: =I27+6
B31: 7) | C31: MANUFACTURING & INVENTORY | I31: =I29+6
B33: 8) | C33: RENT & TAXES | I33: =I31+3
B35: 9) | C35: FINANCING ACTIVITIES | I35: =I33+3
B41: Created by:
B42: Source Address:
B43: Used with permission: www.exinfm.com/free_spreadsheets.html

Sheet Instructions
B1: ='DETAIL.XLS'!$A$1
B2: Financial Model: Instructions
B4: 1) | C4: ENTERING INFORMATION INTO THE MODEL: The DETAIL Worksheet.
C6: - | D6: Enter all inputs & assumptions in either the Assumptions page or the DETAIL worksheet.
C7: - | D7: Inputs are shaded yellow and appear blue when entered.
C8: - | D8: All other cells are protected and their formulas cannot be altered or seen without unprotecting the sheet.
C9: - | D9: At the top of the worksheet are three check lines. Values in each of these cells should always equal zero.
C10: - | D10: For information on the principles of financial projections, please contact a Coopers & Lybrand Emerging Company Services Consultant.
B12: 2) | C12: VIEWING THE RESULTS: The Assumptions Page, Summary Statements, and Revenue Growth and Breakeven Charts.
C14: - | D14: Click on the Assumptions tab to view all inputs and underlying assumptions for the financial model.
C15: - | D15: Click on the Summary Statements tab to view the annual Income Statement, Balance Sheet, and Statement of Sources & Uses for each of the five years projected.
C16: - | D16: At the top of the Summary Statements sheet are three check lines similar to those in the DETAIL worksheet. These should equal zero at all times as well.
C17: - | D17: Click on the Revenue Growth Chart tab to view the growth in revenues over the five-year projection period.
C18: - | D18: Click on the Breakeven Chart tab to view the cash flow breakeven point.
C19: - | D19: Data for the Assumptions page and Financial Charts are drawn automatically from the DETAIL worksheet. You do not need to add anything more to these sheets.
B21: 3) | C21: CUSTOMIZING THE FINANCIAL MODEL
C23: - | D23: To view the formula cells, choose Protection from the TOOLS menu and select Unprotect Worksheet. To protect the sheet again, choose Protection and select Protect Worksheet.
C24: - | D24: The variable inputs in the DETAIL worksheet are designed to accomodate most business models; however, the financial model can be tailored to suit specific business needs or operating procedures.
C25: - | D25: Structural changes to the model, such as additional product lines, extra departments, or embedded sales forecasts, require modifications of the underlying formulas. To make such changes, please contact an ECS Consultant.
B27: 4) | C27: PRINTING THE FINANCIAL STATEMENTS
C29: - | D29: To print the entire model, choose Print from the FILE menu and select "Entire Workbook". Click OK.
C30: - | D30: To print an individual worksheet (such as the Assumptions sheet only) click on the tab of the sheet you would like to print, choose Print from the FILE menu, and select "Selected Sheet". Click OK.

Sheet Assumptions
A1: =I8
A2: Financial Model: Assumptions
D5: LABELS
D8: Company name to be used on all statements................................................................................................................................................................................................................. | I8: Company name
D9: Date projections first begin............................................................................................................................................................................................................................... | I9: 38353
D10: Name of 1st product line..................................................................................................................................................................................................................................... | I10: Product One
D11: Name of 2nd product line..................................................................................................................................................................................................................................... | I11: Product Two
D12: Name of 3rd product line..................................................................................................................................................................................................................................... | I12: Product Three
D13: Name of 4th product line..................................................................................................................................................................................................................................... | I13: Services
D14: Name of department to be included in COGS..................................................................................................................................................................................................................... | I14: Content
D15: Name of 1st department to be included in operating expenses............................................................................................................................................................................................. | I15: Engineering
D16: Name of 2nd department to be included in operating expenses............................................................................................................................................................................................. | I16: Sales & Marketing
D17: Name of 3rd department to be included in operating expenses............................................................................................................................................................................................. | I17: Administration
D22: SALES
D25: UNITS SALES | E25: ='DETAIL.XLS'!R1 | F25: ='DETAIL.XLS'!AE1 | G25: ='DETAIL.XLS'!AF1 | H25: ='DETAIL.XLS'!AG1 | I25: ='DETAIL.XLS'!AH1
D26: =$I$10 | E26: ='DETAIL.XLS'!R246 | F26: ='DETAIL.XLS'!AE246 | G26: ='DETAIL.XLS'!AF246 | H26: ='DETAIL.XLS'!AG246 | I26: ='DETAIL.XLS'!AH246
D27: =$I$11 | E27: ='DETAIL.XLS'!R285 | F27: ='DETAIL.XLS'!AE285 | G27: ='DETAIL.XLS'!AF285 | H27: ='DETAIL.XLS'!AG285 | I27: ='DETAIL.XLS'!AH285
D28: =$I$12 | E28: ='DETAIL.XLS'!R324 | F28: ='DETAIL.XLS'!AE324 | G28: ='DETAIL.XLS'!AF324 | H28: ='DETAIL.XLS'!AG324 | I28: ='DETAIL.XLS'!AH324
D29: =$I$13 | E29: ='DETAIL.XLS'!R363 | F29: ='DETAIL.XLS'!AE363 | G29: ='DETAIL.XLS'!AF363 | H29: ='DETAIL.XLS'!AG363 | I29: ='DETAIL.XLS'!AH363
D32: AVERAGE UNIT PRICE | E32: =$E$25 | F32: =$F$25 | G32: =$G$25 | H32: =$H$25 | I32: =$I$25
D33: =$I$10 | E33: =IF(E26>0,'DETAIL.XLS'!R255/E26,0) | F33: =IF(F26>0,'DETAIL.XLS'!AE255/F26,0) | G33: =IF(G26>0,'DETAIL.XLS'!AF255/G26,0) | H33: =IF(H26>0,'DETAIL.XLS'!AG255/H26,0) | I33: =IF(I26>0,'DETAIL.XLS'!AH255/I26,0)
D34: =$I$11 | E34: =IF(E27>0,'DETAIL.XLS'!R294/E27,0) | F34: =IF(F27>0,'DETAIL.XLS'!AE294/F27,0) | G34: =IF(G27>0,'DETAIL.XLS'!AF294/G27,0) | H34: =IF(H27>0,'DETAIL.XLS'!AG294/H27,0) | I34: =IF(I27>0,'DETAIL.XLS'!AH294/I27,0)
D35: =$I$12 | E35: =IF(E28>0,'DETAIL.XLS'!R333/E28,0) | F35: =IF(F28>0,'DETAIL.XLS'!AE333/F28,0) | G35: =IF(G28>0,'DETAIL.XLS'!AF333/G28,0) | H35: =IF(H28>0,'DETAIL.XLS'!AG333/H28,0) | I35: =IF(I28>0,'DETAIL.XLS'!AH333/I28,0)
D36: =$I$13 | E36: =IF(E29>0,'DETAIL.XLS'!R372/E29,0) | F36: =IF(F29>0,'DETAIL.XLS'!AE372/F29,0) | G36: =IF(G29>0,'DETAIL.XLS'!AF372/G29,0) | H36: =IF(H29>0,'DETAIL.XLS'!AG372/H29,0) | I36: =IF(I29>0,'DETAIL.XLS'!AH372/I29,0)
D39: COST OF GOODS
D42: AVERAGE UNIT COST | E42: =E$25 | F42: =F$25 | G42: =G$25 | H42: =H$25 | I42: =I$25
D43: =$I$10 | E43: =IF(E26>0,'DETAIL.XLS'!R267/E26,0) | F43: =IF(F26>0,'DETAIL.XLS'!AE267/F26,0) | G43: =IF(G26>0,'DETAIL.XLS'!AF267/G26,0) | H43: =IF(H26>0,'DETAIL.XLS'!AG267/H26,0) | I43: =IF(I26>0,'DETAIL.XLS'!AH267/I26,0)
D44: =$I$11 | E44: =IF(E27>0,'DETAIL.XLS'!R306/E27,0) | F44: =IF(F27>0,'DETAIL.XLS'!AE306/F27,0) | G44: =IF(G27>0,'DETAIL.XLS'!AF306/G27,0) | H44: =IF(H27>0,'DETAIL.XLS'!AG306/H27,0) | I44: =IF(I27>0,'DETAIL.XLS'!AH306/I27,0)
D45: =$I$12 | E45: =IF(E28>0,'DETAIL.XLS'!R345/E28,0) | F45: =IF(F28>0,'DETAIL.XLS'!AE345/F28,0) | G45: =IF(G28>0,'DETAIL.XLS'!AF345/G28,0) | H45: =IF(H28>0,'DETAIL.XLS'!AG345/H28,0) | I45: =IF(I28>0,'DETAIL.XLS'!AH345/I28,0)
D46: =$I$13 | E46: =IF(E29>0,'DETAIL.XLS'!R384/E29,0) | F46: =IF(F29>0,'DETAIL.XLS'!AE384/F29,0) | G46: =IF(G29>0,'DETAIL.XLS'!AF384/G29,0) | H46: =IF(H29>0,'DETAIL.XLS'!AG384/H29,0) | I46: =IF(I29>0,'DETAIL.XLS'!AH384/I29,0)
D49: Returns.................................................................................................................................................................................................." | E49: ="(as a percentage of "&$D$26&" revenue)...................................................................................................................................................................................." | I49: 0
D50: Returns.................................................................................................................................................................................................." | E50: ="(as a percentage of "&$D$27&" revenue)...................................................................................................................................................................................." | I50: 0
D51: Returns.................................................................................................................................................................................................." | E51: ="(as a percentage of "&$D$28&" revenue)...................................................................................................................................................................................." | I51: 0
D52: Returns.................................................................................................................................................................................................." | E52: ="(as a percentage of "&$D$29&" revenue)...................................................................................................................................................................................." | I52: 0
D55: BALANCE SHEET
D58: Accounts Receivable (adjustable up to 360 days)................................................................................................................................................................................................................ | F58: (in days)................................................................................................................................................................................................................ | I58: 60
D59: Accounts Payable (fixed at 30 days)..................................................................................................................................................................................................................... | F59: (in days)..................................................................................................................................................................................................................... | I59: 30
D60: Salaries Payable (fixed at 15 days)............................................................................................................................................................................................................................ | F60: (in days)............................................................................................................................................................................................................................ | I60: 15
D61: Taxes Payable (fixed at 90 days)............................................................................................................................................................................................................................. | F61: (in days)............................................................................................................................................................................................................................. | I61: 90
D62: Inventory (adjustable up to 360 days).......................................................................................................................................................................................................................... | F62: (in days).......................................................................................................................................................................................................................... | I62: 0
...

Sheet DETAIL.XLS
A1: =Assumptions!I8 | C1: Assumptions in | E1: Enter existing | F1: =Assumptions!$I$9 | G1: =F1+31 | H1: =G1+31 | I1: =H1+31 | J1: =I1+31 | K1: =J1+31 | L1: =K1+31 | M1: =L1+31 | N1: =M1+31 | ... Q1: =P1+31 | R1: =IF(MONTH(Q1)=12,Q1,IF(MONTH(Q1)>3,"FY "&YEAR(Q1),"FY "&YEAR(F1))) | S1: =Q1+31 | T1: =S1+31 | U1: =T1+31 | V1: =U1+31 | W1: =V1+31 | X1: =W1+31 | Y1: =X1+31 | Z1: =Y1+31 | AA1: =Z1+31 | ... AD1: =AC1+31 | AE1: =IF(MONTH(AD1)=12,AD1,IF(MONTH(AD1)>3,"FY "&YEAR(AD1),"FY "&YEAR(S1))) | AF1: =IF(MONTH(AD1)=12,AD1+365,IF(MONTH(AD1)>3,"FY "&YEAR(AD1+365),"FY "&YEAR(S1+365))) | AG1: =IF(MONTH(AD1)=12,AD1+730,IF(MONTH(AD1)>3,"FY "&YEAR(AD1+730),"FY "&YEAR(S1+730))) | AH1: =IF(MONTH(AD1)=12,AD1+1095,IF(MONTH(AD1)>3,"FY "&YEAR(AD1+1095),"FY "&YEAR(S1+1095)))
B2: Sources & Uses Check | C2: gray cells are entered | E2: or year-to-date | F2: =F82-F189 | G2: =G82-G189 | H2: =H82-H189 | I2: =I82-I189 | J2: =J82-J189 | K2: =K82-K189 | L2: =L82-L189 | M2: =M82-M189 | ... AH2: =AH82-AH189
B3: Rec. & Disb. Check | C3: into and refer to the | E3: entries in this | F3: =F46-F189 | G3: =G46-G189 | H3: =H46-H189 | I3: =I46-I189 | J3: =J46-J189 | K3: =K46-K189 | L3: =L46-L189 | M3: =M46-M189 | ... AH3: =AH46-AH189
B4: Balance Sheet Check | C4: "Assumptions" page. | E4: column. | F4: =F236-F210 | G4: =G236-G210 | H4: =H236-H210 | I4: =I236-I210 | J4: =J236-J210 | K4: =K236-K210 | L4: =L236-L210 | M4: =M236-M210 | ... AH4: =AH236-AH210
A5: RECEIPTS & DISBURSEMENTS
A6: =$A$1
B7: =NOW() | F7: Month 1 | G7: Month 2 | H7: Month 3 | I7: Month 4 | J7: Month 5 | K7: Month 6 | L7: Month 7 | M7: Month 8 | N7: Month 9 | O7: Month 10 | P7: Month 11 | Q7: Month 12 | R7: Total | S7: Month 13 | T7: Month 14 | U7: Month 15 | V7: Month 16 | W7: Month 17 | X7: Month 18 | Y7: Month 19 | Z7: Month 20 | AA7: Month 21 | AB7: Month 22 | AC7: Month 23 | AD7: Month 24 | AE7: Total | AF7: Total | AG7: Total | AH7: Total
B8: =NOW() | F8: =F$1 | G8: =G$1 | H8: =H$1 | I8: =I$1 | J8: =J$1 | K8: =K$1 | L8: =L$1 | M8: =M$1 | ... AH8: =AH$1
A10: BEGINNING CASH | F10: =E189 | G10: =F46 | H10: =G46 | I10: =H46 | J10: =I46 | K10: =J46 | L10: =K46 | M10: =L46 | N10: =M46 | ... Q10: =P46 | R10: =F10 | S10: =Q46 | T10: =S46 | U10: =T46 | V10: =U46 | W10: =V46 | X10: =W46 | Y10: =X46 | Z10: =Y46 | AA10: =Z46 | ... AD10: =AC46 | AE10: =S10 | AF10: =AE46 | AG10: =AF46 | AH10: =AG46
A12: Receipts
B13: Collections | F13: =F93-(F192-E192)-F154 | G13: =G93-(G192-F192)-G154 | H13: =H93-(H192-G192)-H154 | I13: =I93-(I192-H192)-I154 | J13: =J93-(J192-I192)-J154 | K13: =K93-(K192-J192)-K154 | L13: =L93-(L192-K192)-L154 | M13: =M93-(M192-L192)-M154 | ... Q13: =Q93-(Q192-P192)-Q154 | R13: =SUM(F13:Q13) | S13: =S93-(S192-Q192)-S154 | T13: =T93-(T192-S192)-T154 | U13: =U93-(U192-T192)-U154 | V13: =V93-(V192-U192)-V154 | W13: =W93-(W192-V192)-W154 | X13: =X93-(X192-W192)-X154 | Y13: =Y93-(Y192-X192)-Y154 | Z13: =Z93-(Z192-Y192)-Z154 | AA13: =AA93-(AA192-Z192)-AA154 | ... AD13: =AD93-(AD192-AC192)-AD154 | AE13: =SUM(S13:AD13) | AF13: =AF93-(AF192-AE192)-AF154 | AG13: =AG93-(AG192-AF192)-AG154 | AH13: =AH93-(AH192-AG192)-AH154
B14: Financings | F14: =SUM(F231:F232)-SUM(E231:E232) | G14: =SUM(G231:G232)-SUM(F231:F232) | H14: =SUM(H231:H232)-SUM(G231:G232) | I14: =SUM(I231:I232)-SUM(H231:H232) | J14: =SUM(J231:J232)-SUM(I231:I232) | K14: =SUM(K231:K232)-SUM(J231:J232) | L14: =SUM(L231:L232)-SUM(K231:K232) | M14: =SUM(M231:M232)-SUM(L231:L232) | ... Q14: =SUM(Q231:Q232)-SUM(P231:P232) | R14: =SUM(F14:Q14) | S14: =SUM(S231:S232)-SUM(R231:R232) | T14: =SUM(T231:T232)-SUM(S231:S232) | U14: =SUM(U231:U232)-SUM(T231:T232) | V14: =SUM(V231:V232)-SUM(U231:U232) | W14: =SUM(W231:W232)-SUM(V231:V232) | X14: =SUM(X231:X232)-SUM(W231:W232) | Y14: =SUM(Y231:Y232)-SUM(X231:X232) | Z14: =SUM(Z231:Z232)-SUM(Y231:Y232) | ... AD14: =SUM(AD231:AD232)-SUM(AC231:AC232) | AE14: =SUM(S14:AD14) | AF14: =SUM(AF231:AF232)-SUM(AE231:AE232) | AG14: =SUM(AG231:AG232)-SUM(AF231:AF232) | AH14: =SUM(AH231:AH232)-SUM(AG231:AG232)
B15: Borrowings | F15: =SUM(F63:F65) | G15: =SUM(G63:G65) | H15: =SUM(H63:H65) | I15: =SUM(I63:I65) | J15: =SUM(J63:J65) | K15: =SUM(K63:K65) | L15: =SUM(L63:L65) | M15: =SUM(M63:M65) | ... Q15: =SUM(Q63:Q65) | R15: =SUM(F15:Q15) | S15: =SUM(S63:S65) | T15: =SUM(T63:T65) | U15: =SUM(U63:U65) | V15: =SUM(V63:V65) | W15: =SUM(W63:W65) | X15: =SUM(X63:X65) | Y15: =SUM(Y63:Y65) | Z15: =SUM(Z63:Z65) | ... AD15: =SUM(AD63:AD65) | AE15: =SUM(S15:AD15) | AF15: =SUM(AF63:AF65) | AG15: =SUM(AG63:AG65) | AH15: =SUM(AH63:AH65)
B16: Interest Revenue | F16: =F169 | G16: =G169 | H16: =H169 | I16: =I169 | J16: =J169 | K16: =K169 | L16: =L169 | M16: =M169 | ... Q16: =Q169 | R16: =SUM(F16:Q16) | S16: =S169 | T16: =T169 | U16: =U169 | V16: =V169 | W16: =W169 | X16: =X169 | Y16: =Y169 | Z16: =Z169 | ... AD16: =AD169 | AE16: =SUM(S16:AD16) | AF16: =AF169 | AG16: =AG169 | AH16: =AH169
A17: Total receipts | F17: =SUM(F13:F16) | G17: =SUM(G13:G16) | H17: =SUM(H13:H16) | I17: =SUM(I13:I16) | J17: =SUM(J13:J16) | K17: =SUM(K13:K16) | L17: =SUM(L13:L16) | M17: =SUM(M13:M16) | ... Q17: =SUM(Q13:Q16) | R17: =SUM(F17:Q17) | S17: =SUM(S13:S16) | T17: =SUM(T13:T16) | U17: =SUM(U13:U16) | V17: =SUM(V13:V16) | W17: =SUM(W13:W16) | X17: =SUM(X13:X16) | Y17: =SUM(Y13:Y16) | Z17: =SUM(Z13:Z16) | ... AD17: =SUM(AD13:AD16) | AE17: =SUM(S17:AD17) | AF17: =SUM(AF13:AF16) | AG17: =SUM(AG13:AG16) | AH17: =SUM(AH13:AH16)
A19: Disbursements
B20: Salaries | F20: =F480-F216+E216 | G20: =G480-G216+F216 | H20: =H480-H216+G216 | I20: =I480-I216+H216 | J20: =J480-J216+I216 | K20: =K480-K216+J216 | L20: =L480-L216+K216 | M20: =M480-M216+L216 | ... Q20: =Q480-Q216+P216 | R20: =SUM(F20:Q20) | S20: =S480-S216+Q216 | T20: =T480-T216+S216 | U20: =U480-U216+T216 | V20: =V480-V216+U216 | W20: =W480-W216+V216 | X20: =X480-X216+W216 | Y20: =Y480-Y216+X216 | Z20: =Z480-Z216+Y216 | AA20: =AA480-AA216+Z216 | ... AD20: =AD480-AD216+AC216 | AE20: =SUM(S20:AD20) | AF20: =AF480-AF216+AE216 | AG20: =AG480-AG216+AF216 | AH20: =AH480-AH216+AG216
B21: Benefits & Empl Taxes | F21: =F111+F125+F148+F561 | G21: =G111+G125+G148+G561 | H21: =H111+H125+H148+H561 | I21: =I111+I125+I148+I561 | J21: =J111+J125+J148+J561 | K21: =K111+K125+K148+K561 | L21: =L111+L125+L148+L561 | M21: =M111+M125+M148+M561 | ... Q21: =Q111+Q125+Q148+Q561 | R21: =SUM(F21:Q21) | S21: =S111+S125+S148+S561 | T21: =T111+T125+T148+T561 | U21: =U111+U125+U148+U561 | V21: =V111+V125+V148+V561 | W21: =W111+W125+W148+W561 | X21: =X111+X125+X148+X561 | Y21: =Y111+Y125+Y148+Y561 | Z21: =Z111+Z125+Z148+Z561 | ... AD21: =AD111+AD125+AD148+AD561 | AE21: =SUM(S21:AD21) | AF21: =AF111+AF125+AF148+AF561 | AG21: =AG111+AG125+AG148+AG561 | AH21: =AH111+AH125+AH148+AH561
B22: Incentives/commissions | F22: =F110+F124+F147+F560 | G22: =G110+G124+G147 | H22: =H110+H124+H147 | I22: =I110+I124+I147 | J22: =J110+J124+J147 | K22: =K110+K124+K147 | L22: =L110+L124+L147 | M22: =M110+M124+M147 | N22: =N110+N124+N147 | ... Q22: =Q110+Q124+Q147 | R22: =SUM(F22:Q22) | S22: =S110+S124+S147 | T22: =T110+T124+T147 | U22: =U110+U124+U147 | V22: =V110+V124+V147 | W22: =W110+W124+W147 | X22: =X110+X124+X147 | Y22: =Y110+Y124+Y147 | Z22: =Z110+Z124+Z147 | ... AD22: =AD110+AD124+AD147 | AE22: =SUM(S22:AD22) | AF22: =AF110+AF124+AF147 | AG22: =AG110+AG124+AG147 | AH22: =AH110+AH124+AH147
B23: Direct Material | F23: =E588 | G23: =F588 | H23: =G588 | I23: =H588 | J23: =I588 | K23: =J588 | L23: =K588 | M23: =L588 | ... Q23: =P588 | R23: =SUM(F23:Q23) | S23: =Q588 | T23: =S588 | U23: =T588 | V23: =U588 | W23: =V588 | X23: =W588 | Y23: =X588 | Z23: =Y588 | AA23: =Z588 | ... AD23: =AC588 | AE23: =SUM(S23:AD23) | AF23: =AD588+AF588*11/12 | AG23: =AF588/12+AG588*11/12 | AH23: =AG588/12+AH588*11/12
B24: Returns | F24: =F100 | G24: =G100 | H24: =H100 | I24: =I100 | J24: =J100 | K24: =K100 | L24: =L100 | M24: =M100 | ... Q24: =Q100 | R24: =SUM(F24:Q24) | S24: =S100 | T24: =T100 | U24: =U100 | V24: =V100 | W24: =W100 | X24: =X100 | Y24: =Y100 | Z24: =Z100 | ... AD24: =AD100 | AE24: =SUM(S24:AD24) | AF24: =AF100 | AG24: =AG100 | AH24: =AH100
B25: Advertising | F25: =E138 | G25: =F138 | H25: =G138 | I25: =H138 | J25: =I138 | K25: =J138 | L25: =K138 | M25: =L138 | ... Q25: =P138 | R25: =SUM(F25:Q25) | S25: =Q138 | T25: =S138 | U25: =T138 | V25: =U138 | W25: =V138 | X25: =W138 | Y25: =X138 | Z25: =Y138 | AA25: =Z138 | ... AD25: =AC138 | AE25: =SUM(S25:AD25) | AF25: =AD138+AF138*11/12 | AG25: =AF138/12+AG138*11/12 | AH25: =AG138/12+AH138*11/12
B26: Promotional Material | F26: =E140 | G26: =F140 | H26: =G140 | I26: =H140 | J26: =I140 | K26: =J140 | L26: =K140 | M26: =L140 | ... Q26: =P140 | R26: =SUM(F26:Q26) | S26: =Q140 | T26: =S140 | U26: =T140 | V26: =U140 | W26: =V140 | X26: =W140 | Y26: =X140 | Z26: =Y140 | AA26: =Z140 | ... AD26: =AC140 | AE26: =SUM(S26:AD26) | AF26: =AD140+AF140*11/12 | AG26: =AF140/12+AG140*11/12 | AH26: =AG140/12+AH140*11/12
B27: Trade Shows | F27: =F139 | G27: =G139 | H27: =H139 | I27: =I139 | J27: =J139 | K27: =K139 | L27: =L139 | M27: =M139 | ... Q27: =Q139 | R27: =SUM(F27:Q27) | S27: =S139 | T27: =T139 | U27: =U139 | V27: =V139 | W27: =W139 | X27: =X139 | Y27: =Y139 | Z27: =Z139 | ... AD27: =AD139 | AE27: =SUM(S27:AD27) | AF27: =AF139 | AG27: =AG139 | AH27: =AH139
B28: Supplies/Materials | F28: =E113+E126+E149+E565 | G28: =F113+F126+F149+F565 | H28: =G113+G126+G149+G565 | I28: =H113+H126+H149+H565 | J28: =I113+I126+I149+I565 | K28: =J113+J126+J149+J565 | L28: =K113+K126+K149+K565 | M28: =L113+L126+L149+L565 | ... Q28: =P113+P126+P149+P565 | R28: =SUM(F28:Q28) | S28: =Q113+Q126+Q149+Q565 | T28: =S113+S126+S149+S565 | U28: =T113+T126+T149+T565 | V28: =U113+U126+U149+U565 | W28: =V113+V126+V149+V565 | X28: =W113+W126+W149+W565 | Y28: =X113+X126+X149+X565 | Z28: =Y113+Y126+Y149+Y565 | AA28: =Z113+Z126+Z149+Z565 | ... AD28: =AC113+AC126+AC149+AC565 | AE28: =SUM(S28:AD28) | AF28: =(AD113+AD126+AD149+AD565)+(AF113+AF126+AF149+AF565)*11/12 | AG28: =(AF113+AF126+AF149+AF565)/12+(AG113+AG126+AG149+AG565)*11/12 | AH28: =(AG113+AG126+AG149+AG565)/12+(AH113+AH126+AH149+AH565)*11/12
B29: Travel & Meals | F29: =E114+E127+E150+E566 | G29: =F114+F127+F150+F566 | H29: =G114+G127+G150+G566 | I29: =H114+H127+H150+H566 | J29: =I114+I127+I150+I566 | K29: =J114+J127+J150+J566 | L29: =K114+K127+K150+K566 | M29: =L114+L127+L150+L566 | ... Q29: =P114+P127+P150+P566 | R29: =SUM(F29:Q29) | S29: =Q114+Q127+Q150+Q566 | T29: =S114+S127+S150+S566 | U29: =T114+T127+T150+T566 | V29: =U114+U127+U150+U566 | W29: =V114+V127+V150+V566 | X29: =W114+W127+W150+W566 | Y29: =X114+X127+X150+X566 | Z29: =Y114+Y127+Y150+Y566 | AA29: =Z114+Z127+Z150+Z566 | ... AD29: =AC114+AC127+AC150+AC566 | AE29: =SUM(S29:AD29) | AF29: =(AD114+AD127+AD150+AD566)+(AF114+AF127+AF150+AF566)*11/12 | AG29: =(AF114+AF127+AF150+AF566)/12+(AG114+AG127+AG150+AG566)*11/12 | AH29: =(AG114+AG127+AG150+AG566)/12+(AH114+AH127+AH150+AH566)*11/12
B30: Telephone/Postage | F30: =E115+E128+E151+E567 | G30: =F115+F128+F151+F567 | H30: =G115+G128+G151+G567 | I30: =H115+H128+H151+H567 | J30: =I115+I128+I151+I567 | K30: =J115+J128+J151+J567 | L30: =K115+K128+K151+K567 | M30: =L115+L128+L151+L567 | ... Q30: =P115+P128+P151+P567 | R30: =SUM(F30:Q30) | S30: =Q115+Q128+Q151+Q567 | T30: =S115+S128+S151+S567 | U30: =T115+T128+T151+T567 | V30: =U115+U128+U151+U567 | W30: =V115+V128+V151+V567 | X30: =W115+W128+W151+W567 | Y30: =X115+X128+X151+X567 | Z30: =Y115+Y128+Y151+Y567 | AA30: =Z115+Z128+Z151+Z567 | ... AD30: =AC115+AC128+AC151+AC567 | AE30: =SUM(S30:AD30) | AF30: =(AD115+AD128+AD151+AD567)+(AF115+AF128+AF151+AF567)*11/12 | AG30: =(AF115+AF128+AF151+AF567)/12+(AG115+AG128+AG151+AG567)*11/12 | AH30: =(AG115+AG128+AG151+AG567)/12+(AH115+AH128+AH151+AH567)*11/12
B31: Maintenance & Repair | F31: =E157 | G31: =F157 | H31: =G157 | I31: =H157 | J31: =I157 | K31: =J157 | L31: =K157 | M31: =L157 | ... Q31: =P157 | R31: =SUM(F31:Q31) | S31: =Q157 | T31: =S157 | U31: =T157 | V31: =U157 | W31: =V157 | X31: =W157 | Y31: =X157 | Z31: =Y157 | AA31: =Z157 | ... AD31: =AC157 | AE31: =SUM(S31:AD31) | AF31: =AD157+AF157*11/12 | AG31: =AF157/12+AG157*11/12 | AH31: =AG157/12+AH157*11/12
B32: Rent | F32: =F613 | G32: =G613 | H32: =H613 | I32: =I613 | J32: =J613 | K32: =K613 | L32: =L613 | M32: =M613 | ... Q32: =Q613 | R32: =SUM(F32:Q32) | S32: =S613 | T32: =T613 | U32: =U613 | V32: =V613 | W32: =W613 | X32: =X613 | Y32: =Y613 | Z32: =Z613 | ... AD32: =AD613 | AE32: =SUM(S32:AD32) | AF32: =AF613 | AG32: =AG613 | AH32: =AH613
B33: Utilities | F33: =E156 | G33: =F156 | H33: =G156 | I33: =H156 | J33: =I156 | K33: =J156 | L33: =K156 | M33: =L156 | ... Q33: =P156 | R33: =SUM(F33:Q33) | S33: =Q156 | T33: =S156 | U33: =T156 | V33: =U156 | W33: =V156 | X33: =W156 | Y33: =X156 | Z33: =Y156 | AA33: =Z156 | ... AD33: =AC156 | AE33: =SUM(S33:AD33) | AF33: =AD156+AF156*11/12 | AG33: =AF156/12+AG156*11/12 | AH33: =AG156/12+AH156*11/12
B34: Insurance | F34: =F152 | G34: =G152 | H34: =H152 | I34: =I152 | J34: =J152 | K34: =K152 | L34: =L152 | M34: =M152 | ... Q34: =Q152 | R34: =SUM(F34:Q34) | S34: =S152 | T34: =T152 | U34: =U152 | V34: =V152 | W34: =W152 | X34: =X152 | Y34: =Y152 | Z34: =Z152 | ... AD34: =AD152 | AE34: =SUM(S34:AD34) | AF34: =AF152 | AG34: =AG152 | AH34: =AH152
B35: Consultants | F35: =E112 | G35: =F112 | H35: =G112 | I35: =H112 | J35: =I112 | K35: =J112 | L35: =K112 | M35: =L112 | ... Q35: =P112 | R35: =SUM(F35:Q35) | S35: =Q112 | T35: =S112 | U35: =T112 | V35: =U112 | W35: =V112 | X35: =W112 | Y35: =X112 | Z35: =Y112 | AA35: =Z112 | ... AD35: =AC112 | AE35: =SUM(S35:AD35) | AF35: =AD112+AF112*11/12 | AG35: =AF112/12+AG112*11/12 | AH35: =AG112/12+AH112*11/12
B36: Professional Services | F36: =E153 | G36: =F153 | H36: =G153 | I36: =H153 | J36: =I153 | K36: =J153 | L36: =K153 | M36: =L153 | ... Q36: =P153 | R36: =SUM(F36:Q36) | S36: =Q153 | T36: =S153 | U36: =T153 | V36: =U153 | W36: =V153 | X36: =W153 | Y36: =X153 | Z36: =Y153 | AA36: =Z153 | ... AD36: =AC153 | AE36: =SUM(S36:AD36) | AF36: =AD153+AF153*11/12 | AG36: =AF153/12+AG153*11/12 | AH36: =AG153/12+AH153*11/12
B37: Taxes | F37: =-F217+E217+F176 | G37: =-G217+F217+G176 | H37: =-H217+G217+H176 | I37: =-I217+H217+I176 | J37: =-J217+I217+J176 | K37: =-K217+J217+K176 | L37: =-L217+K217+L176 | M37: =-M217+L217+M176 | ... Q37: =-Q217+P217+Q176 | R37: =SUM(F37:Q37) | S37: =-S217+R217+S176 | T37: =-T217+S217+T176 | U37: =-U217+T217+U176 | V37: =-V217+U217+V176 | W37: =-W217+V217+W176 | X37: =-X217+W217+X176 | Y37: =-Y217+X217+Y176 | Z37: =-Z217+Y217+Z176 | ... AD37: =-AD217+AC217+AD176 | AE37: =SUM(S37:AD37) | AF37: =-AF217+AE217+AF176 | AG37: =-AG217+AF217+AG176 | AH37: =-AH217+AG217+AH176
B38: Equipment Purchases | F38: =F200-E200 | G38: =G200-F200 | H38: =H200-G200 | I38: =I200-H200 | J38: =J200-I200 | K38: =K200-J200 | L38: =L200-K200 | M38: =M200-L200 | ... Q38: =Q200-P200 | R38: =SUM(F38:Q38) | S38: =S200-Q200 | T38: =T200-S200 | U38: =U200-T200 | V38: =V200-U200 | W38: =W200-V200 | X38: =X200-W200 | Y38: =Y200-X200 | Z38: =Z200-Y200 | AA38: =AA200-Z200 | ... AD38: =AD200-AC200 | AE38: =SUM(S38:AD38) | AF38: =AF200-AE200 | AG38: =AG200-AF200 | AH38: =AH200-AG200
B39: Debt Repayments | F39: =SUM(F75:F77) | G39: =SUM(G75:G77) | H39: =SUM(H75:H77) | I39: =SUM(I75:I77) | J39: =SUM(J75:J77) | K39: =SUM(K75:K77) | L39: =SUM(L75:L77) | M39: =SUM(M75:M77) | ... Q39: =SUM(Q75:Q77) | R39: =SUM(F39:Q39) | S39: =SUM(S75:S77) | T39: =SUM(T75:T77) | U39: =SUM(U75:U77) | V39: =SUM(V75:V77) | W39: =SUM(W75:W77) | X39: =SUM(X75:X77) | Y39: =SUM(Y75:Y77) | Z39: =SUM(Z75:Z77) | ... AD39: =SUM(AD75:AD77) | AE39: =SUM(S39:AD39) | AF39: =SUM(AF75:AF77) | AG39: =SUM(AG75:AG77) | AH39: =SUM(AH75:AH77)
B40: Interest Expense | F40: =SUM(F170:F172) | G40: =SUM(G170:G172) | H40: =SUM(H170:H172) | I40: =SUM(I170:I172) | J40: =SUM(J170:J172) | K40: =SUM(K170:K172) | L40: =SUM(L170:L172) | M40: =SUM(M170:M172) | ... Q40: =SUM(Q170:Q172) | R40: =SUM(F40:Q40) | S40: =SUM(S170:S172) | T40: =SUM(T170:T172) | U40: =SUM(U170:U172) | V40: =SUM(V170:V172) | W40: =SUM(W170:W172) | X40: =SUM(X170:X172) | Y40: =SUM(Y170:Y172) | Z40: =SUM(Z170:Z172) | ... AD40: =SUM(AD170:AD172) | AE40: =SUM(S40:AD40) | AF40: =SUM(AF170:AF172) | AG40: =SUM(AG170:AG172) | AH40: =SUM(AH170:AH172)
B41: Prior Accounts Payable | F41: =E215 | G41: 0 | H41: 0 | I41: 0 | J41: 0 | K41: 0 | L41: 0 | M41: 0 | N41: 0 | O41: 0 | P41: 0 | Q41: 0 | R41: =SUM(F41:Q41) | S41: 0 | T41: 0 | U41: 0 | V41: 0 | W41: 0 | X41: 0 | Y41: 0 | Z41: 0 | AA41: 0 | AB41: 0 | AC41: 0 | AD41: 0 | AE41: =SUM(S41:AD41) | AF41: 0 | AG41: 0 | AH41: 0
A42: Total Disbursements | F42: =SUM(F20:F41) | G42: =SUM(G20:G41) | H42: =SUM(H20:H41) | I42: =SUM(I20:I41) | J42: =SUM(J20:J41) | K42: =SUM(K20:K41) | L42: =SUM(L20:L41) | M42: =SUM(M20:M41) | ... Q42: =SUM(Q20:Q41) | R42: =SUM(F42:Q42) | S42: =SUM(S20:S41) | T42: =SUM(T20:T41) | U42: =SUM(U20:U41) | V42: =SUM(V20:V41) | W42: =SUM(W20:W41) | X42: =SUM(X20:X41) | Y42: =SUM(Y20:Y41) | Z42: =SUM(Z20:Z41) | ... AD42: =SUM(AD20:AD41) | AE42: =SUM(S42:AD42) | AF42: =SUM(AF20:AF41) | AG42: =SUM(AG20:AG41) | AH42: =SUM(AH20:AH41)
A44: Changes in Cash | F44: =F17-F42 | G44: =G17-G42 | H44: =H17-H42 | I44: =I17-I42 | J44: =J17-J42 | K44: =K17-K42 | L44: =L17-L42 | M44: =M17-M42 | ... AH44: =AH17-AH42
...

Sheet Summary Statements
A1: CHECKS | C1: ='DETAIL.XLS'!R1 | D1: ='DETAIL.XLS'!AE1 | E1: ='DETAIL.XLS'!AF1 | F1: ='DETAIL.XLS'!AG1 | G1: ='DETAIL.XLS'!AH1
B2: Balance Sheet Check | C2: =+C59-C84 | D2: =+D59-D84 | E2: =+E59-E84 | F2: =+F59-F84 | G2: =+G59-G84
B3: S & U to Income Stmt | C3: =+C41-C93 | D3: =+D41-D93 | E3: =+E41-E93 | F3: =+F41-F93 | G3: =+G41-G93
B4: S & U to Balance Sheet | C4: =+C118-C50 | D4: =+D118-D50 | E4: =+E118-E50 | F4: =+F118-F50 | G4: =+G118-G50
A5: ='DETAIL.XLS'!$A$1
A6: Income Statement ($)
C8: =C$1 | D8: =D$1 | E8: =E$1 | F8: =F$1 | G8: =G$1
A10: Revenue
B11: =+'DETAIL.XLS'!B89 | C11: =+'DETAIL.XLS'!R89 | D11: =+'DETAIL.XLS'!AE89 | E11: =+'DETAIL.XLS'!AF89 | F11: =+'DETAIL.XLS'!AG89 | G11: =+'DETAIL.XLS'!AH89
B12: =+'DETAIL.XLS'!B90 | C12: =+'DETAIL.XLS'!R90 | D12: =+'DETAIL.XLS'!AE90 | E12: =+'DETAIL.XLS'!AF90 | F12: =+'DETAIL.XLS'!AG90 | G12: =+'DETAIL.XLS'!AH90
B13: =+'DETAIL.XLS'!B91 | C13: =+'DETAIL.XLS'!R91 | D13: =+'DETAIL.XLS'!AE91 | E13: =+'DETAIL.XLS'!AF91 | F13: =+'DETAIL.XLS'!AG91 | G13: =+'DETAIL.XLS'!AH91
B14: =+'DETAIL.XLS'!B92 | C14: =+'DETAIL.XLS'!R92 | D14: =+'DETAIL.XLS'!AE92 | E14: =+'DETAIL.XLS'!AF92 | F14: =+'DETAIL.XLS'!AG92 | G14: =+'DETAIL.XLS'!AH92
A15: Total Revenue | C15: =SUM(C11:C14) | D15: =SUM(D11:D14) | E15: =SUM(E11:E14) | F15: =SUM(F11:F14) | G15: =SUM(G11:G14)
A17: Cost of Goods Sold | C17: =+'DETAIL.XLS'!R101 | D17: =+'DETAIL.XLS'!AE101 | E17: =+'DETAIL.XLS'!AF101 | F17: =+'DETAIL.XLS'!AG101 | G17: =+'DETAIL.XLS'!AH101
A19: Gross Margin | C19: =+C15-C17 | D19: =+D15-D17 | E19: =+E15-E17 | F19: =+F15-F17 | G19: =+G15-G17
B20: % of Revenue | C20: =IF(C$15=0,0,C19/C$15) | D20: =IF(D$15=0,0,D19/D$15) | E20: =IF(E$15=0,0,E19/E$15) | F20: =IF(F$15=0,0,F19/F$15) | G20: =IF(G$15=0,0,G19/G$15)
A22: Operating Expenses
B23: Engineering | C23: =+'DETAIL.XLS'!R118 | D23: =+'DETAIL.XLS'!AE118 | E23: =+'DETAIL.XLS'!AF118 | F23: =+'DETAIL.XLS'!AG118 | G23: =+'DETAIL.XLS'!AH118
B24: % of Revenue | C24: =IF(C$15=0,0,C23/C$15) | D24: =IF(D$15=0,0,D23/D$15) | E24: =IF(E$15=0,0,E23/E$15) | F24: =IF(F$15=0,0,F23/F$15) | G24: =IF(G$15=0,0,G23/G$15)
B25: Marketing/Sales | C25: =+'DETAIL.XLS'!R130+'DETAIL.XLS'!R141 | D25: =+'DETAIL.XLS'!AE130+'DETAIL.XLS'!AE141 | E25: =+'DETAIL.XLS'!AF130+'DETAIL.XLS'!AF141 | F25: =+'DETAIL.XLS'!AG130+'DETAIL.XLS'!AG141 | G25: =+'DETAIL.XLS'!AH130+'DETAIL.XLS'!AH141
B26: % of Revenue | C26: =IF(C$15=0,0,C25/C$15) | D26: =IF(D$15=0,0,D25/D$15) | E26: =IF(E$15=0,0,E25/E$15) | F26: =IF(F$15=0,0,F25/F$15) | G26: =IF(G$15=0,0,G25/G$15)
B27: Administration | C27: =+'DETAIL.XLS'!R159 | D27: =+'DETAIL.XLS'!AE159 | E27: =+'DETAIL.XLS'!AF159 | F27: =+'DETAIL.XLS'!AG159 | G27: =+'DETAIL.XLS'!AH159
B28: % of Revenue | C28: =IF(C$15=0,0,C27/C$15) | D28: =IF(D$15=0,0,D27/D$15) | E28: =IF(E$15=0,0,E27/E$15) | F28: =IF(F$15=0,0,F27/F$15) | G28: =IF(G$15=0,0,G27/G$15)
A29: Total Operating Expenses | C29: =+C23+C25+C27 | D29: =+D23+D25+D27 | E29: =+E23+E25+E27 | F29: =+F23+F25+F27 | G29: =+G23+G25+G27
B30: % of Revenue | C30: =IF(C$15=0,0,C29/C$15) | D30: =IF(D$15=0,0,D29/D$15) | E30: =IF(E$15=0,0,E29/E$15) | F30: =IF(F$15=0,0,F29/F$15) | G30: =IF(G$15=0,0,G29/G$15)
A32: Income Before Int & Taxes | C32: =+C19-C29 | D32: =+D19-D29 | E32: =+E19-E29 | F32: =+F19-F29 | G32: =+G19-G29
B33: % of Revenue | C33: =IF(C$15=0,0,C32/C$15) | D33: =IF(D$15=0,0,D32/D$15) | E33: =IF(E$15=0,0,E32/E$15) | F33: =IF(F$15=0,0,F32/F$15) | G33: =IF(G$15=0,0,G32/G$15)
B35: Interest Expense | C35: =SUM('DETAIL.XLS'!R170:R172) | D35: =SUM('DETAIL.XLS'!AE170:AE172) | E35: =SUM('DETAIL.XLS'!AF170:AF172) | F35: =SUM('DETAIL.XLS'!AG170:AG172) | G35: =SUM('DETAIL.XLS'!AH170:AH172)
B36: Interest Revenue | C36: ='DETAIL.XLS'!R169 | D36: ='DETAIL.XLS'!AE169 | E36: ='DETAIL.XLS'!AF169 | F36: ='DETAIL.XLS'!AG169 | G36: ='DETAIL.XLS'!AH169
A38: Income Before Taxes | C38: =+C32-C35+C36 | D38: =+D32-D35+D36 | E38: =+E32-E35+E36 | F38: =+F32-F35+F36 | G38: =+G32-G35+G36
B39: =+'DETAIL.XLS'!B176 | C39: =+'DETAIL.XLS'!R176 | D39: =+'DETAIL.XLS'!AE176 | E39: =+'DETAIL.XLS'!AF176 | F39: =+'DETAIL.XLS'!AG176 | G39: =+'DETAIL.XLS'!AH176
A41: Net Income | C41: =+C38-C39 | D41: =+D38-D39 | E41: =+E38-E39 | F41: =+F38-F39 | G41: =+G38-G39
B42: % of Revenue | C42: =IF(C$15=0,0,C41/C$15) | D42: =IF(D$15=0,0,D41/D$15) | E42: =IF(E$15=0,0,E41/E$15) | F42: =IF(F$15=0,0,F41/F$15) | G42: =IF(G$15=0,0,G41/G$15)
A44: =+$A$5
A45: Balance Sheet ($)
C47: =C$1 | D47: =D$1 | E47: =E$1 | F47: =F$1 | G47: =G$1
A48: ASSETS
A49: Current Assets
B50: =+'DETAIL.XLS'!B189 | C50: =+'DETAIL.XLS'!R189 | D50: =+'DETAIL.XLS'!AE189 | E50: =+'DETAIL.XLS'!AF189 | F50: =+'DETAIL.XLS'!AG189 | G50: =+'DETAIL.XLS'!AH189
B51: =+'DETAIL.XLS'!B192 | C51: =+'DETAIL.XLS'!R192 | D51: =+'DETAIL.XLS'!AE192 | E51: =+'DETAIL.XLS'!AF192 | F51: =+'DETAIL.XLS'!AG192 | G51: =+'DETAIL.XLS'!AH192
...

Sheet Revenue Growth Chart

Sheet Breakeven Chart

Sheet Graph Input
A1: Revenue Growth
C2: =+'Summary Statements'!C8 | D2: =+'Summary Statements'!D8 | E2: =+'Summary Statements'!E8 | F2: =+'Summary Statements'!F8 | G2: =+'Summary Statements'!G8
B3: Revenue | C3: =+'Summary Statements'!C15 | D3: =+'Summary Statements'!D15 | E3: =+'Summary Statements'!E15 | F3: =+'Summary Statements'!F15 | G3: =+'Summary Statements'!G15
B4: Gross Margin | C4: =+'Summary Statements'!C19 | D4: =+'Summary Statements'!D19 | E4: =+'Summary Statements'!E19 | F4: =+'Summary Statements'!F19 | G4: =+'Summary Statements'!G19
B5: Net Income | C5: =+'Summary Statements'!C41 | D5: =+'Summary Statements'!D41 | E5: =+'Summary Statements'!E41 | F5: =+'Summary Statements'!F41 | G5: =+'Summary Statements'!G41
A8: Cash Flow Breakeven
C9: =+'DETAIL.XLS'!$F$1 | D9: =+C9+31 | E9: =+D9+31 | F9: =+E9+31 | G9: =+F9+31 | H9: =+G9+31 | I9: =+H9+31 | J9: =+I9+31 | K9: =+J9+31 | ... Z9: =+Y9+31
B10: Receipts | C10: ='DETAIL.XLS'!F17 | D10: ='DETAIL.XLS'!G17 | E10: ='DETAIL.XLS'!H17 | F10: ='DETAIL.XLS'!I17 | G10: ='DETAIL.XLS'!J17 | H10: ='DETAIL.XLS'!K17 | I10: ='DETAIL.XLS'!L17 | J10: ='DETAIL.XLS'!M17 | ... N10: ='DETAIL.XLS'!Q17 | O10: ='DETAIL.XLS'!S17 | P10: ='DETAIL.XLS'!T17 | Q10: ='DETAIL.XLS'!U17 | R10: ='DETAIL.XLS'!V17 | S10: ='DETAIL.XLS'!W17 | T10: ='DETAIL.XLS'!X17 | U10: ='DETAIL.XLS'!Y17 | V10: ='DETAIL.XLS'!Z17 | ... Z10: ='DETAIL.XLS'!AD17
B11: Disbursements | C11: ='DETAIL.XLS'!F42 | D11: ='DETAIL.XLS'!G42 | E11: ='DETAIL.XLS'!H42 | F11: ='DETAIL.XLS'!I42 | G11: ='DETAIL.XLS'!J42 | H11: ='DETAIL.XLS'!K42 | I11: ='DETAIL.XLS'!L42 | J11: ='DETAIL.XLS'!M42 | ... N11: ='DETAIL.XLS'!Q42 | O11: ='DETAIL.XLS'!S42 | P11: ='DETAIL.XLS'!T42 | Q11: ='DETAIL.XLS'!U42 | R11: ='DETAIL.XLS'!V42 | S11: ='DETAIL.XLS'!W42 | T11: ='DETAIL.XLS'!X42 | U11: ='DETAIL.XLS'!Y42 | V11: ='DETAIL.XLS'!Z42 | ... Z11: ='DETAIL.XLS'!AD42
