Workbook

Sheet Cover
E3: Reference Model
E5: Aurobindo Pharma
E6: Prepared By: Gopal Sathis Kumar, Distance learning, Chennai
E14: http://proschoolonline.com
E15: Email ID : mumbai@proschoolonline.com
E17: Mumbai
E19: IMS Proschool Pvt Ltd,
E20: Maharashtra High School Complex,
E21: Principal N.M Kale Marg, Off Gokhale Rd,
E22: Dadar (W), Mumbai 400028
E23: Tel. No. : 022-65285393/94
E24: +91 9372895050

Sheet Directions
A1: Directions
A3: Aurobindo pharma is one of the leading pharmaceutical company of the country. A financial model of such a company is in great demand in the investment market. This gave us the opportunity to guide our student to come out with a financial model on the company. These exercises help the student at IMS Proschool to hone their financial modeling skills. This model is being developed by a financial modeling student at IMS Proschool. This is provided as reference model and is for information purpose only. Keeping in view the objective of the reference model, the formulas and linkages of the model are kept intact. IMS Proschool provides certificate programs in Financial Modeling. The program grooms the candidates for entry level jobs in the finance sector which require financial analysis and modeling skills. The program aims to impart the necessary skills required to perform the role of a Financial Research Analyst. The program equips students with the practical skill sets required to perform financial analysis, modeling and valuation through Excel. For more details, please contact the address furnished below. You can also email us at the below mentioned email-id.
I20: IMS Proschool Pvt Ltd,
I21: Maharashtra High School Complex,
I22: Principal N.M Kale Marg, Off Gokhale Rd,
I23: Dadar (W), Mumbai 400028
I24: Tel. No. : 022-65285393/94
I25: +91 9372895050
I26: Email ID : mumbai@proschoolonline.com

Sheet Company Overview
A1: Aurobindo Pharma
A2: Company Overview
A3: (In Rs Millions, except per share data)
A5: Company Information | F5: Company Description
A6: Industry | B6: Pharmceuticals | F6: Aurobindo Pharma, incorporated in 1986 is a Hyderabad based pharma company, which initially forayed into the pharmaceutical sector as an API supplier focusing on antibiotics like Semi Synthetic Penicillins (SSPs) and Cephalosporins, emerging a market leader in these segments. Over the years, the company has diversified into the cardiovascular (CVS), central nervous system (CNS), gastrointestinal (GI), anti-infective segments, etc. After a strong presence in its core business of bulk actives, the company is now focusing on generic formulations. It has 14 state-of-the-art manufacturing facilities spread across India, China, USA and Brazil. The company’s operations are vertically integrated and its formulations profile is supported by in-house APIs. Aurobindo has a presence across US, Europe, India and other emerging countries like Brazil, China, South Africa, etc. A higher proportion of the company’s revenue is from APIs and formulations are likely to replace this, going forward.
A7: Sector | B7: Pharma
A8: Country | B8: India
A9: Current Market Price Rs | B9: ='DCF Valuation'!E7 -> 753
A10: Ticker | B10: AUROPHARMA
A11: Market Capitalization (Rs in Mn) | B11: =B9*'Profit & Loss Consolidated'!S55 -> 48655.609
A12: Relative Index | B12: S&P CNX Nifty
A13: Year end | B13: 39903
A14: Reporting currency | B14: INR
F17: Products
F18: Aurobindo is a leading player in APIs and has a strong presence in SSPs, CCPs, and ARVs. Aurobindo ranks the highest in terms of DMF filings by any Indian company and is the second largest globally. Aurobindo has set up seven state–of-the-art manufacturing facilities and all have the necessary regulatory approvals. Six of these facilities are situated in India near Hyderabad and one is in China. The key products segments are:- CVS,CNS, Anti-allergic, Cephalosporins,(synthetic & non-synthetic) SSP’s, Gastro intestinals, and ARV’s.
A25: Per Share Data & Key Ratios
A26: For the Fiscal Period Ending | B26: 3 months Jun-30- 2008 | C26: 3 months Sep-30-2008 | D26: 3 months Dec-31-2008 | E26: 3 months Mar-31-2009 | F26: FY2009 A | G26: 3 months Jun-30-2009 | H26: 3 months Sep-30-2009 | I26: 3 months Dec-31- 2009 | J26: 3 months Mar-31-2010 | K26: FY2010 E | L26: 3 months Jun-30- 2010 | M26: 3 months Sep-30-2010 | N26: 3 months Dec-31-2010 | O26: 3 months Mar-31-2011 | P26: FY2011 E
A27: EPS diluted (reported) | B27: ='Profit & Loss Consolidated'!M52 -> 2.43 | C27: ='Profit & Loss Consolidated'!N52 -> -7.15 | D27: ='Profit & Loss Consolidated'!O52 -> 6.19 | E27: ='Profit & Loss Consolidated'!P52 -> 12.37 | F27: ='Profit & Loss Consolidated'!Q52 -> 15.43 | G27: ='Profit & Loss Consolidated'!R52 -> 25.76 | H27: ='Profit & Loss Consolidated'!S52 -> 14.037987 | I27: ='Profit & Loss Consolidated'!T52 -> 15.390835 | ... P27: ='Profit & Loss Consolidated'!AA52 -> 78.966962
A28: Operating Margin (%) | B28: ='Presentation sheet'!H45 -> 0.12372841 | C28: ='Presentation sheet'!I45 -> 0.13271628 | D28: ='Presentation sheet'!J45 -> 0.16741986 | E28: ='Presentation sheet'!K45 -> 0.16205702 | F28: ='Presentation sheet'!L45 -> 0.14757132 | G28: ='Presentation sheet'!M45 -> 0.1964897 | H28: ='Presentation sheet'!N45 -> 0.14080637 | I28: ='Presentation sheet'!O45 -> 0.14899431 | ... P28: ='Presentation sheet'!V45 -> 0.15484751
A29: EBITDA/sales (%) | B29: ='Presentation sheet'!H51 -> 0.16410815 | C29: ='Presentation sheet'!I51 -> 0.17773177 | D29: ='Presentation sheet'!J51 -> 0.21551838 | E29: ='Presentation sheet'!K51 -> 0.20867143 | F29: ='Presentation sheet'!L51 -> 0.19273269 | G29: ='Presentation sheet'!M51 -> 0.2394189 | H29: ='Presentation sheet'!N51 -> 0.17264109 | I29: ='Presentation sheet'!O51 -> 0.18233393 | ... P29: ='Presentation sheet'!V51 -> 0.18605065
A30: EBIT/sales (%) | B30: ='Presentation sheet'!H48 -> 0.12585068 | C30: ='Presentation sheet'!I48 -> 0.13790984 | D30: ='Presentation sheet'!J48 -> 0.17444964 | E30: ='Presentation sheet'!K48 -> 0.16819171 | F30: ='Presentation sheet'!L48 -> 0.15277684 | G30: ='Presentation sheet'!M48 -> 0.19918714 | H30: ='Presentation sheet'!N48 -> 0.14443357 | I30: ='Presentation sheet'!O48 -> 0.15412642 | ... P30: ='Presentation sheet'!V48 -> 0.15825643
A31: Net income/sales (%) | B31: ='Presentation sheet'!H62 -> 0.023231794 | C31: ='Presentation sheet'!I62 -> -0.053064134 | D31: ='Presentation sheet'!J62 -> 0.055286873 | E31: ='Presentation sheet'!K62 -> 0.0921354 | F31: ='Presentation sheet'!L62 -> 0.032683511 | G31: ='Presentation sheet'!M62 -> 0.20134025 | H31: ='Presentation sheet'!N62 -> 0.087503722 | I31: ='Presentation sheet'!O62 -> 0.095936499 | ... P31: ='Presentation sheet'!V62 -> 0.1045313
A32: Interest Cover | B32: ='Presentation sheet'!H86 -> 8.7539623 | C32: ='Presentation sheet'!I86 -> 8.2324376 | D32: ='Presentation sheet'!J86 -> 6.4036121 | E32: ='Presentation sheet'!K86 -> 6.7801047 | F32: ='Presentation sheet'!L86 -> 7.2643113 | G32: ='Presentation sheet'!M86 -> 8.7270723 | H32: ='Presentation sheet'!N86 -> 3.2895413 | I32: ='Presentation sheet'!O86 -> 3.4742309 | ... P32: ='Presentation sheet'!V86 -> 4.2606088
A33: ROE | B33: Quarterly data not available | F33: ='Presentation sheet'!L87 -> 0.081617729 | G33: Quarterly data not available | K33: ='Presentation sheet'!Q87 -> 0.27706017 | L33: Quarterly data not available | P33: ='Presentation sheet'!V87 -> 0.20947993
A34: EV/Sales | H34: ='Presentation sheet'!N88 -> 1.5507274 | I34: ='Presentation sheet'!O88 -> 1.5507274 | J34: ='Presentation sheet'!P88 -> 1.5507274 | K34: ='Presentation sheet'!Q88 -> 1.6334143 | L34: ='Presentation sheet'!R88 -> 1.4240602 | M34: ='Presentation sheet'!S88 -> 1.3902289 | N34: ='Presentation sheet'!T88 -> 1.3299758 | O34: ='Presentation sheet'!U88 -> 1.1585241 | P34: ='Presentation sheet'!V88 -> 1.3172696
A35: EV/EBITDA | H35: ='Presentation sheet'!N89 -> 8.9823775 | I35: ='Presentation sheet'!O89 -> 8.5048756 | J35: ='Presentation sheet'!P89 -> 7.8818402 | K35: ='Presentation sheet'!Q89 -> 8.3522736 | L35: ='Presentation sheet'!R89 -> 6.3363601 | M35: ='Presentation sheet'!S89 -> 8.1100267 | N35: ='Presentation sheet'!T89 -> 7.8437573 | O35: ='Presentation sheet'!U89 -> 6.3961085 | P35: ='Presentation sheet'!V89 -> 7.0801666
A36: P/E | H36: ='Presentation sheet'!N90 -> 13.410042 | I36: ='Presentation sheet'!O90 -> 12.231305 | J36: ='Presentation sheet'!P90 -> 10.817427 | K36: ='Presentation sheet'!Q90 -> 10.373144 | L36: ='Presentation sheet'!R90 -> 8.3979009 | M36: ='Presentation sheet'!S90 -> 12.5954 | N36: ='Presentation sheet'!T90 -> 11.875556 | O36: ='Presentation sheet'!U90 -> 8.5191663 | P36: ='Presentation sheet'!V90 -> 9.5356334
A37: P/Sales | H37: ='DCF Valuation'!$E$7/(('Profit & Loss Consolidated'!S13*4)/'Profit & Loss Consolidated'!S55) -> 1.2017666 | I37: ='DCF Valuation'!$E$7/(('Profit & Loss Consolidated'!T13*4)/'Profit & Loss Consolidated'!T55) -> 1.1112248 | J37: ='DCF Valuation'!$E$7/(('Profit & Loss Consolidated'!U13*4)/'Profit & Loss Consolidated'!U55) -> 1.133756 | K37: ='DCF Valuation'!$E$7/('Profit & Loss Consolidated'!V13/'Profit & Loss Consolidated'!V55) -> 1.2066038 | L37: ='DCF Valuation'!$E$7/(('Profit & Loss Consolidated'!W13*4)/'Profit & Loss Consolidated'!W55) -> 1.0589993 | M37: ='DCF Valuation'!$E$7/(('Profit & Loss Consolidated'!X13*4)/'Profit & Loss Consolidated'!X55) -> 1.078318 | N37: ='DCF Valuation'!$E$7/(('Profit & Loss Consolidated'!Y13*4)/'Profit & Loss Consolidated'!Y55) -> 0.96403409 | O37: ='DCF Valuation'!$E$7/(('Profit & Loss Consolidated'!Z13*4)/'Profit & Loss Consolidated'!Z55) -> 0.85889222 | P37: ='DCF Valuation'!$E$7/('Profit & Loss Consolidated'!AA13/'Profit & Loss Consolidated'!AA55) -> 0.98201535
A38: P/BV | G38: Quarterly data not available | K38: ='DCF Valuation'!$E$7/('Balance Sheet'!F15/'Profit & Loss Consolidated'!V55) -> 2.8739852 | L38: Quarterly data not available | P38: ='DCF Valuation'!$E$7/('Balance Sheet'!G15/'Profit & Loss Consolidated'!AA55) -> 1.9975238
A41: Geographic Revenue breakup for 2009 | I41: Product Revenue Breakup for 2009
A43: India | B43: 24443.844 | I43: Formulations | S43: Active Ingredients | AC43: Formulations | AD43: 14098
A44: China | B44: 366.56211 | I44: USA | J44: 5584 | S44: SSPs | T44: 7379 | AC44: Active Ingredients | AD44: 16466
A45: Rest of the World | B45: 6432.0236 | I45: Europe | J45: 1923 | S45: Cephs | T45: 6344
A46: Consolidated | B46: 31242.43 | I46: ARV's | J46: 4640 | S46: ARVs & Others | T46: 2743
I47: Rest of the World | J47: 1951 | S47: Total | T47: 16466
I48: Total | J48: 14098
A55: Revenue Forecast | L55: Enterprise Value Added
A78: Revenue Data
B79: FY2007 A | C79: FY2008 A | D79: FY2009 A | E79: FY2010 E | F79: FY2011 E | G79: FY2012 E | H79: FY2013 E | I79: FY2014 E | L79: Explicit Forecast FCF (First Stage) | M79: =SUM('DCF Valuation'!D34:H34) -> 7583.456
A80: Formulations | B80: ='Segment Revenue Model'!B23 -> 7196.2 | C80: ='Segment Revenue Model'!G23 -> 10048 | D80: ='Segment Revenue Model'!L23 -> 14098 | E80: ='Segment Revenue Model'!Q23 -> 21408.619 | F80: ='Segment Revenue Model'!V23 -> 28084.807 | G80: ='Segment Revenue Model'!AA23 -> 34825.161 | H80: ='Segment Revenue Model'!AF23 -> 42486.697 | I80: ='Segment Revenue Model'!AK23 -> 50984.036 | L80: Second Stage | M80: =M79 -> 7583.456 | N80: =SUM('DCF Valuation'!I34:M34) -> 13507.846
...

Sheet Presentation sheet
A1: Aurobindo Pharma
A2: Presentation
A3: (In Rs Millions, Except per share items)
A5: For the Fiscal Period Ending | B5: FY2007 A | C5: 3 months Jun-30-2007 | D5: 3 months Sep-30-2007 | E5: 3 months Dec-31-2007 | F5: 3 months Mar-31-2008 | G5: FY2008 A | H5: 3 months Jun-30-2008 | I5: 3 months Sep-30-2008 | J5: 3 months Dec-31-2008 | K5: 3 months Mar-31-2009 | L5: FY2009 A | M5: 3 months Jun-30-2009 | N5: 3 months Sep-30-2009 | O5: 3 months Dec-31-2009 | P5: 3 months Mar-31-2010 | Q5: FY2010 E | R5: 3 months Jun-30-2010 | S5: 3 months Sep-30-2010 | T5: 3 months Dec-31-2010 | U5: 3 months Mar-31-2011 | V5: FY2011 E | W5: 3 months Jun-30-2011 | X5: 3 months Sep-30-2011 | Y5: 3 months Dec-31-2011 | Z5: 3 months Mar-31-2012 | AA5: FY2012 E | AB5: 3 months Jun-30-2012 | AC5: 3 months Sep-30-2012 | AD5: 3 months Dec-31-2012 | AE5: 3 months Mar-31-2013 | AF5: FY2013 E | AG5: 3 months Jun-30-2013 | AH5: 3 months Sep-30-2013 | AI5: 3 months Dec-31-2013 | AJ5: 3 months Mar-31-2014 | AK5: FY2014 E
A7: Geographic Revenue
A8: India | B8: ='Geographic Revenue Model'!D8 -> 16023.4 | C8: Quarterly data not available | G8: ='Geographic Revenue Model'!E8 -> 19058.3 | H8: Quarterly data not available | L8: ='Geographic Revenue Model'!F8 -> 24443.844 | M8: Quarterly data not available | Q8: ='Geographic Revenue Model'!G8 -> 31492.369 | R8: Quarterly data not available | V8: ='Geographic Revenue Model'!H8 -> 39538.67 | W8: Quarterly data not available | AA8: ='Geographic Revenue Model'!I8 -> 47817.384 | AB8: Quarterly data not available | AF8: ='Geographic Revenue Model'!J8 -> 57598.763 | AG8: Quarterly data not available | AK8: ='Geographic Revenue Model'!K8 -> 70890.785
A9: China | B9: ='Geographic Revenue Model'!D9 -> 976 | G9: ='Geographic Revenue Model'!E9 -> 285.8 | L9: ='Geographic Revenue Model'!F9 -> 366.56211 | Q9: ='Geographic Revenue Model'!G9 -> 461.86826 | V9: ='Geographic Revenue Model'!H9 -> 572.71664 | AA9: ='Geographic Revenue Model'!I9 -> 710.16864 | AF9: ='Geographic Revenue Model'!J9 -> 866.40574 | AK9: ='Geographic Revenue Model'!K9 -> 1039.6869
A10: Rest of the World | B10: ='Geographic Revenue Model'!D10 -> 4229.8 | G10: ='Geographic Revenue Model'!E10 -> 5014.9 | L10: ='Geographic Revenue Model'!F10 -> 6432.0236 | Q10: ='Geographic Revenue Model'!G10 -> 7479.4377 | V10: ='Geographic Revenue Model'!H10 -> 8786.3711 | AA10: ='Geographic Revenue Model'!I10 -> 12105.667 | AF10: ='Geographic Revenue Model'!J10 -> 15507.359 | AK10: ='Geographic Revenue Model'!K10 -> 16836.561
A11: Consolidated | B11: ='Geographic Revenue Model'!D11 -> 21229.2 | G11: ='Geographic Revenue Model'!E11 -> 24359 | L11: ='Geographic Revenue Model'!F11 -> 31242.43 | Q11: ='Geographic Revenue Model'!G11 -> 39365.462 | V11: ='Geographic Revenue Model'!H11 -> 48813.173 | AA11: ='Geographic Revenue Model'!I11 -> 60528.334 | AF11: ='Geographic Revenue Model'!J11 -> 73844.568 | AK11: ='Geographic Revenue Model'!K11 -> 88613.481
A14: Segment Revenues
A16: Formulations
A17: USA | B17: ='Segment Revenue Model'!B10 -> 1563 | C17: ='Segment Revenue Model'!C10 -> 546 | D17: ='Segment Revenue Model'!D10 -> 518 | E17: ='Segment Revenue Model'!E10 -> 497 | F17: ='Segment Revenue Model'!F10 -> 798 | G17: ='Segment Revenue Model'!G10 -> 2359 | H17: ='Segment Revenue Model'!H10 -> 817 | I17: ='Segment Revenue Model'!I10 -> 1051 | ... AK17: ='Segment Revenue Model'!AK10 -> 22366.021
A18: Europe | B18: ='Segment Revenue Model'!B11 -> 1280 | C18: ='Segment Revenue Model'!C11 -> 362 | D18: ='Segment Revenue Model'!D11 -> 562 | E18: ='Segment Revenue Model'!E11 -> 641 | F18: ='Segment Revenue Model'!F11 -> 446 | G18: ='Segment Revenue Model'!G11 -> 2011 | H18: ='Segment Revenue Model'!H11 -> 447 | I18: ='Segment Revenue Model'!I11 -> 557 | ... AK18: ='Segment Revenue Model'!AK11 -> 6377.644
A19: ARV's | B19: ='Segment Revenue Model'!B12 -> 2875 | C19: ='Segment Revenue Model'!C12 -> 642 | D19: ='Segment Revenue Model'!D12 -> 1072 | E19: ='Segment Revenue Model'!E12 -> 939 | F19: ='Segment Revenue Model'!F12 -> 1391 | G19: ='Segment Revenue Model'!G12 -> 4044 | H19: ='Segment Revenue Model'!H12 -> 1249 | I19: ='Segment Revenue Model'!I12 -> 858 | ... AK19: ='Segment Revenue Model'!AK12 -> 15311.109
A20: Rest of the World | B20: ='Segment Revenue Model'!B13 -> 1478.2 | C20: ='Segment Revenue Model'!C13 -> 246 | D20: ='Segment Revenue Model'!D13 -> 245 | E20: ='Segment Revenue Model'!E13 -> 389 | F20: ='Segment Revenue Model'!F13 -> 754 | G20: ='Segment Revenue Model'!G13 -> 1634 | H20: ='Segment Revenue Model'!H13 -> 384 | I20: ='Segment Revenue Model'!I13 -> 727 | ... AK20: ='Segment Revenue Model'!AK13 -> 6929.2617
A21: Total | B21: ='Segment Revenue Model'!B14 -> 7196.2 | C21: ='Segment Revenue Model'!C14 -> 1796 | D21: ='Segment Revenue Model'!D14 -> 2397 | E21: ='Segment Revenue Model'!E14 -> 2466 | F21: ='Segment Revenue Model'!F14 -> 3389 | G21: ='Segment Revenue Model'!G14 -> 10048 | H21: ='Segment Revenue Model'!H14 -> 2897 | I21: ='Segment Revenue Model'!I14 -> 3193 | ... AK21: ='Segment Revenue Model'!AK14 -> 50984.036
A23: Active Ingredients
A24: SSPs | B24: ='Segment Revenue Model'!B17 -> 5913 | C24: ='Segment Revenue Model'!C17 -> 2123 | D24: ='Segment Revenue Model'!D17 -> 2278 | E24: ='Segment Revenue Model'!E17 -> 1748 | F24: ='Segment Revenue Model'!F17 -> 1892 | G24: ='Segment Revenue Model'!G17 -> 8041 | H24: ='Segment Revenue Model'!H17 -> 2140 | I24: ='Segment Revenue Model'!I17 -> 1856 | ... AK24: ='Segment Revenue Model'!AK17 -> 15986.447
A25: Cephs | B25: ='Segment Revenue Model'!B18 -> 6429 | C25: ='Segment Revenue Model'!C18 -> 1309 | D25: ='Segment Revenue Model'!D18 -> 1577 | E25: ='Segment Revenue Model'!E18 -> 1620 | F25: ='Segment Revenue Model'!F18 -> 1412 | G25: ='Segment Revenue Model'!G18 -> 5918 | H25: ='Segment Revenue Model'!H18 -> 1564 | I25: ='Segment Revenue Model'!I18 -> 1560 | ... AK25: ='Segment Revenue Model'!AK18 -> 14632.993
A26: ARVs & Others | B26: ='Segment Revenue Model'!B19 -> 2964 | C26: ='Segment Revenue Model'!C19 -> 436 | D26: ='Segment Revenue Model'!D19 -> 418 | E26: ='Segment Revenue Model'!E19 -> 268 | F26: ='Segment Revenue Model'!F19 -> 395 | G26: ='Segment Revenue Model'!G19 -> 1517 | H26: ='Segment Revenue Model'!H19 -> 467 | I26: ='Segment Revenue Model'!I19 -> 631 | ... AK26: ='Segment Revenue Model'!AK19 -> 7010.0052
A27: Total | B27: ='Segment Revenue Model'!B20 -> 15306 | C27: ='Segment Revenue Model'!C20 -> 3868 | D27: ='Segment Revenue Model'!D20 -> 4273 | E27: ='Segment Revenue Model'!E20 -> 3636 | F27: ='Segment Revenue Model'!F20 -> 3699 | G27: ='Segment Revenue Model'!G20 -> 15476 | H27: ='Segment Revenue Model'!H20 -> 4171 | I27: ='Segment Revenue Model'!I20 -> 4047 | ... AK27: ='Segment Revenue Model'!AK20 -> 37629.445
A29: Formulations | B29: ='Segment Revenue Model'!B23 -> 7196.2 | C29: ='Segment Revenue Model'!C23 -> 1796 | D29: ='Segment Revenue Model'!D23 -> 2397 | E29: ='Segment Revenue Model'!E23 -> 2466 | F29: ='Segment Revenue Model'!F23 -> 3389 | G29: ='Segment Revenue Model'!G23 -> 10048 | H29: ='Segment Revenue Model'!H23 -> 2897 | I29: ='Segment Revenue Model'!I23 -> 3193 | ... AK29: ='Segment Revenue Model'!AK23 -> 50984.036
A30: Active Ingredients | B30: ='Segment Revenue Model'!B24 -> 15306 | C30: ='Segment Revenue Model'!C24 -> 3868 | D30: ='Segment Revenue Model'!D24 -> 4273 | E30: ='Segment Revenue Model'!E24 -> 3636 | F30: ='Segment Revenue Model'!F24 -> 3699 | G30: ='Segment Revenue Model'!G24 -> 15476 | H30: ='Segment Revenue Model'!H24 -> 4171 | I30: ='Segment Revenue Model'!I24 -> 4047 | ... AK30: ='Segment Revenue Model'!AK24 -> 37629.445
A31: Total | B31: ='Segment Revenue Model'!B25 -> 22502.2 | C31: ='Segment Revenue Model'!C25 -> 5664 | D31: ='Segment Revenue Model'!D25 -> 6670 | E31: ='Segment Revenue Model'!E25 -> 6102 | F31: ='Segment Revenue Model'!F25 -> 7088 | G31: ='Segment Revenue Model'!G25 -> 25524 | H31: ='Segment Revenue Model'!H25 -> 7068 | I31: ='Segment Revenue Model'!I25 -> 7240 | ... AK31: ='Segment Revenue Model'!AK25 -> 88613.481
A34: Income Statement
A36: Total Income | B36: ='Profit & Loss Consolidated'!G13 -> 21229.2 | C36: ='Profit & Loss Consolidated'!H13 -> 5323.4 | D36: ='Profit & Loss Consolidated'!I13 -> 6302 | E36: ='Profit & Loss Consolidated'!J13 -> 5695.6 | F36: ='Profit & Loss Consolidated'!K13 -> 7056.2 | G36: ='Profit & Loss Consolidated'!L13 -> 24359 | H36: ='Profit & Loss Consolidated'!M13 -> 6832.4 | I36: ='Profit & Loss Consolidated'!N13 -> 7094.53 | ... AK36: ='Profit & Loss Consolidated'!AP13 -> 88331.072
A38: Material Consumed | B38: ='Profit & Loss Consolidated'!G17 -> 11755.7 | C38: ='Profit & Loss Consolidated'!H17 -> 3036.9 | D38: ='Profit & Loss Consolidated'!I17 -> 3309.3 | E38: ='Profit & Loss Consolidated'!J17 -> 2974.7 | F38: ='Profit & Loss Consolidated'!K17 -> 3290.8 | G38: ='Profit & Loss Consolidated'!L17 -> 12611.7 | H38: ='Profit & Loss Consolidated'!M17 -> 3572.4 | I38: ='Profit & Loss Consolidated'!N17 -> 3995 | ... AK38: ='Profit & Loss Consolidated'!AP17 -> 44526.38
A39: Staff Cost | B39: ='Profit & Loss Consolidated'!G19 -> 1504.2 | C39: ='Profit & Loss Consolidated'!H19 -> 442.3 | D39: ='Profit & Loss Consolidated'!I19 -> 492.9 | E39: ='Profit & Loss Consolidated'!J19 -> 497.9 | F39: ='Profit & Loss Consolidated'!K19 -> 496.9 | G39: ='Profit & Loss Consolidated'!L19 -> 1930 | H39: ='Profit & Loss Consolidated'!M19 -> 573.7 | I39: ='Profit & Loss Consolidated'!N19 -> 589.6 | ... AK39: ='Profit & Loss Consolidated'!AP19 -> 7107.4308
A40: Other Expenditure | B40: ='Profit & Loss Consolidated'!G21 -> 4486.8 | C40: ='Profit & Loss Consolidated'!H21 -> 1258.7 | D40: ='Profit & Loss Consolidated'!I21 -> 1422.6 | E40: ='Profit & Loss Consolidated'!J21 -> 1380.6 | F40: ='Profit & Loss Consolidated'!K21 -> 1441.7 | G40: ='Profit & Loss Consolidated'!L21 -> 5503.6 | H40: ='Profit & Loss Consolidated'!M21 -> 1424.7 | I40: ='Profit & Loss Consolidated'!N21 -> 1641.1 | ... AK40: ='Profit & Loss Consolidated'!AP21 -> 19693.563
A41: Depreciation & Amortization | B41: ='Profit & Loss Consolidated'!G20 -> 997.2 | C41: ='Profit & Loss Consolidated'!H20 -> 233.5 | D41: ='Profit & Loss Consolidated'!I20 -> 249.5 | E41: ='Profit & Loss Consolidated'!J20 -> 256 | F41: ='Profit & Loss Consolidated'!K20 -> 264.8 | G41: ='Profit & Loss Consolidated'!L20 -> 1003.8 | H41: ='Profit & Loss Consolidated'!M20 -> 270.4 | I41: ='Profit & Loss Consolidated'!N20 -> 288.3 | ... AK41: ='Profit & Loss Consolidated'!AP20 -> 1969.2694
A42: Total Expenditure | B42: ='Profit & Loss Consolidated'!G22 -> 19204.5 | C42: ='Profit & Loss Consolidated'!H22 -> 4862 | D42: ='Profit & Loss Consolidated'!I22 -> 5599.5 | E42: ='Profit & Loss Consolidated'!J22 -> 5163.7 | F42: ='Profit & Loss Consolidated'!K22 -> 6326.2 | G42: ='Profit & Loss Consolidated'!L22 -> 21951.4 | H42: ='Profit & Loss Consolidated'!M22 -> 5957.9 | I42: ='Profit & Loss Consolidated'!N22 -> 6133.7 | ... AK42: ='Profit & Loss Consolidated'!AP22 -> 75729.827
A44: Operating Income | B44: ='Profit & Loss Consolidated'!G23 -> 2024.7 | C44: ='Profit & Loss Consolidated'!H23 -> 461.4 | D44: ='Profit & Loss Consolidated'!I23 -> 702.5 | E44: ='Profit & Loss Consolidated'!J23 -> 531.9 | F44: ='Profit & Loss Consolidated'!K23 -> 711.8 | G44: ='Profit & Loss Consolidated'!L23 -> 2407.6 | H44: ='Profit & Loss Consolidated'!M23 -> 874.5 | I44: ='Profit & Loss Consolidated'!N23 -> 960.83 | ... AK44: ='Profit & Loss Consolidated'!AP23 -> 12601.246
A45: Operating Income Margin(%) | B45: ='Profit & Loss Consolidated'!G23/'Profit & Loss Consolidated'!G9 -> 0.089977869 | C45: ='Profit & Loss Consolidated'!H23/'Profit & Loss Consolidated'!H9 -> 0.081456112 | D45: ='Profit & Loss Consolidated'!I23/'Profit & Loss Consolidated'!I9 -> 0.10532866 | E45: ='Profit & Loss Consolidated'!J23/'Profit & Loss Consolidated'!J9 -> 0.08716957 | F45: ='Profit & Loss Consolidated'!K23/'Profit & Loss Consolidated'!K9 -> 0.10043742 | G45: ='Profit & Loss Consolidated'!L23/'Profit & Loss Consolidated'!L9 -> 0.094330973 | H45: ='Profit & Loss Consolidated'!M23/'Profit & Loss Consolidated'!M9 -> 0.12372841 | I45: ='Profit & Loss Consolidated'!N23/'Profit & Loss Consolidated'!N9 -> 0.13271628 | ... AK45: ='Profit & Loss Consolidated'!AP23/'Profit & Loss Consolidated'!AP9 -> 0.14220461
A47: Profit Before Interest and Tax (PBIT) | B47: ='Profit & Loss Consolidated'!G25 -> 2517.8 | C47: ='Profit & Loss Consolidated'!H25 -> 796.7 | D47: ='Profit & Loss Consolidated'!I25 -> 728.6 | E47: ='Profit & Loss Consolidated'!J25 -> 707.1 | F47: ='Profit & Loss Consolidated'!K25 -> 1117.6 | G47: ='Profit & Loss Consolidated'!L25 -> 3350 | H47: ='Profit & Loss Consolidated'!M25 -> 889.5 | I47: ='Profit & Loss Consolidated'!N25 -> 998.43 | ... AK47: ='Profit & Loss Consolidated'!AP25 -> 12767.646
A48: PBIT Margin (%) | B48: ='Profit & Loss Consolidated'!G27 -> 0.11189128 | C48: ='Profit & Loss Consolidated'!H27 -> 0.14065038 | D48: ='Profit & Loss Consolidated'!I27 -> 0.10924193 | E48: ='Profit & Loss Consolidated'!J27 -> 0.11588194 | F48: ='Profit & Loss Consolidated'!K27 -> 0.15769719 | G48: ='Profit & Loss Consolidated'!L27 -> 0.13125468 | H48: ='Profit & Loss Consolidated'!M27 -> 0.12585068 | I48: ='Profit & Loss Consolidated'!N27 -> 0.13790984 | ... AK48: ='Profit & Loss Consolidated'!AP27 -> 0.14408243
A50: EBITDA | B50: ='Profit & Loss Consolidated'!G25+'Profit & Loss Consolidated'!G20 -> 3515 | C50: ='Profit & Loss Consolidated'!H25+'Profit & Loss Consolidated'!H20 -> 1030.2 | D50: ='Profit & Loss Consolidated'!I25+'Profit & Loss Consolidated'!I20 -> 978.1 | E50: ='Profit & Loss Consolidated'!J25+'Profit & Loss Consolidated'!J20 -> 963.1 | F50: ='Profit & Loss Consolidated'!K25+'Profit & Loss Consolidated'!K20 -> 1382.4 | G50: ='Profit & Loss Consolidated'!L25+'Profit & Loss Consolidated'!L20 -> 4353.8 | H50: ='Profit & Loss Consolidated'!M25+'Profit & Loss Consolidated'!M20 -> 1159.9 | I50: ='Profit & Loss Consolidated'!N25+'Profit & Loss Consolidated'!N20 -> 1286.73 | ... AK50: ='Profit & Loss Consolidated'!AP25+'Profit & Loss Consolidated'!AP20 -> 14736.915
A51: EBITDA Margin (%) | B51: =B50/'Profit & Loss Consolidated'!G9 -> 0.15620695 | C51: =C50/'Profit & Loss Consolidated'!H9 -> 0.18187275 | D51: =D50/'Profit & Loss Consolidated'!I9 -> 0.14665047 | E51: =E50/'Profit & Loss Consolidated'!J9 -> 0.15783608 | F51: =F50/'Profit & Loss Consolidated'!K9 -> 0.19506138 | G51: =G50/'Profit & Loss Consolidated'!L9 -> 0.17058406 | H51: =H50/'Profit & Loss Consolidated'!M9 -> 0.16410815 | I51: =I50/'Profit & Loss Consolidated'!N9 -> 0.17773177 | ... AK51: =AK50/'Profit & Loss Consolidated'!AP9 -> 0.16630556
A53: Interest (net) | B53: ='Profit & Loss Consolidated'!G29 -> 453.6 | C53: ='Profit & Loss Consolidated'!H29 -> 106.3 | D53: ='Profit & Loss Consolidated'!I29 -> 116.1 | E53: ='Profit & Loss Consolidated'!J29 -> 101 | F53: ='Profit & Loss Consolidated'!K29 -> 109 | G53: ='Profit & Loss Consolidated'!L29 -> 432.4 | H53: ='Profit & Loss Consolidated'!M29 -> 132.5 | I53: ='Profit & Loss Consolidated'!N29 -> 156.3 | ... AK53: ='Profit & Loss Consolidated'!AP29 -> 1695.8558
A55: Profit from Ordinary Activities before Tax (PBT) | B55: ='Profit & Loss Consolidated'!G32 -> 2064.2 | C55: ='Profit & Loss Consolidated'!H32 -> 690.4 | D55: ='Profit & Loss Consolidated'!I32 -> 838.2 | E55: ='Profit & Loss Consolidated'!J32 -> 606.1 | F55: ='Profit & Loss Consolidated'!K32 -> 782.9 | G55: ='Profit & Loss Consolidated'!L32 -> 2917.6 | H55: ='Profit & Loss Consolidated'!M32 -> 219.9 | I55: ='Profit & Loss Consolidated'!N32 -> -208.87 | ... AK55: ='Profit & Loss Consolidated'!AP32 -> 11071.79
A56: PBT Margin (%) | B56: ='Profit & Loss Consolidated'!G34 -> 0.091733253 | C56: ='Profit & Loss Consolidated'!H34 -> 0.12188405 | D56: ='Profit & Loss Consolidated'!I34 -> 0.1256747 | E56: ='Profit & Loss Consolidated'!J34 -> 0.099329717 | F56: ='Profit & Loss Consolidated'!K34 -> 0.11046987 | G56: ='Profit & Loss Consolidated'!L34 -> 0.11431303 | H56: ='Profit & Loss Consolidated'!M34 -> 0.031112495 | I56: ='Profit & Loss Consolidated'!N34 -> -0.028850523 | ... AK56: ='Profit & Loss Consolidated'!AP34 -> 0.12494476
...

Sheet Profit & Loss Consolidated
A1: Aurobindo Pharma
A2: Profit & Loss Consolidated
A3: (In Rs Millions, Except per share items)
A4: For the Fiscal Period Ending | B4: FY2006 A | C4: 3 months Jun-30-2006 | D4: 3 months Sep-30-2006 | E4: 3 months Dec-31-2006 | F4: 3 months Mar-31-2007 | G4: FY2007 A | H4: 3 months Jun-30-2007 | I4: 3 months Sep-30-2007 | J4: 3 months Dec-31-2007 | K4: 3 months Mar-31-2008 | L4: FY2008 A | M4: 3 months Jun-30-2008 | N4: 3 months Sep-30-2008 | O4: 3 months Dec-31-2008 | P4: 3 months Mar-31-2009 | Q4: FY2009 A | R4: 3 months Jun-30-2009 | S4: 3 months Sep-30-2009 | T4: 3 months Dec-31-2009 | U4: 3 months Mar-31-2010 | V4: FY2010 E | W4: 3 months Jun-30-2010 | X4: 3 months Sep-30-2010 | Y4: 3 months Dec-31-2010 | Z4: 3 months Mar-31-2011 | AA4: FY2011 E | AB4: 3 months Jun-30-2011 | AC4: 3 months Sep-30-2011 | AD4: 3 months Dec-31-2011 | AE4: 3 months Mar-31-2012 | AF4: FY2012 E | AG4: 3 months Jun-30-2012 | AH4: 3 months Sep-30-2012 | AI4: 3 months Dec-31-2012 | AJ4: 3 months Mar-31-2013 | AK4: FY2013 E | AL4: 3 months Jun-30-2013 | AM4: 3 months Sep-30-2013 | AN4: 3 months Dec-31-2013 | AO4: 3 months Mar-31-2014 | AP4: FY2014 E
A7: Profit & Loss Consolidated | C7: Numbers for these Quarters are Stand Alone as Consolidated data was not available
A9: Sales (including excise duty) | B9: 16955 | F9: 5611 | G9: ='Segment Revenue Model'!B25 -> 22502.2 | H9: ='Segment Revenue Model'!C25+0.4 -> 5664.4 | I9: ='Segment Revenue Model'!D25-0.4 -> 6669.6 | J9: ='Segment Revenue Model'!E25-0.1 -> 6101.9 | K9: =L9-SUM(H9:J9) -> 7087 | L9: ='Segment Revenue Model'!G25-1.1 -> 25522.9 | M9: ='Segment Revenue Model'!H25-0.1 -> 7067.9 | N9: ='Segment Revenue Model'!I25-0.27 -> 7239.73 | O9: ='Segment Revenue Model'!J25-0.2 -> 7567.8 | P9: =Q9-SUM(M9:O9) -> 8688.3 | Q9: ='Segment Revenue Model'!L25-0.27 -> 30563.73 | R9: ='Segment Revenue Model'!M25 -> 8267.1 | S9: ='Segment Revenue Model'!N25 -> 10366.121 | T9: ='Segment Revenue Model'!O25 -> 10366.121 | U9: ='Segment Revenue Model'!P25 -> 10366.121 | V9: ='Segment Revenue Model'!Q25 -> 39365.462 | W9: ='Segment Revenue Model'!R25 -> 11288.166 | X9: ='Segment Revenue Model'!S25 -> 11562.864 | Y9: ='Segment Revenue Model'!T25 -> 12086.706 | ... AP9: ='Segment Revenue Model'!AK25 -> 88613.481
A10: Less: Excise Duty | B10: 1018.9 | F10: 288 | G10: 1273 | H10: 341 | I10: 385.8 | J10: 406.3 | K10: =L10-SUM(H10:J10) -> 30.8 | L10: 1163.9 | M10: 271.3 | N10: 229.8 | O10: 216.7 | P10: =Q10-SUM(M10:O10) -> 187.8 | Q10: 905.6 | R10: 170.6 | S10: =S9*'Cost Model'!S10 -> 329.03637 | T10: =T9*'Cost Model'!T10 -> 296.82845 | U10: =U9*'Cost Model'!U10 -> 224.06655 | V10: =SUM(R10:U10) -> 1020.5314 | W10: =W9*'Cost Model'!W10 -> 232.94276 | X10: =X9*'Cost Model'!X10 -> 367.02282 | Y10: =Y9*'Cost Model'!Y10 -> 346.09652 | Z10: =Z9*'Cost Model'!Z10 -> 299.92139 | AA10: =SUM(W10:Z10) -> 1245.9835 | AB10: =AB9*'Cost Model'!AB10 -> 288.84903 | AC10: =AC9*'Cost Model'!AC10 -> 455.10829 | AD10: =AD9*'Cost Model'!AD10 -> 429.15969 | AE10: =AE9*'Cost Model'!AE10 -> 371.90252 | AF10: =SUM(AB10:AE10) -> 1545.0195 | AG10: =AG9*'Cost Model'!AG10 -> 352.39581 | AH10: =AH9*'Cost Model'!AH10 -> 555.23212 | AI10: =AI9*'Cost Model'!AI10 -> 523.57482 | AJ10: =AJ9*'Cost Model'!AJ10 -> 453.72107 | AK10: =SUM(AG10:AJ10) -> 1884.9238 | AL10: =AL9*'Cost Model'!AL10 -> 422.87497 | AM10: =AM9*'Cost Model'!AM10 -> 666.27854 | AN10: =AN9*'Cost Model'!AN10 -> 628.28978 | AO10: =AO9*'Cost Model'!AO10 -> 544.46529 | AP10: =SUM(AL10:AO10) -> 2261.9086
A11: Net Sales | B11: =B9-B10 -> 15936.1 | C11: 4385.6 | D11: 4800 | E11: 5284 | F11: =F9-F10 -> 5323 | G11: =G9-G10 -> 21229.2 | H11: =H9-H10 -> 5323.4 | I11: =I9-I10 -> 6283.8 | J11: =J9-J10 -> 5695.6 | K11: =L11-SUM(H11:J11) -> 7056.2 | L11: =L9-L10 -> 24359 | M11: =M9-M10 -> 6796.6 | N11: =N9-N10 -> 7009.93 | O11: =O9-O10 -> 7351.1 | P11: =Q11-SUM(M11:O11) -> 8500.5 | Q11: =Q9-Q10 -> 29658.13 | R11: =R9-R10 -> 8096.5 | S11: =S9-S10 -> 10037.084 | T11: =T9-T10 -> 10069.292 | U11: =U9-U10 -> 10142.054 | V11: =V9-V10 -> 38344.93 | W11: =W9-W10 -> 11055.223 | X11: =X9-X10 -> 11195.841 | ... AP11: =AP9-AP10 -> 86351.572
A12: Other Operating Income | B12: 0 | C12: 0 | D12: 0 | F12: 33 | G12: 0 | H12: 0 | I12: 18.2 | J12: 0 | K12: 0 | L12: 0 | M12: 35.8 | N12: 84.6 | O12: 877.1 | P12: =Q12-SUM(M12:O12) -> 586.8 | Q12: 1584.3 | R12: 431 | S12: =N12 -> 84.6 | T12: =O12 -> 877.1 | U12: =P12 -> 586.8 | V12: =SUM(R12:U12) -> 1979.5 | W12: =R12 -> 431 | X12: =S12 -> 84.6 | Y12: =T12 -> 877.1 | Z12: =U12 -> 586.8 | AA12: =SUM(W12:Z12) -> 1979.5 | AB12: =W12 -> 431 | AC12: =X12 -> 84.6 | AD12: =Y12 -> 877.1 | AE12: =Z12 -> 586.8 | AF12: =SUM(AB12:AE12) -> 1979.5 | AG12: =AB12 -> 431 | AH12: =AC12 -> 84.6 | AI12: =AD12 -> 877.1 | AJ12: =AE12 -> 586.8 | AK12: =SUM(AG12:AJ12) -> 1979.5 | AL12: =AG12 -> 431 | AM12: =AH12 -> 84.6 | AN12: =AI12 -> 877.1 | AO12: =AJ12 -> 586.8 | AP12: =SUM(AL12:AO12) -> 1979.5
A13: Total Income | B13: =B11+B12 -> 15936.1 | C13: =C11+C12 -> 4385.6 | D13: =D11+D12 -> 4800 | E13: =E11+E12 -> 5284 | F13: =F11+F12 -> 5356 | G13: =G11+G12 -> 21229.2 | H13: =H11+H12 -> 5323.4 | I13: =I11+I12 -> 6302 | ... L13: =L11+L12 -> 24359 | M13: =SUM(M11:M12) -> 6832.4 | N13: =N11+N12 -> 7094.53 | O13: =O11+O12 -> 8228.2 | P13: =Q13-SUM(M13:O13) -> 9087.3 | Q13: =SUM(Q11:Q12) -> 31242.43 | R13: =SUM(R11:R12) -> 8527.5 | S13: =SUM(S11:S12) -> 10121.684 | T13: =SUM(T11:T12) -> 10946.392 | U13: =SUM(U11:U12) -> 10728.854 | V13: =SUM(V11:V12) -> 40324.43 | W13: =SUM(W11:W12) -> 11486.223 | X13: =SUM(X11:X12) -> 11280.441 | ... AP13: =SUM(AP11:AP12) -> 88331.072
A15: Expenditure
A16: a. (Increase) / Decrease in Stocks | B16: -518.3 | C16: -445.1 | D16: 84.4 | E16: -222.9 | F16: -440 | G16: -890.5 | H16: -439.6 | I16: -327.4 | J16: -433.5 | K16: =L16-SUM(H16:J16) -> 488.1 | L16: -712.4 | M16: -99.7 | N16: -580.7 | O16: -170.9 | P16: =Q16-SUM(M16:O16) -> 644.1 | Q16: -207.2 | R16: -101.8 | S16: =S9*'Cost Model'!S12 -> -831.46833 | T16: =T9*'Cost Model'!T12 -> -234.09313 | U16: =U9*'Cost Model'!U12 -> 768.48386 | V16: =SUM(R16:U16) -> -398.87761 | W16: =W9*'Cost Model'!W12 -> -139.00102 | X16: =X9*'Cost Model'!X12 -> -927.45931 | Y16: =Y9*'Cost Model'!Y12 -> -272.94829 | Z16: =Z9*'Cost Model'!Z12 -> 1028.6441 | AA16: =SUM(W16:Z16) -> -310.7645 | AB16: =AB9*'Cost Model'!AB12 -> -172.36126 | AC16: =AC9*'Cost Model'!AC12 -> -1150.0495 | AD16: =AD9*'Cost Model'!AD12 -> -338.45588 | AE16: =AE9*'Cost Model'!AE12 -> 1275.5187 | AF16: =SUM(AB16:AE16) -> -385.34799 | AG16: =AG9*'Cost Model'!AG12 -> -210.28074 | AH16: =AH9*'Cost Model'!AH12 -> -1403.0605 | AI16: =AI9*'Cost Model'!AI12 -> -412.91618 | AJ16: =AJ9*'Cost Model'!AJ12 -> 1556.1328 | AK16: =SUM(AG16:AJ16) -> -470.12454 | AL16: =AL9*'Cost Model'!AL12 -> -252.33688 | AM16: =AM9*'Cost Model'!AM12 -> -1683.6725 | AN16: =AN9*'Cost Model'!AN12 -> -495.49942 | AO16: =AO9*'Cost Model'!AO12 -> 1867.3594 | AP16: =SUM(AL16:AO16) -> -564.14945
A17: b. Material Consumed | B17: 9146.3 | C17: 2921.2 | D17: 2541.7 | E17: 3284.6 | F17: 3037 | G17: 11755.7 | H17: 3036.9 | I17: 3309.3 | J17: 2974.7 | K17: =L17-SUM(H17:J17) -> 3290.8 | L17: 12611.7 | M17: 3572.4 | N17: 3995 | O17: 4281.4 | P17: =Q17-SUM(M17:O17) -> 3650.2 | Q17: 15499 | R17: 4013.1 | S17: =S9*'Cost Model'!S13 -> 5720.1929 | T17: =T9*'Cost Model'!T13 -> 5864.5192 | U17: =U9*'Cost Model'!U13 -> 4355.0998 | V17: =SUM(R17:U17) -> 19952.912 | W17: =W9*'Cost Model'!W13 -> 5479.6166 | X17: =X9*'Cost Model'!X13 -> 6380.5751 | Y17: =Y9*'Cost Model'!Y13 -> 6837.9218 | Z17: =Z9*'Cost Model'!Z13 -> 5829.4625 | AA17: =SUM(W17:Z17) -> 24527.576 | AB17: =AB9*'Cost Model'!AB13 -> 6794.7246 | AC17: =AC9*'Cost Model'!AC13 -> 7911.9131 | AD17: =AD9*'Cost Model'!AD13 -> 8479.023 | AE17: =AE9*'Cost Model'!AE13 -> 7228.5334 | AF17: =SUM(AB17:AE17) -> 30414.194 | AG17: =AG9*'Cost Model'!AG13 -> 8289.5641 | AH17: =AH9*'Cost Model'!AH13 -> 9652.534 | AI17: =AI9*'Cost Model'!AI13 -> 10344.408 | AJ17: =AJ9*'Cost Model'!AJ13 -> 8818.8108 | AK17: =SUM(AG17:AJ17) -> 37105.317 | AL17: =AL9*'Cost Model'!AL13 -> 9947.4769 | AM17: =AM9*'Cost Model'!AM13 -> 11583.041 | AN17: =AN9*'Cost Model'!AN13 -> 12413.29 | AO17: =AO9*'Cost Model'!AO13 -> 10582.573 | AP17: =SUM(AL17:AO17) -> 44526.38
A18: C. Purchase of traded goods | B18: 908.5 | C18: 0 | D18: 0 | E18: 0 | F18: 330 | G18: 1351.1 | H18: 330.2 | I18: 452.6 | J18: 488 | K18: =L18-SUM(H18:J18) -> 343.9 | L18: 1614.7 | M18: 216.4 | N18: 200.4 | O18: 157.4 | P18: =Q18-SUM(M18:O18) -> 417.4 | Q18: 991.6 | R18: 302.5 | S18: =S9*'Cost Model'!S14 -> 286.94034 | T18: =T9*'Cost Model'!T14 -> 215.60128 | U18: =U9*'Cost Model'!U14 -> 498.00522 | V18: =SUM(R18:U18) -> 1303.0468 | W18: =W9*'Cost Model'!W14 -> 413.04329 | X18: =X9*'Cost Model'!X14 -> 320.0669 | Y18: =Y9*'Cost Model'!Y14 -> 251.38714 | Z18: =Z9*'Cost Model'!Z14 -> 666.59844 | AA18: =SUM(W18:Z18) -> 1651.0958 | AB18: =AB9*'Cost Model'!AB14 -> 512.17368 | AC18: =AC9*'Cost Model'!AC14 -> 396.88295 | AD18: =AD9*'Cost Model'!AD14 -> 311.72005 | AE18: =AE9*'Cost Model'!AE14 -> 826.58207 | AF18: =SUM(AB18:AE18) -> 2047.3587 | AG18: =AG9*'Cost Model'!AG14 -> 624.85189 | AH18: =AH9*'Cost Model'!AH14 -> 484.1972 | AI18: =AI9*'Cost Model'!AI14 -> 380.29846 | AJ18: =AJ9*'Cost Model'!AJ14 -> 1008.4301 | AK18: =SUM(AG18:AJ18) -> 2497.7777 | AL18: =AL9*'Cost Model'!AL14 -> 749.82227 | AM18: =AM9*'Cost Model'!AM14 -> 581.03664 | AN18: =AN9*'Cost Model'!AN14 -> 456.35815 | AO18: =AO9*'Cost Model'!AO14 -> 1210.1161 | AP18: =SUM(AL18:AO18) -> 2997.3332
A19: d. Staff Cost | B19: 1024.2 | C19: 258 | D19: 288.1 | E19: 262.7 | F19: 442 | G19: 1504.2 | H19: 442.3 | I19: 492.9 | J19: 497.9 | K19: =L19-SUM(H19:J19) -> 496.9 | L19: 1930 | M19: 573.7 | N19: 589.6 | O19: 653.6 | P19: =Q19-SUM(M19:O19) -> 617.8 | Q19: 2434.7 | R19: 690.6 | S19: =S9*'Cost Model'!S15 -> 844.21169 | T19: =T9*'Cost Model'!T15 -> 895.27953 | U19: =U9*'Cost Model'!U15 -> 737.10499 | V19: =SUM(R19:U19) -> 3167.1962 | W19: =W9*'Cost Model'!W15 -> 942.9676 | X19: =X9*'Cost Model'!X15 -> 941.67386 | Y19: =Y9*'Cost Model'!Y15 -> 1043.8795 | Z19: =Z9*'Cost Model'!Z15 -> 986.64235 | AA19: =SUM(W19:Z19) -> 3915.1633 | AB19: =AB9*'Cost Model'!AB15 -> 1169.2798 | AC19: =AC9*'Cost Model'!AC15 -> 1167.6756 | AD19: =AD9*'Cost Model'!AD15 -> 1294.4106 | AE19: =AE9*'Cost Model'!AE15 -> 1223.4365 | AF19: =SUM(AB19:AE19) -> 4854.8025 | AG19: =AG9*'Cost Model'!AG15 -> 1426.5214 | AH19: =AH9*'Cost Model'!AH15 -> 1424.5642 | AI19: =AI9*'Cost Model'!AI15 -> 1579.1809 | AJ19: =AJ9*'Cost Model'!AJ15 -> 1492.5925 | AK19: =SUM(AG19:AJ19) -> 5922.859 | AL19: =AL9*'Cost Model'!AL15 -> 1711.8257 | AM19: =AM9*'Cost Model'!AM15 -> 1709.4771 | AN19: =AN9*'Cost Model'!AN15 -> 1895.0171 | AO19: =AO9*'Cost Model'!AO15 -> 1791.1111 | AP19: =SUM(AL19:AO19) -> 7107.4308
A20: e. Depreciation / Amortization | B20: 721.3 | C20: 142.8 | D20: 149.9 | E20: 162.9 | F20: 234 | G20: 997.2 | H20: 233.5 | I20: 249.5 | J20: 256 | K20: =L20-SUM(H20:J20) -> 264.8 | L20: 1003.8 | M20: 270.4 | N20: 288.3 | O20: 310.8 | P20: =Q20-SUM(M20:O20) -> 351.7 | Q20: 1221.2 | R20: 332.6 | S20: =($V$20-$R$20)/3 -> 292.40251 | T20: =($V$20-$R$20)/3 -> 292.40251 | U20: =($V$20-$R$20)/3 -> 292.40251 | V20: ='Fixed Asset'!H13 -> 1209.8075 | W20: =$AA$20/4 -> 339.18104 | X20: =$AA$20/4 -> 339.18104 | Y20: =$AA$20/4 -> 339.18104 | Z20: =$AA$20/4 -> 339.18104 | AA20: ='Fixed Asset'!I13 -> 1356.7242 | AB20: =$AF$20/4 -> 381.60896 | AC20: =$AF$20/4 -> 381.60896 | AD20: =$AF$20/4 -> 381.60896 | AE20: =$AF$20/4 -> 381.60896 | AF20: ='Fixed Asset'!J13 -> 1526.4359 | AG20: =$AK$20/4 -> 430.63647 | AH20: =$AK$20/4 -> 430.63647 | AI20: =$AK$20/4 -> 430.63647 | AJ20: =$AK$20/4 -> 430.63647 | AK20: ='Fixed Asset'!K13 -> 1722.5459 | AL20: =$AP$20/4 -> 492.31735 | AM20: =$AP$20/4 -> 492.31735 | AN20: =$AP$20/4 -> 492.31735 | AO20: =$AP$20/4 -> 492.31735 | AP20: ='Fixed Asset'!L13 -> 1969.2694
A21: f. Other Expenditure | B21: 3600.5 | C21: 992.7 | D21: 1194.9 | E21: 1174.9 | F21: 1259 | G21: 4486.8 | H21: 1258.7 | I21: 1422.6 | J21: 1380.6 | K21: =L21-SUM(H21:J21) -> 1441.7 | L21: 5503.6 | M21: 1424.7 | N21: 1641.1 | O21: 1728.9 | P21: =Q21-SUM(M21:O21) -> 1998.1 | Q21: 6792.8 | R21: 1666.1 | S21: =S9*'Cost Model'!S17 -> 2349.7894 | T21: =T9*'Cost Model'!T17 -> 2368.1897 | U21: =U9*'Cost Model'!U17 -> 2383.9584 | V21: =SUM(R21:U21) -> 8768.0374 | W21: =W9*'Cost Model'!W17 -> 2274.9469 | X21: =X9*'Cost Model'!X17 -> 2621.0668 | Y21: =Y9*'Cost Model'!Y17 -> 2761.2657 | Z21: =Z9*'Cost Model'!Z17 -> 3191.0166 | AA21: =SUM(W21:Z21) -> 10848.296 | AB21: =AB9*'Cost Model'!AB17 -> 2820.9341 | AC21: =AC9*'Cost Model'!AC17 -> 3250.1228 | AD21: =AD9*'Cost Model'!AD17 -> 3423.9695 | AE21: =AE9*'Cost Model'!AE17 -> 3956.8606 | AF21: =SUM(AB21:AE21) -> 13451.887 | AG21: =AG9*'Cost Model'!AG17 -> 3441.5396 | AH21: =AH9*'Cost Model'!AH17 -> 3965.1498 | AI21: =AI9*'Cost Model'!AI17 -> 4177.2427 | AJ21: =AJ9*'Cost Model'!AJ17 -> 4827.37 | AK21: =SUM(AG21:AJ21) -> 16411.302 | AL21: =AL9*'Cost Model'!AL17 -> 4129.8476 | AM21: =AM9*'Cost Model'!AM17 -> 4758.1798 | AN21: =AN9*'Cost Model'!AN17 -> 5012.6913 | AO21: =AO9*'Cost Model'!AO17 -> 5792.844 | AP21: =SUM(AL21:AO21) -> 19693.563
A22: Total Expenditure | B22: =SUM(B16:B21) -> 14882.5 | C22: =SUM(C16:C21) -> 3869.6 | D22: =SUM(D16:D21) -> 4259 | E22: =SUM(E16:E21) -> 4662.2 | F22: =SUM(F16:F21) -> 4862 | G22: =SUM(G16:G21) -> 19204.5 | H22: =SUM(H16:H21) -> 4862 | I22: =SUM(I16:I21) -> 5599.5 | J22: =SUM(J16:J21) -> 5163.7 | K22: =L22-SUM(H22:J22) -> 6326.2 | L22: =SUM(L16:L21) -> 21951.4 | M22: =SUM(M16:M21) -> 5957.9 | N22: =SUM(N16:N21) -> 6133.7 | O22: =SUM(O16:O21) -> 6961.2 | P22: =Q22-SUM(M22:O22) -> 7679.3 | Q22: =SUM(Q16:Q21) -> 26732.1 | R22: =SUM(R16:R21) -> 6903.1 | S22: =SUM(S16:S21) -> 8662.0684 | T22: =SUM(T16:T21) -> 9401.8991 | U22: =SUM(U16:U21) -> 9035.0547 | V22: =SUM(V16:V21) -> 34002.122 | W22: =SUM(W16:W21) -> 9310.7544 | X22: =SUM(X16:X21) -> 9675.1044 | ... AP22: =SUM(AP16:AP21) -> 75729.827
A23: Operating Income (Profit from Operations before other income) | B23: =B13-B22 -> 1053.6 | C23: =C13-C22 -> 516 | D23: =D13-D22 -> 541 | E23: =E13-E22 -> 621.8 | F23: =F13-F22 -> 494 | G23: =G13-G22 -> 2024.7 | H23: =H13-H22 -> 461.4 | I23: =I13-I22 -> 702.5 | J23: =J13-J22 -> 531.9 | K23: =L23-SUM(H23:J23) -> 711.8 | L23: =L13-L22 -> 2407.6 | M23: =M13-M22 -> 874.5 | N23: =N13-N22 -> 960.83 | O23: =O13-O22 -> 1267 | P23: =Q23-SUM(M23:O23) -> 1408 | Q23: =Q13-Q22 -> 4510.33 | R23: =R13-R22 -> 1624.4 | S23: =S13-S22 -> 1459.6158 | T23: =T13-T22 -> 1544.493 | U23: =U13-U22 -> 1693.7993 | V23: =V13-V22 -> 6322.3081 | W23: =W13-W22 -> 2175.4688 | X23: =X13-X22 -> 1605.3366 | ... AP23: =AP13-AP22 -> 12601.246
A24: Other Income | B24: 225.7 | C24: 171.1 | D24: 267 | E24: 263.3 | F24: 8 | G24: 493.1 | H24: 335.3 | I24: 26.1 | J24: 175.2 | K24: =L24-SUM(H24:J24) -> 405.8 | L24: 942.4 | M24: 15 | N24: 37.6 | O24: 53.2 | P24: =Q24-SUM(M24:O24) -> 53.3 | Q24: 159.1 | R24: 22.3 | S24: =N24 -> 37.6 | T24: =O24 -> 53.2 | U24: =P24 -> 53.3 | V24: =SUM(R24:U24) -> 166.4 | W24: =R24 -> 22.3 | X24: =S24 -> 37.6 | Y24: =T24 -> 53.2 | Z24: =U24 -> 53.3 | AA24: =SUM(W24:Z24) -> 166.4 | AB24: =W24 -> 22.3 | AC24: =X24 -> 37.6 | AD24: =Y24 -> 53.2 | AE24: =Z24 -> 53.3 | AF24: =SUM(AB24:AE24) -> 166.4 | AG24: =W24 -> 22.3 | AH24: =X24 -> 37.6 | AI24: =Y24 -> 53.2 | AJ24: =Z24 -> 53.3 | AK24: =SUM(AG24:AJ24) -> 166.4 | AL24: =AG24 -> 22.3 | AM24: =AH24 -> 37.6 | AN24: =AI24 -> 53.2 | AO24: =AJ24 -> 53.3 | AP24: =SUM(AL24:AO24) -> 166.4
A25: Profit Before Interest and Tax (PBIT) | B25: =B23+B24 -> 1279.3 | C25: =C23+C24 -> 687.1 | D25: =D23+D24 -> 808 | E25: =E23+E24 -> 885.1 | F25: =F23+F24 -> 502 | G25: =G23+G24 -> 2517.8 | H25: =H24+H23 -> 796.7 | I25: =I24+I23 -> 728.6 | J25: =J24+J23 -> 707.1 | K25: =L25-SUM(H25:J25) -> 1117.6 | L25: =L24+L23 -> 3350 | M25: =M24+M23 -> 889.5 | N25: =N23+N24 -> 998.43 | O25: =O23+O24 -> 1320.2 | P25: =Q25-SUM(M25:O25) -> 1461.3 | Q25: =Q23+Q24 -> 4669.43 | R25: =R23+R24 -> 1646.7 | S25: =S23+S24 -> 1497.2158 | T25: =T23+T24 -> 1597.693 | U25: =U23+U24 -> 1747.0993 | V25: =V23+V24 -> 6488.7081 | W25: =W23+W24 -> 2197.7688 | X25: =X23+X24 -> 1642.9366 | ... AP25: =AP23+AP24 -> 12767.646
A27: PBIT Margin (%) | B27: =B25/B9 -> 0.075452669 | C27: =C25/C11 -> 0.15667184 | D27: =D25/D11 -> 0.16833333 | E27: =E25/E11 -> 0.16750568 | F27: =F25/F9 -> 0.089467118 | G27: =G25/G9 -> 0.11189128 | H27: =H25/H9 -> 0.14065038 | I27: =I25/I9 -> 0.10924193 | J27: =J25/J9 -> 0.11588194 | K27: =K25/K9 -> 0.15769719 | L27: =L25/L9 -> 0.13125468 | M27: =M25/M9 -> 0.12585068 | ... AP27: =AP25/AP9 -> 0.14408243
A29: Interest (net) | B29: 604.1 | C29: 180.9 | D29: 202.4 | E29: 196.7 | F29: 106 | G29: 453.6 | H29: 106.3 | I29: 116.1 | J29: 101 | K29: =L29-SUM(H29:J29) -> 109 | L29: 432.4 | M29: 132.5 | N29: 156.3 | O29: 254.7 | P29: =Q29-SUM(M29:O29) -> 267.4 | Q29: 810.9 | R29: 226.8 | S29: =($V$29-$R$29)/3 -> 544.03279 | T29: =($V$29-$R$29)/3 -> 544.03279 | U29: =($V$29-$R$29)/3 -> 544.03279 | V29: ='Debt Schedule'!G33+('Debt Schedule'!$D$220/3) -> 1858.8984 | W29: =$AA$29/4 -> 532.88879 | X29: =$AA$29/4 -> 532.88879 | Y29: =$AA$29/4 -> 532.88879 | Z29: =$AA$29/4 -> 532.88879 | AA29: ='Debt Schedule'!H33+('Debt Schedule'!$D$220/3) -> 2131.5552 | AB29: =$AF$29/4 -> 656.91318 | AC29: =$AF$29/4 -> 656.91318 | AD29: =$AF$29/4 -> 656.91318 | AE29: =$AF$29/4 -> 656.91318 | AF29: ='Debt Schedule'!I33+('Debt Schedule'!$D$220/3) -> 2627.6527 | AG29: =$AK$29/4 -> 435.00881 | AH29: =$AK$29/4 -> 435.00881 | AI29: =$AK$29/4 -> 435.00881 | AJ29: =$AK$29/4 -> 435.00881 | AK29: ='Debt Schedule'!J33 -> 1740.0352 | AL29: =$AP$29/4 -> 423.96395 | AM29: =$AP$29/4 -> 423.96395 | AN29: =$AP$29/4 -> 423.96395 | AO29: =$AP$29/4 -> 423.96395 | AP29: ='Debt Schedule'!K33 -> 1695.8558
A30: Foreign Exchange (Gain) / Loss (net) | B30: 0 | C30: 0 | D30: 0 | F30: -294 | G30: 0 | H30: 0 | I30: -225.7 | J30: 0 | K30: 0 | L30: 0 | M30: 537.1 | N30: 1051 | O30: 570.5 | P30: =Q30-SUM(M30:O30) -> 388.1 | Q30: 2546.7 | R30: -575.4 | S30: =($V$30-$R$30)/3 -> -89.430933 | T30: =($V$30-$R$30)/3 -> -89.430933 | U30: =($V$30-$R$30)/3 -> -89.430933 | V30: ='Debt Schedule'!G48 -> -843.6928 | W30: 0 | X30: 0 | Y30: 0 | Z30: 0 | AA30: ='Debt Schedule'!H48 -> -69.6 | AB30: 0 | AC30: 0 | AD30: 0 | AE30: 0 | AF30: 0 | AG30: 0 | AH30: 0 | AI30: 0 | AJ30: 0 | AK30: 0 | AL30: 0 | AM30: 0 | AN30: 0 | AO30: 0 | AP30: 0
A31: Exceptional Item | B31: 309.8 | C31: 0 | D31: 0 | E31: 0 | F31: 0 | G31: 0 | H31: 0 | I31: 0 | J31: 0 | K31: 0 | L31: 0 | M31: 0 | N31: 0 | O31: 0 | P31: 0 | Q31: 0 | R31: 0 | S31: 0 | T31: 0 | U31: 0 | V31: 0 | W31: 0 | X31: 0 | Y31: 0 | Z31: 0 | AA31: =SUM('Debt Schedule'!B208:B209)+'Debt Schedule'!H40 -> -166.60851 | AB31: 0 | AC31: 0 | AD31: 0 | AE31: 0 | AF31: 0 | AG31: 0 | AH31: 0 | AI31: 0 | AJ31: 0 | AK31: 0 | AL31: 0 | AM31: 0 | AN31: 0 | AO31: 0 | AP31: 0
A32: Profit from Ordinary Activities before Tax (PBT) | B32: =B25-B29-B30+B31 -> 985 | C32: =C25-C29-C30 -> 506.2 | D32: =D25-D29-D30 -> 605.6 | E32: =E25-E29-E30 -> 688.4 | F32: =F25-F29-F30 -> 690 | G32: =G25-G29-G30 -> 2064.2 | H32: =H25-H29-H30 -> 690.4 | I32: =I25-I29-I30 -> 838.2 | J32: =J25-J29-J30 -> 606.1 | K32: =L32-SUM(H32:J32) -> 782.9 | L32: =L25-L29-L30 -> 2917.6 | M32: =M25-M29-M30 -> 219.9 | N32: =N25-N29-N30 -> -208.87 | O32: =O25-O29-O30 -> 495 | P32: =Q32-SUM(M32:O32) -> 805.8 | Q32: =Q25-Q29-Q30 -> 1311.83 | R32: =R25-R29-R30 -> 1995.3 | S32: =S25-S29-S30 -> 1042.614 | T32: =T25-T29-T30 -> 1143.0912 | U32: =U25-U29-U30 -> 1292.4975 | V32: =V25-V29-V30 -> 5473.5026 | W32: =W25-W29-W30 -> 1664.88 | X32: =X25-X29-X30 -> 1110.0478 | ... Z32: =Z25-Z29-Z30 -> 1641.1814 | AA32: =AA25-AA29-AA30-AA31 -> 5829.6518 | AB32: =AB25-AB29-AB30 -> 1998.5036 | AC32: =AC25-AC29-AC30 -> 1389.9758 | AD32: =AD25-AD29-AD30 -> 1279.4668 | AE32: =AE25-AE29-AE30 -> 1924.2853 | AF32: =AF25-AF29-AF30 -> 6592.2315 | AG32: =AG25-AG29-AG30 -> 2739.8001 | AH32: =AH25-AH29-AH30 -> 2070.2382 | AI32: =AI25-AI29-AI30 -> 1757.6352 | ... AP32: =AP25-AP29-AP30 -> 11071.79
A34: PBT Margin (%) | B34: =B32/B9 -> 0.058094957 | C34: =C32/C11 -> 0.1154232 | D34: =D32/D11 -> 0.12616667 | E34: =E32/E11 -> 0.13028009 | F34: =F32/F9 -> 0.12297273 | G34: =G32/G9 -> 0.091733253 | H34: =H32/H9 -> 0.12188405 | I34: =I32/I9 -> 0.1256747 | J34: =J32/J9 -> 0.099329717 | K34: =K32/K9 -> 0.11046987 | L34: =L32/L9 -> 0.11431303 | M34: =M32/M9 -> 0.031112495 | ... AP34: =AP32/AP9 -> 0.12494476
A36: Provision for Taxation
A37: a. Current Tax | B37: 128.4 | C37: 58.1 | D37: 60.5 | E37: 40 | F37: 81 | G37: 203.4 | H37: 80.6 | I37: 199.1 | J37: 153.7 | K37: =L37-SUM(H37:J37) -> 45.8 | L37: 479.2 | M37: 65.3 | N37: 188.3 | O37: 33.9 | P37: =Q37-SUM(M37:O37) -> -5.9 | Q37: 281.6 | R37: 320.1 | S37: 0 | T37: 0 | U37: 0 | W37: 0 | X37: 0 | Y37: 0 | Z37: 0 | AB37: 0 | AC37: 0 | AD37: 0 | AE37: 0 | AG37: 0 | AH37: 0 | AI37: 0 | AJ37: 0 | AL37: 0 | AM37: 0 | AN37: 0 | AO37: 0
A38: b. MAT Credit Entitlement | B38: -80.9 | C38: -52.2 | D38: -13.7 | E38: 11.3 | F38: -4 | G38: -145.4 | H38: -3.8 | I38: 3.9 | J38: 0 | K38: 0 | L38: 0 | M38: -40.8 | N38: 40.8 | O38: 0 | P38: =Q38-SUM(M38:O38) -> 0 | Q38: 0 | R38: 0 | S38: 0 | T38: 0 | U38: 0 | W38: 0 | X38: 0 | Y38: 0 | Z38: 0 | AB38: 0 | AC38: 0 | AD38: 0 | AE38: 0 | AG38: 0 | AH38: 0 | AI38: 0 | AJ38: 0 | AL38: 0 | AM38: 0 | AN38: 0 | AO38: 0
A39: c. Defferred Tax | B39: 159 | C39: 137.4 | D39: 11.5 | E39: 44 | F39: -8 | G39: -40.6 | H39: -7.7 | I39: 10.7 | J39: 6.4 | K39: =L39-SUM(H39:J39) -> 42.7 | L39: 52.1 | M39: 10.1 | N39: -2.9 | O39: 41.6 | P39: =Q39-SUM(M39:O39) -> 10.6 | Q39: 59.4 | R39: 10.7 | S39: 0 | T39: 0 | U39: 0 | W39: 0 | X39: 0 | Y39: 0 | Z39: 0 | AB39: 0 | AC39: 0 | AD39: 0 | AE39: 0 | AG39: 0 | AH39: 0 | AI39: 0 | AJ39: 0 | AL39: 0 | AM39: 0 | AN39: 0 | AO39: 0
A40: d. Fringe Benefit Tax (net of recovery) | B40: 2.8 | C40: 0.8 | D40: 0.9 | E40: 1.1 | F40: 1 | G40: 3.9 | H40: 1 | I40: 1.3 | J40: 1.6 | K40: =L40-SUM(H40:J40) -> 0.8 | L40: 4.7 | M40: 0.9 | N40: 1.7 | O40: 1.6 | P40: =Q40-SUM(M40:O40) -> 1 | Q40: 5.2 | R40: 0 | S40: 0 | T40: 0 | U40: 0 | W40: 0 | X40: 0 | Y40: 0 | Z40: 0 | AB40: 0 | AC40: 0 | AD40: 0 | AE40: 0 | AG40: 0 | AH40: 0 | AI40: 0 | AJ40: 0 | AL40: 0 | AM40: 0 | AN40: 0 | AO40: 0
A41: e. Tax adjustment of previous years | B41: 64.6 | C41: 0 | D41: 0 | E41: -9.2 | F41: 0 | G41: 22.4 | H41: 0 | I41: 0 | J41: 0 | K41: =L41-SUM(H41:J41) -> 0 | L41: 0 | M41: 19.8 | N41: -54.6 | O41: 1.5 | P41: =Q41-SUM(M41:O41) -> 0 | Q41: -33.3 | R41: 0 | S41: 0 | T41: 0 | U41: 0 | W41: 0 | X41: 0 | Y41: 0 | Z41: 0 | AB41: 0 | AC41: 0 | AD41: 0 | AE41: 0 | AG41: 0 | AH41: 0 | AI41: 0 | AJ41: 0 | AL41: 0 | AM41: 0 | AN41: 0 | AO41: 0
A42: Total Tax | B42: =SUM(B37:B41) -> 273.9 | C42: =SUM(C37:C41) -> 144.1 | D42: =SUM(D37:D41) -> 59.2 | E42: =SUM(E37:E41) -> 87.2 | F42: =SUM(F37:F41) -> 70 | G42: =SUM(G37:G41) -> 43.7 | H42: =SUM(H37:H41) -> 70.1 | I42: =SUM(I37:I41) -> 215 | J42: =SUM(J37:J41) -> 161.7 | K42: =L42-SUM(H42:J42) -> 89.2 | L42: =SUM(L37:L41) -> 536 | M42: =SUM(M37:M41) -> 55.3 | N42: =SUM(N37:N41) -> 173.3 | O42: =SUM(O37:O41) -> 78.6 | P42: =Q42-SUM(M42:O42) -> 5.7 | Q42: =SUM(Q37:Q41) -> 312.9 | R42: =SUM(R37:R41) -> 330.8 | S42: =S32*'Cost Model'!S20 -> 135.53981 | T42: =T32*'Cost Model'!T20 -> 148.60185 | U42: =U32*'Cost Model'!U20 -> 168.02467 | V42: =SUM(R42:U42) -> 782.96634 | W42: =W32*'Cost Model'!W20 -> 216.43439 | X42: =X32*'Cost Model'!X20 -> 144.30622 | Y42: =Y32*'Cost Model'!Y20 -> 153.05344 | Z42: =Z32*'Cost Model'!Z20 -> 213.35358 | AA42: =SUM(W42:Z42) -> 727.14763 | AB42: =AB32*'Cost Model'!AB20 -> 259.80547 | AC42: =AC32*'Cost Model'!AC20 -> 180.69685 | AD42: =AD32*'Cost Model'!AD20 -> 166.33068 | AE42: =AE32*'Cost Model'!AE20 -> 250.1571 | AF42: =SUM(AB42:AE42) -> 856.9901 | AG42: =AG32*'Cost Model'!AG20 -> 356.17402 | AH42: =AH32*'Cost Model'!AH20 -> 269.13096 | AI42: =AI32*'Cost Model'!AI20 -> 228.49258 | AJ42: =AJ32*'Cost Model'!AJ20 -> 339.06052 | AK42: =SUM(AG42:AJ42) -> 1192.8581 | AL42: =AL32*'Cost Model'!AL20 -> 431.54712 | AM42: =AM32*'Cost Model'!AM20 -> 335.70405 | AN42: =AN32*'Cost Model'!AN20 -> 265.92739 | AO42: =AO32*'Cost Model'!AO20 -> 406.15412 | AP42: =SUM(AL42:AO42) -> 1439.3327
A43: Profit before Minority Interest | B43: =B32-B42 -> 711.1 | C43: =C32-C42 -> 362.1 | D43: =D32-D42 -> 546.4 | E43: =E32-E42 -> 601.2 | F43: =F32-F42 -> 620 | G43: =G32-G42 -> 2020.5 | H43: =H32-H42 -> 620.3 | I43: =I32-I42 -> 623.2 | J43: =J32-J42 -> 444.4 | K43: =L43-SUM(H43:J43) -> 693.7 | L43: =L32-L42 -> 2381.6 | M43: =M32-M42 -> 164.6 | N43: =N32-N42 -> -382.17 | O43: =O32-O42 -> 416.4 | P43: =Q43-SUM(M43:O43) -> 800.1 | Q43: =Q32-Q42 -> 998.93 | R43: =R32-R42 -> 1664.5 | S43: =S32-S42 -> 907.07414 | T43: =T32-T42 -> 994.48932 | U43: =U32-U42 -> 1124.4728 | V43: =V32-V42 -> 4690.5362 | W43: =W32-W42 -> 1448.4456 | X43: =X32-X42 -> 965.74162 | ... AP43: =AP32-AP42 -> 9632.4571
A44: Minority Interest | B44: -14.1 | C44: 0 | D44: 0 | E44: 0 | F44: 3 | G44: 11 | H44: 2.9 | I44: 2.6 | J44: -1.3 | K44: =L44-SUM(H44:J44) -> -7.6 | L44: -3.4 | M44: 0.4 | N44: 2 | O44: -2 | P44: =Q44-SUM(M44:O44) -> -0.4 | Q44: 0 | R44: 0 | S44: 0 | T44: 0 | U44: 0 | V44: 0 | W44: 0 | X44: 0 | Y44: 0 | Z44: 0 | AA44: 0 | AB44: 0 | AC44: 0 | AD44: 0 | AE44: 0 | AF44: 0 | AG44: 0 | AH44: 0 | AI44: 0 | AJ44: 0 | AK44: 0 | AL44: 0 | AM44: 0 | AN44: 0 | AO44: 0 | AP44: 0
A45: Net Profit for the Period (PAT) | B45: =B43+B44 -> 697 | C45: =C43-C44 -> 362.1 | D45: =D43-D44 -> 546.4 | E45: =E43-E44 -> 601.2 | F45: =F43-F44 -> 617 | G45: =G43-G44 -> 2009.5 | H45: =H43-H44 -> 617.4 | I45: =I43-I44 -> 620.6 | J45: =J43-J44 -> 445.7 | K45: =L45-SUM(H45:J45) -> 701.3 | L45: =L43-L44 -> 2385 | M45: =M43-M44 -> 164.2 | N45: =N43-N44 -> -384.17 | O45: =O43-O44 -> 418.4 | P45: =Q45-SUM(M45:O45) -> 800.5 | Q45: =Q43-Q44 -> 998.93 | R45: =R43-R44 -> 1664.5 | S45: =S43-S44 -> 907.07414 | T45: =T43-T44 -> 994.48932 | U45: =U43-U44 -> 1124.4728 | V45: =V43-V44 -> 4690.5362 | W45: =W43-W44 -> 1448.4456 | X45: =X43-X44 -> 965.74162 | ... AP45: =AP43-AP44 -> 9632.4571
A46: Net Profit Margin (%) | B46: =B45/B9 -> 0.041108817 | C46: =C45/C11 -> 0.082565669 | D46: =D45/D11 -> 0.11383333 | E46: =E45/E11 -> 0.11377744 | F46: =F45/F9 -> 0.10996257 | G46: =G45/G9 -> 0.089302379 | H46: =H45/H9 -> 0.10899654 | I46: =I45/I9 -> 0.093049058 | J46: =J45/J9 -> 0.073042823 | K46: =K45/K9 -> 0.098955835 | L46: =L45/L9 -> 0.093445494 | M46: =M45/M9 -> 0.023231794 | ... AP46: =AP45/AP9 -> 0.10870194
A48: Paid up Equity Share Capital | B48: 266.35 | C48: 266.35 | D48: 266.47 | E48: 266.74 | F48: 266.74 | G48: 266.74 | H48: 266.74 | I48: 268.697 | J48: 268.826 | K48: 268.826 | L48: 268.826 | M48: 268.826 | N48: 268.826 | O48: 268.826 | P48: 268.826 | Q48: 268.826 | R48: 268.826 | S48: =R48 -> 268.826 | T48: =S48 -> 268.826 | U48: =T48 -> 268.826 | V48: =U48 -> 268.826 | W48: =V48 -> 268.826 | X48: ='Balance Sheet'!$G$12 -> 291.07616 | Y48: =X48 -> 291.07616 | Z48: =Y48 -> 291.07616 | AA48: =Z48 -> 291.07616 | AB48: =AA48 -> 291.07616 | AC48: =AB48 -> 291.07616 | AD48: =AC48 -> 291.07616 | AE48: =AD48 -> 291.07616 | AF48: =AE48 -> 291.07616 | ... AP48: =AO48 -> 291.07616
A49: (Face value Rs 5/- per share)
...

Sheet Balance Sheet
A1: Aurobindo Pharma
A2: Balance Sheet
A3: (In Rs Millions, Except per share items)
A4: For the Fiscal Period Ending | B4: FY 2006 A | C4: FY2007 A | D4: FY2008 A | E4: FY2009 E | F4: FY2010 E | G4: FY2011 E | H4: FY2012 E | I4: FY2013 E | J4: FY2014 E
A7: Balance Sheet
A9: I. SOURCES OF FUNDS
A11: Share holder's Fund
A12: Share Capital | B12: 266.3 | C12: 266.7 | D12: 268.8 | E12: =D12+'Cash Flow Statement'!E54 -> 268.8 | F12: =E12+'Cash Flow Statement'!F54 -> 268.8 | G12: =F12+'Cash Flow Statement'!G54+'Debt Schedule'!B208 -> 291.07616 | H12: =G12+'Cash Flow Statement'!H54 -> 291.07616 | I12: =H12+'Cash Flow Statement'!I54 -> 291.07616 | J12: =I12+'Cash Flow Statement'!J54 -> 291.07616
A13: Share Application Money | B13: 0.4 | C13: 0.2 | D13: 0 | E13: 0 | F13: 0 | G13: 0 | H13: 0 | I13: 0 | J13: 0
A14: Reserves & Surplus | B14: 7882 | C14: 8593.2 | D14: 10971.4 | E14: =D14+'Profit & Loss Consolidated'!Q45 -> 11970.33 | F14: =E14+'Profit & Loss Consolidated'!V45 -> 16660.866 | G14: =F14+'Profit & Loss Consolidated'!AA45+'Debt Schedule'!B209 -> 24066.886 | H14: =G14+'Profit & Loss Consolidated'!AF45 -> 29802.127 | I14: =H14+'Profit & Loss Consolidated'!AK45 -> 37785.1 | J14: =I14+'Profit & Loss Consolidated'!AP45 -> 47417.558
B15: =SUM(B12:B14) -> 8148.7 | C15: =SUM(C12:C14) -> 8860.1 | D15: =SUM(D12:D14) -> 11240.2 | E15: =SUM(E12:E14) -> 12239.13 | F15: =SUM(F12:F14) -> 16929.666 | G15: =SUM(G12:G14) -> 24357.962 | H15: =SUM(H12:H14) -> 30093.203 | I15: =SUM(I12:I14) -> 38076.177 | J15: =SUM(J12:J14) -> 47708.634
A16: Minority Interest | B16: 24.3 | C16: 35.4 | D16: 32 | E16: =D16 -> 32 | F16: =E16 -> 32 | G16: =F16 -> 32 | H16: =G16 -> 32 | I16: =H16 -> 32 | J16: =I16 -> 32
A18: Loan Funds
A19: Secured Funds | B19: 7502.5 | C19: 7390.7 | D19: 6334.3 | E19: ='Debt Schedule'!F14 -> 6334.3 | F19: ='Debt Schedule'!G14 -> 6334.3 | G19: ='Debt Schedule'!H14 -> 8334.3 | H19: ='Debt Schedule'!I14 -> 13334.3 | I19: ='Debt Schedule'!J14 -> 13334.3 | J19: ='Debt Schedule'!K14 -> 13334.3
A20: Unsecured Funds | B20: 6228.2 | C20: 13390.7 | D20: 12135.9 | E20: ='Debt Schedule'!F24 -> 12135.9 | F20: ='Debt Schedule'!G24 -> 11200.63 | G20: ='Debt Schedule'!H24 -> 8638.6304 | H20: ='Debt Schedule'!I24 -> 2235.4304 | I20: ='Debt Schedule'!J24 -> 2235.4304 | J20: ='Debt Schedule'!K24 -> 2235.4304
B21: =SUM(B19:B20) -> 13730.7 | C21: =SUM(C19:C20) -> 20781.4 | D21: =SUM(D19:D20) -> 18470.2 | E21: =SUM(E19:E20) -> 18470.2 | F21: =SUM(F19:F20) -> 17534.93 | G21: =SUM(G19:G20) -> 16972.93 | H21: =SUM(H19:H20) -> 15569.73 | I21: =SUM(I19:I20) -> 15569.73 | J21: =SUM(J19:J20) -> 15569.73
A22: Deferred Tax Liability (Net) | B22: 725.6 | C22: 681.9 | D22: 733.4 | E22: =D22 -> 733.4 | F22: =E22 -> 733.4 | G22: =F22 -> 733.4 | H22: =G22 -> 733.4 | I22: =H22 -> 733.4 | J22: =I22 -> 733.4
A23: Total | B23: =B15+B16+B21+B22 -> 22629.3 | C23: =C15+C16+C21+C22 -> 30358.8 | D23: =D15+D16+D21+D22 -> 30475.8 | E23: =E15+E16+E21+E22 -> 31474.73 | F23: =F15+F16+F21+F22 -> 35229.997 | G23: =G15+G16+G21+G22 -> 42096.292 | H23: =H15+H16+H21+H22 -> 46428.334 | I23: =I15+I16+I21+I22 -> 54411.307 | J23: =J15+J16+J21+J22 -> 64043.764
A25: II. APPLICATION OF FUNDS
A27: Fixed Assets
A28: Gross Block | B28: 13561.6 | C28: 14681.4 | D28: 17179.9 | E28: ='Fixed Asset'!G7 -> 19472.18 | F28: ='Fixed Asset'!H7 -> 22227.762 | G28: ='Fixed Asset'!I7 -> 25644.684 | H28: ='Fixed Asset'!J7 -> 29276.384 | I28: ='Fixed Asset'!K7 -> 33707.058 | J28: ='Fixed Asset'!L7 -> 39023.867
A29: Less: Accumulated Depreciation/Amortization | B29: 2724.1 | C29: 3155.3 | D29: 4176.9 | E29: ='Fixed Asset'!G12 -> 5398.1 | F29: ='Fixed Asset'!H12 -> 6607.9075 | G29: ='Fixed Asset'!I12 -> 7964.6317 | H29: ='Fixed Asset'!J12 -> 9491.0676 | I29: ='Fixed Asset'!K12 -> 11213.613 | J29: ='Fixed Asset'!L12 -> 13182.883
A30: Net Block | B30: =B28-B29 -> 10837.5 | C30: =C28-C29 -> 11526.1 | D30: =D28-D29 -> 13003 | E30: =E28-E29 -> 14074.08 | F30: =F28-F29 -> 15619.855 | G30: =G28-G29 -> 17680.052 | H30: =H28-H29 -> 19785.317 | I30: =I28-I29 -> 22493.445 | J30: =J28-J29 -> 25840.984
A31: Capital Work-in-progress (including capital advances) | B31: 1497.4 | C31: 2187.1 | D31: 2145.5 | E31: =D31 -> 2145.5 | F31: =E31 -> 2145.5 | G31: =F31 -> 2145.5 | H31: =G31 -> 2145.5 | I31: =H31 -> 2145.5 | J31: =I31 -> 2145.5
B32: =B30+B31 -> 12334.9 | C32: =C30+C31 -> 13713.2 | D32: =D30+D31 -> 15148.5 | E32: =E30+E31 -> 16219.58 | F32: =F30+F31 -> 17765.355 | G32: =G30+G31 -> 19825.552 | H32: =H30+H31 -> 21930.817 | I32: =I30+I31 -> 24638.945 | J32: =J30+J31 -> 27986.484
A34: Investments | B34: 2.8 | C34: 2.7 | D34: 604.3 | E34: =D34+'Cash Flow Statement'!E47 -> 604.3 | F34: =E34+'Cash Flow Statement'!F47 -> 604.3 | G34: =F34+'Cash Flow Statement'!G47 -> 604.3 | H34: =G34+'Cash Flow Statement'!H47 -> 604.3 | I34: =H34+'Cash Flow Statement'!I47 -> 604.3 | J34: =I34+'Cash Flow Statement'!J47 -> 604.3
A36: Deferred Tax Asset | B36: 0.1 | C36: 0 | D36: 1.2 | E36: =D36 -> 1.2 | F36: =E36 -> 1.2 | G36: =F36 -> 1.2 | H36: =G36 -> 1.2 | I36: =H36 -> 1.2 | J36: =I36 -> 1.2
A38: Current Assets, Loans and Advances
