Workbook

Sheet XXXXXXXXXXXXXXXXXXXXXXXXX

Sheet Instruction
C4: Go Through The Entire Workbook, Sheet By Sheet and Enter Data Using The Following Rules:
E6: - You Must Enter Data In The Light Green Boxes
E8: - You Can Enter Data (or Replace Data) In The Light Yellow Boxes
E10: - The Fields With No Shading Are Automatically Calculated - DO NOT ENTER DATA!
C18: If You Don't Know An Exact Value For A Field Put In Your Best
C19: Estimate, Then Let The Customer Update It If Necessary

Sheet Financial Inputs
A1: ENTER DATA ONLY IN SHADED FIELDS
C4: Insert Customer Logo
C5: In This Area
C6: Financial Inputs
C8: Robotic System Investment | F8: 160000
D9: (Total system price including all robots, peripheral equipment, controls, engineering, build, set-up & run-off at FANUC Robotics, and installation supervision at end users)
C11: Plant Startup Expenses (if not included in Robotic System Investment)
D12: Installation | F12: 5000
D13: Robotic Systems Training | F13: 0
D14: Internal Labor for Startup and Debug | F14: 2500
D15: Production Support/Service Contracts | F15: 0
C17: Combined State and Federal Income Tax Rate | F17: 0.35
C19: Corporate Hurdle Rate for Investment Decisions | F19: 0.33
C21: Capital Evaluation Duration In Years (Enter "5" or "7") | F21: 5 | I21: =IF(Cap_Eval_Dur=5," ",IF(Cap_Eval_Dur=7," ",IF(Cap_Eval_Dur=0,"<== Enter Duration","<== Invalid Duration")))
C23: Corporate Discount Factor / Weighted Average Cost of Capital | F23: 0.06
C25: Corporate Payback Period (Months) for this Application | F25: 24

Sheet Labor Savings
A1: ENTER DATA ONLY IN SHADED FIELDS
C4: Insert Customer Logo
C5: In This Area
C6: Labor Savings
C8: Current Number of Laborers per Shift: | H8: =SUM(F9:F12) -> 2
E9: Operators | F9: 1
E10: Maintenance | F10: 0
E11: Technicians | F11: 0
E12: Material Handlers | F12: 1
C14: Robotic System Number of Laborers per Shift: | H14: =SUM(F15:F18) -> 1
E15: Operators | F15: 0
E16: Maintenance | F16: 0
E17: Technicians | F17: 0
E18: Material Handlers | F18: 1
C20: Number of Shifts: | H20: 2
C22: Annual Hours Per Laborer | H22: =F23*F24*F25 -> 2000
E23: Production Hours Per Day | F23: 8
E24: Production Days Per Week | F24: 5
E25: Production Weeks Per Year | F25: 50
C27: Current Annual Labor Hours: | H27: =Hrs_Laborer*H8*shifts -> 8000
C28: Robotic System Annual Labor Hours: | H28: =Hrs_Laborer*H14*shifts -> 4000
C29: Annual Labor Savings (Hours): | H29: =H27-H28 -> 4000
C31: Burdened Hourly Rate for Laborers:
E32: Operators | F32: 20
E33: Maintenance | F33: 0
E34: Technicians | F34: 0
E35: Material Handlers | F35: 20
C37: Current Annual Labor Cost: | H37: =(((Hrs_Laborer)*(($F$9*$F$32)+($F$10*$F$33)+($F$11*$F$34)+($F$12*$F$35)))*shifts) -> 160000
C38: Robotic System Annual Labor Cost: | H38: =((Hrs_Laborer)*(($F$15*$F$32)+($F$16*$F$33)+($F$17*$F$34)+($F$18*$F$35)))*shifts -> 80000
C39: Annual Labor Savings (Dollars): | H39: =H37-H38 -> 80000
C41: Annual Lost Time and Disability Savings: | H41: =H39*F42 -> 4000
E42: Annual Average Percentage Rate: | F42: 0.05
F49: 15

Sheet PM Labor Savings 
A1: ENTER DATA ONLY IN SHADED FIELDS
C4: Insert Customer Logo
C5: In This Area
C6: Preventive Maintenance (PM) Labor Cost
C8: Total Additional Number of PM Personnel Assigned: | H8: 0
C10: Burdened Hourly Rate for PM: | H10: 0
C12: Number of proposed FANUC Robots In System: | H12: 0
C14: Proposed PM Man-Hours per Year | H14: =F15+F16 -> 0
D15: Number of Robots * 4 Hrs. per Quarter * 4-Quarters | F15: =H12*4*4 -> 0
D16: Yearly Peripheral Equipment Estimate | F16: 0
C18: Annual PM Labor Savings: | H18: =-H10*H14 -> 0

Sheet Production Increase
A1: ENTER DATA ONLY IN SHADED FIELDS
C4: Insert Customer Logo
C5: In This Area
C6: Production Increase
C8: Current Systems Annual Production | I8: =Prod_Rate*Ann_Prod_Hrs -> 228000
E9: Production Rate Per Hour | G9: 60
E10: Total Available Production Hours Per Year | G10: ='Labor Savings'!F23*'Labor Savings'!F24*'Labor Savings'!F25*shifts -> 4000
E11: Less Daily Scheduled Downtime (lunches, breaks, etc. - hrs) | G11: =-F11*'Labor Savings'!$F$24*'Labor Savings'!$F$25*shifts -> 0
E12: Less Annual Unscheduled Downtime (avg. percentage) | F12: 0.05 | G12: =-F12*'Labor Savings'!$F$23*'Labor Savings'!$F$24*'Labor Savings'!$F$25*shifts -> -200
E13: Less Annual Change-Over (hours) | G13: 0
E14: Net Annual Production Hours | G14: =SUM(G10:G13) -> 3800
C16: FANUC Robotics Proposed Systems Annual Production | I16: =Robotic_Prod_Rate*Robotic_Ann_Prod_Hrs -> 280000
E17: Production Rate Per Hour | G17: 70
E18: Total Available Production Hours Per Year | G18: 4000
E19: Less Daily Scheduled Downtime (lunches, breaks, etc. - hrs) | F19: 0 | G19: =-F19*'Labor Savings'!$F$24*'Labor Savings'!$F$25*shifts -> 0
E20: Less Annual Unscheduled Downtime (avg. percentage) | F20: 0 | G20: =-F20*'Labor Savings'!$F$23*'Labor Savings'!$F$24*'Labor Savings'!$F$25*shifts -> 0
E21: Less Annual Change-Over (hours) | G21: 0
E22: Net Annual Production Hours | G22: =SUM(G18:G21) -> 4000
C24: Increased Annual Production | I24: =Robotic_Production-Current_Production -> 52000
E25: Price Per Unit | G25: 25
C27: Increased Annual Revenue | I27: =I24*G25 -> 1300000

Sheet Scrap Savings
A1: ENTER DATA ONLY IN SHADED FIELDS
C4: Insert Customer Logo
C5: In This Area
C6: Scrap Reduction Savings
C8: Current Systems Annual Scrap | I8: =ROUNDUP(G9*G10,0) -> 38
E9: Scrap Rate | G9: 0.01
E10: Net Annual Production Hours (Current System) | G10: =Ann_Prod_Hrs -> 3800
C12: FANUC Robotics Proposed Systems Annual Production | I12: =ROUNDUP(G13*G14,0) -> 20
E13: Scrap Rate | G13: 0.005
E14: Net Annual Production Hours (FANUC Robotics System) | G14: ='Production Increase'!G22 -> 4000
C16: Increased Annual Production | I16: =I8-I12 -> 18
E17: Price Per Unit | G17: =Unit_Price -> 25
C19: Scrap Reduction Savings | I19: =I16*G17 -> 450

Sheet Miscellaneous Savings
A1: ENTER DATA ONLY IN SHADED FIELDS
C4: Insert Customer Logo
C5: In This Area
C6: Miscellaneous Saving
C7: This Sheet To Be Used For Unique Savings Opportunities Specific To Your Application (Modify As Required)
C9: Miscellaneous Saving #1 | I9: 0
C11: Miscellaneous Saving #1 | I11: 0
C13: Miscellaneous Saving #1 | I13: 0
C15: Total Miscellaneous Savings | I15: =SUM(I9:I13) -> 0

Sheet Savings Summary
A1: DO NOT CHANGE ANY VALUES OR ENTER ANY DATA ON THIS SHEET!!!!!!!!!!!!!!!!!
D4: Insert Customer Logo
D5: In This Area
C6: Annual Savings Summary
C9: Operator Labor Savings : | G9: ='Labor Savings'!H39 -> 80000
C11: Lost Time and Disability Savings : | G11: =Disability_Savings -> 4000
C13: Workers Compensation Premiums ($1.3 per $100 of payroll) | G13: ='Financial Spreadsheet '!F17 -> 1040
C15: System Preventive Maintenance: | G15: ='PM Labor Savings '!H18 -> 0
C17: Production Increase Value: | G17: =Inc_Ann_Rev -> 1300000
C19: Scrap Reduction Savings: | G19: =Scrap_Savings -> 450
C21: Miscellaneous Savings: | G21: =Misc_Savings -> 0
C23: Total Annual Profit Increase: | G23: =SUM(G9:G22) -> 1385490

Sheet Investment Summary
A1: DO NOT CHANGE ANY VALUES OR ENTER ANY DATA ON THIS SHEET!!!!!!!!!!!!!!!!!!!!
C4: Insert Customer Logo
C5: In This Area
C6: Investment Summary
C8: Total Initial Investment: | G8: =SUM('Financial Inputs'!F8:F15) -> 167500
C10: Total Annual Profit Increase (Before Income Taxes): | G10: ='Savings Summary'!G23 -> 1385490
C12: Weighted Average Cost of Capital / Discount Factor: | G12: ='Financial Inputs'!F23 -> 0.06
C14: Corporate Hurdle Rate: | G14: =Hurdle_Rate -> 0.33
C16: =Cap_Eval_Dur -> 5 | D16: Year IRR Generated From Project: | G16: ='Financial Spreadsheet '!H38 -> 5.446039
D17: (True Interest Return Generated by the Project)
D18: (If IRR > Hurdle Rate, Accept the Project)
D19: (If IRR < Hurdle Rate, Reject the Project)
C21: =Cap_Eval_Dur -> 5 | D21: Year NPV: | G21: ='Financial Spreadsheet '!G38 -> 3675412.1
D22: (Present Value of Net Annual Cash Flows)
D23: (IF NPV > $0, Accept the Project)
D24: (IF NPV < $0, Reject the Project)
C26: Payback In Months (Before Income Taxes): | G26: =G8/G10*12 -> 1.4507503

Sheet Financial Spreadsheet 
A1: DO NOT CHANGE ANY VALUES OR ENTER ANY DATA ON THIS SHEET!!!!!!!!!!!!!!!!!!!!
C4: Insert Customer Logo
C5: In This Area
D8: Today (Year 0) | F8: Year 1 | G8: Year 2 | H8: Year 3 | I8: Year 4 | J8: Year 5 | K8: Year 6 | L8: Year 7
C10: 5 Year (-) | E10: =IF(Cap_Eval_Dur=5,-Total_Investment,IF(Cap_Eval_Dur<>7,"Invalid Value",0)) -> -167500 | F10: 0
C11: 7 Year (-) | E11: =IF(Cap_Eval_Dur=7,-Total_Investment,IF(Cap_Eval_Dur<>5,"Invalid Value",0)) -> 0 | F11: 0
C12: Total Equipment Investment | E12: =SUM(E10:E11) -> -167500 | F12: =SUM(F10:F11) -> 0 | G12: =SUM(G10:G11) -> 0 | H12: =SUM(H10:H11) -> 0 | I12: =SUM(I10:I11) -> 0 | J12: =SUM(J10:J11) -> 0 | K12: =SUM(K10:K11) -> 0 | L12: =SUM(L10:L11) -> 0
C14: Cash Flow Data:
C15: Operator Labor Savings | F15: =Ann_Lab_Sav -> 80000 | G15: =Ann_Lab_Sav -> 80000 | H15: =Ann_Lab_Sav -> 80000 | I15: =Ann_Lab_Sav -> 80000 | J15: =Ann_Lab_Sav -> 80000 | K15: =Ann_Lab_Sav -> 80000 | L15: =Ann_Lab_Sav -> 80000
C16: Annual lost time and disability savings | F16: =Disability_Savings -> 4000 | G16: =Disability_Savings -> 4000 | H16: =Disability_Savings -> 4000 | I16: =Disability_Savings -> 4000 | J16: =Disability_Savings -> 4000 | K16: =Disability_Savings -> 4000 | L16: =Disability_Savings -> 4000
C17: Workers Comp Premiums | F17: =1.3*Ann_Lab_Sav/100 -> 1040 | G17: =1.3*Ann_Lab_Sav/100 -> 1040 | H17: =1.3*Ann_Lab_Sav/100 -> 1040 | I17: =1.3*Ann_Lab_Sav/100 -> 1040 | J17: =1.3*Ann_Lab_Sav/100 -> 1040 | K17: =1.3*Ann_Lab_Sav/100 -> 1040 | L17: =1.3*Ann_Lab_Sav/100 -> 1040
C18: System Preventive Maintenance | F18: =PM_Lab_Savings -> 0 | G18: =PM_Lab_Savings -> 0 | H18: =PM_Lab_Savings -> 0 | I18: =PM_Lab_Savings -> 0 | J18: =PM_Lab_Savings -> 0 | K18: =PM_Lab_Savings -> 0 | L18: =PM_Lab_Savings -> 0
C19: Increased Annual Revenue (Production Increase) | F19: =Inc_Ann_Rev -> 1300000 | G19: =Inc_Ann_Rev -> 1300000 | H19: =Inc_Ann_Rev -> 1300000 | I19: =Inc_Ann_Rev -> 1300000 | J19: =Inc_Ann_Rev -> 1300000 | K19: =Inc_Ann_Rev -> 1300000 | L19: =Inc_Ann_Rev -> 1300000
C20: Scrap Savings | F20: =Scrap_Savings -> 450 | G20: =Scrap_Savings -> 450 | H20: =Scrap_Savings -> 450 | I20: =Scrap_Savings -> 450 | J20: =Scrap_Savings -> 450 | K20: =Scrap_Savings -> 450 | L20: =Scrap_Savings -> 450
C21: Miscellaneous Savings | F21: =Misc_Savings -> 0 | G21: =Misc_Savings -> 0 | H21: =Misc_Savings -> 0 | I21: =Misc_Savings -> 0 | J21: =Misc_Savings -> 0 | K21: =Misc_Savings -> 0 | L21: =Misc_Savings -> 0
C22: Equipment Depreciation (-) | F22: =E77 -> -33500 | G22: =F77 -> -33500 | H22: =G77 -> -33500 | I22: =H77 -> -33500 | J22: =I77 -> -33500 | K22: =J77 -> 0 | L22: =K77 -> 0
C23: Net Pre-Tax Profit: | F23: =SUM(F15:F22) -> 1351990 | G23: =SUM(G15:G22) -> 1351990 | H23: =SUM(H15:H22) -> 1351990 | I23: =SUM(I15:I22) -> 1351990 | J23: =SUM(J15:J22) -> 1351990 | K23: =SUM(K15:K22) -> 1385490 | L23: =SUM(L15:L22) -> 1385490
C26: Income Taxes @ | D26: =Tax_Rate -> 0.35 | F26: =-F23*Tax_Rate -> -473196.5 | G26: =-G23*Tax_Rate -> -473196.5 | H26: =-H23*Tax_Rate -> -473196.5 | I26: =-I23*Tax_Rate -> -473196.5 | J26: =-J23*Tax_Rate -> -473196.5 | K26: =-K23*Tax_Rate -> -484921.5 | L26: =-L23*Tax_Rate -> -484921.5
C27: Add Depreciation (+) | F27: =-F22 -> 33500 | G27: =-G22 -> 33500 | H27: =-H22 -> 33500 | I27: =-I22 -> 33500 | J27: =-J22 -> 33500 | K27: =-K22 -> 0 | L27: =-L22 -> 0
C28: Net Annual Cash Flow (after tax): | E28: =SUM(E23:E27)+E12 -> -167500 | F28: =SUM(F23:F27)+F12 -> 912293.5 | G28: =SUM(G23:G27)+G12 -> 912293.5 | H28: =SUM(H23:H27)+H12 -> 912293.5 | I28: =SUM(I23:I27)+I12 -> 912293.5 | J28: =SUM(J23:J27)+J12 -> 912293.5 | K28: =SUM(K23:K27)+K12 -> 900568.5 | L28: =SUM(L23:L27)+L12 -> 900568.5
C31: Cumulative Cash Flow: | E31: =E28 -> -167500 | F31: =SUM($E$28:F28) -> 744793.5 | G31: =SUM($E$28:G28) -> 1657087 | H31: =SUM($E$28:H28) -> 2569380.5 | I31: =SUM($E$28:I28) -> 3481674 | J31: =SUM($E$28:J28) -> 4393967.5 | K31: =SUM($E$28:K28) -> 5294536 | L31: =SUM($E$28:L28) -> 6195104.5
C32: Weighted Average Cost of Capital @ | D32: ='Financial Inputs'!F23 -> 0.06 | E32: 1 | F32: =E32/(1+disc_fact) -> 0.94339623 | G32: =F32/(1+disc_fact) -> 0.88999644 | H32: =G32/(1+disc_fact) -> 0.83961928 | I32: =H32/(1+disc_fact) -> 0.79209366 | J32: =I32/(1+disc_fact) -> 0.74725817 | K32: =J32/(1+disc_fact) -> 0.70496054 | L32: =K32/(1+disc_fact) -> 0.66505711
C33: Present Value of Annual Cash Flows | E33: =E28*E32 -> -167500 | F33: =F28*F32 -> 860654.25 | G33: =G28*G32 -> 811937.97 | H33: =H28*H32 -> 765979.21 | I33: =I28*I32 -> 722621.9 | J33: =J28*J32 -> 681718.77 | K33: =K28*K32 -> 634865.26 | L33: =L28*L32 -> 598929.49
C35: Cumulative Discount Cash Flow | E35: =E33 -> -167500 | F35: =SUM($E$33:F33) -> 693154.25 | G35: =SUM($E$33:G33) -> 1505092.2 | H35: =SUM($E$33:H33) -> 2271071.4 | I35: =SUM($E$33:I33) -> 2993693.3 | J35: =SUM($E$33:J33) -> 3675412.1 | K35: =SUM($E$33:K33) -> 4310277.4 | L35: =SUM($E$33:L33) -> 4909206.8
F37: Time Period | G37: NPV | H37: IRR
F38: 5 Years | G38: =SUM(E33:J33) -> 3675412.1 | H38: =IRR(E28:J28) -> 5.446039
F39: 7 Years | G39: =SUM(E33:L33) -> 4909206.8 | H39: =IRR(E28:L28) -> 5.4465105
F40: =SUM(E51:L52) -> 0.18360319 | G40: Years After Tax Payback
C46: Financial Analysis
C47: (continued)
C49: NOT FOR CUSTOMER PRESENTATION
C51: Payback | E51: =IF(F31<0,1,0) -> 0 | F51: =IF(G31<0,1,0) -> 0 | G51: =IF(H31<0,1,0) -> 0 | H51: =IF(I31<0,1,0) -> 0 | I51: =IF(J31<0,1,0) -> 0 | J51: =IF(K31<0,1,0) -> 0 | K51: =IF(L31<0,1,0) -> 0
C52: Calculation Detail: | E52: =IF(F31>0,(-E12/(F31-E12))) -> 0.18360319 | F52: =IF(G31>0,(IF(F31<0,(-F31/(-F31+G31)),0))) -> 0 | G52: =IF(H31>0,(IF(G31<0,(-G31/(-G31+H31)),0))) -> 0 | H52: =IF(I31>0,(IF(H31<0,(-H31/(-H31+I31)),0))) -> 0 | I52: =IF(J31>0,(IF(I31<0,(-I31/(-I31+J31)),0))) -> 0 | J52: =IF(K31>0,(IF(J31<0,(-J31/(-J31+K31)),0))) -> 0 | K52: =IF(L31>0,(IF(K31<0,(-K31/(-K31+L31)),0))) -> 0
C54: Formula Checks: | D54: =(NPV(disc_fact,$F$28:$J$28)+$E$28)-G38 -> 0
C55: (Should = 0 ) | D55: =(NPV(disc_fact,$F$28:$L$28)+$E$28)-G39 -> 0
D56: =NPV(H38,E28:J28) -> 4.0447645e-12
D57: =NPV(H39,E28:L28) -> -4.8673843e-12
C59: IRR 7YR | F59: =IRR(F54:L54,F60) -> #N/A | G59: =IRR(E33:L33,G60) -> 5.0816136
C60: GUESS | F60: 0.5 | G60: 0.5
C62: Depreciation Rates: | E62: =IF(Cap_Eval_Dur=5,0.2,IF(Cap_Eval_Dur=7,1/7,"Invalid Entry")) -> 0.2 | F62: =IF(Cap_Eval_Dur=5,0.2,IF(Cap_Eval_Dur=7,1/7,"Invalid Entry")) -> 0.2 | G62: =IF(Cap_Eval_Dur=5,0.2,IF(Cap_Eval_Dur=7,1/7,"Invalid Entry")) -> 0.2 | H62: =IF(Cap_Eval_Dur=5,0.2,IF(Cap_Eval_Dur=7,1/7,"Invalid Entry")) -> 0.2 | I62: =IF(Cap_Eval_Dur=5,0.2,IF(Cap_Eval_Dur=7,1/7,"Invalid Entry")) -> 0.2 | J62: =IF(Cap_Eval_Dur=5,0,IF(Cap_Eval_Dur=7,1/7,"Invalid Entry")) -> 0 | K62: =IF(Cap_Eval_Dur=5,0,IF(Cap_Eval_Dur=7,1/7,"Invalid Entry")) -> 0 | L62: =SUM(E62:K62)-1 -> 0
...

Sheet Module1

Sheet YyUb15rA40OfsReezZBJfoS3m
