Workbook

Sheet Intro
A1: Sheet | B1: Cell | C1: Row | D1: Column | E1: Type | F1: Formula | G1: Value | H1: ValueJSON | I1: NumberFormat | J1: FontBold | K1: FontItalic | L1: FontSize | M1: FontColor | N1: FillColor | O1: HorizontalAlignment | P1: VerticalAlignment | Q1: WrapText | R1: IncludeFlag | S1: GroupID | T1: GroupDirection | U1: GroupSize | V1: PatternFormula | W1: StyleJSON
A2: Intro | B2: A1 | C2: 1 | D2: 1 | E2: Input | H2: {"type": "null", "value": null} | I2: General | J2: FALSE | K2: FALSE | L2: 11 | M2: Values must be of type <class 'str'> | N2: 00000000 | R2: FALSE | W2: {"number_format": "General", "font": {"name": "Calibri", "size": 11.0, "bold": false, "italic": false, "underline": null, "strike": null, "color": {"type": "theme", "rgb": "Values must be of type <class 'str'>", "indexed": null, "theme": 1, "tint": 0.0, "auto": null}, "vert_align": null}, "fill": {"fill_type": null, "fg_color": {"type": "rgb", "rgb": "00000000", "indexed": null, "theme": null, "tint": 0.0, "auto": null}, "bg_color": {"type": "rgb", "rgb": "00000000", "indexed": null, "theme": null, "tint": 0.0, "auto": null}}, "alignment": {"horizontal": null, "vertical": null, "text_rotation": 0, "wrap_text": null, "shrink_to_fit": null, "indent": 0.0}, "border": {"left": {"style": null, "color": null}, "right": {"style": null, "color": null}, "top": {"style": null, "color": null}, "bottom": {"style": null, "color": null}, "diagonal": {"style": null, "color": null}, "diagonal_down": false, "diagonal_up": false, "outline": true, "vertical": null, "horizontal": null}, "protection": {"locked": true, "hidden": false}}
A3: Intro | B3: B1 | C3: 1 | D3: 2 | E3: Input | H3: {"type": "null", "value": null} | I3: General | J3: FALSE | K3: FALSE | L3: 11 | M3: Values must be of type <class 'str'> | N3: 00000000 | R3: FALSE | W3: {"number_format": "General", "font": {"name": "Calibri", "size": 11.0, "bold": false, "italic": false, "underline": null, "strike": null, "color": {"type": "theme", "rgb": "Values must be of type <class 'str'>", "indexed": null, "theme": 1, "tint": 0.0, "auto": null}, "vert_align": null}, "fill": {"fill_type": null, "fg_color": {"type": "rgb", "rgb": "00000000", "indexed": null, "theme": null, "tint": 0.0, "auto": null}, "bg_color": {"type": "rgb", "rgb": "00000000", "indexed": null, "theme": null, "tint": 0.0, "auto": null}}, "alignment": {"horizontal": null, "vertical": null, "text_rotation": 0, "wrap_text": null, "shrink_to_fit": null, "indent": 0.0}, "border": {"left": {"style": null, "color": null}, "right": {"style": null, "color": null}, "top": {"style": null, "color": null}, "bottom": {"style": null, "color": null}, "diagonal": {"style": null, "color": null}, "diagonal_down": false, "diagonal_up": false, "outline": true, "vertical": null, "horizontal": null}, "protection": {"locked": true, "hidden": false}}
A4: Intro | B4: C1 | C4: 1 | D4: 3 | E4: Input | H4: {"type": "null", "value": null} | I4: General | J4: FALSE | K4: FALSE | L4: 11 | M4: Values must be of type <class 'str'> | N4: 00000000 | R4: FALSE | W4: {"number_format": "General", "font": {"name": "Calibri", "size": 11.0, "bold": false, "italic": false, "underline": null, "strike": null, "color": {"type": "theme", "rgb": "Values must be of type <class 'str'>", "indexed": null, "theme": 1, "tint": 0.0, "auto": null}, "vert_align": null}, "fill": {"fill_type": null, "fg_color": {"type": "rgb", "rgb": "00000000", "indexed": null, "theme": null, "tint": 0.0, "auto": null}, "bg_color": {"type": "rgb", "rgb": "00000000", "indexed": null, "theme": null, "tint": 0.0, "auto": null}}, "alignment": {"horizontal": null, "vertical": null, "text_rotation": 0, "wrap_text": null, "shrink_to_fit": null, "indent": 0.0}, "border": {"left": {"style": null, "color": null}, "right": {"style": null, "color": null}, "top": {"style": null, "color": null}, "bottom": {"style": null, "color": null}, "diagonal": {"style": null, "color": null}, "diagonal_down": false, "diagonal_up": false, "outline": true, "vertical": null, "horizontal": null}, "protection": {"locked": true, "hidden": false}}
A5: Intro | B5: D1 | C5: 1 | D5: 4 | E5: Input | H5: {"type": "null", "value": null} | I5: General | J5: FALSE | K5: FALSE | L5: 11 | M5: Values must be of type <class 'str'> | N5: 00000000 | R5: FALSE | W5: {"number_format": "General", "font": {"name": "Calibri", "size": 11.0, "bold": false, "italic": false, "underline": null, "strike": null, "color": {"type": "theme", "rgb": "Values must be of type <class 'str'>", "indexed": null, "theme": 1, "tint": 0.0, "auto": null}, "vert_align": null}, "fill": {"fill_type": null, "fg_color": {"type": "rgb", "rgb": "00000000", "indexed": null, "theme": null, "tint": 0.0, "auto": null}, "bg_color": {"type": "rgb", "rgb": "00000000", "indexed": null, "theme": null, "tint": 0.0, "auto": null}}, "alignment": {"horizontal": null, "vertical": null, "text_rotation": 0, "wrap_text": null, "shrink_to_fit": null, "indent": 0.0}, "border": {"left": {"style": null, "color": null}, "right": {"style": null, "color": null}, "top": {"style": null, "color": null}, "bottom": {"style": null, "color": null}, "diagonal": {"style": null, "color": null}, "diagonal_down": false, "diagonal_up": false, "outline": true, "vertical": null, "horizontal": null}, "protection": {"locked": true, "hidden": false}}
A6: Intro | B6: E1 | C6: 1 | D6: 5 | E6: Input | H6: {"type": "null", "value": null} | I6: General | J6: FALSE | K6: FALSE | L6: 11 | M6: Values must be of type <class 'str'> | N6: 00000000 | R6: FALSE | W6: {"number_format": "General", "font": {"name": "Calibri", "size": 11.0, "bold": false, "italic": false, "underline": null, "strike": null, "color": {"type": "theme", "rgb": "Values must be of type <class 'str'>", "indexed": null, "theme": 1, "tint": 0.0, "auto": null}, "vert_align": null}, "fill": {"fill_type": null, "fg_color": {"type": "rgb", "rgb": "00000000", "indexed": null, "theme": null, "tint": 0.0, "auto": null}, "bg_color": {"type": "rgb", "rgb": "00000000", "indexed": null, "theme": null, "tint": 0.0, "auto": null}}, "alignment": {"horizontal": null, "vertical": null, "text_rotation": 0, "wrap_text": null, "shrink_to_fit": null, "indent": 0.0}, "border": {"left": {"style": null, "color": null}, "right": {"style": null, "color": null}, "top": {"style": null, "color": null}, "bottom": {"style": null, "color": null}, "diagonal": {"style": null, "color": null}, "diagonal_down": false, "diagonal_up": false, "outline": true, "vertical": null, "horizontal": null}, "protection": {"locked": true, "hidden": false}}
A7: Intro | B7: F1 | C7: 1 | D7: 6 | E7: Input | H7: {"type": "null", "value": null} | I7: General | J7: FALSE | K7: FALSE | L7: 11 | M7: Values must be of type <class 'str'> | N7: 00000000 | R7: FALSE | W7: {"number_format": "General", "font": {"name": "Calibri", "size": 11.0, "bold": false, "italic": false, "underline": null, "strike": null, "color": {"type": "theme", "rgb": "Values must be of type <class 'str'>", "indexed": null, "theme": 1, "tint": 0.0, "auto": null}, "vert_align": null}, "fill": {"fill_type": null, "fg_color": {"type": "rgb", "rgb": "00000000", "indexed": null, "theme": null, "tint": 0.0, "auto": null}, "bg_color": {"type": "rgb", "rgb": "00000000", "indexed": null, "theme": null, "tint": 0.0, "auto": null}}, "alignment": {"horizontal": null, "vertical": null, "text_rotation": 0, "wrap_text": null, "shrink_to_fit": null, "indent": 0.0}, "border": {"left": {"style": null, "color": null}, "right": {"style": null, "color": null}, "top": {"style": null, "color": null}, "bottom": {"style": null, "color": null}, "diagonal": {"style": null, "color": null}, "diagonal_down": false, "diagonal_up": false, "outline": true, "vertical": null, "horizontal": null}, "protection": {"locked": true, "hidden": false}}
A8: Intro | B8: G1 | C8: 1 | D8: 7 | E8: Input | H8: {"type": "null", "value": null} | I8: General | J8: FALSE | K8: FALSE | L8: 11 | M8: Values must be of type <class 'str'> | N8: 00000000 | R8: FALSE | W8: {"number_format": "General", "font": {"name": "Calibri", "size": 11.0, "bold": false, "italic": false, "underline": null, "strike": null, "color": {"type": "theme", "rgb": "Values must be of type <class 'str'>", "indexed": null, "theme": 1, "tint": 0.0, "auto": null}, "vert_align": null}, "fill": {"fill_type": null, "fg_color": {"type": "rgb", "rgb": "00000000", "indexed": null, "theme": null, "tint": 0.0, "auto": null}, "bg_color": {"type": "rgb", "rgb": "00000000", "indexed": null, "theme": null, "tint": 0.0, "auto": null}}, "alignment": {"horizontal": null, "vertical": null, "text_rotation": 0, "wrap_text": null, "shrink_to_fit": null, "indent": 0.0}, "border": {"left": {"style": null, "color": null}, "right": {"style": null, "color": null}, "top": {"style": null, "color": null}, "bottom": {"style": null, "color": null}, "diagonal": {"style": null, "color": null}, "diagonal_down": false, "diagonal_up": false, "outline": true, "vertical": null, "horizontal": null}, "protection": {"locked": true, "hidden": false}}
A9: Intro | B9: A2 | C9: 2 | D9: 1 | E9: Input | H9: {"type": "null", "value": null} | I9: General | J9: FALSE | K9: FALSE | L9: 11 | M9: Values must be of type <class 'str'> | N9: 00000000 | R9: FALSE | W9: {"number_format": "General", "font": {"name": "Calibri", "size": 11.0, "bold": false, "italic": false, "underline": null, "strike": null, "color": {"type": "theme", "rgb": "Values must be of type <class 'str'>", "indexed": null, "theme": 1, "tint": 0.0, "auto": null}, "vert_align": null}, "fill": {"fill_type": null, "fg_color": {"type": "rgb", "rgb": "00000000", "indexed": null, "theme": null, "tint": 0.0, "auto": null}, "bg_color": {"type": "rgb", "rgb": "00000000", "indexed": null, "theme": null, "tint": 0.0, "auto": null}}, "alignment": {"horizontal": null, "vertical": null, "text_rotation": 0, "wrap_text": null, "shrink_to_fit": null, "indent": 0.0}, "border": {"left": {"style": null, "color": null}, "right": {"style": null, "color": null}, "top": {"style": null, "color": null}, "bottom": {"style": null, "color": null}, "diagonal": {"style": null, "color": null}, "diagonal_down": false, "diagonal_up": false, "outline": true, "vertical": null, "horizontal": null}, "protection": {"locked": true, "hidden": false}}
A10: Intro | B10: B2 | C10: 2 | D10: 2 | E10: Input | H10: {"type": "null", "value": null} | I10: General | J10: FALSE | K10: FALSE | L10: 11 | M10: Values must be of type <class 'str'> | N10: 00000000 | R10: FALSE | W10: {"number_format": "General", "font": {"name": "Calibri", "size": 11.0, "bold": false, "italic": false, "underline": null, "strike": null, "color": {"type": "theme", "rgb": "Values must be of type <class 'str'>", "indexed": null, "theme": 1, "tint": 0.0, "auto": null}, "vert_align": null}, "fill": {"fill_type": null, "fg_color": {"type": "rgb", "rgb": "00000000", "indexed": null, "theme": null, "tint": 0.0, "auto": null}, "bg_color": {"type": "rgb", "rgb": "00000000", "indexed": null, "theme": null, "tint": 0.0, "auto": null}}, "alignment": {"horizontal": null, "vertical": null, "text_rotation": 0, "wrap_text": null, "shrink_to_fit": null, "indent": 0.0}, "border": {"left": {"style": null, "color": null}, "right": {"style": null, "color": null}, "top": {"style": null, "color": null}, "bottom": {"style": null, "color": null}, "diagonal": {"style": null, "color": null}, "diagonal_down": false, "diagonal_up": false, "outline": true, "vertical": null, "horizontal": null}, "protection": {"locked": true, "hidden": false}}
A11: Intro | B11: C2 | C11: 2 | D11: 3 | E11: Input | H11: {"type": "null", "value": null} | I11: General | J11: FALSE | K11: FALSE | L11: 11 | M11: Values must be of type <class 'str'> | N11: 00000000 | R11: FALSE | W11: {"number_format": "General", "font": {"name": "Calibri", "size": 11.0, "bold": false, "italic": false, "underline": null, "strike": null, "color": {"type": "theme", "rgb": "Values must be of type <class 'str'>", "indexed": null, "theme": 1, "tint": 0.0, "auto": null}, "vert_align": null}, "fill": {"fill_type": null, "fg_color": {"type": "rgb", "rgb": "00000000", "indexed": null, "theme": null, "tint": 0.0, "auto": null}, "bg_color": {"type": "rgb", "rgb": "00000000", "indexed": null, "theme": null, "tint": 0.0, "auto": null}}, "alignment": {"horizontal": null, "vertical": null, "text_rotation": 0, "wrap_text": null, "shrink_to_fit": null, "indent": 0.0}, "border": {"left": {"style": null, "color": null}, "right": {"style": null, "color": null}, "top": {"style": null, "color": null}, "bottom": {"style": null, "color": null}, "diagonal": {"style": null, "color": null}, "diagonal_down": false, "diagonal_up": false, "outline": true, "vertical": null, "horizontal": null}, "protection": {"locked": true, "hidden": false}}
A12: Intro | B12: D2 | C12: 2 | D12: 4 | E12: Input | H12: {"type": "null", "value": null} | I12: General | J12: FALSE | K12: FALSE | L12: 11 | M12: Values must be of type <class 'str'> | N12: 00000000 | R12: FALSE | W12: {"number_format": "General", "font": {"name": "Calibri", "size": 11.0, "bold": false, "italic": false, "underline": null, "strike": null, "color": {"type": "theme", "rgb": "Values must be of type <class 'str'>", "indexed": null, "theme": 1, "tint": 0.0, "auto": null}, "vert_align": null}, "fill": {"fill_type": null, "fg_color": {"type": "rgb", "rgb": "00000000", "indexed": null, "theme": null, "tint": 0.0, "auto": null}, "bg_color": {"type": "rgb", "rgb": "00000000", "indexed": null, "theme": null, "tint": 0.0, "auto": null}}, "alignment": {"horizontal": null, "vertical": null, "text_rotation": 0, "wrap_text": null, "shrink_to_fit": null, "indent": 0.0}, "border": {"left": {"style": null, "color": null}, "right": {"style": null, "color": null}, "top": {"style": null, "color": null}, "bottom": {"style": null, "color": null}, "diagonal": {"style": null, "color": null}, "diagonal_down": false, "diagonal_up": false, "outline": true, "vertical": null, "horizontal": null}, "protection": {"locked": true, "hidden": false}}
A13: Intro | B13: E2 | C13: 2 | D13: 5 | E13: Input | G13: Reference Model | H13: {"type": "str", "value": "Reference Model"} | I13: General | J13: TRUE | K13: FALSE | L13: 22 | M13: FF404040 | N13: 00000000 | O13: center | R13: TRUE | W13: {"number_format": "General", "font": {"name": "Calibri", "size": 22.0, "bold": true, "italic": false, "underline": "single", "strike": null, "color": {"type": "rgb", "rgb": "FF404040", "indexed": null, "theme": null, "tint": 0.0, "auto": null}, "vert_align": null}, "fill": {"fill_type": null, "fg_color": {"type": "rgb", "rgb": "00000000", "indexed": null, "theme": null, "tint": 0.0, "auto": null}, "bg_color": {"type": "rgb", "rgb": "00000000", "indexed": null, "theme": null, "tint": 0.0, "auto": null}}, "alignment": {"horizontal": "center", "vertical": null, "text_rotation": 0, "wrap_text": null, "shrink_to_fit": null, "indent": 0.0}, "border": {"left": {"style": null, "color": null}, "right": {"style": null, "color": null}, "top": {"style": null, "color": null}, "bottom": {"style": null, "color": null}, "diagonal": {"style": null, "color": null}, "diagonal_down": false, "diagonal_up": false, "outline": true, "vertical": null, "horizontal": null}, "protection": {"locked": true, "hidden": false}}
A14: Intro | B14: F2 | C14: 2 | D14: 6 | E14: Input | H14: {"type": "null", "value": null} | I14: General | J14: FALSE | K14: FALSE | L14: 11 | M14: Values must be of type <class 'str'> | N14: 00000000 | R14: FALSE | W14: {"number_format": "General", "font": {"name": "Calibri", "size": 11.0, "bold": false, "italic": false, "underline": null, "strike": null, "color": {"type": "theme", "rgb": "Values must be of type <class 'str'>", "indexed": null, "theme": 1, "tint": 0.0, "auto": null}, "vert_align": null}, "fill": {"fill_type": null, "fg_color": {"type": "rgb", "rgb": "00000000", "indexed": null, "theme": null, "tint": 0.0, "auto": null}, "bg_color": {"type": "rgb", "rgb": "00000000", "indexed": null, "theme": null, "tint": 0.0, "auto": null}}, "alignment": {"horizontal": null, "vertical": null, "text_rotation": 0, "wrap_text": null, "shrink_to_fit": null, "indent": 0.0}, "border": {"left": {"style": null, "color": null}, "right": {"style": null, "color": null}, "top": {"style": null, "color": null}, "bottom": {"style": null, "color": null}, "diagonal": {"style": null, "color": null}, "diagonal_down": false, "diagonal_up": false, "outline": true, "vertical": null, "horizontal": null}, "protection": {"locked": true, "hidden": false}}
A15: Intro | B15: G2 | C15: 2 | D15: 7 | E15: Input | H15: {"type": "null", "value": null} | I15: General | J15: FALSE | K15: FALSE | L15: 11 | M15: Values must be of type <class 'str'> | N15: 00000000 | R15: FALSE | W15: {"number_format": "General", "font": {"name": "Calibri", "size": 11.0, "bold": false, "italic": false, "underline": null, "strike": null, "color": {"type": "theme", "rgb": "Values must be of type <class 'str'>", "indexed": null, "theme": 1, "tint": 0.0, "auto": null}, "vert_align": null}, "fill": {"fill_type": null, "fg_color": {"type": "rgb", "rgb": "00000000", "indexed": null, "theme": null, "tint": 0.0, "auto": null}, "bg_color": {"type": "rgb", "rgb": "00000000", "indexed": null, "theme": null, "tint": 0.0, "auto": null}}, "alignment": {"horizontal": null, "vertical": null, "text_rotation": 0, "wrap_text": null, "shrink_to_fit": null, "indent": 0.0}, "border": {"left": {"style": null, "color": null}, "right": {"style": null, "color": null}, "top": {"style": null, "color": null}, "bottom": {"style": null, "color": null}, "diagonal": {"style": null, "color": null}, "diagonal_down": false, "diagonal_up": false, "outline": true, "vertical": null, "horizontal": null}, "protection": {"locked": true, "hidden": false}}
A16: Intro | B16: A3 | C16: 3 | D16: 1 | E16: Input | H16: {"type": "null", "value": null} | I16: General | J16: FALSE | K16: FALSE | L16: 11 | M16: Values must be of type <class 'str'> | N16: 00000000 | R16: FALSE | W16: {"number_format": "General", "font": {"name": "Calibri", "size": 11.0, "bold": false, "italic": false, "underline": null, "strike": null, "color": {"type": "theme", "rgb": "Values must be of type <class 'str'>", "indexed": null, "theme": 1, "tint": 0.0, "auto": null}, "vert_align": null}, "fill": {"fill_type": null, "fg_color": {"type": "rgb", "rgb": "00000000", "indexed": null, "theme": null, "tint": 0.0, "auto": null}, "bg_color": {"type": "rgb", "rgb": "00000000", "indexed": null, "theme": null, "tint": 0.0, "auto": null}}, "alignment": {"horizontal": null, "vertical": null, "text_rotation": 0, "wrap_text": null, "shrink_to_fit": null, "indent": 0.0}, "border": {"left": {"style": null, "color": null}, "right": {"style": null, "color": null}, "top": {"style": null, "color": null}, "bottom": {"style": null, "color": null}, "diagonal": {"style": null, "color": null}, "diagonal_down": false, "diagonal_up": false, "outline": true, "vertical": null, "horizontal": null}, "protection": {"locked": true, "hidden": false}}
A17: Intro | B17: B3 | C17: 3 | D17: 2 | E17: Input | H17: {"type": "null", "value": null} | I17: General | J17: FALSE | K17: FALSE | L17: 11 | M17: Values must be of type <class 'str'> | N17: 00000000 | R17: FALSE | W17: {"number_format": "General", "font": {"name": "Calibri", "size": 11.0, "bold": false, "italic": false, "underline": null, "strike": null, "color": {"type": "theme", "rgb": "Values must be of type <class 'str'>", "indexed": null, "theme": 1, "tint": 0.0, "auto": null}, "vert_align": null}, "fill": {"fill_type": null, "fg_color": {"type": "rgb", "rgb": "00000000", "indexed": null, "theme": null, "tint": 0.0, "auto": null}, "bg_color": {"type": "rgb", "rgb": "00000000", "indexed": null, "theme": null, "tint": 0.0, "auto": null}}, "alignment": {"horizontal": null, "vertical": null, "text_rotation": 0, "wrap_text": null, "shrink_to_fit": null, "indent": 0.0}, "border": {"left": {"style": null, "color": null}, "right": {"style": null, "color": null}, "top": {"style": null, "color": null}, "bottom": {"style": null, "color": null}, "diagonal": {"style": null, "color": null}, "diagonal_down": false, "diagonal_up": false, "outline": true, "vertical": null, "horizontal": null}, "protection": {"locked": true, "hidden": false}}
A18: Intro | B18: C3 | C18: 3 | D18: 3 | E18: Input | H18: {"type": "null", "value": null} | I18: General | J18: FALSE | K18: FALSE | L18: 11 | M18: Values must be of type <class 'str'> | N18: 00000000 | R18: FALSE | W18: {"number_format": "General", "font": {"name": "Calibri", "size": 11.0, "bold": false, "italic": false, "underline": null, "strike": null, "color": {"type": "theme", "rgb": "Values must be of type <class 'str'>", "indexed": null, "theme": 1, "tint": 0.0, "auto": null}, "vert_align": null}, "fill": {"fill_type": null, "fg_color": {"type": "rgb", "rgb": "00000000", "indexed": null, "theme": null, "tint": 0.0, "auto": null}, "bg_color": {"type": "rgb", "rgb": "00000000", "indexed": null, "theme": null, "tint": 0.0, "auto": null}}, "alignment": {"horizontal": null, "vertical": null, "text_rotation": 0, "wrap_text": null, "shrink_to_fit": null, "indent": 0.0}, "border": {"left": {"style": null, "color": null}, "right": {"style": null, "color": null}, "top": {"style": null, "color": null}, "bottom": {"style": null, "color": null}, "diagonal": {"style": null, "color": null}, "diagonal_down": false, "diagonal_up": false, "outline": true, "vertical": null, "horizontal": null}, "protection": {"locked": true, "hidden": false}}
A19: Intro | B19: D3 | C19: 3 | D19: 4 | E19: Input | H19: {"type": "null", "value": null} | I19: General | J19: FALSE | K19: FALSE | L19: 11 | M19: Values must be of type <class 'str'> | N19: 00000000 | R19: FALSE | W19: {"number_format": "General", "font": {"name": "Calibri", "size": 11.0, "bold": false, "italic": false, "underline": null, "strike": null, "color": {"type": "theme", "rgb": "Values must be of type <class 'str'>", "indexed": null, "theme": 1, "tint": 0.0, "auto": null}, "vert_align": null}, "fill": {"fill_type": null, "fg_color": {"type": "rgb", "rgb": "00000000", "indexed": null, "theme": null, "tint": 0.0, "auto": null}, "bg_color": {"type": "rgb", "rgb": "00000000", "indexed": null, "theme": null, "tint": 0.0, "auto": null}}, "alignment": {"horizontal": null, "vertical": null, "text_rotation": 0, "wrap_text": null, "shrink_to_fit": null, "indent": 0.0}, "border": {"left": {"style": null, "color": null}, "right": {"style": null, "color": null}, "top": {"style": null, "color": null}, "bottom": {"style": null, "color": null}, "diagonal": {"style": null, "color": null}, "diagonal_down": false, "diagonal_up": false, "outline": true, "vertical": null, "horizontal": null}, "protection": {"locked": true, "hidden": false}}
A20: Intro | B20: E3 | C20: 3 | D20: 5 | E20: Input | H20: {"type": "null", "value": null} | I20: General | J20: FALSE | K20: FALSE | L20: 11 | M20: Values must be of type <class 'str'> | N20: 00000000 | R20: FALSE | W20: {"number_format": "General", "font": {"name": "Calibri", "size": 11.0, "bold": false, "italic": false, "underline": null, "strike": null, "color": {"type": "theme", "rgb": "Values must be of type <class 'str'>", "indexed": null, "theme": 1, "tint": 0.0, "auto": null}, "vert_align": null}, "fill": {"fill_type": null, "fg_color": {"type": "rgb", "rgb": "00000000", "indexed": null, "theme": null, "tint": 0.0, "auto": null}, "bg_color": {"type": "rgb", "rgb": "00000000", "indexed": null, "theme": null, "tint": 0.0, "auto": null}}, "alignment": {"horizontal": null, "vertical": null, "text_rotation": 0, "wrap_text": null, "shrink_to_fit": null, "indent": 0.0}, "border": {"left": {"style": null, "color": null}, "right": {"style": null, "color": null}, "top": {"style": null, "color": null}, "bottom": {"style": null, "color": null}, "diagonal": {"style": null, "color": null}, "diagonal_down": false, "diagonal_up": false, "outline": true, "vertical": null, "horizontal": null}, "protection": {"locked": true, "hidden": false}}
A21: Intro | B21: F3 | C21: 3 | D21: 6 | E21: Input | H21: {"type": "null", "value": null} | I21: General | J21: FALSE | K21: FALSE | L21: 11 | M21: Values must be of type <class 'str'> | N21: 00000000 | R21: FALSE | W21: {"number_format": "General", "font": {"name": "Calibri", "size": 11.0, "bold": false, "italic": false, "underline": null, "strike": null, "color": {"type": "theme", "rgb": "Values must be of type <class 'str'>", "indexed": null, "theme": 1, "tint": 0.0, "auto": null}, "vert_align": null}, "fill": {"fill_type": null, "fg_color": {"type": "rgb", "rgb": "00000000", "indexed": null, "theme": null, "tint": 0.0, "auto": null}, "bg_color": {"type": "rgb", "rgb": "00000000", "indexed": null, "theme": null, "tint": 0.0, "auto": null}}, "alignment": {"horizontal": null, "vertical": null, "text_rotation": 0, "wrap_text": null, "shrink_to_fit": null, "indent": 0.0}, "border": {"left": {"style": null, "color": null}, "right": {"style": null, "color": null}, "top": {"style": null, "color": null}, "bottom": {"style": null, "color": null}, "diagonal": {"style": null, "color": null}, "diagonal_down": false, "diagonal_up": false, "outline": true, "vertical": null, "horizontal": null}, "protection": {"locked": true, "hidden": false}}
A22: Intro | B22: G3 | C22: 3 | D22: 7 | E22: Input | H22: {"type": "null", "value": null} | I22: General | J22: FALSE | K22: FALSE | L22: 11 | M22: Values must be of type <class 'str'> | N22: 00000000 | R22: FALSE | W22: {"number_format": "General", "font": {"name": "Calibri", "size": 11.0, "bold": false, "italic": false, "underline": null, "strike": null, "color": {"type": "theme", "rgb": "Values must be of type <class 'str'>", "indexed": null, "theme": 1, "tint": 0.0, "auto": null}, "vert_align": null}, "fill": {"fill_type": null, "fg_color": {"type": "rgb", "rgb": "00000000", "indexed": null, "theme": null, "tint": 0.0, "auto": null}, "bg_color": {"type": "rgb", "rgb": "00000000", "indexed": null, "theme": null, "tint": 0.0, "auto": null}}, "alignment": {"horizontal": null, "vertical": null, "text_rotation": 0, "wrap_text": null, "shrink_to_fit": null, "indent": 0.0}, "border": {"left": {"style": null, "color": null}, "right": {"style": null, "color": null}, "top": {"style": null, "color": null}, "bottom": {"style": null, "color": null}, "diagonal": {"style": null, "color": null}, "diagonal_down": false, "diagonal_up": false, "outline": true, "vertical": null, "horizontal": null}, "protection": {"locked": true, "hidden": false}}
A23: Intro | B23: A4 | C23: 4 | D23: 1 | E23: Input | H23: {"type": "null", "value": null} | I23: General | J23: FALSE | K23: FALSE | L23: 11 | M23: Values must be of type <class 'str'> | N23: 00000000 | R23: FALSE | W23: {"number_format": "General", "font": {"name": "Calibri", "size": 11.0, "bold": false, "italic": false, "underline": null, "strike": null, "color": {"type": "theme", "rgb": "Values must be of type <class 'str'>", "indexed": null, "theme": 1, "tint": 0.0, "auto": null}, "vert_align": null}, "fill": {"fill_type": null, "fg_color": {"type": "rgb", "rgb": "00000000", "indexed": null, "theme": null, "tint": 0.0, "auto": null}, "bg_color": {"type": "rgb", "rgb": "00000000", "indexed": null, "theme": null, "tint": 0.0, "auto": null}}, "alignment": {"horizontal": null, "vertical": null, "text_rotation": 0, "wrap_text": null, "shrink_to_fit": null, "indent": 0.0}, "border": {"left": {"style": null, "color": null}, "right": {"style": null, "color": null}, "top": {"style": null, "color": null}, "bottom": {"style": null, "color": null}, "diagonal": {"style": null, "color": null}, "diagonal_down": false, "diagonal_up": false, "outline": true, "vertical": null, "horizontal": null}, "protection": {"locked": true, "hidden": false}}
A24: Intro | B24: B4 | C24: 4 | D24: 2 | E24: Input | H24: {"type": "null", "value": null} | I24: General | J24: FALSE | K24: FALSE | L24: 11 | M24: Values must be of type <class 'str'> | N24: 00000000 | R24: FALSE | W24: {"number_format": "General", "font": {"name": "Calibri", "size": 11.0, "bold": false, "italic": false, "underline": null, "strike": null, "color": {"type": "theme", "rgb": "Values must be of type <class 'str'>", "indexed": null, "theme": 1, "tint": 0.0, "auto": null}, "vert_align": null}, "fill": {"fill_type": null, "fg_color": {"type": "rgb", "rgb": "00000000", "indexed": null, "theme": null, "tint": 0.0, "auto": null}, "bg_color": {"type": "rgb", "rgb": "00000000", "indexed": null, "theme": null, "tint": 0.0, "auto": null}}, "alignment": {"horizontal": null, "vertical": null, "text_rotation": 0, "wrap_text": null, "shrink_to_fit": null, "indent": 0.0}, "border": {"left": {"style": null, "color": null}, "right": {"style": null, "color": null}, "top": {"style": null, "color": null}, "bottom": {"style": null, "color": null}, "diagonal": {"style": null, "color": null}, "diagonal_down": false, "diagonal_up": false, "outline": true, "vertical": null, "horizontal": null}, "protection": {"locked": true, "hidden": false}}
A25: Intro | B25: C4 | C25: 4 | D25: 3 | E25: Input | H25: {"type": "null", "value": null} | I25: General | J25: FALSE | K25: FALSE | L25: 11 | M25: Values must be of type <class 'str'> | N25: 00000000 | R25: FALSE | W25: {"number_format": "General", "font": {"name": "Calibri", "size": 11.0, "bold": false, "italic": false, "underline": null, "strike": null, "color": {"type": "theme", "rgb": "Values must be of type <class 'str'>", "indexed": null, "theme": 1, "tint": 0.0, "auto": null}, "vert_align": null}, "fill": {"fill_type": null, "fg_color": {"type": "rgb", "rgb": "00000000", "indexed": null, "theme": null, "tint": 0.0, "auto": null}, "bg_color": {"type": "rgb", "rgb": "00000000", "indexed": null, "theme": null, "tint": 0.0, "auto": null}}, "alignment": {"horizontal": null, "vertical": null, "text_rotation": 0, "wrap_text": null, "shrink_to_fit": null, "indent": 0.0}, "border": {"left": {"style": null, "color": null}, "right": {"style": null, "color": null}, "top": {"style": null, "color": null}, "bottom": {"style": null, "color": null}, "diagonal": {"style": null, "color": null}, "diagonal_down": false, "diagonal_up": false, "outline": true, "vertical": null, "horizontal": null}, "protection": {"locked": true, "hidden": false}}
A26: Intro | B26: D4 | C26: 4 | D26: 4 | E26: Input | H26: {"type": "null", "value": null} | I26: General | J26: FALSE | K26: FALSE | L26: 11 | M26: Values must be of type <class 'str'> | N26: 00000000 | R26: FALSE | W26: {"number_format": "General", "font": {"name": "Calibri", "size": 11.0, "bold": false, "italic": false, "underline": null, "strike": null, "color": {"type": "theme", "rgb": "Values must be of type <class 'str'>", "indexed": null, "theme": 1, "tint": 0.0, "auto": null}, "vert_align": null}, "fill": {"fill_type": null, "fg_color": {"type": "rgb", "rgb": "00000000", "indexed": null, "theme": null, "tint": 0.0, "auto": null}, "bg_color": {"type": "rgb", "rgb": "00000000", "indexed": null, "theme": null, "tint": 0.0, "auto": null}}, "alignment": {"horizontal": null, "vertical": null, "text_rotation": 0, "wrap_text": null, "shrink_to_fit": null, "indent": 0.0}, "border": {"left": {"style": null, "color": null}, "right": {"style": null, "color": null}, "top": {"style": null, "color": null}, "bottom": {"style": null, "color": null}, "diagonal": {"style": null, "color": null}, "diagonal_down": false, "diagonal_up": false, "outline": true, "vertical": null, "horizontal": null}, "protection": {"locked": true, "hidden": false}}
A27: Intro | B27: E4 | C27: 4 | D27: 5 | E27: Input | G27: ACC Cement | H27: {"type": "str", "value": "ACC Cement"} | I27: General | J27: TRUE | K27: FALSE | L27: 32 | M27: Values must be of type <class 'str'> | N27: 00000000 | O27: center | R27: TRUE | W27: {"number_format": "General", "font": {"name": "Calibri", "size": 32.0, "bold": true, "italic": false, "underline": null, "strike": null, "color": {"type": "theme", "rgb": "Values must be of type <class 'str'>", "indexed": null, "theme": 1, "tint": 0.0, "auto": null}, "vert_align": null}, "fill": {"fill_type": null, "fg_color": {"type": "rgb", "rgb": "00000000", "indexed": null, "theme": null, "tint": 0.0, "auto": null}, "bg_color": {"type": "rgb", "rgb": "00000000", "indexed": null, "theme": null, "tint": 0.0, "auto": null}}, "alignment": {"horizontal": "center", "vertical": null, "text_rotation": 0, "wrap_text": null, "shrink_to_fit": null, "indent": 0.0}, "border": {"left": {"style": null, "color": null}, "right": {"style": null, "color": null}, "top": {"style": null, "color": null}, "bottom": {"style": null, "color": null}, "diagonal": {"style": null, "color": null}, "diagonal_down": false, "diagonal_up": false, "outline": true, "vertical": null, "horizontal": null}, "protection": {"locked": true, "hidden": false}}
A28: Intro | B28: F4 | C28: 4 | D28: 6 | E28: Input | H28: {"type": "null", "value": null} | I28: General | J28: FALSE | K28: FALSE | L28: 11 | M28: Values must be of type <class 'str'> | N28: 00000000 | R28: FALSE | W28: {"number_format": "General", "font": {"name": "Calibri", "size": 11.0, "bold": false, "italic": false, "underline": null, "strike": null, "color": {"type": "theme", "rgb": "Values must be of type <class 'str'>", "indexed": null, "theme": 1, "tint": 0.0, "auto": null}, "vert_align": null}, "fill": {"fill_type": null, "fg_color": {"type": "rgb", "rgb": "00000000", "indexed": null, "theme": null, "tint": 0.0, "auto": null}, "bg_color": {"type": "rgb", "rgb": "00000000", "indexed": null, "theme": null, "tint": 0.0, "auto": null}}, "alignment": {"horizontal": null, "vertical": null, "text_rotation": 0, "wrap_text": null, "shrink_to_fit": null, "indent": 0.0}, "border": {"left": {"style": null, "color": null}, "right": {"style": null, "color": null}, "top": {"style": null, "color": null}, "bottom": {"style": null, "color": null}, "diagonal": {"style": null, "color": null}, "diagonal_down": false, "diagonal_up": false, "outline": true, "vertical": null, "horizontal": null}, "protection": {"locked": true, "hidden": false}}
A29: Intro | B29: G4 | C29: 4 | D29: 7 | E29: Input | H29: {"type": "null", "value": null} | I29: General | J29: FALSE | K29: FALSE | L29: 11 | M29: Values must be of type <class 'str'> | N29: 00000000 | R29: FALSE | W29: {"number_format": "General", "font": {"name": "Calibri", "size": 11.0, "bold": false, "italic": false, "underline": null, "strike": null, "color": {"type": "theme", "rgb": "Values must be of type <class 'str'>", "indexed": null, "theme": 1, "tint": 0.0, "auto": null}, "vert_align": null}, "fill": {"fill_type": null, "fg_color": {"type": "rgb", "rgb": "00000000", "indexed": null, "theme": null, "tint": 0.0, "auto": null}, "bg_color": {"type": "rgb", "rgb": "00000000", "indexed": null, "theme": null, "tint": 0.0, "auto": null}}, "alignment": {"horizontal": null, "vertical": null, "text_rotation": 0, "wrap_text": null, "shrink_to_fit": null, "indent": 0.0}, "border": {"left": {"style": null, "color": null}, "right": {"style": null, "color": null}, "top": {"style": null, "color": null}, "bottom": {"style": null, "color": null}, "diagonal": {"style": null, "color": null}, "diagonal_down": false, "diagonal_up": false, "outline": true, "vertical": null, "horizontal": null}, "protection": {"locked": true, "hidden": false}}
A30: Intro | B30: A5 | C30: 5 | D30: 1 | E30: Input | H30: {"type": "null", "value": null} | I30: General | J30: FALSE | K30: FALSE | L30: 11 | M30: Values must be of type <class 'str'> | N30: 00000000 | R30: FALSE | W30: {"number_format": "General", "font": {"name": "Calibri", "size": 11.0, "bold": false, "italic": false, "underline": null, "strike": null, "color": {"type": "theme", "rgb": "Values must be of type <class 'str'>", "indexed": null, "theme": 1, "tint": 0.0, "auto": null}, "vert_align": null}, "fill": {"fill_type": null, "fg_color": {"type": "rgb", "rgb": "00000000", "indexed": null, "theme": null, "tint": 0.0, "auto": null}, "bg_color": {"type": "rgb", "rgb": "00000000", "indexed": null, "theme": null, "tint": 0.0, "auto": null}}, "alignment": {"horizontal": null, "vertical": null, "text_rotation": 0, "wrap_text": null, "shrink_to_fit": null, "indent": 0.0}, "border": {"left": {"style": null, "color": null}, "right": {"style": null, "color": null}, "top": {"style": null, "color": null}, "bottom": {"style": null, "color": null}, "diagonal": {"style": null, "color": null}, "diagonal_down": false, "diagonal_up": false, "outline": true, "vertical": null, "horizontal": null}, "protection": {"locked": true, "hidden": false}}
A31: Intro | B31: B5 | C31: 5 | D31: 2 | E31: Input | H31: {"type": "null", "value": null} | I31: General | J31: FALSE | K31: FALSE | L31: 11 | M31: Values must be of type <class 'str'> | N31: 00000000 | R31: FALSE | W31: {"number_format": "General", "font": {"name": "Calibri", "size": 11.0, "bold": false, "italic": false, "underline": null, "strike": null, "color": {"type": "theme", "rgb": "Values must be of type <class 'str'>", "indexed": null, "theme": 1, "tint": 0.0, "auto": null}, "vert_align": null}, "fill": {"fill_type": null, "fg_color": {"type": "rgb", "rgb": "00000000", "indexed": null, "theme": null, "tint": 0.0, "auto": null}, "bg_color": {"type": "rgb", "rgb": "00000000", "indexed": null, "theme": null, "tint": 0.0, "auto": null}}, "alignment": {"horizontal": null, "vertical": null, "text_rotation": 0, "wrap_text": null, "shrink_to_fit": null, "indent": 0.0}, "border": {"left": {"style": null, "color": null}, "right": {"style": null, "color": null}, "top": {"style": null, "color": null}, "bottom": {"style": null, "color": null}, "diagonal": {"style": null, "color": null}, "diagonal_down": false, "diagonal_up": false, "outline": true, "vertical": null, "horizontal": null}, "protection": {"locked": true, "hidden": false}}
A32: Intro | B32: C5 | C32: 5 | D32: 3 | E32: Input | H32: {"type": "null", "value": null} | I32: General | J32: FALSE | K32: FALSE | L32: 11 | M32: Values must be of type <class 'str'> | N32: 00000000 | R32: FALSE | W32: {"number_format": "General", "font": {"name": "Calibri", "size": 11.0, "bold": false, "italic": false, "underline": null, "strike": null, "color": {"type": "theme", "rgb": "Values must be of type <class 'str'>", "indexed": null, "theme": 1, "tint": 0.0, "auto": null}, "vert_align": null}, "fill": {"fill_type": null, "fg_color": {"type": "rgb", "rgb": "00000000", "indexed": null, "theme": null, "tint": 0.0, "auto": null}, "bg_color": {"type": "rgb", "rgb": "00000000", "indexed": null, "theme": null, "tint": 0.0, "auto": null}}, "alignment": {"horizontal": null, "vertical": null, "text_rotation": 0, "wrap_text": null, "shrink_to_fit": null, "indent": 0.0}, "border": {"left": {"style": null, "color": null}, "right": {"style": null, "color": null}, "top": {"style": null, "color": null}, "bottom": {"style": null, "color": null}, "diagonal": {"style": null, "color": null}, "diagonal_down": false, "diagonal_up": false, "outline": true, "vertical": null, "horizontal": null}, "protection": {"locked": true, "hidden": false}}
A33: Intro | B33: D5 | C33: 5 | D33: 4 | E33: Input | G33: Prepared By: | H33: {"type": "str", "value": "Prepared By: "} | I33: General | J33: TRUE | K33: FALSE | L33: 11 | M33: Values must be of type <class 'str'> | N33: 00000000 | O33: center | R33: TRUE | W33: {"number_format": "General", "font": {"name": "Calibri", "size": 11.0, "bold": true, "italic": false, "underline": null, "strike": null, "color": {"type": "theme", "rgb": "Values must be of type <class 'str'>", "indexed": null, "theme": 1, "tint": 0.249977111117893, "auto": null}, "vert_align": null}, "fill": {"fill_type": null, "fg_color": {"type": "rgb", "rgb": "00000000", "indexed": null, "theme": null, "tint": 0.0, "auto": null}, "bg_color": {"type": "rgb", "rgb": "00000000", "indexed": null, "theme": null, "tint": 0.0, "auto": null}}, "alignment": {"horizontal": "center", "vertical": null, "text_rotation": 0, "wrap_text": null, "shrink_to_fit": null, "indent": 0.0}, "border": {"left": {"style": null, "color": null}, "right": {"style": null, "color": null}, "top": {"style": null, "color": null}, "bottom": {"style": null, "color": null}, "diagonal": {"style": null, "color": null}, "diagonal_down": false, "diagonal_up": false, "outline": true, "vertical": null, "horizontal": null}, "protection": {"locked": true, "hidden": false}}
A34: Intro | B34: E5 | C34: 5 | D34: 5 | E34: Input | G34: Suvin Shetty , Yogesh Choudhari , Akshada Joshi | H34: {"type": "str", "value": "Suvin Shetty , Yogesh Choudhari , Akshada Joshi "} | I34: General | J34: FALSE | K34: FALSE | L34: 11 | M34: FF000000 | N34: 00000000 | R34: TRUE | W34: {"number_format": "General", "font": {"name": "Calibri", "size": 11.0, "bold": false, "italic": false, "underline": null, "strike": null, "color": {"type": "rgb", "rgb": "FF000000", "indexed": null, "theme": null, "tint": 0.0, "auto": null}, "vert_align": null}, "fill": {"fill_type": null, "fg_color": {"type": "rgb", "rgb": "00000000", "indexed": null, "theme": null, "tint": 0.0, "auto": null}, "bg_color": {"type": "rgb", "rgb": "00000000", "indexed": null, "theme": null, "tint": 0.0, "auto": null}}, "alignment": {"horizontal": null, "vertical": null, "text_rotation": 0, "wrap_text": null, "shrink_to_fit": null, "indent": 0.0}, "border": {"left": {"style": null, "color": null}, "right": {"style": null, "color": null}, "top": {"style": null, "color": null}, "bottom": {"style": null, "color": null}, "diagonal": {"style": null, "color": null}, "diagonal_down": false, "diagonal_up": false, "outline": true, "vertical": null, "horizontal": null}, "protection": {"locked": true, "hidden": false}}
A35: Intro | B35: F5 | C35: 5 | D35: 6 | E35: Input | H35: {"type": "null", "value": null} | I35: General | J35: FALSE | K35: FALSE | L35: 11 | M35: Values must be of type <class 'str'> | N35: 00000000 | R35: FALSE | W35: {"number_format": "General", "font": {"name": "Calibri", "size": 11.0, "bold": false, "italic": false, "underline": null, "strike": null, "color": {"type": "theme", "rgb": "Values must be of type <class 'str'>", "indexed": null, "theme": 1, "tint": 0.0, "auto": null}, "vert_align": null}, "fill": {"fill_type": null, "fg_color": {"type": "rgb", "rgb": "00000000", "indexed": null, "theme": null, "tint": 0.0, "auto": null}, "bg_color": {"type": "rgb", "rgb": "00000000", "indexed": null, "theme": null, "tint": 0.0, "auto": null}}, "alignment": {"horizontal": null, "vertical": null, "text_rotation": 0, "wrap_text": null, "shrink_to_fit": null, "indent": 0.0}, "border": {"left": {"style": null, "color": null}, "right": {"style": null, "color": null}, "top": {"style": null, "color": null}, "bottom": {"style": null, "color": null}, "diagonal": {"style": null, "color": null}, "diagonal_down": false, "diagonal_up": false, "outline": true, "vertical": null, "horizontal": null}, "protection": {"locked": true, "hidden": false}}
A36: Intro | B36: G5 | C36: 5 | D36: 7 | E36: Input | H36: {"type": "null", "value": null} | I36: General | J36: FALSE | K36: FALSE | L36: 11 | M36: Values must be of type <class 'str'> | N36: 00000000 | R36: FALSE | W36: {"number_format": "General", "font": {"name": "Calibri", "size": 11.0, "bold": false, "italic": false, "underline": null, "strike": null, "color": {"type": "theme", "rgb": "Values must be of type <class 'str'>", "indexed": null, "theme": 1, "tint": 0.0, "auto": null}, "vert_align": null}, "fill": {"fill_type": null, "fg_color": {"type": "rgb", "rgb": "00000000", "indexed": null, "theme": null, "tint": 0.0, "auto": null}, "bg_color": {"type": "rgb", "rgb": "00000000", "indexed": null, "theme": null, "tint": 0.0, "auto": null}}, "alignment": {"horizontal": null, "vertical": null, "text_rotation": 0, "wrap_text": null, "shrink_to_fit": null, "indent": 0.0}, "border": {"left": {"style": null, "color": null}, "right": {"style": null, "color": null}, "top": {"style": null, "color": null}, "bottom": {"style": null, "color": null}, "diagonal": {"style": null, "color": null}, "diagonal_down": false, "diagonal_up": false, "outline": true, "vertical": null, "horizontal": null}, "protection": {"locked": true, "hidden": false}}
A37: Intro | B37: A6 | C37: 6 | D37: 1 | E37: Input | H37: {"type": "null", "value": null} | I37: General | J37: FALSE | K37: FALSE | L37: 11 | M37: Values must be of type <class 'str'> | N37: 00000000 | R37: FALSE | W37: {"number_format": "General", "font": {"name": "Calibri", "size": 11.0, "bold": false, "italic": false, "underline": null, "strike": null, "color": {"type": "theme", "rgb": "Values must be of type <class 'str'>", "indexed": null, "theme": 1, "tint": 0.0, "auto": null}, "vert_align": null}, "fill": {"fill_type": null, "fg_color": {"type": "rgb", "rgb": "00000000", "indexed": null, "theme": null, "tint": 0.0, "auto": null}, "bg_color": {"type": "rgb", "rgb": "00000000", "indexed": null, "theme": null, "tint": 0.0, "auto": null}}, "alignment": {"horizontal": null, "vertical": null, "text_rotation": 0, "wrap_text": null, "shrink_to_fit": null, "indent": 0.0}, "border": {"left": {"style": null, "color": null}, "right": {"style": null, "color": null}, "top": {"style": null, "color": null}, "bottom": {"style": null, "color": null}, "diagonal": {"style": null, "color": null}, "diagonal_down": false, "diagonal_up": false, "outline": true, "vertical": null, "horizontal": null}, "protection": {"locked": true, "hidden": false}}
A38: Intro | B38: B6 | C38: 6 | D38: 2 | E38: Input | H38: {"type": "null", "value": null} | I38: General | J38: FALSE | K38: FALSE | L38: 11 | M38: Values must be of type <class 'str'> | N38: 00000000 | R38: FALSE | W38: {"number_format": "General", "font": {"name": "Calibri", "size": 11.0, "bold": false, "italic": false, "underline": null, "strike": null, "color": {"type": "theme", "rgb": "Values must be of type <class 'str'>", "indexed": null, "theme": 1, "tint": 0.0, "auto": null}, "vert_align": null}, "fill": {"fill_type": null, "fg_color": {"type": "rgb", "rgb": "00000000", "indexed": null, "theme": null, "tint": 0.0, "auto": null}, "bg_color": {"type": "rgb", "rgb": "00000000", "indexed": null, "theme": null, "tint": 0.0, "auto": null}}, "alignment": {"horizontal": null, "vertical": null, "text_rotation": 0, "wrap_text": null, "shrink_to_fit": null, "indent": 0.0}, "border": {"left": {"style": null, "color": null}, "right": {"style": null, "color": null}, "top": {"style": null, "color": null}, "bottom": {"style": null, "color": null}, "diagonal": {"style": null, "color": null}, "diagonal_down": false, "diagonal_up": false, "outline": true, "vertical": null, "horizontal": null}, "protection": {"locked": true, "hidden": false}}
A39: Intro | B39: C6 | C39: 6 | D39: 3 | E39: Input | H39: {"type": "null", "value": null} | I39: General | J39: FALSE | K39: FALSE | L39: 11 | M39: Values must be of type <class 'str'> | N39: 00000000 | R39: FALSE | W39: {"number_format": "General", "font": {"name": "Calibri", "size": 11.0, "bold": false, "italic": false, "underline": null, "strike": null, "color": {"type": "theme", "rgb": "Values must be of type <class 'str'>", "indexed": null, "theme": 1, "tint": 0.0, "auto": null}, "vert_align": null}, "fill": {"fill_type": null, "fg_color": {"type": "rgb", "rgb": "00000000", "indexed": null, "theme": null, "tint": 0.0, "auto": null}, "bg_color": {"type": "rgb", "rgb": "00000000", "indexed": null, "theme": null, "tint": 0.0, "auto": null}}, "alignment": {"horizontal": null, "vertical": null, "text_rotation": 0, "wrap_text": null, "shrink_to_fit": null, "indent": 0.0}, "border": {"left": {"style": null, "color": null}, "right": {"style": null, "color": null}, "top": {"style": null, "color": null}, "bottom": {"style": null, "color": null}, "diagonal": {"style": null, "color": null}, "diagonal_down": false, "diagonal_up": false, "outline": true, "vertical": null, "horizontal": null}, "protection": {"locked": true, "hidden": false}}
A40: Intro | B40: D6 | C40: 6 | D40: 4 | E40: Input | G40: Year | H40: {"type": "str", "value": "Year"} | I40: General | J40: TRUE | K40: FALSE | L40: 11 | M40: Values must be of type <class 'str'> | N40: 00000000 | O40: center | R40: TRUE | W40: {"number_format": "General", "font": {"name": "Calibri", "size": 11.0, "bold": true, "italic": false, "underline": null, "strike": null, "color": {"type": "theme", "rgb": "Values must be of type <class 'str'>", "indexed": null, "theme": 1, "tint": 0.0, "auto": null}, "vert_align": null}, "fill": {"fill_type": null, "fg_color": {"type": "rgb", "rgb": "00000000", "indexed": null, "theme": null, "tint": 0.0, "auto": null}, "bg_color": {"type": "rgb", "rgb": "00000000", "indexed": null, "theme": null, "tint": 0.0, "auto": null}}, "alignment": {"horizontal": "center", "vertical": null, "text_rotation": 0, "wrap_text": null, "shrink_to_fit": null, "indent": 0.0}, "border": {"left": {"style": null, "color": null}, "right": {"style": null, "color": null}, "top": {"style": null, "color": null}, "bottom": {"style": null, "color": null}, "diagonal": {"style": null, "color": null}, "diagonal_down": false, "diagonal_up": false, "outline": true, "vertical": null, "horizontal": null}, "protection": {"locked": true, "hidden": false}}
...

Sheet Revenue Model
A1: Sheet | B1: Cell | C1: Row | D1: Column | E1: Type | F1: Formula | G1: Value | H1: ValueJSON | I1: NumberFormat | J1: FontBold | K1: FontItalic | L1: FontSize | M1: FontColor | N1: FillColor | O1: HorizontalAlignment | P1: VerticalAlignment | Q1: WrapText | R1: IncludeFlag | S1: GroupID | T1: GroupDirection | U1: GroupSize | V1: PatternFormula | W1: StyleJSON
A2: Revenue Model | B2: A1 | C2: 1 | D2: 1 | E2: Input | G2: ACC Ltd | H2: {"type": "str", "value": "ACC Ltd"} | I2: General | J2: TRUE | K2: FALSE | L2: 11 | M2: Values must be of type <class 'str'> | N2: Values must be of type <class 'str'> | P2: center | R2: TRUE | W2: {"number_format": "General", "font": {"name": "Calibri", "size": 11.0, "bold": true, "italic": false, "underline": null, "strike": null, "color": {"type": "theme", "rgb": "Values must be of type <class 'str'>", "indexed": null, "theme": 0, "tint": 0.0, "auto": null}, "vert_align": null}, "fill": {"fill_type": "solid", "fg_color": {"type": "theme", "rgb": "Values must be of type <class 'str'>", "indexed": null, "theme": 4, "tint": 0.0, "auto": null}, "bg_color": {"type": "indexed", "rgb": "Values must be of type <class 'str'>", "indexed": 64, "theme": null, "tint": 0.0, "auto": null}}, "alignment": {"horizontal": null, "vertical": "center", "text_rotation": 0, "wrap_text": null, "shrink_to_fit": null, "indent": 0.0}, "border": {"left": {"style": "thin", "color": {"type": "auto", "rgb": "Values must be of type <class 'str'>", "indexed": null, "theme": null, "tint": 0.0, "auto": true}}, "right": {"style": "thin", "color": {"type": "auto", "rgb": "Values must be of type <class 'str'>", "indexed": null, "theme": null, "tint": 0.0, "auto": true}}, "top": {"style": "thin", "color": {"type": "auto", "rgb": "Values must be of type <class 'str'>", "indexed": null, "theme": null, "tint": 0.0, "auto": true}}, "bottom": {"style": "thin", "color": {"type": "auto", "rgb": "Values must be of type <class 'str'>", "indexed": null, "theme": null, "tint": 0.0, "auto": true}}, "diagonal": {"style": null, "color": null}, "diagonal_down": false, "diagonal_up": false, "outline": true, "vertical": null, "horizontal": null}, "protection": {"locked": true, "hidden": false}}
A3: Revenue Model | B3: B1 | C3: 1 | D3: 2 | E3: Input | G3: 2015 | H3: {"type": "int", "value": 2015} | I3: General | J3: TRUE | K3: FALSE | L3: 11 | M3: Values must be of type <class 'str'> | N3: Values must be of type <class 'str'> | O3: center | P3: center | R3: TRUE | W3: {"number_format": "General", "font": {"name": "Calibri", "size": 11.0, "bold": true, "italic": false, "underline": null, "strike": null, "color": {"type": "theme", "rgb": "Values must be of type <class 'str'>", "indexed": null, "theme": 0, "tint": 0.0, "auto": null}, "vert_align": null}, "fill": {"fill_type": "solid", "fg_color": {"type": "theme", "rgb": "Values must be of type <class 'str'>", "indexed": null, "theme": 4, "tint": 0.0, "auto": null}, "bg_color": {"type": "indexed", "rgb": "Values must be of type <class 'str'>", "indexed": 64, "theme": null, "tint": 0.0, "auto": null}}, "alignment": {"horizontal": "center", "vertical": "center", "text_rotation": 0, "wrap_text": null, "shrink_to_fit": null, "indent": 0.0}, "border": {"left": {"style": "thin", "color": {"type": "auto", "rgb": "Values must be of type <class 'str'>", "indexed": null, "theme": null, "tint": 0.0, "auto": true}}, "right": {"style": "thin", "color": {"type": "auto", "rgb": "Values must be of type <class 'str'>", "indexed": null, "theme": null, "tint": 0.0, "auto": true}}, "top": {"style": "thin", "color": {"type": "auto", "rgb": "Values must be of type <class 'str'>", "indexed": null, "theme": null, "tint": 0.0, "auto": true}}, "bottom": {"style": "thin", "color": {"type": "auto", "rgb": "Values must be of type <class 'str'>", "indexed": null, "theme": null, "tint": 0.0, "auto": true}}, "diagonal": {"style": null, "color": null}, "diagonal_down": false, "diagonal_up": false, "outline": true, "vertical": null, "horizontal": null}, "protection": {"locked": true, "hidden": false}}
A4: Revenue Model | B4: C1 | C4: 1 | D4: 3 | E4: Input | G4: 2016 | H4: {"type": "int", "value": 2016} | I4: General | J4: TRUE | K4: FALSE | L4: 11 | M4: Values must be of type <class 'str'> | N4: Values must be of type <class 'str'> | O4: center | P4: center | R4: TRUE | W4: {"number_format": "General", "font": {"name": "Calibri", "size": 11.0, "bold": true, "italic": false, "underline": null, "strike": null, "color": {"type": "theme", "rgb": "Values must be of type <class 'str'>", "indexed": null, "theme": 0, "tint": 0.0, "auto": null}, "vert_align": null}, "fill": {"fill_type": "solid", "fg_color": {"type": "theme", "rgb": "Values must be of type <class 'str'>", "indexed": null, "theme": 4, "tint": 0.0, "auto": null}, "bg_color": {"type": "indexed", "rgb": "Values must be of type <class 'str'>", "indexed": 64, "theme": null, "tint": 0.0, "auto": null}}, "alignment": {"horizontal": "center", "vertical": "center", "text_rotation": 0, "wrap_text": null, "shrink_to_fit": null, "indent": 0.0}, "border": {"left": {"style": "thin", "color": {"type": "auto", "rgb": "Values must be of type <class 'str'>", "indexed": null, "theme": null, "tint": 0.0, "auto": true}}, "right": {"style": "thin", "color": {"type": "auto", "rgb": "Values must be of type <class 'str'>", "indexed": null, "theme": null, "tint": 0.0, "auto": true}}, "top": {"style": "thin", "color": {"type": "auto", "rgb": "Values must be of type <class 'str'>", "indexed": null, "theme": null, "tint": 0.0, "auto": true}}, "bottom": {"style": "thin", "color": {"type": "auto", "rgb": "Values must be of type <class 'str'>", "indexed": null, "theme": null, "tint": 0.0, "auto": true}}, "diagonal": {"style": null, "color": null}, "diagonal_down": false, "diagonal_up": false, "outline": true, "vertical": null, "horizontal": null}, "protection": {"locked": true, "hidden": false}}
A5: Revenue Model | B5: D1 | C5: 1 | D5: 4 | E5: Input | G5: 2017 | H5: {"type": "int", "value": 2017} | I5: General | J5: TRUE | K5: FALSE | L5: 11 | M5: Values must be of type <class 'str'> | N5: Values must be of type <class 'str'> | O5: center | P5: center | R5: TRUE | W5: {"number_format": "General", "font": {"name": "Calibri", "size": 11.0, "bold": true, "italic": false, "underline": null, "strike": null, "color": {"type": "theme", "rgb": "Values must be of type <class 'str'>", "indexed": null, "theme": 0, "tint": 0.0, "auto": null}, "vert_align": null}, "fill": {"fill_type": "solid", "fg_color": {"type": "theme", "rgb": "Values must be of type <class 'str'>", "indexed": null, "theme": 4, "tint": 0.0, "auto": null}, "bg_color": {"type": "indexed", "rgb": "Values must be of type <class 'str'>", "indexed": 64, "theme": null, "tint": 0.0, "auto": null}}, "alignment": {"horizontal": "center", "vertical": "center", "text_rotation": 0, "wrap_text": null, "shrink_to_fit": null, "indent": 0.0}, "border": {"left": {"style": "thin", "color": {"type": "auto", "rgb": "Values must be of type <class 'str'>", "indexed": null, "theme": null, "tint": 0.0, "auto": true}}, "right": {"style": "thin", "color": {"type": "auto", "rgb": "Values must be of type <class 'str'>", "indexed": null, "theme": null, "tint": 0.0, "auto": true}}, "top": {"style": "thin", "color": {"type": "auto", "rgb": "Values must be of type <class 'str'>", "indexed": null, "theme": null, "tint": 0.0, "auto": true}}, "bottom": {"style": "thin", "color": {"type": "auto", "rgb": "Values must be of type <class 'str'>", "indexed": null, "theme": null, "tint": 0.0, "auto": true}}, "diagonal": {"style": null, "color": null}, "diagonal_down": false, "diagonal_up": false, "outline": true, "vertical": null, "horizontal": null}, "protection": {"locked": true, "hidden": false}}
A6: Revenue Model | B6: E1 | C6: 1 | D6: 5 | E6: Input | G6: 2018 F | H6: {"type": "str", "value": "2018 F"} | I6: General | J6: TRUE | K6: FALSE | L6: 11 | M6: Values must be of type <class 'str'> | N6: Values must be of type <class 'str'> | O6: center | P6: center | R6: TRUE | W6: {"number_format": "General", "font": {"name": "Calibri", "size": 11.0, "bold": true, "italic": false, "underline": null, "strike": null, "color": {"type": "theme", "rgb": "Values must be of type <class 'str'>", "indexed": null, "theme": 0, "tint": 0.0, "auto": null}, "vert_align": null}, "fill": {"fill_type": "solid", "fg_color": {"type": "theme", "rgb": "Values must be of type <class 'str'>", "indexed": null, "theme": 4, "tint": 0.0, "auto": null}, "bg_color": {"type": "indexed", "rgb": "Values must be of type <class 'str'>", "indexed": 64, "theme": null, "tint": 0.0, "auto": null}}, "alignment": {"horizontal": "center", "vertical": "center", "text_rotation": 0, "wrap_text": null, "shrink_to_fit": null, "indent": 0.0}, "border": {"left": {"style": "thin", "color": {"type": "auto", "rgb": "Values must be of type <class 'str'>", "indexed": null, "theme": null, "tint": 0.0, "auto": true}}, "right": {"style": "thin", "color": {"type": "auto", "rgb": "Values must be of type <class 'str'>", "indexed": null, "theme": null, "tint": 0.0, "auto": true}}, "top": {"style": "thin", "color": {"type": "auto", "rgb": "Values must be of type <class 'str'>", "indexed": null, "theme": null, "tint": 0.0, "auto": true}}, "bottom": {"style": "thin", "color": {"type": "auto", "rgb": "Values must be of type <class 'str'>", "indexed": null, "theme": null, "tint": 0.0, "auto": true}}, "diagonal": {"style": null, "color": null}, "diagonal_down": false, "diagonal_up": false, "outline": true, "vertical": null, "horizontal": null}, "protection": {"locked": true, "hidden": false}}
