Workbook

Sheet Intro
E2: Reference Model
E4: ACC Cement
D5: Prepared By: | E5: Suvin Shetty , Yogesh Choudhari , Akshada Joshi
D6: Year | E6: 2017
E13: http://proschoolonline.com
E14: Email ID : mumbai@proschoolonline.com
E16: Mumbai
E18: IMS Proschool Pvt Ltd,
E19: Maharashtra High School Complex,
E20: Principal N.M Kale Marg, Off Gokhale Rd,
E21: Dadar (W), Mumbai 400028
E22: Tel. No. : 022-65285393/94
E23: +91 9372895050

Sheet Revenue Model
A1: ACC Ltd | B1: 2015 | C1: 2016 | D1: 2017 | E1: 2018 F | F1: 2019 F | G1: 2020 F | H1: 2021 F | I1: 2022 F
A2: Cement Sales - Value in cr | B2: ='DuPoint Analysis'!E9-1443 | C2: ='DuPoint Analysis'!F9-1534 | D2: ='DuPoint Analysis'!G9-916 | E2: =E4*E11 | F2: =F4*F11 | G2: =G4*G11 | H2: =H4*H11 | I2: =I4*I11
A4: Cement Sales - Volume Million Tonnes | B4: 23.62 | C4: 22.99 | D4: 26.21 | E4: =E5*E6 | F4: =F5*F6 | G4: =G5*G6 | H4: =H5*H6 | I4: =I5*I6
A5: Cement Production Million Tonnes | B5: 23.84 | C5: 23.18 | D5: 26.56 | E5: =E9*E8 | F5: =F9*F8 | G5: =G9*G8 | H5: =H9*H8 | I5: =I9*I8
A6: Sales as % of prodn | B6: =B4/B5 | C6: =C4/C5 | D6: =D4/D5 | E6: =$D$6 | F6: =$D$6 | G6: =$D$6 | H6: =$D$6 | I6: =$D$6 | J6: Assuming this to be same over the period
A8: Capacity utilisation | B8: 0.77 | C8: 0.73 | D8: 0.79 | E8: =D8+2% | F8: =E8+2% | G8: =F8+2% | H8: =G8+2% | I8: =H8+2% | J8: Assuming the utilisation to reach 90% as per various media reports
A9: Capacity Million Tonnes | B9: =B5*100%/B8 | C9: =C5*100%/C8 | D9: =D5*100%/D8 | E9: =$D$9 | F9: =$D$9 | G9: =$D$9 | H9: =$D$9 | I9: =$D$9 | J9: Assuming the capacity to remain same
A11: Average price in crores per Million Tonnes | B11: =B2/B4 | C11: =C2/C4 | D11: =D2/D4 | E11: =D11*(1+E12) | F11: =E11*(1+F12) | G11: =F11*(1+G12) | H11: =G11*(1+H12) | I11: =H11*(1+I12)
C12: =C11/B11-1 | D12: =D11/C11-1 | E12: =DCF!$B$33 | F12: =DCF!$B$33 | G12: =DCF!$B$33 | H12: =DCF!$B$33 | I12: =DCF!$B$33 | J12: Assuming the price to increase by 5% every year
A15: Average price per tonne | B15: =B11*10000000/1000000 | C15: =C11*10000000/1000000 | D15: =D11*10000000/1000000 | E15: =E11*10000000/1000000 | F15: =F11*10000000/1000000 | G15: =G11*10000000/1000000 | H15: =H11*10000000/1000000 | I15: =I11*10000000/1000000
A16: Average price per kg | B16: =B15/1000 | C16: =C15/1000 | D16: =D15/1000 | E16: =E15/1000 | F16: =F15/1000 | G16: =G15/1000 | H16: =H15/1000 | I16: =I15/1000
A19: Raw Materials | B19: 1848.12 | C19: 1606.77 | D19: 1965.98 | E19: =E$2*E29 | F19: =F$2*F29 | G19: =G$2*G29 | H19: =H$2*H29 | I19: =I$2*I29
A20: Power | B20: 2396.67 | C20: 2159.91 | D20: 2716.94 | E20: =E$2*E30 | F20: =F$2*F30 | G20: =G$2*G30 | H20: =H$2*H30 | I20: =I$2*I30
A21: Transport | B21: 2704.21 | C21: 2636.11 | D21: 3433.75 | E21: =E$2*E31 | F21: =F$2*F31 | G21: =G$2*G31 | H21: =H$2*H31 | I21: =I$2*I31
A22: Salaries | B22: 772.16 | C22: 756.72 | D22: 821.36 | E22: =E$2*E32 | F22: =F$2*F32 | G22: =G$2*G32 | H22: =H$2*H32 | I22: =I$2*I32
A23: Other exps | B23: 2547.89 | C23: 2357.68 | D23: 2440.8 | E23: =E$2*E33 | F23: =F$2*F33 | G23: =G$2*G33 | H23: =H$2*H33 | I23: =I$2*I33
A24: Total expenses | B24: =SUM(B19:B23) | C24: =SUM(C19:C23) | D24: =SUM(D19:D23) | E24: =SUM(E19:E23) | F24: =SUM(F19:F23) | G24: =SUM(G19:G23) | H24: =SUM(H19:H23) | I24: =SUM(I19:I23)
A26: EBITDA | B26: =B2-B24 | C26: =C2-C24 | D26: =D2-D24 | E26: =E2-E24 | F26: =F2-F24 | G26: =G2-G24 | H26: =H2-H24 | I26: =I2-I24
A27: Margin | B27: =B26/B2 | C27: =C26/C2 | D27: =D26/D2 | E27: =E26/E2 | F27: =F26/F2 | G27: =G26/G2 | H27: =H26/H2 | I27: =I26/I2
A29: Raw Materials as % of sales | B29: =B19/B$2 | C29: =C19/C$2 | D29: =D19/D$2 | E29: =D29 | F29: =E29 | G29: =F29 | H29: =G29 | I29: =H29
A30: Power as % of sales | B30: =B20/B$2 | C30: =C20/C$2 | D30: =D20/D$2 | E30: =D30 | F30: =E30 | G30: =F30 | H30: =G30 | I30: =H30
A31: Transport as % of sales | B31: =B21/B$2 | C31: =C21/C$2 | D31: =D21/D$2 | E31: =D31+1.5% | F31: =E31+0.5% | G31: =F31+0.5% | H31: =G31+0.5% | I31: =H31+0.5%
A32: Salaries as % of sales | B32: =B22/B$2 | C32: =C22/C$2 | D32: =D22/D$2 | E32: =D32 | F32: =E32 | G32: =F32 | H32: =G32 | I32: =H32
A33: Other exps as % of sales | B33: =B23/B$2 | C33: =C23/C$2 | D33: =D23/D$2 | E33: =D33 | F33: =E33 | G33: =F33 | H33: =G33 | I33: =H33
A35: Average Diesel prices | B35: 48.72 | C35: 43.58 | D35: 50.83
A36: Growth | C36: =C35/B35-1 | D36: =D35/C35-1
A37: Crude | B37: 53.03 | C37: 45.13 | D37: 54.17 | E37: 72.82
C38: =C37/B37-1 | D38: =D37/C37-1 | E38: =E37/D37-1
A39: INR USD | B39: 66.768 | C39: 69.596 | D39: 67.809
C40: =C39/B39-1 | D40: =D39/C39-1
C41: =C21/B21-1 | D41: =D21/C21-1

Sheet FAS
B1: 2015 | C1: 2016 | D1: 2017 | E1: 2018 F | F1: 2019 F | G1: 2020 F | H1: 2021 F | I1: 2022 F
A2: Freehold Non Mining Land | B2: 92.69 | C2: 130.61 | D2: 130.61
A3: Freehold Mining Land | B3: 296.85 | C3: 303.09 | D3: 304.3
A4: Leasehold Land | B4: 40.05 | C4: 36.1 | D4: 38.46
A5: Buildings | B5: 928.56 | C5: 1515.39 | D5: 1472.4
A6: Plant and Equipment | B6: 3763.42 | C6: 5264.32 | D6: 4984.63
A7: Railway Sidings | B7: 109.03 | C7: 181.92 | D7: 212.14
A8: Furniture and Fixtures | B8: 19.67 | C8: 18.72 | D8: 16.51
A9: Vehicles | B9: 33.78 | C9: 41.91 | D9: 39.33
A10: Office equipment | B10: 30.95 | C10: 32.42 | D10: 26.08
A12: Computer Software | B12: 0.25 | C12: 3.63 | D12: 1.63
A13: Mining Rights | B13: 15.57 | C13: 24.09 | D13: 38.4
A17: Freehold Non Mining Land | B17: - | C17: - | D17: -
A18: Freehold Mining Land | B18: 0.25 | C18: 0.24 | D18: 0.27
A19: Leasehold Land | B19: 4.72 | C19: 0.29 | D19: 0.51
A20: Buildings | B20: 75.12 | C20: 65.24 | D20: 77.91
A21: Plant and Equipment | B21: 527.11 | C21: 498.55 | D21: 514.24
A22: Railway Sidings | B22: 13.23 | C22: 14.29 | D22: 20.06
A23: Furniture and Fixtures | B23: 5.96 | C23: 4.71 | D23: 4.52
A24: Vehicles | B24: 7.66 | C24: 8.78 | D24: 9.29
A25: Office equipment | B25: 23.32 | C25: 14 | D25: 13.56
A27: Computer Software | B27: 0.56 | C27: 0.36 | D27: 0.79
A28: Mining Rights | B28: 5.88 | C28: 2.89 | D28: 2.47

Sheet Financial Statements
B1: 2015 | C1: 2016 | D1: 2017 | E1: 2018 F | F1: 2019 F | G1: 2020 F | H1: 2021 F | I1: 2022 F | L1: 2015 | M1: 2016 | N1: 2017 | O1: 2018 F | P1: 2019 F | Q1: 2020 F | R1: 2021 F | S1: 2022 F
A2: Revenue | B2: ='Revenue Model'!B2 | C2: ='Revenue Model'!C2 | D2: ='Revenue Model'!D2 | E2: ='Revenue Model'!E2 | F2: ='Revenue Model'!F2 | G2: ='Revenue Model'!G2 | H2: ='Revenue Model'!H2 | I2: ='Revenue Model'!I2 | K2: Sources of Funds
A3: Expenses | K3: Equity | N3: 188 | O3: 187.99 | P3: 187.99 | Q3: 187.99 | R3: 187.99 | S3: 187.99
A4: ='Revenue Model'!A19 | B4: ='Revenue Model'!B19 | C4: ='Revenue Model'!C19 | D4: ='Revenue Model'!D19 | E4: ='Revenue Model'!E19 | F4: ='Revenue Model'!F19 | G4: ='Revenue Model'!G19 | H4: ='Revenue Model'!H19 | I4: ='Revenue Model'!I19 | K4: Reserves & Surplus | N4: 9167.86 | O4: =N4+E20 | P4: =O4+F20 | Q4: =P4+G20 | R4: =Q4+H20 | S4: =R4+I20
A5: ='Revenue Model'!A20 | B5: ='Revenue Model'!B20 | C5: ='Revenue Model'!C20 | D5: ='Revenue Model'!D20 | E5: ='Revenue Model'!E20 | F5: ='Revenue Model'!F20 | G5: ='Revenue Model'!G20 | H5: ='Revenue Model'!H20 | I5: ='Revenue Model'!I20 | K5: Debt | N5: 0 | O5: 0 | P5: 0 | Q5: 0 | R5: 0 | S5: 0
A6: ='Revenue Model'!A21 | B6: ='Revenue Model'!B21 | C6: ='Revenue Model'!C21 | D6: ='Revenue Model'!D21 | E6: ='Revenue Model'!E21 | F6: ='Revenue Model'!F21 | G6: ='Revenue Model'!G21 | H6: ='Revenue Model'!H21 | I6: ='Revenue Model'!I21 | N6: =SUM(N3:N5) | O6: =SUM(O3:O5) | P6: =SUM(P3:P5) | Q6: =SUM(Q3:Q5) | R6: =SUM(R3:R5) | S6: =SUM(S3:S5)
A7: ='Revenue Model'!A22 | B7: ='Revenue Model'!B22 | C7: ='Revenue Model'!C22 | D7: ='Revenue Model'!D22 | E7: ='Revenue Model'!E22 | F7: ='Revenue Model'!F22 | G7: ='Revenue Model'!G22 | H7: ='Revenue Model'!H22 | I7: ='Revenue Model'!I22 | K7: Uses of Funds
A8: ='Revenue Model'!A23 | B8: ='Revenue Model'!B23 | C8: ='Revenue Model'!C23 | D8: ='Revenue Model'!D23 | E8: ='Revenue Model'!E23 | F8: ='Revenue Model'!F23 | G8: ='Revenue Model'!G23 | H8: ='Revenue Model'!H23 | I8: ='Revenue Model'!I23 | K8: Fixed Assets | N8: ='Asset schedule'!D6+'Asset schedule'!D14+'Asset schedule'!D22+'Asset schedule'!D30+'Asset schedule'!D38+'Asset schedule'!D46+'Asset schedule'!D54+'Asset schedule'!D62+'Asset schedule'!D70+'Asset schedule'!D78+'Asset schedule'!D86 | O8: ='Asset schedule'!E6+'Asset schedule'!E14+'Asset schedule'!E22+'Asset schedule'!E30+'Asset schedule'!E38+'Asset schedule'!E46+'Asset schedule'!E54+'Asset schedule'!E62+'Asset schedule'!E70+'Asset schedule'!E78+'Asset schedule'!E86 | P8: ='Asset schedule'!F6+'Asset schedule'!F14+'Asset schedule'!F22+'Asset schedule'!F30+'Asset schedule'!F38+'Asset schedule'!F46+'Asset schedule'!F54+'Asset schedule'!F62+'Asset schedule'!F70+'Asset schedule'!F78+'Asset schedule'!F86 | Q8: ='Asset schedule'!G6+'Asset schedule'!G14+'Asset schedule'!G22+'Asset schedule'!G30+'Asset schedule'!G38+'Asset schedule'!G46+'Asset schedule'!G54+'Asset schedule'!G62+'Asset schedule'!G70+'Asset schedule'!G78+'Asset schedule'!G86 | R8: ='Asset schedule'!H6+'Asset schedule'!H14+'Asset schedule'!H22+'Asset schedule'!H30+'Asset schedule'!H38+'Asset schedule'!H46+'Asset schedule'!H54+'Asset schedule'!H62+'Asset schedule'!H70+'Asset schedule'!H78+'Asset schedule'!H86 | S8: ='Asset schedule'!I6+'Asset schedule'!I14+'Asset schedule'!I22+'Asset schedule'!I30+'Asset schedule'!I38+'Asset schedule'!I46+'Asset schedule'!I54+'Asset schedule'!I62+'Asset schedule'!I70+'Asset schedule'!I78+'Asset schedule'!I86
A9: ='Revenue Model'!A24 | B9: =SUM(B4:B8) | C9: =SUM(C4:C8) | D9: =SUM(D4:D8) | E9: =SUM(E4:E8) | F9: =SUM(F4:F8) | G9: =SUM(G4:G8) | H9: =SUM(H4:H8) | I9: =SUM(I4:I8) | K9: Cash | N9: =N34 | O9: =O34 | P9: =P34 | Q9: =Q34 | R9: =R34 | S9: =S34
A10: EBITDA | B10: =B2-B9 | C10: =C2-C9 | D10: =D2-D9 | E10: =E2-E9 | F10: =F2-F9 | G10: =G2-G9 | H10: =H2-H9 | I10: =I2-I9 | N10: =SUM(N8:N9) | O10: =SUM(O8:O9) | P10: =SUM(P8:P9) | Q10: =SUM(Q8:Q9) | R10: =SUM(R8:R9) | S10: =SUM(S8:S9)
A11: D&A | B11: 663 | C11: 609.18 | D11: ='Asset schedule'!D5+'Asset schedule'!D13+'Asset schedule'!D21+'Asset schedule'!D29+'Asset schedule'!D37+'Asset schedule'!D45+'Asset schedule'!D53+'Asset schedule'!D61+'Asset schedule'!D69+'Asset schedule'!D77+'Asset schedule'!D85 | E11: ='Asset schedule'!E5+'Asset schedule'!E13+'Asset schedule'!E21+'Asset schedule'!E29+'Asset schedule'!E37+'Asset schedule'!E45+'Asset schedule'!E53+'Asset schedule'!E61+'Asset schedule'!E69+'Asset schedule'!E77+'Asset schedule'!E85 | F11: ='Asset schedule'!F5+'Asset schedule'!F13+'Asset schedule'!F21+'Asset schedule'!F29+'Asset schedule'!F37+'Asset schedule'!F45+'Asset schedule'!F53+'Asset schedule'!F61+'Asset schedule'!F69+'Asset schedule'!F77+'Asset schedule'!F85 | G11: ='Asset schedule'!G5+'Asset schedule'!G13+'Asset schedule'!G21+'Asset schedule'!G29+'Asset schedule'!G37+'Asset schedule'!G45+'Asset schedule'!G53+'Asset schedule'!G61+'Asset schedule'!G69+'Asset schedule'!G77+'Asset schedule'!G85 | H11: ='Asset schedule'!H5+'Asset schedule'!H13+'Asset schedule'!H21+'Asset schedule'!H29+'Asset schedule'!H37+'Asset schedule'!H45+'Asset schedule'!H53+'Asset schedule'!H61+'Asset schedule'!H69+'Asset schedule'!H77+'Asset schedule'!H85 | I11: ='Asset schedule'!I5+'Asset schedule'!I13+'Asset schedule'!I21+'Asset schedule'!I29+'Asset schedule'!I37+'Asset schedule'!I45+'Asset schedule'!I53+'Asset schedule'!I61+'Asset schedule'!I69+'Asset schedule'!I77+'Asset schedule'!I85 | N11: =N6-N10 | O11: =O6-O10 | P11: =P6-P10 | Q11: =Q6-Q10 | R11: =R6-R10 | S11: =S6-S10
A12: EBIT | B12: =B10-B11 | C12: =C10-C11 | D12: =D10-D11 | E12: =E10-E11 | F12: =F10-F11 | G12: =G10-G11 | H12: =H10-H11 | I12: =I10-I11
A13: Interest | B13: 64.64 | C13: 78.67 | D13: 98.53 | E13: =D13 | F13: =E13 | G13: =F13 | H13: =G13 | I13: =H13 | L13: 2015 | M13: 2016 | N13: 2017 | O13: 2018 F | P13: 2019 F | Q13: 2020 F | R13: 2021 F | S13: 2022 F
A14: PBT | B14: =B12-B13 | C14: =C12-C13 | D14: =D12-D13 | E14: =E12-E13 | F14: =F12-F13 | G14: =G12-G13 | H14: =H12-H13 | I14: =I12-I13 | K14: Cash flow from Operation
A15: Taxes | B15: 189.98 | C15: 226.89 | D15: 385.55 | E15: =E14*E16 | F15: =F14*F16 | G15: =G14*G16 | H15: =H14*H16 | I15: =I14*I16 | K15: PAT | O15: =E17 | P15: =F17 | Q15: =G17 | R15: =H17 | S15: =I17
A16: Tax rate | B16: =B15/B14 | C16: =C15/C14 | D16: =D15/D14 | E16: =AVERAGE($C$16:$D$16) | F16: =AVERAGE($C$16:$D$16) | G16: =AVERAGE($C$16:$D$16) | H16: =AVERAGE($C$16:$D$16) | I16: =AVERAGE($C$16:$D$16) | K16: Depreciation | O16: =E11 | P16: =F11 | Q16: =G11 | R16: =H11 | S16: =I11
A17: PAT | B17: =B14-B15 | C17: =C14-C15 | D17: =D14-D15 | E17: =E14-E15 | F17: =F14-F15 | G17: =G14-G15 | H17: =H14-H15 | I17: =I14-I15 | K17: Interest | O17: =E13 | P17: =F13 | Q17: =G13 | R17: =H13 | S17: =I13
K18: Change in inventory | O18: ='Balance Sheet'!D18-'Balance Sheet'!E18 | P18: ='Balance Sheet'!E18-'Balance Sheet'!F18 | Q18: ='Balance Sheet'!F18-'Balance Sheet'!G18 | R18: ='Balance Sheet'!G18-'Balance Sheet'!H18 | S18: ='Balance Sheet'!H18-'Balance Sheet'!I18
A19: Dividend | B19: 561.67 | C19: 319.21 | D19: 319.24 | E19: =E17*E21 | F19: =F17*F21 | G19: =G17*G21 | H19: =H17*H21 | I19: =I17*I21 | K19: Change in receivables | O19: ='Balance Sheet'!D21-'Balance Sheet'!E21 | P19: ='Balance Sheet'!E21-'Balance Sheet'!F21 | Q19: ='Balance Sheet'!F21-'Balance Sheet'!G21 | R19: ='Balance Sheet'!G21-'Balance Sheet'!H21 | S19: ='Balance Sheet'!H21-'Balance Sheet'!I21
A20: PAT transferred to BS | B20: =B17-B19 | C20: =C17-C19 | D20: =D17-D19 | E20: =E17-E19 | F20: =F17-F19 | G20: =G17-G19 | H20: =H17-H19 | I20: =I17-I19 | K20: Change in payables | O20: ='Balance Sheet'!E44-'Balance Sheet'!D44 | P20: ='Balance Sheet'!F44-'Balance Sheet'!E44 | Q20: ='Balance Sheet'!G44-'Balance Sheet'!F44 | R20: ='Balance Sheet'!H44-'Balance Sheet'!G44 | S20: ='Balance Sheet'!I44-'Balance Sheet'!H44
A21: Dividend payout ratio | B21: =B19/B17 | C21: =C19/C17 | D21: =D19/D17 | E21: =D21 | F21: =E21 | G21: =F21 | H21: =G21 | I21: =H21 | O21: =SUM(O15:O20) | P21: =SUM(P15:P20) | Q21: =SUM(Q15:Q20) | R21: =SUM(R15:R20) | S21: =SUM(S15:S20)
K22: Cash flow from investing
K23: Fixed Asset | O23: =-'Asset schedule'!P2 | P23: =-'Asset schedule'!Q2 | Q23: =-'Asset schedule'!R2 | R23: =-'Asset schedule'!S2 | S23: =-'Asset schedule'!T2
O24: =SUM(O23) | P24: =SUM(P23) | Q24: =SUM(Q23) | R24: =SUM(R23) | S24: =SUM(S23)
K25: Cash flow from Financing
K26: Equity | O26: 0 | P26: 0 | Q26: 0 | R26: 0 | S26: 0
K27: Debt | O27: 0 | P27: 0 | Q27: 0 | R27: 0 | S27: 0
K28: Dividend | O28: =-E19 | P28: =-F19 | Q28: =-G19 | R28: =-H19 | S28: =-I19
K29: Interest | O29: =-E13 | P29: =-F13 | Q29: =-G13 | R29: =-H13 | S29: =-I13
O30: =SUM(O26:O29) | P30: =SUM(P26:P29) | Q30: =SUM(Q26:Q29) | R30: =SUM(R26:R29) | S30: =SUM(S26:S29)
K32: Opening bal | N32: 1810 | O32: =N34 | P32: =O34 | Q32: =P34 | R32: =Q34 | S32: =R34
K33: Cash in | N33: 749.11 | O33: =O21+O24+O30 | P33: =P21+P24+P30 | Q33: =Q21+Q24+Q30 | R33: =R21+R24+R30 | S33: =S21+S24+S30
K34: Closing bal | N34: =N32+N33 | O34: =O32+O33 | P34: =P32+P33 | Q34: =Q32+Q33 | R34: =R32+R33 | S34: =S32+S33

Sheet Asset schedule
A1: Freehold Non Mining Land | B1: 2015 | C1: 2016 | D1: 2017 | E1: 2018 F | F1: 2019 F | G1: 2020 F | H1: 2021 F | I1: 2022 F | O1: 2017 | P1: 2018 F | Q1: 2019 F | R1: 2020 F | S1: 2021 F | T1: 2022 F
A2: Opening balance | D2: 130.61 | E2: =D6 | F2: =E6 | G2: =F6 | H2: =G6 | I2: =H6 | L2: Capex | O2: =SUM(O5:O15) | P2: ='Financial Statements'!E2*'Asset schedule'!P3 | Q2: ='Financial Statements'!F2*'Asset schedule'!Q3 | R2: ='Financial Statements'!G2*'Asset schedule'!R3 | S2: ='Financial Statements'!H2*'Asset schedule'!S3 | T2: ='Financial Statements'!I2*'Asset schedule'!T3
A3: Add: purchase during the year | D3: 0 | E3: =INDEX($L$4:$T$15,MATCH($A1,$L$4:$L$15,0),MATCH(E1,$L$4:$T$4,0)) | F3: =INDEX($L$4:$T$15,MATCH($A1,$L$4:$L$15,0),MATCH(F1,$L$4:$T$4,0)) | G3: =INDEX($L$4:$T$15,MATCH($A1,$L$4:$L$15,0),MATCH(G1,$L$4:$T$4,0)) | H3: =INDEX($L$4:$T$15,MATCH($A1,$L$4:$L$15,0),MATCH(H1,$L$4:$T$4,0)) | I3: =INDEX($L$4:$T$15,MATCH($A1,$L$4:$L$15,0),MATCH(I1,$L$4:$T$4,0)) | L3: Capex as % of revenue | O3: =O2/'Financial Statements'!D2 | P3: =O3 | Q3: =P3 | R3: =Q3 | S3: =R3 | T3: =S3
A4: Less: Sale during the year | D4: 0 | E4: 0 | F4: 0 | G4: 0 | H4: 0 | I4: 0 | O4: 2017 | P4: 2018 F | Q4: 2019 F | R4: 2020 F | S4: 2021 F | T4: 2022 F
A5: Less: Dep | D5: 0 | E5: =E2*$B7 | F5: =F2*$B$7 | G5: =G2*$B$7 | H5: =H2*$B$7 | I5: =I2*$B$7 | L5: Freehold Non Mining Land | N5: =O5/$O$16 | O5: =D3 | P5: =P$2*$N5 | Q5: =Q$2*$N5 | R5: =R$2*$N5 | S5: =S$2*$N5 | T5: =T$2*$N5
A6: Closing balance | D6: 130.61 | E6: =E2+E3-E4-E5 | F6: =F2+F3-F4-F5 | G6: =G2+G3-G4-G5 | H6: =H2+H3-H4-H5 | I6: =I2+I3-I4-I5 | L6: Freehold Mining Land | N6: =O6/$O$16 | O6: =D11 | P6: =P$2*$N6 | Q6: =Q$2*$N6 | R6: =R$2*$N6 | S6: =S$2*$N6 | T6: =T$2*$N6
A7: Depreciation rate | B7: =D5/(D2+D3-D4) | L7: Leasehold Land | N7: =O7/$O$16 | O7: =D19 | P7: =P$2*$N7 | Q7: =Q$2*$N7 | R7: =R$2*$N7 | S7: =S$2*$N7 | T7: =T$2*$N7
L8: Buildings | N8: =O8/$O$16 | O8: =D27 | P8: =P$2*$N8 | Q8: =Q$2*$N8 | R8: =R$2*$N8 | S8: =S$2*$N8 | T8: =T$2*$N8
A9: Freehold Mining Land | B9: 2015 | C9: 2016 | D9: 2017 | E9: 2018 F | F9: 2019 F | G9: 2020 F | H9: 2021 F | I9: 2022 F | L9: Plants & Eq | N9: =O9/$O$16 | O9: =D35 | P9: =P$2*$N9 | Q9: =Q$2*$N9 | R9: =R$2*$N9 | S9: =S$2*$N9 | T9: =T$2*$N9
A10: Opening balance | D10: 303.09 | E10: =D14 | F10: =E14 | G10: =F14 | H10: =G14 | I10: =H14 | L10: Railway sidings | N10: =O10/$O$16 | O10: =D43 | P10: =P$2*$N10 | Q10: =Q$2*$N10 | R10: =R$2*$N10 | S10: =S$2*$N10 | T10: =T$2*$N10
A11: Add: purchase during the year | D11: 2.44 | E11: =INDEX($L$4:$T$15,MATCH($A9,$L$4:$L$15,0),MATCH(E9,$L$4:$T$4,0)) | F11: =INDEX($L$4:$T$15,MATCH($A9,$L$4:$L$15,0),MATCH(F9,$L$4:$T$4,0)) | G11: =INDEX($L$4:$T$15,MATCH($A9,$L$4:$L$15,0),MATCH(G9,$L$4:$T$4,0)) | H11: =INDEX($L$4:$T$15,MATCH($A9,$L$4:$L$15,0),MATCH(H9,$L$4:$T$4,0)) | I11: =INDEX($L$4:$T$15,MATCH($A9,$L$4:$L$15,0),MATCH(I9,$L$4:$T$4,0)) | L11: Office Eq | N11: =O11/$O$16 | O11: =D51 | P11: =P$2*$N11 | Q11: =Q$2*$N11 | R11: =R$2*$N11 | S11: =S$2*$N11 | T11: =T$2*$N11
A12: Less: Sale during the year | D12: 0.96 | E12: 0 | F12: 0 | G12: 0 | H12: 0 | I12: 0 | L12: Software | N12: =O12/$O$16 | O12: =D59 | P12: =P$2*$N12 | Q12: =Q$2*$N12 | R12: =R$2*$N12 | S12: =S$2*$N12 | T12: =T$2*$N12
A13: Less: Dep | D13: 0.27 | E13: =E10*$B15 | F13: =F10*$B15 | G13: =G10*$B15 | H13: =H10*$B15 | I13: =I10*$B15 | L13: Mining rights | N13: =O13/$O$16 | O13: =D67 | P13: =P$2*$N13 | Q13: =Q$2*$N13 | R13: =R$2*$N13 | S13: =S$2*$N13 | T13: =T$2*$N13
A14: Closing balance | D14: 304.3 | E14: =E10+E11-E12-E13 | F14: =F10+F11-F12-F13 | G14: =G10+G11-G12-G13 | H14: =H10+H11-H12-H13 | I14: =I10+I11-I12-I13 | L14: Vehicles | N14: =O14/$O$16 | O14: =D75 | P14: =P$2*$N14 | Q14: =Q$2*$N14 | R14: =R$2*$N14 | S14: =S$2*$N14 | T14: =T$2*$N14
A15: Depreciation rate | B15: =D13/(D10+D11-D12) | L15: Furniture | N15: =O15/$O$16 | O15: =D83 | P15: =P$2*$N15 | Q15: =Q$2*$N15 | R15: =R$2*$N15 | S15: =S$2*$N15 | T15: =T$2*$N15
O16: =SUM(O5:O15) | P16: =SUM(P5:P15) | Q16: =SUM(Q5:Q15) | R16: =SUM(R5:R15) | S16: =SUM(S5:S15) | T16: =SUM(T5:T15)
A17: Leasehold Land | B17: 2015 | C17: 2016 | D17: 2017 | E17: 2018 F | F17: 2019 F | G17: 2020 F | H17: 2021 F | I17: 2022 F
A18: Opening balance | D18: 36.1 | E18: =D22 | F18: =E22 | G18: =F22 | H18: =G22 | I18: =H22
A19: Add: purchase during the year | D19: 2.87 | E19: =INDEX($L$4:$T$15,MATCH($A17,$L$4:$L$15,0),MATCH(E17,$L$4:$T$4,0)) | F19: =INDEX($L$4:$T$15,MATCH($A17,$L$4:$L$15,0),MATCH(F17,$L$4:$T$4,0)) | G19: =INDEX($L$4:$T$15,MATCH($A17,$L$4:$L$15,0),MATCH(G17,$L$4:$T$4,0)) | H19: =INDEX($L$4:$T$15,MATCH($A17,$L$4:$L$15,0),MATCH(H17,$L$4:$T$4,0)) | I19: =INDEX($L$4:$T$15,MATCH($A17,$L$4:$L$15,0),MATCH(I17,$L$4:$T$4,0))
A20: Less: Sale during the year | D20: 0 | E20: 0 | F20: 0 | G20: 0 | H20: 0 | I20: 0
A21: Less: Dep | D21: 0.51 | E21: =E18*$B23 | F21: =F18*$B23 | G21: =G18*$B23 | H21: =H18*$B23 | I21: =I18*$B23
A22: Closing balance | D22: 38.46 | E22: =E18+E19-E20-E21 | F22: =F18+F19-F20-F21 | G22: =G18+G19-G20-G21 | H22: =H18+H19-H20-H21 | I22: =I18+I19-I20-I21
A23: Depreciation rate | B23: =D21/(D18+D19-D20)
A25: Buildings | B25: 2015 | C25: 2016 | D25: 2017 | E25: 2018 F | F25: 2019 F | G25: 2020 F | H25: 2021 F | I25: 2022 F
A26: Opening balance | D26: 1515.39 | E26: =D30 | F26: =E30 | G26: =F30 | H26: =G30 | I26: =H30
A27: Add: purchase during the year | D27: 35.77 | E27: =INDEX($L$4:$T$15,MATCH($A25,$L$4:$L$15,0),MATCH(E25,$L$4:$T$4,0)) | F27: =INDEX($L$4:$T$15,MATCH($A25,$L$4:$L$15,0),MATCH(F25,$L$4:$T$4,0)) | G27: =INDEX($L$4:$T$15,MATCH($A25,$L$4:$L$15,0),MATCH(G25,$L$4:$T$4,0)) | H27: =INDEX($L$4:$T$15,MATCH($A25,$L$4:$L$15,0),MATCH(H25,$L$4:$T$4,0)) | I27: =INDEX($L$4:$T$15,MATCH($A25,$L$4:$L$15,0),MATCH(I25,$L$4:$T$4,0))
A28: Less: Sale during the year | D28: 1.13 | E28: 0 | F28: 0 | G28: 0 | H28: 0 | I28: 0
A29: Less: Dep | D29: 77.91 | E29: =E26*$B31 | F29: =F26*$B31 | G29: =G26*$B31 | H29: =H26*$B31 | I29: =I26*$B31
A30: Closing balance | D30: 1472.4 | E30: =E26+E27-E28-E29 | F30: =F26+F27-F28-F29 | G30: =G26+G27-G28-G29 | H30: =H26+H27-H28-H29 | I30: =I26+I27-I28-I29
A31: Depreciation rate | B31: =D29/(D26+D27-D28)
A33: Plants & Eq | B33: 2015 | C33: 2016 | D33: 2017 | E33: 2018 F | F33: 2019 F | G33: 2020 F | H33: 2021 F | I33: 2022 F
A34: Opening balance | D34: 5264.32 | E34: =D38 | F34: =E38 | G34: =F38 | H34: =G38 | I34: =H38
A35: Add: purchase during the year | D35: 252.46 | E35: =INDEX($L$4:$T$15,MATCH($A33,$L$4:$L$15,0),MATCH(E33,$L$4:$T$4,0)) | F35: =INDEX($L$4:$T$15,MATCH($A33,$L$4:$L$15,0),MATCH(F33,$L$4:$T$4,0)) | G35: =INDEX($L$4:$T$15,MATCH($A33,$L$4:$L$15,0),MATCH(G33,$L$4:$T$4,0)) | H35: =INDEX($L$4:$T$15,MATCH($A33,$L$4:$L$15,0),MATCH(H33,$L$4:$T$4,0)) | I35: =INDEX($L$4:$T$15,MATCH($A33,$L$4:$L$15,0),MATCH(I33,$L$4:$T$4,0))
A36: Less: Sale during the year | D36: 22.6 | E36: 0 | F36: 0 | G36: 0 | H36: 0 | I36: 0
A37: Less: Dep | D37: 514.24 | E37: =E34*$B39 | F37: =F34*$B39 | G37: =G34*$B39 | H37: =H34*$B39 | I37: =I34*$B39
A38: Closing balance | D38: 4984.63 | E38: =E34+E35-E36-E37 | F38: =F34+F35-F36-F37 | G38: =G34+G35-G36-G37 | H38: =H34+H35-H36-H37 | I38: =I34+I35-I36-I37
A39: Depreciation rate | B39: =D37/(D34+D35-D36)
A41: Railway sidings | B41: 2015 | C41: 2016 | D41: 2017 | E41: 2018 F | F41: 2019 F | G41: 2020 F | H41: 2021 F | I41: 2022 F
A42: Opening balance | D42: 181.92 | E42: =D46 | F42: =E46 | G42: =F46 | H42: =G46 | I42: =H46
A43: Add: purchase during the year | D43: 50.34 | E43: =INDEX($L$4:$T$15,MATCH($A41,$L$4:$L$15,0),MATCH(E41,$L$4:$T$4,0)) | F43: =INDEX($L$4:$T$15,MATCH($A41,$L$4:$L$15,0),MATCH(F41,$L$4:$T$4,0)) | G43: =INDEX($L$4:$T$15,MATCH($A41,$L$4:$L$15,0),MATCH(G41,$L$4:$T$4,0)) | H43: =INDEX($L$4:$T$15,MATCH($A41,$L$4:$L$15,0),MATCH(H41,$L$4:$T$4,0)) | I43: =INDEX($L$4:$T$15,MATCH($A41,$L$4:$L$15,0),MATCH(I41,$L$4:$T$4,0))
...

Sheet Balance Sheet
B1: 2015 | C1: 2016 | D1: 2017 | E1: 2018 F | F1: 2019 F | G1: 2020 F | H1: 2021 F | I1: 2022 F
A2: A. ASSETS
A3: 1) Non-current assets
A4: a) Property, Plant and Equipment | C4: 7524.48 | D4: 7224.46 | E4: ='Asset schedule'!E6+'Asset schedule'!E14+'Asset schedule'!E22+'Asset schedule'!E30+'Asset schedule'!E38+'Asset schedule'!E46+'Asset schedule'!E54+'Asset schedule'!E62+'Asset schedule'!E70+'Asset schedule'!E78+'Asset schedule'!E86 | F4: ='Asset schedule'!F6+'Asset schedule'!F14+'Asset schedule'!F22+'Asset schedule'!F30+'Asset schedule'!F38+'Asset schedule'!F46+'Asset schedule'!F54+'Asset schedule'!F62+'Asset schedule'!F70+'Asset schedule'!F78+'Asset schedule'!F86 | G4: ='Asset schedule'!G6+'Asset schedule'!G14+'Asset schedule'!G22+'Asset schedule'!G30+'Asset schedule'!G38+'Asset schedule'!G46+'Asset schedule'!G54+'Asset schedule'!G62+'Asset schedule'!G70+'Asset schedule'!G78+'Asset schedule'!G86 | H4: ='Asset schedule'!H6+'Asset schedule'!H14+'Asset schedule'!H22+'Asset schedule'!H30+'Asset schedule'!H38+'Asset schedule'!H46+'Asset schedule'!H54+'Asset schedule'!H62+'Asset schedule'!H70+'Asset schedule'!H78+'Asset schedule'!H86 | I4: ='Asset schedule'!I6+'Asset schedule'!I14+'Asset schedule'!I22+'Asset schedule'!I30+'Asset schedule'!I38+'Asset schedule'!I46+'Asset schedule'!I54+'Asset schedule'!I62+'Asset schedule'!I70+'Asset schedule'!I78+'Asset schedule'!I86
A5: b) Capital work-in-progress | C5: 260.98 | D5: 269.25 | E5: =D5 | F5: =E5 | G5: =F5 | H5: =G5 | I5: =H5
A6: c) Goodwill on consolidation | C6: 15.57 | D6: 15.57 | E6: =D6 | F6: =E6 | G6: =F6 | H6: =G6 | I6: =H6
A7: d) Other Intangible assets | C7: 27.72 | D7: 40.03
A8: e) Intangible assets under development | C8: - | D8: - | E8: - | F8: - | G8: - | H8: - | I8: -
A9: f ) Investments in associates and joint ventures | C9: 85.13 | D9: 91.16 | E9: 91.16 | F9: 91.16 | G9: 91.16 | H9: 91.16 | I9: 91.16
A10: g) Financial Assets
A11: (i) Investments | C11: 32.05 | D11: 3.7 | E11: 3.7 | F11: 3.7 | G11: 3.7 | H11: 3.7 | I11: 3.7
A12: (ii) Loans | C12: 199.58 | D12: 222.59 | E12: 222.59 | F12: 222.59 | G12: 222.59 | H12: 222.59 | I12: 222.59
A13: (iii) Other financial assets | C13: 0.06 | D13: 0.06 | E13: 0.06 | F13: 0.06 | G13: 0.06 | H13: 0.06 | I13: 0.06
A14: h) Non-current Tax Assets (Net) | C14: 304.72 | D14: 296.95 | E14: 296.95 | F14: 296.95 | G14: 296.95 | H14: 296.95 | I14: 296.95
A15: i) Other non-current assets | C15: 838.93 | D15: 1027.05 | E15: 1027.05 | F15: 1027.05 | G15: 1027.05 | H15: 1027.05 | I15: 1027.05
A16: Total Non-current assets | C16: =SUM(C4:C15) | D16: =SUM(D4:D15) | E16: =SUM(E4:E15) | F16: =SUM(F4:F15) | G16: =SUM(G4:G15) | H16: =SUM(H4:H15) | I16: =SUM(I4:I15)
A17: Current assets
A18: a) Inventories | C18: 1224.63 | D18: 1404.78 | E18: =SUM('Financial Statements'!E4:E7)*'Balance Sheet'!E57 | F18: =SUM('Financial Statements'!F4:F7)*'Balance Sheet'!F57 | G18: =SUM('Financial Statements'!G4:G7)*'Balance Sheet'!G57 | H18: =SUM('Financial Statements'!H4:H7)*'Balance Sheet'!H57 | I18: =SUM('Financial Statements'!I4:I7)*'Balance Sheet'!I57
A19: b) Financial assets
A20: (i) Investments | C20: - | D20: - | E20: - | F20: - | G20: - | H20: - | I20: -
A21: (ii) Trade receivables | C21: 533.18 | D21: 665.97 | E21: ='Financial Statements'!E2*'Balance Sheet'!E58 | F21: ='Financial Statements'!F2*'Balance Sheet'!F58 | G21: ='Financial Statements'!G2*'Balance Sheet'!G58 | H21: ='Financial Statements'!H2*'Balance Sheet'!H58 | I21: ='Financial Statements'!I2*'Balance Sheet'!I58
A22: (iii) Cash and Cash Equivalents | C22: 1809.63 | D22: 2559.66 | E22: ='Financial Statements'!O34 | F22: ='Financial Statements'!P34 | G22: ='Financial Statements'!Q34 | H22: ='Financial Statements'!R34 | I22: ='Financial Statements'!S34
A23: (iv) Bank balances other than Cash Equivalents | C23: 167.53 | D23: 168.89 | E23: 168.89 | F23: 168.89 | G23: 168.89 | H23: 168.89 | I23: 168.89
A24: (v) Loans | C24: 29.42 | D24: 41.4 | E24: 41.4 | F24: 41.4 | G24: 41.4 | H24: 41.4 | I24: 41.4
A25: (vi) Other financial assets | C25: 5.05 | D25: 8.88 | E25: 8.88 | F25: 8.88 | G25: 8.88 | H25: 8.88 | I25: 8.88
A26: c) Other current assets | C26: 323.21 | D26: 792.26 | E26: 792.26 | F26: 792.26 | G26: 792.26 | H26: 792.26 | I26: 792.26
C27: =SUM(C18:C26) | D27: =SUM(D18:D26) | E27: =SUM(E18:E26) | F27: =SUM(F18:F26) | G27: =SUM(G18:G26) | H27: =SUM(H18:H26) | I27: =SUM(I18:I26)
A28: d) Non-current assets classified as held for sale | C28: 12.07 | D28: 13.08 | E28: 13.08 | F28: 13.08 | G28: 13.08 | H28: 13.08 | I28: 13.08
A29: Total Current assets | C29: =C27+C28 | D29: =D27+D28 | E29: =E27+E28 | F29: =F27+F28 | G29: =G27+G28 | H29: =H27+H28 | I29: =I27+I28
A30: TOTAL - ASSETS | C30: =C29+C16 | D30: =D29+D16 | E30: =E29+E16 | F30: =F29+F16 | G30: =G29+G16 | H30: =H29+H16 | I30: =I29+I16
A31: EQUITY AND LIABILITIES
A32: Equity
A33: Equity Share Capital | C33: 187.99 | D33: 187.99 | E33: =D33 | F33: =E33 | G33: =F33 | H33: =G33 | I33: =H33
A34: Other Equity | C34: 8625.44 | D34: 9167.86 | E34: =D34+'Financial Statements'!E20 | F34: =E34+'Financial Statements'!F20 | G34: =F34+'Financial Statements'!G20 | H34: =G34+'Financial Statements'!H20 | I34: =H34+'Financial Statements'!I20
A35: controlling interest | C35: 2.78 | D35: 2.88 | E35: 2.88 | F35: 2.88 | G35: 2.88 | H35: 2.88 | I35: 2.88
A36: Total Equity | C36: =C33+C34+C35 | D36: =D33+D34+D35 | E36: =E33+E34+E35 | F36: =F33+F34+F35 | G36: =G33+G34+G35 | H36: =H33+H34+H35 | I36: =I33+I34+I35
A37: Liabilities
A38: Non-current liabilities
A39: Provisions | C39: 141.36 | D39: 142.79 | E39: 142.79 | F39: 142.79 | G39: 142.79 | H39: 142.79 | I39: 142.79
A40: Deferred tax liabilities (Net) | C40: 456.31 | D40: 551.56 | E40: 551.56 | F40: 551.56 | G40: 551.56 | H40: 551.56 | I40: 551.56
...

Sheet DCF
B1: 2018 F | C1: 2019 F | D1: 2020 F | E1: 2021 F | F1: 2022 F
A2: EBIT | B2: ='Financial Statements'!E12 | C2: ='Financial Statements'!F12 | D2: ='Financial Statements'!G12 | E2: ='Financial Statements'!H12 | F2: ='Financial Statements'!I12
A3: Less: Tax on EBIT | B3: =B2*'Financial Statements'!E16 | C3: =C2*'Financial Statements'!F16 | D3: =D2*'Financial Statements'!G16 | E3: =E2*'Financial Statements'!H16 | F3: =F2*'Financial Statements'!I16
A4: Debt free earning | B4: =B2-B3 | C4: =C2-C3 | D4: =D2-D3 | E4: =E2-E3 | F4: =F2-F3
A6: Add: Dep & Ammo | B6: ='Financial Statements'!E11 | C6: ='Financial Statements'!F11 | D6: ='Financial Statements'!G11 | E6: ='Financial Statements'!H11 | F6: ='Financial Statements'!I11
A7: Less: Capex | B7: =-'Asset schedule'!P2 | C7: =-'Asset schedule'!Q2 | D7: =-'Asset schedule'!R2 | E7: =-'Asset schedule'!S2 | F7: =-'Asset schedule'!T2
A8: Add/Less: Change in WC | B8: ='Financial Statements'!O18+'Financial Statements'!O19+'Financial Statements'!O20 | C8: ='Financial Statements'!P18+'Financial Statements'!P19+'Financial Statements'!P20 | D8: ='Financial Statements'!Q18+'Financial Statements'!Q19+'Financial Statements'!Q20 | E8: ='Financial Statements'!R18+'Financial Statements'!R19+'Financial Statements'!R20 | F8: ='Financial Statements'!S18+'Financial Statements'!S19+'Financial Statements'!S20
A9: FCFF | B9: =SUM(B4:B8) | C9: =SUM(C4:C8) | D9: =SUM(D4:D8) | E9: =SUM(E4:E8) | F9: =SUM(F4:F8)
A10: Terminal value | F10: =F9*(1+B27)/(H21-B27) | G10: FCC*(1+g)/(WACC-g)
A11: FCFF after TV | B11: =SUM(B9:B10) | C11: =SUM(C9:C10) | D11: =SUM(D9:D10) | E11: =SUM(E9:E10) | F11: =SUM(F9:F10)
A14: Cost of Debt | B14: 0
A15: Cost of Equity | B15: =B17+B18*(B19-B17) | C15: CAPM= | D15: Rf+B(Rm-Rf)
A17: Rf | B17: 0.078 | C17: 10 year govt bond
A18: B | B18: 1.0129 | C18: B= | D18: Covar(Rm,Re)/Var Rm
A19: Rm | B19: 0.14 | C19: CAGR of market return of 8 years
A21: Debt | B21: 0 | D21: Wd | E21: =B21/(B21+B22) | G21: WACC | H21: =B15*E22+B14*E21*(1-'Financial Statements'!D16)
A22: Equity | B22: =B24*B25 | D22: We | E22: =B22/(B21+B22)
G23: EV | H23: =NPV(H21,B11:F11) | I23: Eq+debt-cash
A24: CMP | B24: 1460.45 | G24: Cash | H24: ='Balance Sheet'!D22
A25: Shares outstanding | B25: 18.7 | G25: Eq | H25: =H23+H24
A27: G (India's long term GDP growth) | B27: 0.03 | G27: Intrinsic value | H27: =H25/B25
B32: 2018 F | I32: =H27 | J32: 0.12 | K32: 0.13 | L32: 0.14 | M32: 0.15 | N32: 0.16 | O32: 0.17
A33: Revenue growth | B33: 0.05 | I33: 0.05 | K33: 708.99617 | L33: 657.07317 | M33: 613.79094 | N33: 577.1562 | O33: 545.7451
I34: =I33+1% | J34: 793.08567 | K34: 727.25272 | L34: 673.38422 | M34: 628.48949 | N34: 590.49803 | O34: 557.93088
I35: =I34+1% | J35: 814.3696 | K35: 746.06778 | L35: 690.18978 | M35: 643.62965 | N35: 604.23711 | O35: 570.47623
I36: =I35+1% | J36: 836.30594 | K36: 765.45445 | L36: 707.50138 | M36: 659.22167 | N36: 618.38262 | O36: 583.38943
I37: =I36+1% | J37: 858.90993 | K37: 785.42604 | L37: 725.33074 | M37: 675.27598 | N37: 632.94389 | O37: 596.6789
I38: =I37+1% | J38: 882.19705 | K38: 805.99604 | L38: 743.68978 | M38: 691.80316 | N38: 647.93041 | O38: 610.35316

Sheet Relative
B1: ACC | F1: Ultratech | J1: Ambuja | N1: Dalmia Bharat
B2: 2017 | C2: 2018 | D2: 2019 | E2: 2020 | F2: 2017 | G2: 2018 | H2: 2019 | I2: 2020 | J2: 2017 | K2: 2018 | L2: 2019 | M2: 2020 | N2: 2017 | O2: 2018 | P2: 2019 | Q2: 2020
A3: EPS | B3: ='Financial Statements'!D17/Relative!$B$8 | C3: ='Financial Statements'!E17/Relative!$B$8 | D3: ='Financial Statements'!F17/Relative!$B$8 | E3: ='Financial Statements'!G17/Relative!$B$8 | F3: 80.9 | G3: 104 | H3: 137 | I3: 171 | J3: 6.29 | K3: 6.84 | L3: 8.15 | M3: 9.1 | N3: 59.9 | O3: 32.1 | P3: 57.3 | Q3: 58.9
A4: Sales | B4: ='Financial Statements'!D2 | C4: ='Financial Statements'!E2 | D4: ='Financial Statements'!F2 | E4: ='Financial Statements'!G2 | F4: 32304.6 | G4: 36502.9 | H4: 42844.3 | I4: 47414.1 | J4: 10446.9 | K4: 11454.7 | L4: 12499.4 | M4: 13725.6 | N4: 8608.8 | O4: 9801 | P4: 11238 | Q4: 12870.2
A5: EBITDA | B5: ='Financial Statements'!D10 | C5: ='Financial Statements'!E10 | D5: ='Financial Statements'!F10 | E5: ='Financial Statements'!G10 | F5: 6145.2 | G5: 6794.3 | H5: 8412.2 | I5: 9651.1 | J5: 1940.1 | K5: 2104.5 | L5: 2439.1 | M5: 2746.9 | N5: 2026.4 | O5: 2122.8 | P5: 2520.7 | Q5: 2851.9
A6: Debt | B6: 0 | F6: =15863+2763 | J6: 24 | N6: 5967.8
A7: Cash | B7: ='Balance Sheet'!D22 | F7: 218 | J7: 6231 | N7: 353
A8: No of shares | B8: 18.7 | F8: 27.4 | J8: 198.5 | N8: 8.8
A9: CMP | B9: 1758 | F9: 3950 | J9: 233 | N9: 2874
P11: Mean | Q11: Median
A12: EV | B12: =(B9*B8)+B6-B7 | F12: =(F9*F8)+F6-F7 | J12: =(J9*J8)+J6-J7 | N12: =(N9*N8)+N6-N7 | P12: =AVERAGE(B12,F12,J12,N12) | Q12: =MEDIAN(B12,F12,J12,N12)
A13: Growth | B13: =(E4/B4)^(1/3)-1 | F13: =(I4/F4)^(1/3)-1 | J13: =(M4/J4)^(1/3)-1 | N13: =(Q4/N4)^(1/3)-1 | P13: =AVERAGE(B13,F13,J13,N13) | Q13: =MEDIAN(B13,F13,J13,N13)
A14: Trailing PE | B14: =B9/B3 | F14: =F9/F3 | J14: =J9/J3 | N14: =N9/N3 | P14: =AVERAGE(B14,F14,J14,N14) | Q14: =MEDIAN(B14,F14,J14,N14)
A15: Trailing PS | B15: =B9/(B4/B8) | F15: =F9/(F4/F8) | J15: =J9/(J4/J8) | N15: =N9/(N4/N8) | P15: =AVERAGE(B15,F15,J15,N15) | Q15: =MEDIAN(B15,F15,J15,N15)
A16: Trailing PEG | B16: =B14/B13 | F16: =F14/F13 | J16: =J14/J13 | N16: =N14/N13 | P16: =AVERAGE(B16,F16,J16,N16) | Q16: =MEDIAN(B16,F16,J16,N16)
A18: Leading PE | B18: =B9/C3 | F18: =F9/G3 | J18: =J9/K3 | N18: =N9/O3 | P18: =AVERAGE(B18,F18,J18,N18) | Q18: =MEDIAN(B18,F18,J18,N18)
A19: Leading PS | B19: =B9/(C4/B8) | F19: =F9/(G4/F8) | J19: =J9/(K4/J8) | N19: =N9/(O4/N8) | P19: =AVERAGE(B19,F19,J19,N19) | Q19: =MEDIAN(B19,F19,J19,N19)
A20: Leading PEG | B20: =B18/B13 | F20: =F18/F13 | J20: =J18/J13 | N20: =N18/N13 | P20: =AVERAGE(B20,F20,J20,N20) | Q20: =MEDIAN(B20,F20,J20,N20)
A22: Trailing EV/EBITDA | B22: =B12/B5 | F22: =F12/F5 | J22: =J12/J5 | N22: =N12/N5 | P22: =AVERAGE(B22,F22,J22,N22) | Q22: =MEDIAN(B22,F22,J22,N22)
A23: Trailing EV/Sales | B23: =B12/B4 | F23: =F12/F4 | J23: =J12/J4 | N23: =N12/N4 | P23: =AVERAGE(B23,F23,J23,N23) | Q23: =MEDIAN(B23,F23,J23,N23)
A24: Leading EV/EBITDA | B24: =B12/C5 | F24: =F12/G5 | J24: =J12/K5 | N24: =N12/O5 | P24: =AVERAGE(B24,F24,J24,N24) | Q24: =MEDIAN(B24,F24,J24,N24)
A25: Leading EV/Sales | B25: =B12/C4 | F25: =F12/G4 | J25: =J12/K4 | N25: =N12/O4 | P25: =AVERAGE(B25,F25,J25,N25) | Q25: =MEDIAN(B25,F25,J25,N25)
B28: min | C28: max | D28: Weights
A29: Trailing PE | B29: =$Q$14*$B$3*0.8 | C29: =$Q$14*$B$3*1.2 | D29: 0.05
A30: Trailing PS | B30: =$Q$15*($B$4/$B$8)*0.8 | C30: =$Q$15*($B$4/$B$8)*1.2 | D30: 0.05 | I30: Final Valuation
A31: Trailing PEG | B31: =$Q$16*$B$3*$B$13*0.8 | C31: =$Q$16*$B$3*$B$13*1.2 | D31: 0.05 | I31: Min | J31: Max
A32: Leading PE | B32: =$Q$18*$C$3*0.8 | C32: =$Q$18*$C$3*1.2 | D32: 0.05 | I32: =SUMPRODUCT(B29:B40,D29:D40) | J32: =SUMPRODUCT(C29:C40,D29:D40)
A33: Leading PS | B33: =$Q$19*($C$4/$B$8)*0.8 | C33: =$Q$19*($C$4/$B$8)*1.2 | D33: 0.05
A34: Leading PEG | B34: =$Q$20*$C$3*$B$13*0.8 | C34: =$Q$20*$C$3*$B$13*1.2 | D34: 0.05
A35: Trailing EV/EBITDA | B35: =D45*0.8 | C35: =D45*1.2 | D35: 0.05
A36: Trailing EV/Sales | B36: =D46*0.8 | C36: =D46*1.2 | D36: 0.05
A37: Leading EV/EBITDA | B37: =D47*0.8 | C37: =D47*1.2 | D37: 0.05
A38: Leading EV/Sales | B38: =D48*0.8 | C38: =D48*1.2 | D38: 0.05
A40: DCF | B40: =DCF!H27*0.8 | C40: =DCF!H27*1.2 | D40: 0.5
B44: EV | C44: Equity value | D44: Stock price
A45: Trailing EV/EBITDA | B45: =Q22*B5 | C45: =B45-$B$6+$B$7 | D45: =C45/$B$8
A46: Trailing EV/Sales | B46: =Q23*B4 | C46: =B46-$B$6+$B$7 | D46: =C46/$B$8
A47: Leading EV/EBITDA | B47: =Q24*C5 | C47: =B47-$B$6+$B$7 | D47: =C47/$B$8
A48: Leading EV/Sales | B48: =Q25*C4 | C48: =B48-$B$6+$B$7 | D48: =C48/$B$8

Sheet DuPoint Analysis
A1: ROE=NPM*ATR*FL | E1: NPM-Net Profit Margin
E2: ATR-Asset Turnover Ratio
E3: FL-Financial Leverage
A5: Cement Industry | B5: Net Profit | E5: Sales | H5: Assets (non current) | L5: Equity
B6: 2015 | C6: 2016 | D6: 2017 | E6: 2015 | F6: 2016 | G6: 2017 | H6: 2015 | I6: 2016 | J6: 2017 | K6: 2015 | L6: 2016 | M6: 2017
A7: Ultratech | B7: 2370 | C7: 2628 | D7: 2231 | E7: 29535.1 | F7: 30669.45 | G7: 28894.04 | H7: 22532.71 | I7: 24110.15 | J7: 28894.04 | K7: 18858 | L7: 21632 | M7: 23941
A8: Ambuja | B8: 808 | C8: 932 | D8: 1250 | E8: 9368 | F8: 9117 | G8: 10240 | H8: 19567 | I8: 19139 | J8: 19124 | K8: 26249.33 | L8: 19356.87 | M8: 19973.21
A9: ACC | B9: 587.32 | C9: 658.42 | D9: 924.51 | E9: 13360 | F9: 12646.2 | G9: 14329.58 | H9: 9396.32 | I9: 9289.22 | J9: 9190.82 | K9: 8421.14 | L9: 8816.21 | M9: 9358.73
A12: Cement Industry | B12: Net profit Margin | E12: Sales/Assets | H12: Assets/Equity | K12: ROE
B13: 2015 | C13: 2016 | D13: 2017 | E13: 2015 | F13: 2016 | G13: 2017 | H13: 2015 | I13: 2016 | J13: 2017 | K13: 2015 | L13: 2016 | M13: 2017
A14: Ultratech | B14: =B7/E7 | C14: =C7/F7 | D14: =D7/G7 | E14: =E7/H7 | F14: =F7/I7 | G14: =G7/J7 | H14: =H7/K7 | I14: =I7/L7 | J14: =J7/M7 | K14: =B14*E14*H14 | L14: =C14*F14*I14 | M14: =D14*G14*J14
A15: Ambuja | B15: =B8/E8 | C15: =C8/F8 | D15: =D8/G8 | E15: =E8/H8 | F15: =F8/I8 | G15: =G8/J8 | H15: =H8/K8 | I15: =I8/L8 | J15: =J8/M8 | K15: =B15*E15*H15 | L15: =C15*F15*I15 | M15: =D15*G15*J15
A16: ACC | B16: =B9/E9 | C16: =C9/F9 | D16: =D9/G9 | E16: =E9/H9 | F16: =F9/I9 | G16: =G9/J9 | H16: =H9/K9 | I16: =I9/L9 | J16: =J9/M9 | K16: =B16*E16*H16 | L16: =C16*F16*I16 | M16: =D16*G16*J16
